Workbook
Name camusat_ocm: '[1]CAMUSAT OCM DB'!$A$1:$G$431
Name ihs_ocm: '[1]IHS OCM DB'!$A$1:$U$1703

Sheet Cells Huawei 23032026 8h
A1: Alarm Source | B1: Site code | C1: Ticket ID | D1: Powerco | E1: Topologie | F1: Alarm Name | G1: Summary | H1: Alarm Location Info | I1: First Occurred On | J1: Duration | K1: Possible Cause | L1: Raw Alarm Severity | M1: Domain | N1: Alarm Identifier | O1: Clearance Status | P1: Alarm Occurrences | Q1: Action Plan | R1: Action de resolution | S1: Date de resolution | T1: Comment | U1: Porteur | V1: RCA | W1: Causes | X1: SBC | Y1: Ville | Z1: Region | AA1: Temps | AB1: Nombre | AC1: STATUT Cells | AD1: Ages Cells | AE1: Jour d'extraction | AF1: SEMAINE | AG1: Occurrence
A2: SUO_222_H_Buea-Bakwere-Town-MTN | B2: =LEFT(A2,7) -> SUO_222 | C2: INC-20260323-00001351 | D2: #N/A | E2: #N/A | F2: BBU CPRI Interface Error | G2: Cabinet No.=0, Subrack No.=0, Slot No.=4, Port No.=0, Sub Port No.=0, Board Type=UBBP, Specific Problem=Receive No Signal Equipment Alarm | H2: Cabinet No.=0, Subrack No.=0, Slot No.=4, Port No.=0, Sub Port No.=0, Board Type=UBBP, Specific Problem=Receive No Signal | I2: 2026-03-22 23:52:30 | J2: =NOW()-I2 -> 4.8633595 | K2: INVALID_MESSAGE_RECEIVED | L2: Major | M2: RAN | N2: 160657224 1 OCM_NEW_U2020_RAN BBU CPRI Interface Error | O2: Uncleared | P2: 1 | T2: 19/03/2026: Relance faite a MTN ce jour || Escalade faite a silvain 18/03/2026 : Power instability || Mail sent to MTN | U2: MTN | V2: #N/A | W2: #N/A | Y2: =VLOOKUP(B2, [2]SBC!A$1:P$65536, 11, 0) -> Buéa | Z2: =LEFT(B2,3) -> SUO | AA2: =IF(J2 < 1/24, "T<1H", IF(AND(J2<2/24, J2>1/24), "1H<T<2H", IF(AND(J2<4/24, J2>2/24), "2H<T<4H", IF(AND(J2<8/24, J2>4/24), "4H<T<8H", IF(AND(J2<16/24, J2>8/24), "8H<T<16H",IF(AND(J2<24/24, J2>16/24),"16H<T<24H", IF(AND(J2<48/24, J2>24/24),"24H<T<48H",IF(AND(J2<72/24, J2>24/24),"48H<T<72H", "T>72H")))))))) -> T>72H | AB2: 1 | AC2: DOWN | AD2: Old case | AE2: 23/03/2026 8h | AF2: W13
A3: ADM_048_H_Ngd-Q-Haoussa_L | B3: =LEFT(A3,7) -> ADM_048 | C3: INC-20260322-00014363 | D3: #N/A | E3: #N/A | F3: Cell Unavailable | G3: eNodeB Function Name=ADM_048_H_Ngd-Q-Haoussa_L, Local Cell ID=63, Cell FDD TDD indication=TDD, NB-IoT Cell Flag=FALSE, Cell Name=ADM_048_H_Ngd-Q-Haoussa_L26_33, eNodeB ID=21048, Cell ID=63, Specific Problem=RF Power OFF Processing Error Alarm | H3: eNodeB Function Name=ADM_048_H_Ngd-Q-Haoussa_L, Local Cell ID=63, Cell FDD TDD indication=TDD, NB-IoT Cell Flag=FALSE, Cell Name=ADM_048_H_Ngd-Q-Haoussa_L26_33, eNodeB ID=21048, Cell ID=63, Specific Problem=RF Power OFF | I3: 2026-03-22 20:44:19 | J3: =NOW()-I3 -> 4.9940424 | K3: Unknown Probable Cause | L3: Major | M3: RAN-4G | N3: 160548282 1 OCM_NEW_U2020_RAN Cell Unavailable | O3: Uncleared | P3: 1 | T3: 23/03/2026 : Probable disjonction des breakers || Check Connectivite entre BBU & RRU/Check FO ou SFP | U3: TELEINFRA | V3: disjonction au niveau de DC | W3: disjonction des breakers | Y3: =VLOOKUP(B3, [2]SBC!A$1:P$65536, 11, 0) -> Ngaoundere | Z3: =LEFT(B3,3) -> ADM | AA3: =IF(J3 < 1/24, "T<1H", IF(AND(J3<2/24, J3>1/24), "1H<T<2H", IF(AND(J3<4/24, J3>2/24), "2H<T<4H", IF(AND(J3<8/24, J3>4/24), "4H<T<8H", IF(AND(J3<16/24, J3>8/24), "8H<T<16H",IF(AND(J3<24/24, J3>16/24),"16H<T<24H", IF(AND(J3<48/24, J3>24/24),"24H<T<48H",IF(AND(J3<72/24, J3>24/24),"48H<T<72H", "T>72H")))))))) -> T>72H | AB3: 1 | AC3: Up | AD3: New case | AE3: 23/03/2026 8h | AF3: W13
A4: ADM_048_H_Ngd-Q-Haoussa_L | B4: =LEFT(A4,7) -> ADM_048 | C4: INC-20260322-00014363 | D4: #N/A | E4: #N/A | F4: Cell Unavailable | G4: eNodeB Function Name=ADM_048_H_Ngd-Q-Haoussa_L, Local Cell ID=62, Cell FDD TDD indication=TDD, NB-IoT Cell Flag=FALSE, Cell Name=ADM_048_H_Ngd-Q-Haoussa_L26_23, eNodeB ID=21048, Cell ID=62, Specific Problem=RF Power OFF Processing Error Alarm | H4: eNodeB Function Name=ADM_048_H_Ngd-Q-Haoussa_L, Local Cell ID=62, Cell FDD TDD indication=TDD, NB-IoT Cell Flag=FALSE, Cell Name=ADM_048_H_Ngd-Q-Haoussa_L26_23, eNodeB ID=21048, Cell ID=62, Specific Problem=RF Power OFF | I4: 2026-03-22 20:44:19 | J4: =NOW()-I4 -> 4.9940424 | K4: Unknown Probable Cause | L4: Major | M4: RAN-4G | N4: 160548281 1 OCM_NEW_U2020_RAN Cell Unavailable | O4: Uncleared | P4: 1 | T4: 23/03/2026 : Probable disjonction des breakers || Check Connectivite entre BBU & RRU/Check FO ou SFP | U4: TELEINFRA | V4: disjonction au niveau de DC | W4: disjonction des breakers | Y4: =VLOOKUP(B4, [2]SBC!A$1:P$65536, 11, 0) -> Ngaoundere | Z4: =LEFT(B4,3) -> ADM | AA4: =IF(J4 < 1/24, "T<1H", IF(AND(J4<2/24, J4>1/24), "1H<T<2H", IF(AND(J4<4/24, J4>2/24), "2H<T<4H", IF(AND(J4<8/24, J4>4/24), "4H<T<8H", IF(AND(J4<16/24, J4>8/24), "8H<T<16H",IF(AND(J4<24/24, J4>16/24),"16H<T<24H", IF(AND(J4<48/24, J4>24/24),"24H<T<48H",IF(AND(J4<72/24, J4>24/24),"48H<T<72H", "T>72H")))))))) -> T>72H | AB4: 1 | AC4: Up | AD4: New case | AE4: 23/03/2026 8h | AF4: W13
A5: ADM_048_H_Ngd-Q-Haoussa_L | B5: =LEFT(A5,7) -> ADM_048 | C5: INC-20260322-00014363 | D5: #N/A | E5: #N/A | F5: Cell Unavailable | G5: eNodeB Function Name=ADM_048_H_Ngd-Q-Haoussa_L, Local Cell ID=61, Cell FDD TDD indication=TDD, NB-IoT Cell Flag=FALSE, Cell Name=ADM_048_H_Ngd-Q-Haoussa_L26_13, eNodeB ID=21048, Cell ID=61, Specific Problem=RF Power OFF Processing Error Alarm | H5: eNodeB Function Name=ADM_048_H_Ngd-Q-Haoussa_L, Local Cell ID=61, Cell FDD TDD indication=TDD, NB-IoT Cell Flag=FALSE, Cell Name=ADM_048_H_Ngd-Q-Haoussa_L26_13, eNodeB ID=21048, Cell ID=61, Specific Problem=RF Power OFF | I5: 2026-03-22 20:44:19 | J5: =NOW()-I5 -> 4.9940424 | K5: Unknown Probable Cause | L5: Major | M5: RAN-4G | N5: 160548280 1 OCM_NEW_U2020_RAN Cell Unavailable | O5: Uncleared | P5: 1 | T5: 23/03/2026 : Probable disjonction des breakers || Check Connectivite entre BBU & RRU/Check FO ou SFP | U5: TELEINFRA | V5: disjonction au niveau de DC | W5: disjonction des breakers | Y5: =VLOOKUP(B5, [2]SBC!A$1:P$65536, 11, 0) -> Ngaoundere | Z5: =LEFT(B5,3) -> ADM | AA5: =IF(J5 < 1/24, "T<1H", IF(AND(J5<2/24, J5>1/24), "1H<T<2H", IF(AND(J5<4/24, J5>2/24), "2H<T<4H", IF(AND(J5<8/24, J5>4/24), "4H<T<8H", IF(AND(J5<16/24, J5>8/24), "8H<T<16H",IF(AND(J5<24/24, J5>16/24),"16H<T<24H", IF(AND(J5<48/24, J5>24/24),"24H<T<48H",IF(AND(J5<72/24, J5>24/24),"48H<T<72H", "T>72H")))))))) -> T>72H | AB5: 1 | AC5: Up | AD5: New case | AE5: 23/03/2026 8h | AF5: W13
A6: ADM_048_H_Ngd-Q-Haoussa_L | B6: =LEFT(A6,7) -> ADM_048 | C6: INC-20260322-00014363 | D6: #N/A | E6: #N/A | F6: Cell Unavailable | G6: eNodeB Function Name=ADM_048_H_Ngd-Q-Haoussa_L, Local Cell ID=52, Cell FDD TDD indication=TDD, NB-IoT Cell Flag=FALSE, Cell Name=ADM_048_H_Ngd-Q-Haoussa_L26_22, eNodeB ID=21048, Cell ID=52, Specific Problem=RF Power OFF Processing Error Alarm | H6: eNodeB Function Name=ADM_048_H_Ngd-Q-Haoussa_L, Local Cell ID=52, Cell FDD TDD indication=TDD, NB-IoT Cell Flag=FALSE, Cell Name=ADM_048_H_Ngd-Q-Haoussa_L26_22, eNodeB ID=21048, Cell ID=52, Specific Problem=RF Power OFF | I6: 2026-03-22 20:44:19 | J6: =NOW()-I6 -> 4.9940424 | K6: Unknown Probable Cause | L6: Major | M6: RAN-4G | N6: 160548278 1 OCM_NEW_U2020_RAN Cell Unavailable | O6: Uncleared | P6: 1 | T6: 23/03/2026 : Probable disjonction des breakers || Check Connectivite entre BBU & RRU/Check FO ou SFP | U6: TELEINFRA | V6: disjonction au niveau de DC | W6: disjonction des breakers | Y6: =VLOOKUP(B6, [2]SBC!A$1:P$65536, 11, 0) -> Ngaoundere | Z6: =LEFT(B6,3) -> ADM | AA6: =IF(J6 < 1/24, "T<1H", IF(AND(J6<2/24, J6>1/24), "1H<T<2H", IF(AND(J6<4/24, J6>2/24), "2H<T<4H", IF(AND(J6<8/24, J6>4/24), "4H<T<8H", IF(AND(J6<16/24, J6>8/24), "8H<T<16H",IF(AND(J6<24/24, J6>16/24),"16H<T<24H", IF(AND(J6<48/24, J6>24/24),"24H<T<48H",IF(AND(J6<72/24, J6>24/24),"48H<T<72H", "T>72H")))))))) -> T>72H | AB6: 1 | AC6: Up | AD6: New case | AE6: 23/03/2026 8h | AF6: W13
A7: ADM_048_H_Ngd-Q-Haoussa_L | B7: =LEFT(A7,7) -> ADM_048 | C7: INC-20260322-00014363 | D7: #N/A | E7: #N/A | F7: Cell Unavailable | G7: eNodeB Function Name=ADM_048_H_Ngd-Q-Haoussa_L, Local Cell ID=12, Cell FDD TDD indication=FDD, NB-IoT Cell Flag=FALSE, Cell Name=ADM_048_H_Ngd-Q-Haoussa_L8_2, eNodeB ID=21048, Cell ID=12, Specific Problem=RF Power OFF Processing Error Alarm | H7: eNodeB Function Name=ADM_048_H_Ngd-Q-Haoussa_L, Local Cell ID=12, Cell FDD TDD indication=FDD, NB-IoT Cell Flag=FALSE, Cell Name=ADM_048_H_Ngd-Q-Haoussa_L8_2, eNodeB ID=21048, Cell ID=12, Specific Problem=RF Power OFF | I7: 2026-03-22 20:44:19 | J7: =NOW()-I7 -> 4.9940424 | K7: Unknown Probable Cause | L7: Major | M7: RAN-4G | N7: 160548277 1 OCM_NEW_U2020_RAN Cell Unavailable | O7: Uncleared | P7: 1 | T7: 23/03/2026 : Probable disjonction des breakers || Check Connectivite entre BBU & RRU/Check FO ou SFP | U7: TELEINFRA | V7: disjonction au niveau de DC | W7: disjonction des breakers | Y7: =VLOOKUP(B7, [2]SBC!A$1:P$65536, 11, 0) -> Ngaoundere | Z7: =LEFT(B7,3) -> ADM | AA7: =IF(J7 < 1/24, "T<1H", IF(AND(J7<2/24, J7>1/24), "1H<T<2H", IF(AND(J7<4/24, J7>2/24), "2H<T<4H", IF(AND(J7<8/24, J7>4/24), "4H<T<8H", IF(AND(J7<16/24, J7>8/24), "8H<T<16H",IF(AND(J7<24/24, J7>16/24),"16H<T<24H", IF(AND(J7<48/24, J7>24/24),"24H<T<48H",IF(AND(J7<72/24, J7>24/24),"48H<T<72H", "T>72H")))))))) -> T>72H | AB7: 1 | AC7: Up | AD7: New case | AE7: 23/03/2026 8h | AF7: W13
A8: ADM_048_H_Ngd-Q-Haoussa_L | B8: =LEFT(A8,7) -> ADM_048 | C8: INC-20260322-00014363 | D8: #N/A | E8: #N/A | F8: Cell Unavailable | G8: eNodeB Function Name=ADM_048_H_Ngd-Q-Haoussa_L, Local Cell ID=53, Cell FDD TDD indication=TDD, NB-IoT Cell Flag=FALSE, Cell Name=ADM_048_H_Ngd-Q-Haoussa_L26_32, eNodeB ID=21048, Cell ID=53, Specific Problem=RF Power OFF Processing Error Alarm | H8: eNodeB Function Name=ADM_048_H_Ngd-Q-Haoussa_L, Local Cell ID=53, Cell FDD TDD indication=TDD, NB-IoT Cell Flag=FALSE, Cell Name=ADM_048_H_Ngd-Q-Haoussa_L26_32, eNodeB ID=21048, Cell ID=53, Specific Problem=RF Power OFF | I8: 2026-03-22 20:44:19 | J8: =NOW()-I8 -> 4.9940424 | K8: Unknown Probable Cause | L8: Major | M8: RAN-4G | N8: 160548279 1 OCM_NEW_U2020_RAN Cell Unavailable | O8: Uncleared | P8: 1 | T8: 23/03/2026 : Probable disjonction des breakers || Check Connectivite entre BBU & RRU/Check FO ou SFP | U8: TELEINFRA | V8: disjonction au niveau de DC | W8: disjonction des breakers | Y8: =VLOOKUP(B8, [2]SBC!A$1:P$65536, 11, 0) -> Ngaoundere | Z8: =LEFT(B8,3) -> ADM | AA8: =IF(J8 < 1/24, "T<1H", IF(AND(J8<2/24, J8>1/24), "1H<T<2H", IF(AND(J8<4/24, J8>2/24), "2H<T<4H", IF(AND(J8<8/24, J8>4/24), "4H<T<8H", IF(AND(J8<16/24, J8>8/24), "8H<T<16H",IF(AND(J8<24/24, J8>16/24),"16H<T<24H", IF(AND(J8<48/24, J8>24/24),"24H<T<48H",IF(AND(J8<72/24, J8>24/24),"48H<T<72H", "T>72H")))))))) -> T>72H | AB8: 1 | AC8: Up | AD8: New case | AE8: 23/03/2026 8h | AF8: W13
A9: ADM_048_H_Ngd-Q-Haoussa_L | B9: =LEFT(A9,7) -> ADM_048 | C9: INC-20260322-00014363 | D9: #N/A | E9: #N/A | F9: Cell Unavailable | G9: eNodeB Function Name=ADM_048_H_Ngd-Q-Haoussa_L, Local Cell ID=1, Cell FDD TDD indication=FDD, NB-IoT Cell Flag=FALSE, Cell Name=ADM_048_H_Ngd-Q-Haoussa_L7_1, eNodeB ID=21048, Cell ID=1, Specific Problem=RF Power OFF Processing Error Alarm | H9: eNodeB Function Name=ADM_048_H_Ngd-Q-Haoussa_L, Local Cell ID=1, Cell FDD TDD indication=FDD, NB-IoT Cell Flag=FALSE, Cell Name=ADM_048_H_Ngd-Q-Haoussa_L7_1, eNodeB ID=21048, Cell ID=1, Specific Problem=RF Power OFF | I9: 2026-03-22 20:44:19 | J9: =NOW()-I9 -> 4.9940424 | K9: Unknown Probable Cause | L9: Major | M9: RAN-4G | N9: 160548283 1 OCM_NEW_U2020_RAN Cell Unavailable | O9: Uncleared | P9: 1 | T9: 23/03/2026 : Probable disjonction des breakers || Check Connectivite entre BBU & RRU/Check FO ou SFP | U9: TELEINFRA | V9: disjonction au niveau de DC | W9: disjonction des breakers | Y9: =VLOOKUP(B9, [2]SBC!A$1:P$65536, 11, 0) -> Ngaoundere | Z9: =LEFT(B9,3) -> ADM | AA9: =IF(J9 < 1/24, "T<1H", IF(AND(J9<2/24, J9>1/24), "1H<T<2H", IF(AND(J9<4/24, J9>2/24), "2H<T<4H", IF(AND(J9<8/24, J9>4/24), "4H<T<8H", IF(AND(J9<16/24, J9>8/24), "8H<T<16H",IF(AND(J9<24/24, J9>16/24),"16H<T<24H", IF(AND(J9<48/24, J9>24/24),"24H<T<48H",IF(AND(J9<72/24, J9>24/24),"48H<T<72H", "T>72H")))))))) -> T>72H | AB9: 1 | AC9: Up | AD9: New case | AE9: 23/03/2026 8h | AF9: W13
A10: ADM_048_H_Ngd-Q-Haoussa_L | B10: =LEFT(A10,7) -> ADM_048 | C10: INC-20260322-00014363 | D10: #N/A | E10: #N/A | F10: Cell Unavailable | G10: eNodeB Function Name=ADM_048_H_Ngd-Q-Haoussa_L, Local Cell ID=11, Cell FDD TDD indication=FDD, NB-IoT Cell Flag=FALSE, Cell Name=ADM_048_H_Ngd-Q-Haoussa_L8_1, eNodeB ID=21048, Cell ID=11, Specific Problem=RF Power OFF Processing Error Alarm | H10: eNodeB Function Name=ADM_048_H_Ngd-Q-Haoussa_L, Local Cell ID=11, Cell FDD TDD indication=FDD, NB-IoT Cell Flag=FALSE, Cell Name=ADM_048_H_Ngd-Q-Haoussa_L8_1, eNodeB ID=21048, Cell ID=11, Specific Problem=RF Power OFF | I10: 2026-03-22 20:44:19 | J10: =NOW()-I10 -> 4.9940424 | K10: Unknown Probable Cause | L10: Major | M10: RAN-4G | N10: 160548276 1 OCM_NEW_U2020_RAN Cell Unavailable | O10: Uncleared | P10: 1 | T10: 23/03/2026 : Probable disjonction des breakers || Check Connectivite entre BBU & RRU/Check FO ou SFP | U10: TELEINFRA | V10: disjonction au niveau de DC | W10: disjonction des breakers | Y10: =VLOOKUP(B10, [2]SBC!A$1:P$65536, 11, 0) -> Ngaoundere | Z10: =LEFT(B10,3) -> ADM | AA10: =IF(J10 < 1/24, "T<1H", IF(AND(J10<2/24, J10>1/24), "1H<T<2H", IF(AND(J10<4/24, J10>2/24), "2H<T<4H", IF(AND(J10<8/24, J10>4/24), "4H<T<8H", IF(AND(J10<16/24, J10>8/24), "8H<T<16H",IF(AND(J10<24/24, J10>16/24),"16H<T<24H", IF(AND(J10<48/24, J10>24/24),"24H<T<48H",IF(AND(J10<72/24, J10>24/24),"48H<T<72H", "T>72H")))))))) -> T>72H | AB10: 1 | AC10: Up | AD10: New case | AE10: 23/03/2026 8h | AF10: W13
A11: ADM_048_H_Ngd-Q-Haoussa_L | B11: =LEFT(A11,7) -> ADM_048 | C11: INC-20260322-00014363 | D11: #N/A | E11: #N/A | F11: Cell Unavailable | G11: eNodeB Function Name=ADM_048_H_Ngd-Q-Haoussa_L, Local Cell ID=2, Cell FDD TDD indication=FDD, NB-IoT Cell Flag=FALSE, Cell Name=ADM_048_H_Ngd-Q-Haoussa_L7_2, eNodeB ID=21048, Cell ID=2, Specific Problem=RF Power OFF Processing Error Alarm | H11: eNodeB Function Name=ADM_048_H_Ngd-Q-Haoussa_L, Local Cell ID=2, Cell FDD TDD indication=FDD, NB-IoT Cell Flag=FALSE, Cell Name=ADM_048_H_Ngd-Q-Haoussa_L7_2, eNodeB ID=21048, Cell ID=2, Specific Problem=RF Power OFF | I11: 2026-03-22 20:44:19 | J11: =NOW()-I11 -> 4.9940424 | K11: Unknown Probable Cause | L11: Major | M11: RAN-4G | N11: 160548274 1 OCM_NEW_U2020_RAN Cell Unavailable | O11: Uncleared | P11: 1 | T11: 23/03/2026 : Probable disjonction des breakers || Check Connectivite entre BBU & RRU/Check FO ou SFP | U11: TELEINFRA | V11: disjonction au niveau de DC | W11: disjonction des breakers | Y11: =VLOOKUP(B11, [2]SBC!A$1:P$65536, 11, 0) -> Ngaoundere | Z11: =LEFT(B11,3) -> ADM | AA11: =IF(J11 < 1/24, "T<1H", IF(AND(J11<2/24, J11>1/24), "1H<T<2H", IF(AND(J11<4/24, J11>2/24), "2H<T<4H", IF(AND(J11<8/24, J11>4/24), "4H<T<8H", IF(AND(J11<16/24, J11>8/24), "8H<T<16H",IF(AND(J11<24/24, J11>16/24),"16H<T<24H", IF(AND(J11<48/24, J11>24/24),"24H<T<48H",IF(AND(J11<72/24, J11>24/24),"48H<T<72H", "T>72H")))))))) -> T>72H | AB11: 1 | AC11: Up | AD11: New case | AE11: 23/03/2026 8h | AF11: W13
A12: ADM_048_H_Ngd-Q-Haoussa_L | B12: =LEFT(A12,7) -> ADM_048 | C12: INC-20260322-00014363 | D12: #N/A | E12: #N/A | F12: Cell Unavailable | G12: eNodeB Function Name=ADM_048_H_Ngd-Q-Haoussa_L, Local Cell ID=3, Cell FDD TDD indication=FDD, NB-IoT Cell Flag=FALSE, Cell Name=ADM_048_H_Ngd-Q-Haoussa_L7_3, eNodeB ID=21048, Cell ID=3, Specific Problem=RF Power OFF Processing Error Alarm | H12: eNodeB Function Name=ADM_048_H_Ngd-Q-Haoussa_L, Local Cell ID=3, Cell FDD TDD indication=FDD, NB-IoT Cell Flag=FALSE, Cell Name=ADM_048_H_Ngd-Q-Haoussa_L7_3, eNodeB ID=21048, Cell ID=3, Specific Problem=RF Power OFF | I12: 2026-03-22 20:44:19 | J12: =NOW()-I12 -> 4.9940424 | K12: Unknown Probable Cause | L12: Major | M12: RAN-4G | N12: 160548275 1 OCM_NEW_U2020_RAN Cell Unavailable | O12: Uncleared | P12: 1 | T12: 23/03/2026 : Probable disjonction des breakers || Check Connectivite entre BBU & RRU/Check FO ou SFP | U12: TELEINFRA | V12: disjonction au niveau de DC | W12: disjonction des breakers | Y12: =VLOOKUP(B12, [2]SBC!A$1:P$65536, 11, 0) -> Ngaoundere | Z12: =LEFT(B12,3) -> ADM | AA12: =IF(J12 < 1/24, "T<1H", IF(AND(J12<2/24, J12>1/24), "1H<T<2H", IF(AND(J12<4/24, J12>2/24), "2H<T<4H", IF(AND(J12<8/24, J12>4/24), "4H<T<8H", IF(AND(J12<16/24, J12>8/24), "8H<T<16H",IF(AND(J12<24/24, J12>16/24),"16H<T<24H", IF(AND(J12<48/24, J12>24/24),"24H<T<48H",IF(AND(J12<72/24, J12>24/24),"48H<T<72H", "T>72H")))))))) -> T>72H | AB12: 1 | AC12: Up | AD12: New case | AE12: 23/03/2026 8h | AF12: W13
A13: ADM_048_H_Ngd-Q-Haoussa_L | B13: =LEFT(A13,7) -> ADM_048 | C13: INC-20260322-00014363 | D13: #N/A | E13: #N/A | F13: Cell Unavailable | G13: eNodeB Function Name=ADM_048_H_Ngd-Q-Haoussa_L, Local Cell ID=42, Cell FDD TDD indication=TDD, NB-IoT Cell Flag=FALSE, Cell Name=ADM_048_H_Ngd-Q-Haoussa_L26_21, eNodeB ID=21048, Cell ID=42, Specific Problem=RF Power OFF Processing Error Alarm | H13: eNodeB Function Name=ADM_048_H_Ngd-Q-Haoussa_L, Local Cell ID=42, Cell FDD TDD indication=TDD, NB-IoT Cell Flag=FALSE, Cell Name=ADM_048_H_Ngd-Q-Haoussa_L26_21, eNodeB ID=21048, Cell ID=42, Specific Problem=RF Power OFF | I13: 2026-03-22 20:44:22 | J13: =NOW()-I13 -> 4.9940076 | K13: Unknown Probable Cause | L13: Major | M13: RAN-4G | N13: 160548291 1 OCM_NEW_U2020_RAN Cell Unavailable | O13: Uncleared | P13: 1 | T13: 23/03/2026 : Probable disjonction des breakers || Check Connectivite entre BBU & RRU/Check FO ou SFP | U13: TELEINFRA | V13: disjonction au niveau de DC | W13: disjonction des breakers | Y13: =VLOOKUP(B13, [2]SBC!A$1:P$65536, 11, 0) -> Ngaoundere | Z13: =LEFT(B13,3) -> ADM | AA13: =IF(J13 < 1/24, "T<1H", IF(AND(J13<2/24, J13>1/24), "1H<T<2H", IF(AND(J13<4/24, J13>2/24), "2H<T<4H", IF(AND(J13<8/24, J13>4/24), "4H<T<8H", IF(AND(J13<16/24, J13>8/24), "8H<T<16H",IF(AND(J13<24/24, J13>16/24),"16H<T<24H", IF(AND(J13<48/24, J13>24/24),"24H<T<48H",IF(AND(J13<72/24, J13>24/24),"48H<T<72H", "T>72H")))))))) -> T>72H | AB13: 1 | AC13: Up | AD13: New case | AE13: 23/03/2026 8h | AF13: W13
A14: ADM_048_H_Ngd-Q-Haoussa_L | B14: =LEFT(A14,7) -> ADM_048 | C14: INC-20260322-00014363 | D14: #N/A | E14: #N/A | F14: Cell Unavailable | G14: eNodeB Function Name=ADM_048_H_Ngd-Q-Haoussa_L, Local Cell ID=43, Cell FDD TDD indication=TDD, NB-IoT Cell Flag=FALSE, Cell Name=ADM_048_H_Ngd-Q-Haoussa_L26_31, eNodeB ID=21048, Cell ID=43, Specific Problem=RF Power OFF Processing Error Alarm | H14: eNodeB Function Name=ADM_048_H_Ngd-Q-Haoussa_L, Local Cell ID=43, Cell FDD TDD indication=TDD, NB-IoT Cell Flag=FALSE, Cell Name=ADM_048_H_Ngd-Q-Haoussa_L26_31, eNodeB ID=21048, Cell ID=43, Specific Problem=RF Power OFF | I14: 2026-03-22 20:44:22 | J14: =NOW()-I14 -> 4.9940076 | K14: Unknown Probable Cause | L14: Major | M14: RAN-4G | N14: 160548292 1 OCM_NEW_U2020_RAN Cell Unavailable | O14: Uncleared | P14: 1 | T14: 23/03/2026 : Probable disjonction des breakers || Check Connectivite entre BBU & RRU/Check FO ou SFP | U14: TELEINFRA | V14: disjonction au niveau de DC | W14: disjonction des breakers | Y14: =VLOOKUP(B14, [2]SBC!A$1:P$65536, 11, 0) -> Ngaoundere | Z14: =LEFT(B14,3) -> ADM | AA14: =IF(J14 < 1/24, "T<1H", IF(AND(J14<2/24, J14>1/24), "1H<T<2H", IF(AND(J14<4/24, J14>2/24), "2H<T<4H", IF(AND(J14<8/24, J14>4/24), "4H<T<8H", IF(AND(J14<16/24, J14>8/24), "8H<T<16H",IF(AND(J14<24/24, J14>16/24),"16H<T<24H", IF(AND(J14<48/24, J14>24/24),"24H<T<48H",IF(AND(J14<72/24, J14>24/24),"48H<T<72H", "T>72H")))))))) -> T>72H | AB14: 1 | AC14: Up | AD14: New case | AE14: 23/03/2026 8h | AF14: W13
... A17: ADM_048_H_Ngd-Q-Haoussa_L | B17: =LEFT(A17,7) -> ADM_048 | C17: INC-20260322-00014363 | D17: #N/A | E17: #N/A | F17: Cell Unavailable | G17: eNodeB Function Name=ADM_048_H_Ngd-Q-Haoussa_L, Local Cell ID=51, Cell FDD TDD indication=TDD, NB-IoT Cell Flag=FALSE, Cell Name=ADM_048_H_Ngd-Q-Haoussa_L26_12, eNodeB ID=21048, Cell ID=51, Specific Problem=RF Power OFF Processing Error Alarm | H17: eNodeB Function Name=ADM_048_H_Ngd-Q-Haoussa_L, Local Cell ID=51, Cell FDD TDD indication=TDD, NB-IoT Cell Flag=FALSE, Cell Name=ADM_048_H_Ngd-Q-Haoussa_L26_12, eNodeB ID=21048, Cell ID=51, Specific Problem=RF Power OFF | I17: 2026-03-22 20:44:22 | J17: =NOW()-I17 -> 4.9940076 | K17: Unknown Probable Cause | L17: Major | M17: RAN-4G | N17: 160548293 1 OCM_NEW_U2020_RAN Cell Unavailable | O17: Uncleared | P17: 1 | T17: 23/03/2026 : Probable disjonction des breakers || Check Connectivite entre BBU & RRU/Check FO ou SFP | U17: TELEINFRA | V17: disjonction au niveau de DC | W17: disjonction des breakers | Y17: =VLOOKUP(B17, [2]SBC!A$1:P$65536, 11, 0) -> Ngaoundere | Z17: =LEFT(B17,3) -> ADM | AA17: =IF(J17 < 1/24, "T<1H", IF(AND(J17<2/24, J17>1/24), "1H<T<2H", IF(AND(J17<4/24, J17>2/24), "2H<T<4H", IF(AND(J17<8/24, J17>4/24), "4H<T<8H", IF(AND(J17<16/24, J17>8/24), "8H<T<16H",IF(AND(J17<24/24, J17>16/24),"16H<T<24H", IF(AND(J17<48/24, J17>24/24),"24H<T<48H",IF(AND(J17<72/24, J17>24/24),"48H<T<72H", "T>72H")))))))) -> T>72H | AB17: 1 | AC17: Up | AD17: New case | AE17: 23/03/2026 8h | AF17: W13
A18: SUO_222_H_Buea-Bakwere-Town-MTN_L | B18: =LEFT(A18,7) -> SUO_222 | C18: INC-20260323-00001713 | D18: #N/A | E18: #N/A | F18: Cell Unavailable | G18: eNodeB Function Name=SUO_222_H_Buea-Bakwere-Town-MTN_L, Local Cell ID=21, Cell FDD TDD indication=FDD, NB-IoT Cell Flag=FALSE, Cell Name=SUO_222_H_Buea-Bakwere-Town-MTN_L18_1, eNodeB ID=15222, Cell ID=21, Specific Problem=RF module abnormal Processing Error Alarm | H18: eNodeB Function Name=SUO_222_H_Buea-Bakwere-Town-MTN_L, Local Cell ID=21, Cell FDD TDD indication=FDD, NB-IoT Cell Flag=FALSE, Cell Name=SUO_222_H_Buea-Bakwere-Town-MTN_L18_1, eNodeB ID=15222, Cell ID=21, Specific Problem=RF module abnormal | I18: 2026-03-23 02:08:00 | J18: =NOW()-I18 -> 4.7692623 | K18: Unknown Probable Cause | L18: Major | M18: RAN-4G | N18: 160657960 1 OCM_NEW_U2020_RAN Cell Unavailable | O18: Uncleared | P18: 1 | T18: 19/03/2026: Relance faite a MTN ce jour || Escalade faite a silvain 18/03/2026 : Power instability || Mail sent to MTN | U18: MTN | V18: #N/A | W18: #N/A | Y18: =VLOOKUP(B18, [2]SBC!A$1:P$65536, 11, 0) -> Buéa | Z18: =LEFT(B18,3) -> SUO | AA18: =IF(J18 < 1/24, "T<1H", IF(AND(J18<2/24, J18>1/24), "1H<T<2H", IF(AND(J18<4/24, J18>2/24), "2H<T<4H", IF(AND(J18<8/24, J18>4/24), "4H<T<8H", IF(AND(J18<16/24, J18>8/24), "8H<T<16H",IF(AND(J18<24/24, J18>16/24),"16H<T<24H", IF(AND(J18<48/24, J18>24/24),"24H<T<48H",IF(AND(J18<72/24, J18>24/24),"48H<T<72H", "T>72H")))))))) -> T>72H | AB18: 1 | AC18: DOWN | AD18: Old case | AE18: 23/03/2026 8h | AF18: W13
A19: NRD_040_H_Ouro-Kessoun_L | B19: =LEFT(A19,7) -> NRD_040 | C19: INC-20260323-00002332 | D19: #N/A | E19: #N/A | F19: Cell Unavailable | G19: eNodeB Function Name=NRD_040_H_Ouro-Kessoun_L, Local Cell ID=22, Cell FDD TDD indication=FDD, NB-IoT Cell Flag=FALSE, Cell Name=NRD_040_H_Ouro-Kessoun_L18_6S_2, eNodeB ID=16040, Cell ID=22, Specific Problem=RF module abnormal Processing Error Alarm | H19: eNodeB Function Name=NRD_040_H_Ouro-Kessoun_L, Local Cell ID=22, Cell FDD TDD indication=FDD, NB-IoT Cell Flag=FALSE, Cell Name=NRD_040_H_Ouro-Kessoun_L18_6S_2, eNodeB ID=16040, Cell ID=22, Specific Problem=RF module abnormal | I19: 2026-03-23 03:38:30 | J19: =NOW()-I19 -> 4.706415 | K19: Unknown Probable Cause | L19: Major | M19: RAN-4G | N19: 160680026 1 OCM_NEW_U2020_RAN Cell Unavailable | O19: Uncleared | P19: 1 | T19: 23/03/2026 : Relance faite ce jour au RM pour l'update du remplacement du PWC 18/03/2026 : Relance faite de nouveau ce matin au L3 pour revoir l'ETR 17032026. 35 Cells down. || Feeback IHS : Apres investigations, nous avons remplacé les redresseurs dans les sites dont tu m’as fait les mails à savoir : Zileng, Ouro-Kessoun, Pitoa Ville et le site en objet, mais ces redresseurs passent HS, l’action est de remplacer la baie. J’ai déjà commandé les baies de ces sites qui quittent Douala aujourd’hui, les issues seront résolus dans une semaine. || commande en cours | U19: IHS | V19: #N/A | W19: #N/A | Y19: =VLOOKUP(B19, [2]SBC!A$1:P$65536, 11, 0) -> Garoua | Z19: =LEFT(B19,3) -> NRD | AA19: =IF(J19 < 1/24, "T<1H", IF(AND(J19<2/24, J19>1/24), "1H<T<2H", IF(AND(J19<4/24, J19>2/24), "2H<T<4H", IF(AND(J19<8/24, J19>4/24), "4H<T<8H", IF(AND(J19<16/24, J19>8/24), "8H<T<16H",IF(AND(J19<24/24, J19>16/24),"16H<T<24H", IF(AND(J19<48/24, J19>24/24),"24H<T<48H",IF(AND(J19<72/24, J19>24/24),"48H<T<72H", "T>72H")))))))) -> T>72H | AB19: 1 | AC19: DOWN | AD19: New case | AE19: 23/03/2026 8h | AF19: W13
A20: NRD_040_H_Ouro-Kessoun_L | B20: =LEFT(A20,7) -> NRD_040 | C20: INC-20260323-00002332 | D20: #N/A | E20: #N/A | F20: Cell Unavailable | G20: eNodeB Function Name=NRD_040_H_Ouro-Kessoun_L, Local Cell ID=25, Cell FDD TDD indication=FDD, NB-IoT Cell Flag=FALSE, Cell Name=NRD_040_H_Ouro-Kessoun_L18_6S_5, eNodeB ID=16040, Cell ID=25, Specific Problem=RF module abnormal Processing Error Alarm | H20: eNodeB Function Name=NRD_040_H_Ouro-Kessoun_L, Local Cell ID=25, Cell FDD TDD indication=FDD, NB-IoT Cell Flag=FALSE, Cell Name=NRD_040_H_Ouro-Kessoun_L18_6S_5, eNodeB ID=16040, Cell ID=25, Specific Problem=RF module abnormal | I20: 2026-03-23 03:38:30 | J20: =NOW()-I20 -> 4.706415 | K20: Unknown Probable Cause | L20: Major | M20: RAN-4G | N20: 160680033 1 OCM_NEW_U2020_RAN Cell Unavailable | O20: Uncleared | P20: 1 | T20: 23/03/2026 : Relance faite ce jour au RM pour l'update du remplacement du PWC 18/03/2026 : Relance faite de nouveau ce matin au L3 pour revoir l'ETR 17032026. 35 Cells down. || Feeback IHS : Apres investigations, nous avons remplacé les redresseurs dans les sites dont tu m’as fait les mails à savoir : Zileng, Ouro-Kessoun, Pitoa Ville et le site en objet, mais ces redresseurs passent HS, l’action est de remplacer la baie. J’ai déjà commandé les baies de ces sites qui quittent Douala aujourd’hui, les issues seront résolus dans une semaine. || commande en cours | U20: IHS | V20: #N/A | W20: #N/A | Y20: =VLOOKUP(B20, [2]SBC!A$1:P$65536, 11, 0) -> Garoua | Z20: =LEFT(B20,3) -> NRD | AA20: =IF(J20 < 1/24, "T<1H", IF(AND(J20<2/24, J20>1/24), "1H<T<2H", IF(AND(J20<4/24, J20>2/24), "2H<T<4H", IF(AND(J20<8/24, J20>4/24), "4H<T<8H", IF(AND(J20<16/24, J20>8/24), "8H<T<16H",IF(AND(J20<24/24, J20>16/24),"16H<T<24H", IF(AND(J20<48/24, J20>24/24),"24H<T<48H",IF(AND(J20<72/24, J20>24/24),"48H<T<72H", "T>72H")))))))) -> T>72H | AB20: 1 | AC20: DOWN | AD20: New case | AE20: 23/03/2026 8h | AF20: W13
A21: NRD_040_H_Ouro-Kessoun_L | B21: =LEFT(A21,7) -> NRD_040 | C21: INC-20260323-00002332 | D21: #N/A | E21: #N/A | F21: Cell Unavailable | G21: eNodeB Function Name=NRD_040_H_Ouro-Kessoun_L, Local Cell ID=21, Cell FDD TDD indication=FDD, NB-IoT Cell Flag=FALSE, Cell Name=NRD_040_H_Ouro-Kessoun_L18_1, eNodeB ID=16040, Cell ID=21, Specific Problem=RF module abnormal Processing Error Alarm | H21: eNodeB Function Name=NRD_040_H_Ouro-Kessoun_L, Local Cell ID=21, Cell FDD TDD indication=FDD, NB-IoT Cell Flag=FALSE, Cell Name=NRD_040_H_Ouro-Kessoun_L18_1, eNodeB ID=16040, Cell ID=21, Specific Problem=RF module abnormal | I21: 2026-03-23 03:38:30 | J21: =NOW()-I21 -> 4.706415 | K21: Unknown Probable Cause | L21: Major | M21: RAN-4G | N21: 160680000 1 OCM_NEW_U2020_RAN Cell Unavailable | O21: Uncleared | P21: 1 | T21: 23/03/2026 : Relance faite ce jour au RM pour l'update du remplacement du PWC 18/03/2026 : Relance faite de nouveau ce matin au L3 pour revoir l'ETR 17032026. 35 Cells down. || Feeback IHS : Apres investigations, nous avons remplacé les redresseurs dans les sites dont tu m’as fait les mails à savoir : Zileng, Ouro-Kessoun, Pitoa Ville et le site en objet, mais ces redresseurs passent HS, l’action est de remplacer la baie. J’ai déjà commandé les baies de ces sites qui quittent Douala aujourd’hui, les issues seront résolus dans une semaine. || commande en cours | U21: IHS | V21: #N/A | W21: #N/A | Y21: =VLOOKUP(B21, [2]SBC!A$1:P$65536, 11, 0) -> Garoua | Z21: =LEFT(B21,3) -> NRD | AA21: =IF(J21 < 1/24, "T<1H", IF(AND(J21<2/24, J21>1/24), "1H<T<2H", IF(AND(J21<4/24, J21>2/24), "2H<T<4H", IF(AND(J21<8/24, J21>4/24), "4H<T<8H", IF(AND(J21<16/24, J21>8/24), "8H<T<16H",IF(AND(J21<24/24, J21>16/24),"16H<T<24H", IF(AND(J21<48/24, J21>24/24),"24H<T<48H",IF(AND(J21<72/24, J21>24/24),"48H<T<72H", "T>72H")))))))) -> T>72H | AB21: 1 | AC21: DOWN | AD21: New case | AE21: 23/03/2026 8h | AF21: W13
A22: ADM_048_H_Ngd-Q-Haoussa | B22: =LEFT(A22,7) -> ADM_048 | C22: INC-20260322-00014189 | D22: #N/A | E22: #N/A | F22: GSM Local Cell Unusable | G22: GBTS Function Name=ADM_048_H_Ngd-Q-Haoussa, Local Cell ID=0, Specific Problem=RF Resource Unavailable Quality of Service Alarm | H22: GBTS Function Name=ADM_048_H_Ngd-Q-Haoussa, Local Cell ID=0, Specific Problem=RF Resource Unavailable | I22: 2026-03-22 20:44:19 | J22: =NOW()-I22 -> 4.9940424 | K22: REDUCED_ALARM_REPORTING | L22: Major | M22: RAN-2G | N22: 160548273 1 OCM_NEW_U2020_RAN GSM Local Cell Unusable | O22: Uncleared | P22: 1 | T22: 23/03/2026 : Probable disjonction des breakers || Check Connectivite entre BBU & RRU/Check FO ou SFP | U22: TELEINFRA | V22: disjonction au niveau de DC | W22: disjonction des breakers | Y22: =VLOOKUP(B22, [2]SBC!A$1:P$65536, 11, 0) -> Ngaoundere | Z22: =LEFT(B22,3) -> ADM | AA22: =IF(J22 < 1/24, "T<1H", IF(AND(J22<2/24, J22>1/24), "1H<T<2H", IF(AND(J22<4/24, J22>2/24), "2H<T<4H", IF(AND(J22<8/24, J22>4/24), "4H<T<8H", IF(AND(J22<16/24, J22>8/24), "8H<T<16H",IF(AND(J22<24/24, J22>16/24),"16H<T<24H", IF(AND(J22<48/24, J22>24/24),"24H<T<48H",IF(AND(J22<72/24, J22>24/24),"48H<T<72H", "T>72H")))))))) -> T>72H | AB22: 1 | AC22: Up | AD22: New case | AE22: 23/03/2026 8h | AF22: W13
A23: ADM_048_H_Ngd-Q-Haoussa | B23: =LEFT(A23,7) -> ADM_048 | C23: INC-20260322-00014189 | D23: #N/A | E23: #N/A | F23: GSM Local Cell Unusable | G23: GBTS Function Name=ADM_048_H_Ngd-Q-Haoussa, Local Cell ID=2, Specific Problem=RF Resource Unavailable Quality of Service Alarm | H23: GBTS Function Name=ADM_048_H_Ngd-Q-Haoussa, Local Cell ID=2, Specific Problem=RF Resource Unavailable | I23: 2026-03-22 20:44:19 | J23: =NOW()-I23 -> 4.9940424 | K23: REDUCED_ALARM_REPORTING | L23: Major | M23: RAN-2G | N23: 160548271 1 OCM_NEW_U2020_RAN GSM Local Cell Unusable | O23: Uncleared | P23: 1 | T23: 23/03/2026 : Probable disjonction des breakers || Check Connectivite entre BBU & RRU/Check FO ou SFP | U23: TELEINFRA | V23: disjonction au niveau de DC | W23: disjonction des breakers | Y23: =VLOOKUP(B23, [2]SBC!A$1:P$65536, 11, 0) -> Ngaoundere | Z23: =LEFT(B23,3) -> ADM | AA23: =IF(J23 < 1/24, "T<1H", IF(AND(J23<2/24, J23>1/24), "1H<T<2H", IF(AND(J23<4/24, J23>2/24), "2H<T<4H", IF(AND(J23<8/24, J23>4/24), "4H<T<8H", IF(AND(J23<16/24, J23>8/24), "8H<T<16H",IF(AND(J23<24/24, J23>16/24),"16H<T<24H", IF(AND(J23<48/24, J23>24/24),"24H<T<48H",IF(AND(J23<72/24, J23>24/24),"48H<T<72H", "T>72H")))))))) -> T>72H | AB23: 1 | AC23: Up | AD23: New case | AE23: 23/03/2026 8h | AF23: W13
A24: ADM_048_H_Ngd-Q-Haoussa | B24: =LEFT(A24,7) -> ADM_048 | C24: INC-20260322-00014189 | D24: #N/A | E24: #N/A | F24: GSM Local Cell Unusable | G24: GBTS Function Name=ADM_048_H_Ngd-Q-Haoussa, Local Cell ID=1, Specific Problem=RF Resource Unavailable Quality of Service Alarm | H24: GBTS Function Name=ADM_048_H_Ngd-Q-Haoussa, Local Cell ID=1, Specific Problem=RF Resource Unavailable | I24: 2026-03-22 20:44:19 | J24: =NOW()-I24 -> 4.9940424 | K24: REDUCED_ALARM_REPORTING | L24: Major | M24: RAN-2G | N24: 160548272 1 OCM_NEW_U2020_RAN GSM Local Cell Unusable | O24: Uncleared | P24: 1 | T24: 23/03/2026 : Probable disjonction des breakers || Check Connectivite entre BBU & RRU/Check FO ou SFP | U24: TELEINFRA | V24: disjonction au niveau de DC | W24: disjonction des breakers | Y24: =VLOOKUP(B24, [2]SBC!A$1:P$65536, 11, 0) -> Ngaoundere | Z24: =LEFT(B24,3) -> ADM | AA24: =IF(J24 < 1/24, "T<1H", IF(AND(J24<2/24, J24>1/24), "1H<T<2H", IF(AND(J24<4/24, J24>2/24), "2H<T<4H", IF(AND(J24<8/24, J24>4/24), "4H<T<8H", IF(AND(J24<16/24, J24>8/24), "8H<T<16H",IF(AND(J24<24/24, J24>16/24),"16H<T<24H", IF(AND(J24<48/24, J24>24/24),"24H<T<48H",IF(AND(J24<72/24, J24>24/24),"48H<T<72H", "T>72H")))))))) -> T>72H | AB24: 1 | AC24: Up | AD24: New case | AE24: 23/03/2026 8h | AF24: W13
A25: SUO_222_H_Buea-Bakwere-Town-MTN | B25: =LEFT(A25,7) -> SUO_222 | C25: INC-20260323-00001354 | D25: #N/A | E25: #N/A | F25: GSM Local Cell Unusable | G25: GBTS Function Name=SUO_222_H_Buea-Bakwere-Town-MTN, Local Cell ID=3, Specific Problem=RF Resource Unavailable Quality of Service Alarm | H25: GBTS Function Name=SUO_222_H_Buea-Bakwere-Town-MTN, Local Cell ID=3, Specific Problem=RF Resource Unavailable | I25: 2026-03-22 23:59:38 | J25: =NOW()-I25 -> 4.8584058 | K25: REDUCED_ALARM_REPORTING | L25: Major | M25: RAN-2G | N25: 160657278 1 OCM_NEW_U2020_RAN GSM Local Cell Unusable | O25: Uncleared | P25: 1 | T25: 19/03/2026: Relance faite a MTN ce jour || Escalade faite a silvain 18/03/2026 : Power instability || Mail sent to MTN | U25: MTN | V25: #N/A | W25: #N/A | Y25: =VLOOKUP(B25, [2]SBC!A$1:P$65536, 11, 0) -> Buéa | Z25: =LEFT(B25,3) -> SUO | AA25: =IF(J25 < 1/24, "T<1H", IF(AND(J25<2/24, J25>1/24), "1H<T<2H", IF(AND(J25<4/24, J25>2/24), "2H<T<4H", IF(AND(J25<8/24, J25>4/24), "4H<T<8H", IF(AND(J25<16/24, J25>8/24), "8H<T<16H",IF(AND(J25<24/24, J25>16/24),"16H<T<24H", IF(AND(J25<48/24, J25>24/24),"24H<T<48H",IF(AND(J25<72/24, J25>24/24),"48H<T<72H", "T>72H")))))))) -> T>72H | AB25: 1 | AC25: DOWN | AD25: Old case | AE25: 23/03/2026 8h | AF25: W13
A26: NRD_040_H_Ouro-Kessoun | B26: =LEFT(A26,7) -> NRD_040 | C26: INC-20260323-00002332 | D26: #N/A | E26: #N/A | F26: GSM Local Cell Unusable | G26: GBTS Function Name=NRD_040_H_Ouro-Kessoun, Local Cell ID=4, Specific Problem=RF Resource Unavailable Quality of Service Alarm | H26: GBTS Function Name=NRD_040_H_Ouro-Kessoun, Local Cell ID=4, Specific Problem=RF Resource Unavailable | I26: 2026-03-23 03:25:36 | J26: =NOW()-I26 -> 4.7153734 | K26: REDUCED_ALARM_REPORTING | L26: Major | M26: RAN-2G | N26: 160677343 1 OCM_NEW_U2020_RAN GSM Local Cell Unusable | O26: Uncleared | P26: 1 | T26: 23/03/2026 : Relance faite ce jour au RM pour l'update du remplacement du PWC 18/03/2026 : Relance faite de nouveau ce matin au L3 pour revoir l'ETR 17032026. 35 Cells down. || Feeback IHS : Apres investigations, nous avons remplacé les redresseurs dans les sites dont tu m’as fait les mails à savoir : Zileng, Ouro-Kessoun, Pitoa Ville et le site en objet, mais ces redresseurs passent HS, l’action est de remplacer la baie. J’ai déjà commandé les baies de ces sites qui quittent Douala aujourd’hui, les issues seront résolus dans une semaine. || commande en cours | U26: IHS | V26: #N/A | W26: #N/A | Y26: =VLOOKUP(B26, [2]SBC!A$1:P$65536, 11, 0) -> Garoua | Z26: =LEFT(B26,3) -> NRD | AA26: =IF(J26 < 1/24, "T<1H", IF(AND(J26<2/24, J26>1/24), "1H<T<2H", IF(AND(J26<4/24, J26>2/24), "2H<T<4H", IF(AND(J26<8/24, J26>4/24), "4H<T<8H", IF(AND(J26<16/24, J26>8/24), "8H<T<16H",IF(AND(J26<24/24, J26>16/24),"16H<T<24H", IF(AND(J26<48/24, J26>24/24),"24H<T<48H",IF(AND(J26<72/24, J26>24/24),"48H<T<72H", "T>72H")))))))) -> T>72H | AB26: 1 | AC26: DOWN | AD26: New case | AE26: 23/03/2026 8h | AF26: W13
A27: NRD_040_H_Ouro-Kessoun | B27: =LEFT(A27,7) -> NRD_040 | C27: INC-20260323-00002332 | D27: #N/A | E27: #N/A | F27: GSM Local Cell Unusable | G27: GBTS Function Name=NRD_040_H_Ouro-Kessoun, Local Cell ID=3, Specific Problem=RF Resource Unavailable Quality of Service Alarm | H27: GBTS Function Name=NRD_040_H_Ouro-Kessoun, Local Cell ID=3, Specific Problem=RF Resource Unavailable | I27: 2026-03-23 03:38:36 | J27: =NOW()-I27 -> 4.7063456 | K27: REDUCED_ALARM_REPORTING | L27: Major | M27: RAN-2G | N27: 160680025 1 OCM_NEW_U2020_RAN GSM Local Cell Unusable | O27: Uncleared | P27: 1 | T27: 23/03/2026 : Relance faite ce jour au RM pour l'update du remplacement du PWC 18/03/2026 : Relance faite de nouveau ce matin au L3 pour revoir l'ETR 17032026. 35 Cells down. || Feeback IHS : Apres investigations, nous avons remplacé les redresseurs dans les sites dont tu m’as fait les mails à savoir : Zileng, Ouro-Kessoun, Pitoa Ville et le site en objet, mais ces redresseurs passent HS, l’action est de remplacer la baie. J’ai déjà commandé les baies de ces sites qui quittent Douala aujourd’hui, les issues seront résolus dans une semaine. || commande en cours | U27: IHS | V27: #N/A | W27: #N/A | Y27: =VLOOKUP(B27, [2]SBC!A$1:P$65536, 11, 0) -> Garoua | Z27: =LEFT(B27,3) -> NRD | AA27: =IF(J27 < 1/24, "T<1H", IF(AND(J27<2/24, J27>1/24), "1H<T<2H", IF(AND(J27<4/24, J27>2/24), "2H<T<4H", IF(AND(J27<8/24, J27>4/24), "4H<T<8H", IF(AND(J27<16/24, J27>8/24), "8H<T<16H",IF(AND(J27<24/24, J27>16/24),"16H<T<24H", IF(AND(J27<48/24, J27>24/24),"24H<T<48H",IF(AND(J27<72/24, J27>24/24),"48H<T<72H", "T>72H")))))))) -> T>72H | AB27: 1 | AC27: DOWN | AD27: New case | AE27: 23/03/2026 8h | AF27: W13
A28: NRD_040_H_Ouro-Kessoun | B28: =LEFT(A28,7) -> NRD_040 | C28: INC-20260323-00002332 | D28: #N/A | E28: #N/A | F28: GSM Local Cell Unusable | G28: GBTS Function Name=NRD_040_H_Ouro-Kessoun, Local Cell ID=2, Specific Problem=RF Resource Unavailable Quality of Service Alarm | H28: GBTS Function Name=NRD_040_H_Ouro-Kessoun, Local Cell ID=2, Specific Problem=RF Resource Unavailable | I28: 2026-03-23 03:38:36 | J28: =NOW()-I28 -> 4.7063456 | K28: REDUCED_ALARM_REPORTING | L28: Major | M28: RAN-2G | N28: 160680032 1 OCM_NEW_U2020_RAN GSM Local Cell Unusable | O28: Uncleared | P28: 1 | T28: 23/03/2026 : Relance faite ce jour au RM pour l'update du remplacement du PWC 18/03/2026 : Relance faite de nouveau ce matin au L3 pour revoir l'ETR 17032026. 35 Cells down. || Feeback IHS : Apres investigations, nous avons remplacé les redresseurs dans les sites dont tu m’as fait les mails à savoir : Zileng, Ouro-Kessoun, Pitoa Ville et le site en objet, mais ces redresseurs passent HS, l’action est de remplacer la baie. J’ai déjà commandé les baies de ces sites qui quittent Douala aujourd’hui, les issues seront résolus dans une semaine. || commande en cours | U28: IHS | V28: #N/A | W28: #N/A | Y28: =VLOOKUP(B28, [2]SBC!A$1:P$65536, 11, 0) -> Garoua | Z28: =LEFT(B28,3) -> NRD | AA28: =IF(J28 < 1/24, "T<1H", IF(AND(J28<2/24, J28>1/24), "1H<T<2H", IF(AND(J28<4/24, J28>2/24), "2H<T<4H", IF(AND(J28<8/24, J28>4/24), "4H<T<8H", IF(AND(J28<16/24, J28>8/24), "8H<T<16H",IF(AND(J28<24/24, J28>16/24),"16H<T<24H", IF(AND(J28<48/24, J28>24/24),"24H<T<48H",IF(AND(J28<72/24, J28>24/24),"48H<T<72H", "T>72H")))))))) -> T>72H | AB28: 1 | AC28: DOWN | AD28: New case | AE28: 23/03/2026 8h | AF28: W13
A29: SUO_222_H_Buea-Bakwere-Town-MTN | B29: =LEFT(A29,7) -> SUO_222 | C29: INC-20260323-00001353 | D29: #N/A | E29: #N/A | F29: Local Cell Unusable | G29: NodeB Function Name=SUO_222_H_Buea-Bakwere-Town-MTN_U, Local Cell ID=51450, Specific Problem=RF Board Unavailable Quality of Service Alarm | H29: NodeB Function Name=SUO_222_H_Buea-Bakwere-Town-MTN_U, Local Cell ID=51450, Specific Problem=RF Board Unavailable | I29: 2026-03-22 23:54:42 | J29: =NOW()-I29 -> 4.8618317 | K29: REDUCED_ALARM_REPORTING | L29: Major | M29: RAN | N29: 160657230 1 OCM_NEW_U2020_RAN Local Cell Unusable | O29: Uncleared | P29: 1 | T29: 19/03/2026: Relance faite a MTN ce jour || Escalade faite a silvain 18/03/2026 : Power instability || Mail sent to MTN | U29: MTN | V29: #N/A | W29: #N/A | Y29: =VLOOKUP(B29, [2]SBC!A$1:P$65536, 11, 0) -> Buéa | Z29: =LEFT(B29,3) -> SUO | AA29: =IF(J29 < 1/24, "T<1H", IF(AND(J29<2/24, J29>1/24), "1H<T<2H", IF(AND(J29<4/24, J29>2/24), "2H<T<4H", IF(AND(J29<8/24, J29>4/24), "4H<T<8H", IF(AND(J29<16/24, J29>8/24), "8H<T<16H",IF(AND(J29<24/24, J29>16/24),"16H<T<24H", IF(AND(J29<48/24, J29>24/24),"24H<T<48H",IF(AND(J29<72/24, J29>24/24),"48H<T<72H", "T>72H")))))))) -> T>72H | AB29: 1 | AC29: DOWN | AD29: Old case | AE29: 23/03/2026 8h | AF29: W13
A30: SUO_222_H_Buea-Bakwere-Town-MTN | B30: =LEFT(A30,7) -> SUO_222 | C30: INC-20260323-00001351 | D30: #N/A | E30: #N/A | F30: Local Cell Unusable | G30: NodeB Function Name=SUO_222_H_Buea-Bakwere-Town-MTN_U, Local Cell ID=51452, Specific Problem=RF Board Unavailable Quality of Service Alarm | H30: NodeB Function Name=SUO_222_H_Buea-Bakwere-Town-MTN_U, Local Cell ID=51452, Specific Problem=RF Board Unavailable | I30: 2026-03-22 23:54:42 | J30: =NOW()-I30 -> 4.8618317 | K30: REDUCED_ALARM_REPORTING | L30: Major | M30: RAN | N30: 160657234 1 OCM_NEW_U2020_RAN Local Cell Unusable | O30: Uncleared | P30: 1 | T30: 19/03/2026: Relance faite a MTN ce jour || Escalade faite a silvain 18/03/2026 : Power instability || Mail sent to MTN | U30: MTN | V30: #N/A | W30: #N/A | Y30: =VLOOKUP(B30, [2]SBC!A$1:P$65536, 11, 0) -> Buéa | Z30: =LEFT(B30,3) -> SUO | AA30: =IF(J30 < 1/24, "T<1H", IF(AND(J30<2/24, J30>1/24), "1H<T<2H", IF(AND(J30<4/24, J30>2/24), "2H<T<4H", IF(AND(J30<8/24, J30>4/24), "4H<T<8H", IF(AND(J30<16/24, J30>8/24), "8H<T<16H",IF(AND(J30<24/24, J30>16/24),"16H<T<24H", IF(AND(J30<48/24, J30>24/24),"24H<T<48H",IF(AND(J30<72/24, J30>24/24),"48H<T<72H", "T>72H")))))))) -> T>72H | AB30: 1 | AC30: DOWN | AD30: Old case | AE30: 23/03/2026 8h | AF30: W13
A31: SUO_222_H_Buea-Bakwere-Town-MTN | B31: =LEFT(A31,7) -> SUO_222 | C31: INC-20260323-00001351 | D31: #N/A | E31: #N/A | F31: Local Cell Unusable | G31: NodeB Function Name=SUO_222_H_Buea-Bakwere-Town-MTN_U, Local Cell ID=51451, Specific Problem=RF Board Unavailable Quality of Service Alarm | H31: NodeB Function Name=SUO_222_H_Buea-Bakwere-Town-MTN_U, Local Cell ID=51451, Specific Problem=RF Board Unavailable | I31: 2026-03-22 23:54:42 | J31: =NOW()-I31 -> 4.8618317 | K31: REDUCED_ALARM_REPORTING | L31: Major | M31: RAN | N31: 160657232 1 OCM_NEW_U2020_RAN Local Cell Unusable | O31: Uncleared | P31: 1 | T31: 19/03/2026: Relance faite a MTN ce jour || Escalade faite a silvain 18/03/2026 : Power instability || Mail sent to MTN | U31: MTN | V31: #N/A | W31: #N/A | Y31: =VLOOKUP(B31, [2]SBC!A$1:P$65536, 11, 0) -> Buéa | Z31: =LEFT(B31,3) -> SUO | AA31: =IF(J31 < 1/24, "T<1H", IF(AND(J31<2/24, J31>1/24), "1H<T<2H", IF(AND(J31<4/24, J31>2/24), "2H<T<4H", IF(AND(J31<8/24, J31>4/24), "4H<T<8H", IF(AND(J31<16/24, J31>8/24), "8H<T<16H",IF(AND(J31<24/24, J31>16/24),"16H<T<24H", IF(AND(J31<48/24, J31>24/24),"24H<T<48H",IF(AND(J31<72/24, J31>24/24),"48H<T<72H", "T>72H")))))))) -> T>72H | AB31: 1 | AC31: DOWN | AD31: Old case | AE31: 23/03/2026 8h | AF31: W13
A32: NRD_040_H_Ouro-Kessoun | B32: =LEFT(A32,7) -> NRD_040 | C32: INC-20260323-00002332 | D32: #N/A | E32: #N/A | F32: Local Cell Unusable | G32: NodeB Function Name=NRD_040_H_Ouro-Kessoun_U, Local Cell ID=52154, Specific Problem=Downlink RF Resource Unavailable Quality of Service Alarm | H32: NodeB Function Name=NRD_040_H_Ouro-Kessoun_U, Local Cell ID=52154, Specific Problem=Downlink RF Resource Unavailable | I32: 2026-03-23 03:23:58 | J32: =NOW()-I32 -> 4.7165076 | K32: REDUCED_ALARM_REPORTING | L32: Major | M32: RAN | N32: 160676653 1 OCM_NEW_U2020_RAN Local Cell Unusable | O32: Uncleared | P32: 1 | T32: 23/03/2026 : Relance faite ce jour au RM pour l'update du remplacement du PWC 18/03/2026 : Relance faite de nouveau ce matin au L3 pour revoir l'ETR 17032026. 35 Cells down. || Feeback IHS : Apres investigations, nous avons remplacé les redresseurs dans les sites dont tu m’as fait les mails à savoir : Zileng, Ouro-Kessoun, Pitoa Ville et le site en objet, mais ces redresseurs passent HS, l’action est de remplacer la baie. J’ai déjà commandé les baies de ces sites qui quittent Douala aujourd’hui, les issues seront résolus dans une semaine. || commande en cours | U32: IHS | V32: #N/A | W32: #N/A | Y32: =VLOOKUP(B32, [2]SBC!A$1:P$65536, 11, 0) -> Garoua | Z32: =LEFT(B32,3) -> NRD | AA32: =IF(J32 < 1/24, "T<1H", IF(AND(J32<2/24, J32>1/24), "1H<T<2H", IF(AND(J32<4/24, J32>2/24), "2H<T<4H", IF(AND(J32<8/24, J32>4/24), "4H<T<8H", IF(AND(J32<16/24, J32>8/24), "8H<T<16H",IF(AND(J32<24/24, J32>16/24),"16H<T<24H", IF(AND(J32<48/24, J32>24/24),"24H<T<48H",IF(AND(J32<72/24, J32>24/24),"48H<T<72H", "T>72H")))))))) -> T>72H | AB32: 1 | AC32: DOWN | AD32: New case | AE32: 23/03/2026 8h | AF32: W13
A33: NRD_040_H_Ouro-Kessoun | B33: =LEFT(A33,7) -> NRD_040 | C33: INC-20260323-00002332 | D33: #N/A | E33: #N/A | F33: Local Cell Unusable | G33: NodeB Function Name=NRD_040_H_Ouro-Kessoun_U, Local Cell ID=52154, Specific Problem=Uplink RF Resource Unavailable Quality of Service Alarm | H33: NodeB Function Name=NRD_040_H_Ouro-Kessoun_U, Local Cell ID=52154, Specific Problem=Uplink RF Resource Unavailable | I33: 2026-03-23 03:23:58 | J33: =NOW()-I33 -> 4.7165076 | K33: REDUCED_ALARM_REPORTING | L33: Major | M33: RAN | N33: 160676652 1 OCM_NEW_U2020_RAN Local Cell Unusable | O33: Uncleared | P33: 1 | T33: 23/03/2026 : Relance faite ce jour au RM pour l'update du remplacement du PWC 18/03/2026 : Relance faite de nouveau ce matin au L3 pour revoir l'ETR 17032026. 35 Cells down. || Feeback IHS : Apres investigations, nous avons remplacé les redresseurs dans les sites dont tu m’as fait les mails à savoir : Zileng, Ouro-Kessoun, Pitoa Ville et le site en objet, mais ces redresseurs passent HS, l’action est de remplacer la baie. J’ai déjà commandé les baies de ces sites qui quittent Douala aujourd’hui, les issues seront résolus dans une semaine. || commande en cours | U33: IHS | V33: #N/A | W33: #N/A | Y33: =VLOOKUP(B33, [2]SBC!A$1:P$65536, 11, 0) -> Garoua | Z33: =LEFT(B33,3) -> NRD | AA33: =IF(J33 < 1/24, "T<1H", IF(AND(J33<2/24, J33>1/24), "1H<T<2H", IF(AND(J33<4/24, J33>2/24), "2H<T<4H", IF(AND(J33<8/24, J33>4/24), "4H<T<8H", IF(AND(J33<16/24, J33>8/24), "8H<T<16H",IF(AND(J33<24/24, J33>16/24),"16H<T<24H", IF(AND(J33<48/24, J33>24/24),"24H<T<48H",IF(AND(J33<72/24, J33>24/24),"48H<T<72H", "T>72H")))))))) -> T>72H | AB33: 1 | AC33: DOWN | AD33: New case | AE33: 23/03/2026 8h | AF33: W13
A34: NRD_040_H_Ouro-Kessoun | B34: =LEFT(A34,7) -> NRD_040 | C34: INC-20260323-00002332 | D34: #N/A | E34: #N/A | F34: Local Cell Unusable | G34: NodeB Function Name=NRD_040_H_Ouro-Kessoun_U, Local Cell ID=52155, Specific Problem=Uplink RF Resource Unavailable Quality of Service Alarm | H34: NodeB Function Name=NRD_040_H_Ouro-Kessoun_U, Local Cell ID=52155, Specific Problem=Uplink RF Resource Unavailable | I34: 2026-03-23 03:23:59 | J34: =NOW()-I34 -> 4.7164961 | K34: REDUCED_ALARM_REPORTING | L34: Major | M34: RAN | N34: 160676662 1 OCM_NEW_U2020_RAN Local Cell Unusable | O34: Uncleared | P34: 1 | T34: 23/03/2026 : Relance faite ce jour au RM pour l'update du remplacement du PWC 18/03/2026 : Relance faite de nouveau ce matin au L3 pour revoir l'ETR 17032026. 35 Cells down. || Feeback IHS : Apres investigations, nous avons remplacé les redresseurs dans les sites dont tu m’as fait les mails à savoir : Zileng, Ouro-Kessoun, Pitoa Ville et le site en objet, mais ces redresseurs passent HS, l’action est de remplacer la baie. J’ai déjà commandé les baies de ces sites qui quittent Douala aujourd’hui, les issues seront résolus dans une semaine. || commande en cours | U34: IHS | V34: #N/A | W34: #N/A | Y34: =VLOOKUP(B34, [2]SBC!A$1:P$65536, 11, 0) -> Garoua | Z34: =LEFT(B34,3) -> NRD | AA34: =IF(J34 < 1/24, "T<1H", IF(AND(J34<2/24, J34>1/24), "1H<T<2H", IF(AND(J34<4/24, J34>2/24), "2H<T<4H", IF(AND(J34<8/24, J34>4/24), "4H<T<8H", IF(AND(J34<16/24, J34>8/24), "8H<T<16H",IF(AND(J34<24/24, J34>16/24),"16H<T<24H", IF(AND(J34<48/24, J34>24/24),"24H<T<48H",IF(AND(J34<72/24, J34>24/24),"48H<T<72H", "T>72H")))))))) -> T>72H | AB34: 1 | AC34: DOWN | AD34: New case | AE34: 23/03/2026 8h | AF34: W13
A35: NRD_040_H_Ouro-Kessoun | B35: =LEFT(A35,7) -> NRD_040 | C35: INC-20260323-00002332 | D35: #N/A | E35: #N/A | F35: Local Cell Unusable | G35: NodeB Function Name=NRD_040_H_Ouro-Kessoun_U, Local Cell ID=52153, Specific Problem=Downlink RF Resource Unavailable Quality of Service Alarm | H35: NodeB Function Name=NRD_040_H_Ouro-Kessoun_U, Local Cell ID=52153, Specific Problem=Downlink RF Resource Unavailable | I35: 2026-03-23 03:23:59 | J35: =NOW()-I35 -> 4.7164961 | K35: REDUCED_ALARM_REPORTING | L35: Major | M35: RAN | N35: 160676661 1 OCM_NEW_U2020_RAN Local Cell Unusable | O35: Uncleared | P35: 1 | T35: 23/03/2026 : Relance faite ce jour au RM pour l'update du remplacement du PWC 18/03/2026 : Relance faite de nouveau ce matin au L3 pour revoir l'ETR 17032026. 35 Cells down. || Feeback IHS : Apres investigations, nous avons remplacé les redresseurs dans les sites dont tu m’as fait les mails à savoir : Zileng, Ouro-Kessoun, Pitoa Ville et le site en objet, mais ces redresseurs passent HS, l’action est de remplacer la baie. J’ai déjà commandé les baies de ces sites qui quittent Douala aujourd’hui, les issues seront résolus dans une semaine. || commande en cours | U35: IHS | V35: #N/A | W35: #N/A | Y35: =VLOOKUP(B35, [2]SBC!A$1:P$65536, 11, 0) -> Garoua | Z35: =LEFT(B35,3) -> NRD | AA35: =IF(J35 < 1/24, "T<1H", IF(AND(J35<2/24, J35>1/24), "1H<T<2H", IF(AND(J35<4/24, J35>2/24), "2H<T<4H", IF(AND(J35<8/24, J35>4/24), "4H<T<8H", IF(AND(J35<16/24, J35>8/24), "8H<T<16H",IF(AND(J35<24/24, J35>16/24),"16H<T<24H", IF(AND(J35<48/24, J35>24/24),"24H<T<48H",IF(AND(J35<72/24, J35>24/24),"48H<T<72H", "T>72H")))))))) -> T>72H | AB35: 1 | AC35: DOWN | AD35: New case | AE35: 23/03/2026 8h | AF35: W13
A36: NRD_040_H_Ouro-Kessoun | B36: =LEFT(A36,7) -> NRD_040 | C36: INC-20260323-00002332 | D36: #N/A | E36: #N/A | F36: Local Cell Unusable | G36: NodeB Function Name=NRD_040_H_Ouro-Kessoun_U, Local Cell ID=52155, Specific Problem=Downlink RF Resource Unavailable Quality of Service Alarm | H36: NodeB Function Name=NRD_040_H_Ouro-Kessoun_U, Local Cell ID=52155, Specific Problem=Downlink RF Resource Unavailable | I36: 2026-03-23 03:23:59 | J36: =NOW()-I36 -> 4.7164961 | K36: REDUCED_ALARM_REPORTING | L36: Major | M36: RAN | N36: 160676663 1 OCM_NEW_U2020_RAN Local Cell Unusable | O36: Uncleared | P36: 1 | T36: 23/03/2026 : Relance faite ce jour au RM pour l'update du remplacement du PWC 18/03/2026 : Relance faite de nouveau ce matin au L3 pour revoir l'ETR 17032026. 35 Cells down. || Feeback IHS : Apres investigations, nous avons remplacé les redresseurs dans les sites dont tu m’as fait les mails à savoir : Zileng, Ouro-Kessoun, Pitoa Ville et le site en objet, mais ces redresseurs passent HS, l’action est de remplacer la baie. J’ai déjà commandé les baies de ces sites qui quittent Douala aujourd’hui, les issues seront résolus dans une semaine. || commande en cours | U36: IHS | V36: #N/A | W36: #N/A | Y36: =VLOOKUP(B36, [2]SBC!A$1:P$65536, 11, 0) -> Garoua | Z36: =LEFT(B36,3) -> NRD | AA36: =IF(J36 < 1/24, "T<1H", IF(AND(J36<2/24, J36>1/24), "1H<T<2H", IF(AND(J36<4/24, J36>2/24), "2H<T<4H", IF(AND(J36<8/24, J36>4/24), "4H<T<8H", IF(AND(J36<16/24, J36>8/24), "8H<T<16H",IF(AND(J36<24/24, J36>16/24),"16H<T<24H", IF(AND(J36<48/24, J36>24/24),"24H<T<48H",IF(AND(J36<72/24, J36>24/24),"48H<T<72H", "T>72H")))))))) -> T>72H | AB36: 1 | AC36: DOWN | AD36: New case | AE36: 23/03/2026 8h | AF36: W13
... A44: NRD_311_URH_NADOURA | B44: =LEFT(A44,7) -> NRD_311 | C44: INC-20260323-00002291 | D44: #N/A | E44: #N/A | F44: RF Unit CPRI Interface Error | G44: Cabinet No.=0, Subrack No.=70, Slot No.=0, Port No.=Port 0(West), Sub Port No.=NULL, Board Type=MRRU, Specific Problem=CPRI Interface Reception Error Communication Alarm | H44: Cabinet No.=0, Subrack No.=70, Slot No.=0, Port No.=Port 0(West), Sub Port No.=NULL, Board Type=MRRU, Specific Problem=CPRI Interface Reception Error | I44: 2026-03-23 03:17:04 | J44: =NOW()-I44 -> 4.7212993 | K44: CALL_ESTABLISHMENT_ERROR | L44: Major | M44: RAN | N44: 160675034 1 OCM_NEW_U2020_RAN RF Unit CPRI Interface Error | O44: Uncleared | P44: 1 | T44: 23/03/2026 : Besoin d'analyse BO RAN || Check Connectivite(FO et SFP) entre BBU & RRU | U44: TELEINFRA | V44: #N/A | W44: #N/A | Y44: =VLOOKUP(B44, [2]SBC!A$1:P$65536, 11, 0) -> #N/A | Z44: =LEFT(B44,3) -> NRD | AA44: =IF(J44 < 1/24, "T<1H", IF(AND(J44<2/24, J44>1/24), "1H<T<2H", IF(AND(J44<4/24, J44>2/24), "2H<T<4H", IF(AND(J44<8/24, J44>4/24), "4H<T<8H", IF(AND(J44<16/24, J44>8/24), "8H<T<16H",IF(AND(J44<24/24, J44>16/24),"16H<T<24H", IF(AND(J44<48/24, J44>24/24),"24H<T<48H",IF(AND(J44<72/24, J44>24/24),"48H<T<72H", "T>72H")))))))) -> T>72H | AB44: 1 | AC44: DOWN | AD44: New case | AE44: 23/03/2026 8h | AF44: W13
A45: ADM_048_H_Ngd-Q-Haoussa | B45: =LEFT(A45,7) -> ADM_048 | C45: INC-20260322-00014189 | D45: #N/A | E45: #N/A | F45: RF Unit DC Input Power Failure | G45: Cabinet No.=0, Subrack No.=62, Slot No.=0, Board Type=MRRU Equipment Alarm | H45: Cabinet No.=0, Subrack No.=62, Slot No.=0, Board Type=MRRU | I45: 2026-03-22 20:44:21 | J45: =NOW()-I45 -> 4.9940192 | K45: EXTERNAL_POWER_SUPPLY_FAILURE | L45: Major | M45: RAN | N45: 160548975 1 OCM_NEW_U2020_RAN RF Unit DC Input Power Failure | O45: Uncleared | P45: 1 | T45: 23/03/2026 : Probable disjonction des breakers || Check Connectivite entre BBU & RRU/Check FO ou SFP | U45: TELEINFRA | V45: disjonction au niveau de DC | W45: disjonction des breakers | Y45: =VLOOKUP(B45, [2]SBC!A$1:P$65536, 11, 0) -> Ngaoundere | Z45: =LEFT(B45,3) -> ADM | AA45: =IF(J45 < 1/24, "T<1H", IF(AND(J45<2/24, J45>1/24), "1H<T<2H", IF(AND(J45<4/24, J45>2/24), "2H<T<4H", IF(AND(J45<8/24, J45>4/24), "4H<T<8H", IF(AND(J45<16/24, J45>8/24), "8H<T<16H",IF(AND(J45<24/24, J45>16/24),"16H<T<24H", IF(AND(J45<48/24, J45>24/24),"24H<T<48H",IF(AND(J45<72/24, J45>24/24),"48H<T<72H", "T>72H")))))))) -> T>72H | AB45: 1 | AC45: Up | AD45: New case | AE45: 23/03/2026 8h | AF45: W13
A46: ADM_048_H_Ngd-Q-Haoussa | B46: =LEFT(A46,7) -> ADM_048 | C46: INC-20260322-00014189 | D46: #N/A | E46: #N/A | F46: RF Unit DC Input Power Failure | G46: Cabinet No.=0, Subrack No.=61, Slot No.=0, Board Type=MRRU Equipment Alarm | H46: Cabinet No.=0, Subrack No.=61, Slot No.=0, Board Type=MRRU | I46: 2026-03-22 20:44:21 | J46: =NOW()-I46 -> 4.9940192 | K46: EXTERNAL_POWER_SUPPLY_FAILURE | L46: Major | M46: RAN | N46: 160548976 1 OCM_NEW_U2020_RAN RF Unit DC Input Power Failure | O46: Uncleared | P46: 1 | T46: 23/03/2026 : Probable disjonction des breakers || Check Connectivite entre BBU & RRU/Check FO ou SFP | U46: TELEINFRA | V46: disjonction au niveau de DC | W46: disjonction des breakers | Y46: =VLOOKUP(B46, [2]SBC!A$1:P$65536, 11, 0) -> Ngaoundere | Z46: =LEFT(B46,3) -> ADM | AA46: =IF(J46 < 1/24, "T<1H", IF(AND(J46<2/24, J46>1/24), "1H<T<2H", IF(AND(J46<4/24, J46>2/24), "2H<T<4H", IF(AND(J46<8/24, J46>4/24), "4H<T<8H", IF(AND(J46<16/24, J46>8/24), "8H<T<16H",IF(AND(J46<24/24, J46>16/24),"16H<T<24H", IF(AND(J46<48/24, J46>24/24),"24H<T<48H",IF(AND(J46<72/24, J46>24/24),"48H<T<72H", "T>72H")))))))) -> T>72H | AB46: 1 | AC46: Up | AD46: New case | AE46: 23/03/2026 8h | AF46: W13
A47: ADM_048_H_Ngd-Q-Haoussa | B47: =LEFT(A47,7) -> ADM_048 | C47: INC-20260322-00014189 | D47: #N/A | E47: #N/A | F47: RF Unit DC Input Power Failure | G47: Cabinet No.=0, Subrack No.=80, Slot No.=0, Board Type=MRRU Equipment Alarm | H47: Cabinet No.=0, Subrack No.=80, Slot No.=0, Board Type=MRRU | I47: 2026-03-22 20:44:21 | J47: =NOW()-I47 -> 4.9940192 | K47: EXTERNAL_POWER_SUPPLY_FAILURE | L47: Major | M47: RAN | N47: 160548979 1 OCM_NEW_U2020_RAN RF Unit DC Input Power Failure | O47: Uncleared | P47: 1 | T47: 23/03/2026 : Probable disjonction des breakers || Check Connectivite entre BBU & RRU/Check FO ou SFP | U47: TELEINFRA | V47: disjonction au niveau de DC | W47: disjonction des breakers | Y47: =VLOOKUP(B47, [2]SBC!A$1:P$65536, 11, 0) -> Ngaoundere | Z47: =LEFT(B47,3) -> ADM | AA47: =IF(J47 < 1/24, "T<1H", IF(AND(J47<2/24, J47>1/24), "1H<T<2H", IF(AND(J47<4/24, J47>2/24), "2H<T<4H", IF(AND(J47<8/24, J47>4/24), "4H<T<8H", IF(AND(J47<16/24, J47>8/24), "8H<T<16H",IF(AND(J47<24/24, J47>16/24),"16H<T<24H", IF(AND(J47<48/24, J47>24/24),"24H<T<48H",IF(AND(J47<72/24, J47>24/24),"48H<T<72H", "T>72H")))))))) -> T>72H | AB47: 1 | AC47: Up | AD47: New case | AE47: 23/03/2026 8h | AF47: W13
A48: ADM_048_H_Ngd-Q-Haoussa | B48: =LEFT(A48,7) -> ADM_048 | C48: INC-20260322-00014189 | D48: #N/A | E48: #N/A | F48: RF Unit DC Input Power Failure | G48: Cabinet No.=0, Subrack No.=60, Slot No.=0, Board Type=MRRU Equipment Alarm | H48: Cabinet No.=0, Subrack No.=60, Slot No.=0, Board Type=MRRU | I48: 2026-03-22 20:44:21 | J48: =NOW()-I48 -> 4.9940192 | K48: EXTERNAL_POWER_SUPPLY_FAILURE | L48: Major | M48: RAN | N48: 160548977 1 OCM_NEW_U2020_RAN RF Unit DC Input Power Failure | O48: Uncleared | P48: 1 | T48: 23/03/2026 : Probable disjonction des breakers || Check Connectivite entre BBU & RRU/Check FO ou SFP | U48: TELEINFRA | V48: disjonction au niveau de DC | W48: disjonction des breakers | Y48: =VLOOKUP(B48, [2]SBC!A$1:P$65536, 11, 0) -> Ngaoundere | Z48: =LEFT(B48,3) -> ADM | AA48: =IF(J48 < 1/24, "T<1H", IF(AND(J48<2/24, J48>1/24), "1H<T<2H", IF(AND(J48<4/24, J48>2/24), "2H<T<4H", IF(AND(J48<8/24, J48>4/24), "4H<T<8H", IF(AND(J48<16/24, J48>8/24), "8H<T<16H",IF(AND(J48<24/24, J48>16/24),"16H<T<24H", IF(AND(J48<48/24, J48>24/24),"24H<T<48H",IF(AND(J48<72/24, J48>24/24),"48H<T<72H", "T>72H")))))))) -> T>72H | AB48: 1 | AC48: Up | AD48: New case | AE48: 23/03/2026 8h | AF48: W13
A49: ADM_048_H_Ngd-Q-Haoussa | B49: =LEFT(A49,7) -> ADM_048 | C49: INC-20260322-00014189 | D49: #N/A | E49: #N/A | F49: RF Unit DC Input Power Failure | G49: Cabinet No.=0, Subrack No.=81, Slot No.=0, Board Type=MRRU Equipment Alarm | H49: Cabinet No.=0, Subrack No.=81, Slot No.=0, Board Type=MRRU | I49: 2026-03-22 20:44:21 | J49: =NOW()-I49 -> 4.9940192 | K49: EXTERNAL_POWER_SUPPLY_FAILURE | L49: Major | M49: RAN | N49: 160548978 1 OCM_NEW_U2020_RAN RF Unit DC Input Power Failure | O49: Uncleared | P49: 1 | T49: 23/03/2026 : Probable disjonction des breakers || Check Connectivite entre BBU & RRU/Check FO ou SFP | U49: TELEINFRA | V49: disjonction au niveau de DC | W49: disjonction des breakers | Y49: =VLOOKUP(B49, [2]SBC!A$1:P$65536, 11, 0) -> Ngaoundere | Z49: =LEFT(B49,3) -> ADM | AA49: =IF(J49 < 1/24, "T<1H", IF(AND(J49<2/24, J49>1/24), "1H<T<2H", IF(AND(J49<4/24, J49>2/24), "2H<T<4H", IF(AND(J49<8/24, J49>4/24), "4H<T<8H", IF(AND(J49<16/24, J49>8/24), "8H<T<16H",IF(AND(J49<24/24, J49>16/24),"16H<T<24H", IF(AND(J49<48/24, J49>24/24),"24H<T<48H",IF(AND(J49<72/24, J49>24/24),"48H<T<72H", "T>72H")))))))) -> T>72H | AB49: 1 | AC49: Up | AD49: New case | AE49: 23/03/2026 8h | AF49: W13
...

Sheet Cells Huawei 23032026 12h
A1: Alarm Source | B1: Site code | C1: Ticket ID | D1: Powerco | E1: Topologie | F1: Alarm Name | G1: Summary | H1: Alarm Location Info | I1: First Occurred On | J1: Duration | K1: Possible Cause | L1: Raw Alarm Severity | M1: Domain | N1: Alarm Identifier | O1: Clearance Status | P1: Alarm Occurrences | Q1: Action Plan | R1: Action de resolution | S1: Date de resolution | T1: Comment | U1: Porteur | V1: RCA | W1: Causes | X1: SBC | Y1: Ville | Z1: Region | AA1: Temps | AB1: Nombre | AC1: STATUT Cells | AD1: Ages Cells | AE1: Jour d'extraction | AF1: SEMAINE | AG1: Occurrence
