Workbook

Sheet RAPPORT
A1: oprationnel | B1: Operationnel | E1: oprationnel | F1: Operationnel | H1: oprationnel | I1: Operationnel
A3: Row Labels | B3: Sum of NUR DU 26/04/2026 | E3: Row Labels | F3: Sum of NUR DU 26/04/2026 | H3: Row Labels | I3: Sum of NUR DU 26/04/2026
A4: ACCESS-ISSUE | B4: 19.36622 | E4: ACCESS-ISSUE | F4: 19.36622 | H4: ACCESS-ISSUE | I4: 19.36622
A5: ACTIVE | B5: 395.71906 | E5: ENVTECH | F5: 12.326928 | H5: AKTIVCO | I5: 216.9684
A6: no impacts | B6: 45.567945 | E6: no impacts | F6: 45.567945 | H6: AKTIVCO GRID ONLY | I6: 361.51932
A7: No root cause | B7: 225.93662 | E7: No root cause | F7: 225.93662 | H7: BSS | I7: 207.98778
A8: PASSIVE | B8: 1303.484 | E8: POWER ISSUE | F8: 1291.1571 | H8: ENVTECH | I8: 12.326928
A9: PLANNED WORKS | B9: 5.8660821 | E9: RAN ISSUE | F9: 207.98778 | H9: Fiber AOF | I9: 39.888947
A10: SPARE-ISSUE | B10: 134.06102 | E10: SPARE-ISSUE | F10: 134.06102 | H10: IHS | I10: 568.37362
A11: Grand Total | B11: 2130.001 | E11: TRAVAUX OCM | F11: 4.6214612 | H11: IHS GRID ONLY | I11: 89.350247
E12: TRAVAUX-HUAWEI | F12: 1.2446209 | H12: no impacts | I12: 45.567945
E13: TX ISSUE | F13: 187.73128 | H13: No root cause | I13: 225.93662
E14: Grand Total | F14: 2130.001 | H14: Partners | I14: 54.945507
H15: PDH | I15: 147.84233
H16: SPARE-ISSUE | I16: 134.06102
H17: TRAVAUX OCM | I17: 4.6214612
H18: TRAVAUX-HUAWEI | I18: 1.2446209
H19: Grand Total | I19: 2130.001
D39: NUR DAILY RECAP - NUR 2130
A40: RCA | B40: NUR | D40: RCA | E40: NUR | G40: RCA | H40: NUR
A41: ACCESS-ISSUE | B41: =GETPIVOTDATA("NUR DU 26/04/2026",$A$3,"CATEGORIE","ACCESS-ISSUE") -> 19.36622 | D41: ACCESS-ISSUE | E41: =GETPIVOTDATA("NUR DU 26/04/2026",$E$3,"SUB RCA","ACCESS-ISSUE") -> 19.36622 | G41: ACCESS-ISSUE | H41: =GETPIVOTDATA("NUR DU 26/04/2026",$H$3,"OCM NOMENCLATURE","ACCESS-ISSUE") -> 19.36622
A42: ACTIVE | B42: =GETPIVOTDATA("NUR DU 26/04/2026",$A$3,"CATEGORIE","ACTIVE") -> 395.71906 | D42: ENV TCH OCM | E42: =GETPIVOTDATA("NUR DU 26/04/2026",$E$3,"SUB RCA","ENVTECH") -> 12.326928 | G42: AKTIVCO With Backup | H42: =GETPIVOTDATA("NUR DU 26/04/2026",$H$3,"OCM NOMENCLATURE","AKTIVCO") -> 216.9684
A43: No root cause | B43: =GETPIVOTDATA("NUR DU 26/04/2026",$A$3,"CATEGORIE","No root cause") -> 225.93662 | D43: No root cause | E43: =GETPIVOTDATA("NUR DU 26/04/2026",$E$3,"SUB RCA","No root cause") -> 225.93662 | G43: AKTIVCO GRID ONLY | H43: =GETPIVOTDATA("NUR DU 26/04/2026",$H$3,"OCM NOMENCLATURE","AKTIVCO GRID ONLY") -> 361.51932
A44: PASSIVE | B44: =GETPIVOTDATA("NUR DU 26/04/2026",$A$3,"CATEGORIE","PASSIVE") -> 1303.484 | D44: POWER ISSUE | E44: =GETPIVOTDATA("NUR DU 26/04/2026",$E$3,"SUB RCA","POWER ISSUE") -> 1291.1571 | G44: Hardware issue | H44: =GETPIVOTDATA("NUR DU 26/04/2026",$H$3,"OCM NOMENCLATURE","BSS") -> 207.98778
A45: PLANNED WORKS | B45: =GETPIVOTDATA("NUR DU 26/04/2026",$A$3,"CATEGORIE","PLANNED WORKS") -> 5.8660821 | D45: RAN ISSUE | E45: =GETPIVOTDATA("NUR DU 26/04/2026",$E$3,"SUB RCA","RAN ISSUE") -> 207.98778 | G45: ENVTECH | H45: =GETPIVOTDATA("NUR DU 26/04/2026",$H$3,"OCM NOMENCLATURE","ENVTECH") -> 12.326928
A46: SPARE-ISSUE | B46: =GETPIVOTDATA("NUR DU 26/04/2026",$A$3,"CATEGORIE","SPARE-ISSUE") -> 134.06102 | D46: SPARE-ISSUE | E46: =GETPIVOTDATA("NUR DU 26/04/2026",$E$3,"SUB RCA","SPARE-ISSUE") -> 134.06102 | G46: Fiber AOF | H46: =GETPIVOTDATA("NUR DU 26/04/2026",$H$3,"OCM NOMENCLATURE","Fiber AOF") -> 39.888947
A47: Grand Total | B47: =GETPIVOTDATA("NUR DU 26/04/2026",$A$3) -> 2130.001 | D47: PLANNED WORKS | E47: =GETPIVOTDATA("NUR DU 26/04/2026",$E$3,"SUB RCA","TRAVAUX OCM")+GETPIVOTDATA("NUR DU 26/04/2026",$E$3,"SUB RCA","TRAVAUX-HUAWEI") -> 5.8660821 | G47: IHS | H47: =GETPIVOTDATA("NUR DU 26/04/2026",$H$3,"OCM NOMENCLATURE","IHS") -> 568.37362
D48: TX ISSUE | E48: =GETPIVOTDATA("NUR DU 26/04/2026",$E$3,"SUB RCA","TX ISSUE") -> 187.73128 | G48: IHS GRID ONLY | H48: =GETPIVOTDATA("NUR DU 26/04/2026",$H$3,"OCM NOMENCLATURE","IHS GRID ONLY") -> 89.350247
D49: Grand Total | E49: =GETPIVOTDATA("NUR DU 26/04/2026",$E$3) -> 2130.001 | G49: No root cause | H49: =GETPIVOTDATA("NUR DU 26/04/2026",$H$3,"OCM NOMENCLATURE","No root cause") -> 225.93662
G50: Power MTN | H50: =GETPIVOTDATA("NUR DU 26/04/2026",$H$3,"OCM NOMENCLATURE","Partners") -> 54.945507
G51: TX issue MPR / ODU -- | H51: =GETPIVOTDATA("NUR DU 26/04/2026",$H$3,"OCM NOMENCLATURE","PDH") -> 147.84233
G52: SPARE-ISSUE | H52: =GETPIVOTDATA("NUR DU 26/04/2026",$H$3,"OCM NOMENCLATURE","SPARE-ISSUE") -> 134.06102
G53: PLANNED WORKS | H53: =GETPIVOTDATA("NUR DU 26/04/2026",$H$3,"OCM NOMENCLATURE","TRAVAUX OCM")+GETPIVOTDATA("NUR DU 26/04/2026",$H$3,"OCM NOMENCLATURE","TRAVAUX-HUAWEI") -> 5.8660821
G54: Grand Total | H54: =GETPIVOTDATA("NUR DU 26/04/2026",$H$3) -> 2130.001
B57: CTR_211

Sheet FOLLOW UP
A1: Nom du Physique | B1: Codesite | C1: CLUSTER | D1: Owner | E1: Topology | F1: Region | G1: Ville | H1: Vendor | I1: 21/4/2026 | J1: 22/4/2026 | K1: 23/4/2026 | L1: 24/4/2026 | M1: 25/4/2026 | N1: 26/4/2026 | O1: 27/04/2026 | P1: Repetitive | Q1: Vendor | R1: Raison d'exclusion | S1: OCM NOMENCLATURE | T1: SUB RCA | U1: CAUSE | V1: CATEGORIE | W1: RCA | X1: Action Plan | Y1: ETR | Z1: Owner | AA1: Status | AB1: Verifications 26/04/2026 | AC1: INCIDENT 27/04/2026 | AD1: impacts | AE1: top offenders 26/04/2026 | AF1: RETOUR CAMUSAT 26/04/2026 | AG1: RETOUR IHS 26/04/2026 | AH1: Hourly IHS 26/04/2026 | AI1: Cells Huawei 27042026 10h | AJ1: Cells Huawei 27042026 15h | AK1: cells down 27042026 11h28 | AL1: cells down 27042026 18h01 | AM1: cell downs 27042026 11h | AN1: cell downs 27042026 17h40 | AO1: OCM Ran 27/04/2026 17H | AP1: OCM Ran 27/04/2026 11H | AQ1: Ticket 26/04/2026 | AR1: Dashbord suivi TOP OFFENDERS 26/04/2026 | AS1: SITE WITH GPS ISSUE || 14/04/2026: hardware issue, site with GPS issue (alarm : TDD down 09Apr 02pm) | AT1: nokia number cell | AU1: HUAWEI number cell | AV1: ZTE number cell
A2: Bonewonda-III | B2: LIT_615 | C2: =_xlfn.XLOOKUP(B2,'[1]daily break down'!$D:$D,'[1]daily break down'!$E:$E,"") -> Douala | D2: CAMUSAT | E2: Good Grid no GE - 8h | F2: LITTORAL | G2: Douala | H2: =_xlfn.XLOOKUP(B2,[2]CALCULATION!$B:$B,[2]CALCULATION!$H:$H,"") -> ZTE | I2: 0 | J2: 13.732654 | K2: 13.868557 | L2: 60.682481 | M2: 48.377382 | N2: 36.683564 | O2: 63.555052 | P2: REPETITIF | Q2: Operationnel | S2: {=IFERROR(_xlfn.IFS( U2="MPR ISSUE","PDH", U2="BSS Hardware Issue","BSS", U2="Sites strategiques, MLL, Pylone, etc.","ENVTECH", U2="AKTIVCO DEFAUT GE & POWER Cabinet","AKTIVCO", U2="AKTIVCO Coupure ENEO & Baisse de tension","AKTIVCO GRID ONLY", U2="Coupure ENEO & Baisse de tension","IHS GRID ONLY", U2="Defaut GE & POWER Cabinet","IHS", U2="Sharing","Partners", U2="Sites strategiques & DataCenter","SST & DC", U2="Exclu","Exclu", U2="SAT","SAT", U2="SPARE-ISSUE","SPARE-ISSUE", U2="Fiber CAmtel","TRANS_FO_CAMTEL", U2="Fiber AOF","Fiber AOF", U2="Projet OCM (HUAWEI)","TRAVAUX-HUAWEI", U2="Projet OCM (NOKIA)","TRAVAUX-NOKIA", U2="ACCESS-ISSUE","ACCESS-ISSUE", U2="Projet OCM (ZTE, NOKIA, autres projets)","TRAVAUX OCM", U2="No root CAuse","No root cause", U2="ODU HS","PDH", U2="IP & VLAN","PDH", U2="Warehouse HUAWEI","SPARE-ISSUE", U2="SPARE-HS","SPARE-ISSUE", U2="Power Telco","BSS",U2="no impacts","no impacts" ),"")} -> AKTIVCO GRID ONLY | T2: {=IFERROR(_xlfn.IFS( U2="MPR ISSUE","TX ISSUE", U2="BSS Hardware Issue","RAN ISSUE", U2="Sites strategiques, MLL, Pylone, etc.","ENVTECH", U2="AKTIVCO DEFAUT GE & POWER Cabinet","POWER ISSUE", U2="AKTIVCO Coupure ENEO & Baisse de tension","POWER ISSUE", U2="Coupure ENEO & Baisse de tension","POWER ISSUE", U2="Defaut GE & POWER Cabinet","POWER ISSUE", U2="Sharing","POWER ISSUE", U2="Sites strategiques & DataCenter","POWER ISSUE", U2="Exclu","Exclu", U2="SAT","TX ISSUE", U2="SPARE-ISSUE","SPARE-ISSUE", U2="Fiber CAmtel","TX ISSUE", U2="Fiber AOF","TX ISSUE", U2="Projet OCM (HUAWEI)","TRAVAUX-HUAWEI", U2="Projet OCM (NOKIA)","TRAVAUX -NOKIA", U2="ACCESS-ISSUE","ACCESS-ISSUE", U2="Projet OCM (ZTE, NOKIA, autres projets)","TRAVAUX OCM", U2="No root CAuse","No root cause", U2="ODU HS","TX ISSUE", U2="IP & VLAN","TX ISSUE", U2="Warehouse HUAWEI","SPARE-ISSUE", U2="SPARE-HS","SPARE-ISSUE", U2="Power Telco","RAN ISSUE",U2="no impacts","no impacts" ),"")} -> POWER ISSUE | U2: AKTIVCO Coupure ENEO & Baisse de tension | V2: {=IFERROR(_xlfn.IFS( U2="MPR ISSUE","ACTIVE", U2="BSS Hardware Issue","ACTIVE", U2="Sites strategiques, MLL, Pylone, etc.","PASSIVE", U2="AKTIVCO DEFAUT GE & POWER Cabinet","PASSIVE", U2="AKTIVCO Coupure ENEO & Baisse de tension","PASSIVE", U2="Coupure ENEO & Baisse de tension","PASSIVE", U2="Defaut GE & POWER Cabinet","PASSIVE", U2="Sharing","PASSIVE", U2="Sites strategiques & DataCenter","PASSIVE", U2="Exclu","Exclu", U2="SAT","ACTIVE", U2="SPARE-ISSUE","SPARE-ISSUE", U2="Fiber CAmtel","ACTIVE", U2="Fiber AOF","ACTIVE", U2="Projet OCM (HUAWEI)","PLANNED WORKS", U2="Projet OCM (NOKIA)","PLANNED WORKS", U2="ACCESS-ISSUE","ACCESS-ISSUE", U2="Projet OCM (ZTE, NOKIA, autres projets)","PLANNED WORKS", U2="No root CAuse","No root cause", U2="ODU HS","ACTIVE", U2="IP & VLAN","ACTIVE", U2="Warehouse HUAWEI","SPARE-ISSUE", U2="SPARE-HS","SPARE-ISSUE", U2="Power Telco","ACTIVE", U2="no impacts","no impacts" ),"")} -> PASSIVE | W2: Grid Outage | X2: Awaiting Grid return | Z2: CAMUSAT | AA2: Ongoing | AB2: (04/27/2026 top offenders):-27/04/2026 Grid Grid and GEN faulty / Grid return awaited ESCALADE L3 CAMUSAT ..(04/27/2026 cell zte):-22/04/2026 : Site down..(04/27/2026 ocm ran 17h):-27/04/2026 Grid Grid and GEN faulty / Grid return awaited ESCALADE L3 CAMUSAT ..(04/27/2026 ocm ran 11h):-27/04/2026 Grid Grid and GEN faulty / Grid return awaited ESCALADE L3 CAMUSAT | AC2: =_xlfn.XLOOKUP(B2,'INCIDENT-04-27-2026'!E:E,'INCIDENT-04-27-2026'!F:F,"") | AE2: (04/27/2026 top offenders):-27/04/2026 Grid Grid and GEN faulty / Grid return awaited ESCALADE L3 CAMUSAT | AF2: =_xlfn.XLOOKUP(B2,'[13]Input_27-04'!$B:$B,'[13]Input_27-04'!$M:$M,"") -> GE faulty | AI2: =_xlfn.XLOOKUP(B2,'[3]Cells Huawei 27042026 10h'!$B:$B,'[3]Cells Huawei 27042026 10h'!$T:$T,"") | AJ2: =_xlfn.XLOOKUP(B2,'[3]Cells Huawei 27042026 15h'!$B:$B,'[3]Cells Huawei 27042026 15h'!$T:$T,"") | AK2: =_xlfn.XLOOKUP(B2,'[4]cells down 27042026 11h28'!$B:$B,'[4]cells down 27042026 11h28'!$R:$R,"") | AL2: =_xlfn.XLOOKUP(B2,'[4]cells down 27042026 18h01'!$B:$B,'[4]cells down 27042026 18h01'!$R:$R,"") -> (04/27/2026 cell zte):-22/04/2026 : Site down | AM2: =_xlfn.XLOOKUP(B2,'[5]cell downs 27042026 11h'!$B:$B,'[5]cell downs 27042026 11h'!$R:$R,"") | AN2: =_xlfn.XLOOKUP(B2,'[5]cell downs 27042026 17h40'!$B:$B,'[5]cell downs 27042026 17h40'!$R:$R,"") | AO2: =_xlfn.XLOOKUP(B2,'[6]ALL SITES DOWN'!$D:$D,'[6]ALL SITES DOWN'!$J:$J,"") -> (04/27/2026 ocm ran 17h):-27/04/2026 Grid Grid and GEN faulty / Grid return awaited ESCALADE L3 CAMUSAT | AP2: =_xlfn.XLOOKUP(B2,'[7]ALL SITES DOWN'!$D:$D,'[7]ALL SITES DOWN'!$J:$J,"") -> (04/27/2026 ocm ran 11h):-27/04/2026 Grid Grid and GEN faulty / Grid return awaited ESCALADE L3 CAMUSAT | AQ2: =_xlfn.XLOOKUP(B2,[8]sheet1!$AC:$AC,[8]sheet1!$AF:$AF,"") | AT2: =_xlfn.XLOOKUP(B2,'[9]cell downs 18042026 17h'!$B:$B,'[9]cell downs 18042026 17h'!$B:$B,"") | AU2: =_xlfn.XLOOKUP(B2,'[10]Cells Huawei 19042026 15h'!$B:$B,'[10]Cells Huawei 19042026 15h'!$B:$B,"") | AV2: =_xlfn.XLOOKUP(B2,'[11]cells down 19042026 9H40'!$B:$B,'[11]cells down 19042026 9H40'!$B:$B,"")
A3: Ancien-Troisieme | B3: LIT_653 | C3: =_xlfn.XLOOKUP(B3,'[1]daily break down'!$D:$D,'[1]daily break down'!$E:$E,"") -> Douala | D3: CAMUSAT | E3: Good Grid no GE - 8h | F3: LITTORAL | G3: Douala | H3: =_xlfn.XLOOKUP(B3,[2]CALCULATION!$B:$B,[2]CALCULATION!$H:$H,"") -> ZTE | I3: 0 | J3: 0 | K3: 0 | L3: 0 | M3: 17.279266 | N3: 58.181682 | O3: 58.59212 | P3: REPETITIF | Q3: Operationnel | S3: {=IFERROR(_xlfn.IFS( U3="MPR ISSUE","PDH", U3="BSS Hardware Issue","BSS", U3="Sites strategiques, MLL, Pylone, etc.","ENVTECH", U3="AKTIVCO DEFAUT GE & POWER Cabinet","AKTIVCO", U3="AKTIVCO Coupure ENEO & Baisse de tension","AKTIVCO GRID ONLY", U3="Coupure ENEO & Baisse de tension","IHS GRID ONLY", U3="Defaut GE & POWER Cabinet","IHS", U3="Sharing","Partners", U3="Sites strategiques & DataCenter","SST & DC", U3="Exclu","Exclu", U3="SAT","SAT", U3="SPARE-ISSUE","SPARE-ISSUE", U3="Fiber CAmtel","TRANS_FO_CAMTEL", U3="Fiber AOF","Fiber AOF", U3="Projet OCM (HUAWEI)","TRAVAUX-HUAWEI", U3="Projet OCM (NOKIA)","TRAVAUX-NOKIA", U3="ACCESS-ISSUE","ACCESS-ISSUE", U3="Projet OCM (ZTE, NOKIA, autres projets)","TRAVAUX OCM", U3="No root CAuse","No root cause", U3="ODU HS","PDH", U3="IP & VLAN","PDH", U3="Warehouse HUAWEI","SPARE-ISSUE", U3="SPARE-HS","SPARE-ISSUE", U3="Power Telco","BSS",U3="no impacts","no impacts" ),"")} -> AKTIVCO GRID ONLY | T3: {=IFERROR(_xlfn.IFS( U3="MPR ISSUE","TX ISSUE", U3="BSS Hardware Issue","RAN ISSUE", U3="Sites strategiques, MLL, Pylone, etc.","ENVTECH", U3="AKTIVCO DEFAUT GE & POWER Cabinet","POWER ISSUE", U3="AKTIVCO Coupure ENEO & Baisse de tension","POWER ISSUE", U3="Coupure ENEO & Baisse de tension","POWER ISSUE", U3="Defaut GE & POWER Cabinet","POWER ISSUE", U3="Sharing","POWER ISSUE", U3="Sites strategiques & DataCenter","POWER ISSUE", U3="Exclu","Exclu", U3="SAT","TX ISSUE", U3="SPARE-ISSUE","SPARE-ISSUE", U3="Fiber CAmtel","TX ISSUE", U3="Fiber AOF","TX ISSUE", U3="Projet OCM (HUAWEI)","TRAVAUX-HUAWEI", U3="Projet OCM (NOKIA)","TRAVAUX -NOKIA", U3="ACCESS-ISSUE","ACCESS-ISSUE", U3="Projet OCM (ZTE, NOKIA, autres projets)","TRAVAUX OCM", U3="No root CAuse","No root cause", U3="ODU HS","TX ISSUE", U3="IP & VLAN","TX ISSUE", U3="Warehouse HUAWEI","SPARE-ISSUE", U3="SPARE-HS","SPARE-ISSUE", U3="Power Telco","RAN ISSUE",U3="no impacts","no impacts" ),"")} -> POWER ISSUE | U3: AKTIVCO Coupure ENEO & Baisse de tension | V3: {=IFERROR(_xlfn.IFS( U3="MPR ISSUE","ACTIVE", U3="BSS Hardware Issue","ACTIVE", U3="Sites strategiques, MLL, Pylone, etc.","PASSIVE", U3="AKTIVCO DEFAUT GE & POWER Cabinet","PASSIVE", U3="AKTIVCO Coupure ENEO & Baisse de tension","PASSIVE", U3="Coupure ENEO & Baisse de tension","PASSIVE", U3="Defaut GE & POWER Cabinet","PASSIVE", U3="Sharing","PASSIVE", U3="Sites strategiques & DataCenter","PASSIVE", U3="Exclu","Exclu", U3="SAT","ACTIVE", U3="SPARE-ISSUE","SPARE-ISSUE", U3="Fiber CAmtel","ACTIVE", U3="Fiber AOF","ACTIVE", U3="Projet OCM (HUAWEI)","PLANNED WORKS", U3="Projet OCM (NOKIA)","PLANNED WORKS", U3="ACCESS-ISSUE","ACCESS-ISSUE", U3="Projet OCM (ZTE, NOKIA, autres projets)","PLANNED WORKS", U3="No root CAuse","No root cause", U3="ODU HS","ACTIVE", U3="IP & VLAN","ACTIVE", U3="Warehouse HUAWEI","SPARE-ISSUE", U3="SPARE-HS","SPARE-ISSUE", U3="Power Telco","ACTIVE", U3="no impacts","no impacts" ),"")} -> PASSIVE | W3: Power Issue | X3: Awaiting CAMUSAT's return | Z3: MTN | AA3: Ongoing | AB3: (04/27/2026 top offenders):-27/04/2026 : Besoin d'analyse BO RAN || Power issue || Mail sent to camusat..(04/27/2026 cell zte):-27/04/2026 : Besoin d'analyse BO RAN..(04/27/2026 cell zte):-27/04/2026 : Besoin d'analyse BO RAN || Power issue || Mail sent to camusat..(04/27/2026 ticket):-INC-20260427-00017150 | AC3: =_xlfn.XLOOKUP(B3,'INCIDENT-04-27-2026'!E:E,'INCIDENT-04-27-2026'!F:F,"") | AE3: (04/27/2026 top offenders):-27/04/2026 : Besoin d'analyse BO RAN || Power issue || Mail sent to camusat | AF3: =_xlfn.XLOOKUP(B3,'[13]Input_27-04'!$B:$B,'[13]Input_27-04'!$M:$M,"") -> Mauvaises phases ENEO | AI3: =_xlfn.XLOOKUP(B3,'[3]Cells Huawei 27042026 10h'!$B:$B,'[3]Cells Huawei 27042026 10h'!$T:$T,"") | AJ3: =_xlfn.XLOOKUP(B3,'[3]Cells Huawei 27042026 15h'!$B:$B,'[3]Cells Huawei 27042026 15h'!$T:$T,"") | AK3: =_xlfn.XLOOKUP(B3,'[4]cells down 27042026 11h28'!$B:$B,'[4]cells down 27042026 11h28'!$R:$R,"") -> (04/27/2026 cell zte):-27/04/2026 : Besoin d'analyse BO RAN | AL3: =_xlfn.XLOOKUP(B3,'[4]cells down 27042026 18h01'!$B:$B,'[4]cells down 27042026 18h01'!$R:$R,"") -> (04/27/2026 cell zte):-27/04/2026 : Besoin d'analyse BO RAN || Power issue || Mail sent to camusat | AM3: =_xlfn.XLOOKUP(B3,'[5]cell downs 27042026 11h'!$B:$B,'[5]cell downs 27042026 11h'!$R:$R,"") | AN3: =_xlfn.XLOOKUP(B3,'[5]cell downs 27042026 17h40'!$B:$B,'[5]cell downs 27042026 17h40'!$R:$R,"") | AO3: =_xlfn.XLOOKUP(B3,'[6]ALL SITES DOWN'!$D:$D,'[6]ALL SITES DOWN'!$J:$J,"") | AP3: =_xlfn.XLOOKUP(B3,'[7]ALL SITES DOWN'!$D:$D,'[7]ALL SITES DOWN'!$J:$J,"") | AQ3: =_xlfn.XLOOKUP(B3,[8]sheet1!$AC:$AC,[8]sheet1!$AF:$AF,"") -> (04/27/2026 ticket):-INC-20260427-00017150 | AT3: =_xlfn.XLOOKUP(B3,'[9]cell downs 18042026 17h'!$B:$B,'[9]cell downs 18042026 17h'!$B:$B,"") | AU3: =_xlfn.XLOOKUP(B3,'[10]Cells Huawei 19042026 15h'!$B:$B,'[10]Cells Huawei 19042026 15h'!$B:$B,"") | AV3: =_xlfn.XLOOKUP(B3,'[11]cells down 19042026 9H40'!$B:$B,'[11]cells down 19042026 9H40'!$B:$B,"")
A4: Institute-Samba-New | B4: CTR_868 | C4: =_xlfn.XLOOKUP(B4,'[1]daily break down'!$D:$D,'[1]daily break down'!$E:$E,"") -> Yaounde | D4: CAMUSAT | E4: Good Grid no GE - 8h | F4: CENTRE | G4: Yaounde | H4: =_xlfn.XLOOKUP(B4,[2]CALCULATION!$B:$B,[2]CALCULATION!$H:$H,"") -> ZTE | I4: 9.3119084 | J4: 12.948695 | K4: 13.868557 | L4: 13.868557 | M4: 13.868557 | N4: 13.868557 | O4: 57.190301 | P4: REPETITIF | Q4: Operationnel | S4: {=IFERROR(_xlfn.IFS( U4="MPR ISSUE","PDH", U4="BSS Hardware Issue","BSS", U4="Sites strategiques, MLL, Pylone, etc.","ENVTECH", U4="AKTIVCO DEFAUT GE & POWER Cabinet","AKTIVCO", U4="AKTIVCO Coupure ENEO & Baisse de tension","AKTIVCO GRID ONLY", U4="Coupure ENEO & Baisse de tension","IHS GRID ONLY", U4="Defaut GE & POWER Cabinet","IHS", U4="Sharing","Partners", U4="Sites strategiques & DataCenter","SST & DC", U4="Exclu","Exclu", U4="SAT","SAT", U4="SPARE-ISSUE","SPARE-ISSUE", U4="Fiber CAmtel","TRANS_FO_CAMTEL", U4="Fiber AOF","Fiber AOF", U4="Projet OCM (HUAWEI)","TRAVAUX-HUAWEI", U4="Projet OCM (NOKIA)","TRAVAUX-NOKIA", U4="ACCESS-ISSUE","ACCESS-ISSUE", U4="Projet OCM (ZTE, NOKIA, autres projets)","TRAVAUX OCM", U4="No root CAuse","No root cause", U4="ODU HS","PDH", U4="IP & VLAN","PDH", U4="Warehouse HUAWEI","SPARE-ISSUE", U4="SPARE-HS","SPARE-ISSUE", U4="Power Telco","BSS",U4="no impacts","no impacts" ),"")} -> AKTIVCO GRID ONLY | T4: {=IFERROR(_xlfn.IFS( U4="MPR ISSUE","TX ISSUE", U4="BSS Hardware Issue","RAN ISSUE", U4="Sites strategiques, MLL, Pylone, etc.","ENVTECH", U4="AKTIVCO DEFAUT GE & POWER Cabinet","POWER ISSUE", U4="AKTIVCO Coupure ENEO & Baisse de tension","POWER ISSUE", U4="Coupure ENEO & Baisse de tension","POWER ISSUE", U4="Defaut GE & POWER Cabinet","POWER ISSUE", U4="Sharing","POWER ISSUE", U4="Sites strategiques & DataCenter","POWER ISSUE", U4="Exclu","Exclu", U4="SAT","TX ISSUE", U4="SPARE-ISSUE","SPARE-ISSUE", U4="Fiber CAmtel","TX ISSUE", U4="Fiber AOF","TX ISSUE", U4="Projet OCM (HUAWEI)","TRAVAUX-HUAWEI", U4="Projet OCM (NOKIA)","TRAVAUX -NOKIA", U4="ACCESS-ISSUE","ACCESS-ISSUE", U4="Projet OCM (ZTE, NOKIA, autres projets)","TRAVAUX OCM", U4="No root CAuse","No root cause", U4="ODU HS","TX ISSUE", U4="IP & VLAN","TX ISSUE", U4="Warehouse HUAWEI","SPARE-ISSUE", U4="SPARE-HS","SPARE-ISSUE", U4="Power Telco","RAN ISSUE",U4="no impacts","no impacts" ),"")} -> POWER ISSUE | U4: AKTIVCO Coupure ENEO & Baisse de tension | V4: {=IFERROR(_xlfn.IFS( U4="MPR ISSUE","ACTIVE", U4="BSS Hardware Issue","ACTIVE", U4="Sites strategiques, MLL, Pylone, etc.","PASSIVE", U4="AKTIVCO DEFAUT GE & POWER Cabinet","PASSIVE", U4="AKTIVCO Coupure ENEO & Baisse de tension","PASSIVE", U4="Coupure ENEO & Baisse de tension","PASSIVE", U4="Defaut GE & POWER Cabinet","PASSIVE", U4="Sharing","PASSIVE", U4="Sites strategiques & DataCenter","PASSIVE", U4="Exclu","Exclu", U4="SAT","ACTIVE", U4="SPARE-ISSUE","SPARE-ISSUE", U4="Fiber CAmtel","ACTIVE", U4="Fiber AOF","ACTIVE", U4="Projet OCM (HUAWEI)","PLANNED WORKS", U4="Projet OCM (NOKIA)","PLANNED WORKS", U4="ACCESS-ISSUE","ACCESS-ISSUE", U4="Projet OCM (ZTE, NOKIA, autres projets)","PLANNED WORKS", U4="No root CAuse","No root cause", U4="ODU HS","ACTIVE", U4="IP & VLAN","ACTIVE", U4="Warehouse HUAWEI","SPARE-ISSUE", U4="SPARE-HS","SPARE-ISSUE", U4="Power Telco","ACTIVE", U4="no impacts","no impacts" ),"")} -> PASSIVE | W4: Grid Outage | X4: Awaiting Grid return | Z4: CAMUSAT | AA4: Ongoing | AB4: (04/27/2026 top offenders):-27.04.26: Camusat: Grid outage and Grid only site / Grid return awaited..(04/27/2026 cell zte):-0..(04/27/2026 ocm ran 17h):-power status check ongoing..(04/27/2026 ticket):-INC-20260427-00011306…2026-04-27 19:58:38…Grid outage and Grid only site / Grid return awaited | AC4: =_xlfn.XLOOKUP(B4,'INCIDENT-04-27-2026'!E:E,'INCIDENT-04-27-2026'!F:F,"") | AE4: (04/27/2026 top offenders):-27.04.26: Camusat: Grid outage and Grid only site / Grid return awaited | AF4: =_xlfn.XLOOKUP(B4,'[13]Input_27-04'!$B:$B,'[13]Input_27-04'!$M:$M,"") -> Grid outage, / grid return awaited | AI4: =_xlfn.XLOOKUP(B4,'[3]Cells Huawei 27042026 10h'!$B:$B,'[3]Cells Huawei 27042026 10h'!$T:$T,"") | AJ4: =_xlfn.XLOOKUP(B4,'[3]Cells Huawei 27042026 15h'!$B:$B,'[3]Cells Huawei 27042026 15h'!$T:$T,"") | AK4: =_xlfn.XLOOKUP(B4,'[4]cells down 27042026 11h28'!$B:$B,'[4]cells down 27042026 11h28'!$R:$R,"") | AL4: =_xlfn.XLOOKUP(B4,'[4]cells down 27042026 18h01'!$B:$B,'[4]cells down 27042026 18h01'!$R:$R,"") -> (04/27/2026 cell zte):-0 | AM4: =_xlfn.XLOOKUP(B4,'[5]cell downs 27042026 11h'!$B:$B,'[5]cell downs 27042026 11h'!$R:$R,"") | AN4: =_xlfn.XLOOKUP(B4,'[5]cell downs 27042026 17h40'!$B:$B,'[5]cell downs 27042026 17h40'!$R:$R,"") | AO4: =_xlfn.XLOOKUP(B4,'[6]ALL SITES DOWN'!$D:$D,'[6]ALL SITES DOWN'!$J:$J,"") -> (04/27/2026 ocm ran 17h):-power status check ongoing | AP4: =_xlfn.XLOOKUP(B4,'[7]ALL SITES DOWN'!$D:$D,'[7]ALL SITES DOWN'!$J:$J,"") | AQ4: =_xlfn.XLOOKUP(B4,[8]sheet1!$AC:$AC,[8]sheet1!$AF:$AF,"") -> (04/27/2026 ticket):-INC-20260427-00011306…2026-04-27 19:58:38…Grid outage and Grid only site / Grid return awaited | AT4: =_xlfn.XLOOKUP(B4,'[9]cell downs 18042026 17h'!$B:$B,'[9]cell downs 18042026 17h'!$B:$B,"") | AU4: =_xlfn.XLOOKUP(B4,'[10]Cells Huawei 19042026 15h'!$B:$B,'[10]Cells Huawei 19042026 15h'!$B:$B,"") | AV4: =_xlfn.XLOOKUP(B4,'[11]cells down 19042026 9H40'!$B:$B,'[11]cells down 19042026 9H40'!$B:$B,"") -> CTR_868
A5: Rd-Pt-Longkak | B5: CTR_449 | C5: =_xlfn.XLOOKUP(B5,'[1]daily break down'!$D:$D,'[1]daily break down'!$E:$E,"") -> Yaounde | D5: IHS | E5: Grid-Gen | F5: CENTRE | G5: Yaounde | H5: =_xlfn.XLOOKUP(B5,[2]CALCULATION!$B:$B,[2]CALCULATION!$H:$H,"") -> ZTE | I5: 18.985744 | J5: 9.2457046 | K5: 7.0823631 | L5: 1.681509 | M5: 4.5175005 | N5: 8.1458153 | O5: 56.225548 | P5: REPETITIF | Q5: Operationnel | S5: {=IFERROR(_xlfn.IFS( U5="MPR ISSUE","PDH", U5="BSS Hardware Issue","BSS", U5="Sites strategiques, MLL, Pylone, etc.","ENVTECH", U5="AKTIVCO DEFAUT GE & POWER Cabinet","AKTIVCO", U5="AKTIVCO Coupure ENEO & Baisse de tension","AKTIVCO GRID ONLY", U5="Coupure ENEO & Baisse de tension","IHS GRID ONLY", U5="Defaut GE & POWER Cabinet","IHS", U5="Sharing","Partners", U5="Sites strategiques & DataCenter","SST & DC", U5="Exclu","Exclu", U5="SAT","SAT", U5="SPARE-ISSUE","SPARE-ISSUE", U5="Fiber CAmtel","TRANS_FO_CAMTEL", U5="Fiber AOF","Fiber AOF", U5="Projet OCM (HUAWEI)","TRAVAUX-HUAWEI", U5="Projet OCM (NOKIA)","TRAVAUX-NOKIA", U5="ACCESS-ISSUE","ACCESS-ISSUE", U5="Projet OCM (ZTE, NOKIA, autres projets)","TRAVAUX OCM", U5="No root CAuse","No root cause", U5="ODU HS","PDH", U5="IP & VLAN","PDH", U5="Warehouse HUAWEI","SPARE-ISSUE", U5="SPARE-HS","SPARE-ISSUE", U5="Power Telco","BSS",U5="no impacts","no impacts" ),"")} -> BSS | T5: {=IFERROR(_xlfn.IFS( U5="MPR ISSUE","TX ISSUE", U5="BSS Hardware Issue","RAN ISSUE", U5="Sites strategiques, MLL, Pylone, etc.","ENVTECH", U5="AKTIVCO DEFAUT GE & POWER Cabinet","POWER ISSUE", U5="AKTIVCO Coupure ENEO & Baisse de tension","POWER ISSUE", U5="Coupure ENEO & Baisse de tension","POWER ISSUE", U5="Defaut GE & POWER Cabinet","POWER ISSUE", U5="Sharing","POWER ISSUE", U5="Sites strategiques & DataCenter","POWER ISSUE", U5="Exclu","Exclu", U5="SAT","TX ISSUE", U5="SPARE-ISSUE","SPARE-ISSUE", U5="Fiber CAmtel","TX ISSUE", U5="Fiber AOF","TX ISSUE", U5="Projet OCM (HUAWEI)","TRAVAUX-HUAWEI", U5="Projet OCM (NOKIA)","TRAVAUX -NOKIA", U5="ACCESS-ISSUE","ACCESS-ISSUE", U5="Projet OCM (ZTE, NOKIA, autres projets)","TRAVAUX OCM", U5="No root CAuse","No root cause", U5="ODU HS","TX ISSUE", U5="IP & VLAN","TX ISSUE", U5="Warehouse HUAWEI","SPARE-ISSUE", U5="SPARE-HS","SPARE-ISSUE", U5="Power Telco","RAN ISSUE",U5="no impacts","no impacts" ),"")} -> RAN ISSUE | U5: BSS Hardware issue | V5: {=IFERROR(_xlfn.IFS( U5="MPR ISSUE","ACTIVE", U5="BSS Hardware Issue","ACTIVE", U5="Sites strategiques, MLL, Pylone, etc.","PASSIVE", U5="AKTIVCO DEFAUT GE & POWER Cabinet","PASSIVE", U5="AKTIVCO Coupure ENEO & Baisse de tension","PASSIVE", U5="Coupure ENEO & Baisse de tension","PASSIVE", U5="Defaut GE & POWER Cabinet","PASSIVE", U5="Sharing","PASSIVE", U5="Sites strategiques & DataCenter","PASSIVE", U5="Exclu","Exclu", U5="SAT","ACTIVE", U5="SPARE-ISSUE","SPARE-ISSUE", U5="Fiber CAmtel","ACTIVE", U5="Fiber AOF","ACTIVE", U5="Projet OCM (HUAWEI)","PLANNED WORKS", U5="Projet OCM (NOKIA)","PLANNED WORKS", U5="ACCESS-ISSUE","ACCESS-ISSUE", U5="Projet OCM (ZTE, NOKIA, autres projets)","PLANNED WORKS", U5="No root CAuse","No root cause", U5="ODU HS","ACTIVE", U5="IP & VLAN","ACTIVE", U5="Warehouse HUAWEI","SPARE-ISSUE", U5="SPARE-HS","SPARE-ISSUE", U5="Power Telco","ACTIVE", U5="no impacts","no impacts" ),"")} -> ACTIVE | W5: Impacted by CTR_197_Z_Charles-Atangana(CTR-197) | AA5: Ongoing | AB5: CTR_197_Z_Charles-Atangana(CTR-197) , En attente de retour ENEO sur CTR_197_Z_Charles-Atangana(CTR-197)…power issues responsabilité ihs ..(04/27/2026 top offenders):-Impacted by CTR_197_Z_Charles-Atangana(CTR-197)..(04/27/2026 ocm ran 17h):-Impacted by CTR_197_Z_Charles-Atangana(CTR-197)..(04/27/2026 ocm ran 11h):-Impacted by CTR_197_Z_Charles-Atangana(CTR-197)..(04/27/2026 ticket):-INC-20260427-00002062…2026-04-27 19:15:19…Site impacted by CTR_197_Z_Charles-Atangana(CTR-197) // En attente de retour ENEO sur CTR_197_Z_Charles-Atangana(CTR-197)…power issues responsabilité ihs | AC5: =_xlfn.XLOOKUP(B5,'INCIDENT-04-27-2026'!E:E,'INCIDENT-04-27-2026'!F:F,"") | AD5: CTR_197_Z_Charles-Atangana(CTR-197) , En attente de retour ENEO sur CTR_197_Z_Charles-Atangana(CTR-197)…power issues responsabilité ihs | AE5: (04/27/2026 top offenders):-Impacted by CTR_197_Z_Charles-Atangana(CTR-197) | AF5: =_xlfn.XLOOKUP(B5,'[13]Input_27-04'!$B:$B,'[13]Input_27-04'!$M:$M,"") | AI5: =_xlfn.XLOOKUP(B5,'[3]Cells Huawei 27042026 10h'!$B:$B,'[3]Cells Huawei 27042026 10h'!$T:$T,"") | AJ5: =_xlfn.XLOOKUP(B5,'[3]Cells Huawei 27042026 15h'!$B:$B,'[3]Cells Huawei 27042026 15h'!$T:$T,"") | AK5: =_xlfn.XLOOKUP(B5,'[4]cells down 27042026 11h28'!$B:$B,'[4]cells down 27042026 11h28'!$R:$R,"") | AL5: =_xlfn.XLOOKUP(B5,'[4]cells down 27042026 18h01'!$B:$B,'[4]cells down 27042026 18h01'!$R:$R,"") | AM5: =_xlfn.XLOOKUP(B5,'[5]cell downs 27042026 11h'!$B:$B,'[5]cell downs 27042026 11h'!$R:$R,"") | AN5: =_xlfn.XLOOKUP(B5,'[5]cell downs 27042026 17h40'!$B:$B,'[5]cell downs 27042026 17h40'!$R:$R,"") | AO5: =_xlfn.XLOOKUP(B5,'[6]ALL SITES DOWN'!$D:$D,'[6]ALL SITES DOWN'!$J:$J,"") -> (04/27/2026 ocm ran 17h):-Impacted by CTR_197_Z_Charles-Atangana(CTR-197) | AP5: =_xlfn.XLOOKUP(B5,'[7]ALL SITES DOWN'!$D:$D,'[7]ALL SITES DOWN'!$J:$J,"") -> (04/27/2026 ocm ran 11h):-Impacted by CTR_197_Z_Charles-Atangana(CTR-197) | AQ5: =_xlfn.XLOOKUP(B5,[8]sheet1!$AC:$AC,[8]sheet1!$AF:$AF,"") -> (04/27/2026 ticket):-INC-20260427-00002062…2026-04-27 19:15:19…Site impacted by CTR_197_Z_Charles-Atangana(CTR-197) // En attente de retour ENEO sur CTR_197_Z_Charles-Atangana(CTR-197)…power issues responsabilité ihs | AS5: CTR_449 | AT5: =_xlfn.XLOOKUP(B5,'[9]cell downs 18042026 17h'!$B:$B,'[9]cell downs 18042026 17h'!$B:$B,"") | AU5: =_xlfn.XLOOKUP(B5,'[10]Cells Huawei 19042026 15h'!$B:$B,'[10]Cells Huawei 19042026 15h'!$B:$B,"") | AV5: =_xlfn.XLOOKUP(B5,'[11]cells down 19042026 9H40'!$B:$B,'[11]cells down 19042026 9H40'!$B:$B,"") -> CTR_449
A6: Nkolmintag | B6: LIT_539 | C6: =_xlfn.XLOOKUP(B6,'[1]daily break down'!$D:$D,'[1]daily break down'!$E:$E,"") -> Douala | D6: CAMUSAT | E6: Good Grid no GE - 12h | F6: LITTORAL | G6: Douala | H6: =_xlfn.XLOOKUP(B6,[2]CALCULATION!$B:$B,[2]CALCULATION!$H:$H,"") -> ZTE | I6: 2.0669964 | J6: 8.4491543 | K6: 4.2033178 | L6: 3.7941632 | M6: 1.4785815 | N6: 3.8880827 | O6: 49.477307 | P6: REPETITIF | Q6: Operationnel | S6: {=IFERROR(_xlfn.IFS( U6="MPR ISSUE","PDH", U6="BSS Hardware Issue","BSS", U6="Sites strategiques, MLL, Pylone, etc.","ENVTECH", U6="AKTIVCO DEFAUT GE & POWER Cabinet","AKTIVCO", U6="AKTIVCO Coupure ENEO & Baisse de tension","AKTIVCO GRID ONLY", U6="Coupure ENEO & Baisse de tension","IHS GRID ONLY", U6="Defaut GE & POWER Cabinet","IHS", U6="Sharing","Partners", U6="Sites strategiques & DataCenter","SST & DC", U6="Exclu","Exclu", U6="SAT","SAT", U6="SPARE-ISSUE","SPARE-ISSUE", U6="Fiber CAmtel","TRANS_FO_CAMTEL", U6="Fiber AOF","Fiber AOF", U6="Projet OCM (HUAWEI)","TRAVAUX-HUAWEI", U6="Projet OCM (NOKIA)","TRAVAUX-NOKIA", U6="ACCESS-ISSUE","ACCESS-ISSUE", U6="Projet OCM (ZTE, NOKIA, autres projets)","TRAVAUX OCM", U6="No root CAuse","No root cause", U6="ODU HS","PDH", U6="IP & VLAN","PDH", U6="Warehouse HUAWEI","SPARE-ISSUE", U6="SPARE-HS","SPARE-ISSUE", U6="Power Telco","BSS",U6="no impacts","no impacts" ),"")} -> AKTIVCO GRID ONLY | T6: {=IFERROR(_xlfn.IFS( U6="MPR ISSUE","TX ISSUE", U6="BSS Hardware Issue","RAN ISSUE", U6="Sites strategiques, MLL, Pylone, etc.","ENVTECH", U6="AKTIVCO DEFAUT GE & POWER Cabinet","POWER ISSUE", U6="AKTIVCO Coupure ENEO & Baisse de tension","POWER ISSUE", U6="Coupure ENEO & Baisse de tension","POWER ISSUE", U6="Defaut GE & POWER Cabinet","POWER ISSUE", U6="Sharing","POWER ISSUE", U6="Sites strategiques & DataCenter","POWER ISSUE", U6="Exclu","Exclu", U6="SAT","TX ISSUE", U6="SPARE-ISSUE","SPARE-ISSUE", U6="Fiber CAmtel","TX ISSUE", U6="Fiber AOF","TX ISSUE", U6="Projet OCM (HUAWEI)","TRAVAUX-HUAWEI", U6="Projet OCM (NOKIA)","TRAVAUX -NOKIA", U6="ACCESS-ISSUE","ACCESS-ISSUE", U6="Projet OCM (ZTE, NOKIA, autres projets)","TRAVAUX OCM", U6="No root CAuse","No root cause", U6="ODU HS","TX ISSUE", U6="IP & VLAN","TX ISSUE", U6="Warehouse HUAWEI","SPARE-ISSUE", U6="SPARE-HS","SPARE-ISSUE", U6="Power Telco","RAN ISSUE",U6="no impacts","no impacts" ),"")} -> POWER ISSUE | U6: AKTIVCO Coupure ENEO & Baisse de tension | V6: {=IFERROR(_xlfn.IFS( U6="MPR ISSUE","ACTIVE", U6="BSS Hardware Issue","ACTIVE", U6="Sites strategiques, MLL, Pylone, etc.","PASSIVE", U6="AKTIVCO DEFAUT GE & POWER Cabinet","PASSIVE", U6="AKTIVCO Coupure ENEO & Baisse de tension","PASSIVE", U6="Coupure ENEO & Baisse de tension","PASSIVE", U6="Defaut GE & POWER Cabinet","PASSIVE", U6="Sharing","PASSIVE", U6="Sites strategiques & DataCenter","PASSIVE", U6="Exclu","Exclu", U6="SAT","ACTIVE", U6="SPARE-ISSUE","SPARE-ISSUE", U6="Fiber CAmtel","ACTIVE", U6="Fiber AOF","ACTIVE", U6="Projet OCM (HUAWEI)","PLANNED WORKS", U6="Projet OCM (NOKIA)","PLANNED WORKS", U6="ACCESS-ISSUE","ACCESS-ISSUE", U6="Projet OCM (ZTE, NOKIA, autres projets)","PLANNED WORKS", U6="No root CAuse","No root cause", U6="ODU HS","ACTIVE", U6="IP & VLAN","ACTIVE", U6="Warehouse HUAWEI","SPARE-ISSUE", U6="SPARE-HS","SPARE-ISSUE", U6="Power Telco","ACTIVE", U6="no impacts","no impacts" ),"")} -> PASSIVE | W6: Grid outage grid only site | X6: Awaiting Grid return | Z6: CAMUSAT | AA6: Ongoing | AB6: (04/27/2026 top offenders):-27/04/2026 Grid outage grid only site /Grid return awaited..(04/27/2026 cell zte):-27/04/2026 : Besoin d'analyse BO RAN..(04/27/2026 cell zte):-27/04/2026 : Besoin d'analyse BO RAN || Site down..(04/27/2026 ocm ran 17h):-27/04/2026 Grid outage grid only site /Grid return awaited..(04/27/2026 ticket):-INC-20260427-00007626…2026-04-27 19:54:29…Grid outage and Grid only site / Grid return awaited | AC6: =_xlfn.XLOOKUP(B6,'INCIDENT-04-27-2026'!E:E,'INCIDENT-04-27-2026'!F:F,"") | AE6: (04/27/2026 top offenders):-27/04/2026 Grid outage grid only site /Grid return awaited | AF6: =_xlfn.XLOOKUP(B6,'[13]Input_27-04'!$B:$B,'[13]Input_27-04'!$M:$M,"") -> Grid outage, / grid return awaited | AI6: =_xlfn.XLOOKUP(B6,'[3]Cells Huawei 27042026 10h'!$B:$B,'[3]Cells Huawei 27042026 10h'!$T:$T,"") | AJ6: =_xlfn.XLOOKUP(B6,'[3]Cells Huawei 27042026 15h'!$B:$B,'[3]Cells Huawei 27042026 15h'!$T:$T,"") | AK6: =_xlfn.XLOOKUP(B6,'[4]cells down 27042026 11h28'!$B:$B,'[4]cells down 27042026 11h28'!$R:$R,"") -> (04/27/2026 cell zte):-27/04/2026 : Besoin d'analyse BO RAN | AL6: =_xlfn.XLOOKUP(B6,'[4]cells down 27042026 18h01'!$B:$B,'[4]cells down 27042026 18h01'!$R:$R,"") -> (04/27/2026 cell zte):-27/04/2026 : Besoin d'analyse BO RAN || Site down | AM6: =_xlfn.XLOOKUP(B6,'[5]cell downs 27042026 11h'!$B:$B,'[5]cell downs 27042026 11h'!$R:$R,"") | AN6: =_xlfn.XLOOKUP(B6,'[5]cell downs 27042026 17h40'!$B:$B,'[5]cell downs 27042026 17h40'!$R:$R,"") | AO6: =_xlfn.XLOOKUP(B6,'[6]ALL SITES DOWN'!$D:$D,'[6]ALL SITES DOWN'!$J:$J,"") -> (04/27/2026 ocm ran 17h):-27/04/2026 Grid outage grid only site /Grid return awaited | AP6: =_xlfn.XLOOKUP(B6,'[7]ALL SITES DOWN'!$D:$D,'[7]ALL SITES DOWN'!$J:$J,"") | AQ6: =_xlfn.XLOOKUP(B6,[8]sheet1!$AC:$AC,[8]sheet1!$AF:$AF,"") -> (04/27/2026 ticket):-INC-20260427-00007626…2026-04-27 19:54:29…Grid outage and Grid only site / Grid return awaited | AT6: =_xlfn.XLOOKUP(B6,'[9]cell downs 18042026 17h'!$B:$B,'[9]cell downs 18042026 17h'!$B:$B,"") | AU6: =_xlfn.XLOOKUP(B6,'[10]Cells Huawei 19042026 15h'!$B:$B,'[10]Cells Huawei 19042026 15h'!$B:$B,"") | AV6: =_xlfn.XLOOKUP(B6,'[11]cells down 19042026 9H40'!$B:$B,'[11]cells down 19042026 9H40'!$B:$B,"")
A7: Bonas-Yde-MTN-IHS | B7: CTR_524 | C7: =_xlfn.XLOOKUP(B7,'[1]daily break down'!$D:$D,'[1]daily break down'!$E:$E,"") -> Yaounde | D7: IHS | E7: Grid-Gen | F7: CENTRE | G7: Yaounde | H7: =_xlfn.XLOOKUP(B7,[2]CALCULATION!$B:$B,[2]CALCULATION!$H:$H,"") -> ZTE | I7: 0 | J7: 0 | K7: 0.028910662 | L7: 0 | M7: 8.8723451 | N7: 13.868557 | O7: 46.838269 | P7: REPETITIF | Q7: Operationnel | S7: {=IFERROR(_xlfn.IFS( U7="MPR ISSUE","PDH", U7="BSS Hardware Issue","BSS", U7="Sites strategiques, MLL, Pylone, etc.","ENVTECH", U7="AKTIVCO DEFAUT GE & POWER Cabinet","AKTIVCO", U7="AKTIVCO Coupure ENEO & Baisse de tension","AKTIVCO GRID ONLY", U7="Coupure ENEO & Baisse de tension","IHS GRID ONLY", U7="Defaut GE & POWER Cabinet","IHS", U7="Sharing","Partners", U7="Sites strategiques & DataCenter","SST & DC", U7="Exclu","Exclu", U7="SAT","SAT", U7="SPARE-ISSUE","SPARE-ISSUE", U7="Fiber CAmtel","TRANS_FO_CAMTEL", U7="Fiber AOF","Fiber AOF", U7="Projet OCM (HUAWEI)","TRAVAUX-HUAWEI", U7="Projet OCM (NOKIA)","TRAVAUX-NOKIA", U7="ACCESS-ISSUE","ACCESS-ISSUE", U7="Projet OCM (ZTE, NOKIA, autres projets)","TRAVAUX OCM", U7="No root CAuse","No root cause", U7="ODU HS","PDH", U7="IP & VLAN","PDH", U7="Warehouse HUAWEI","SPARE-ISSUE", U7="SPARE-HS","SPARE-ISSUE", U7="Power Telco","BSS",U7="no impacts","no impacts" ),"")} -> IHS | T7: {=IFERROR(_xlfn.IFS( U7="MPR ISSUE","TX ISSUE", U7="BSS Hardware Issue","RAN ISSUE", U7="Sites strategiques, MLL, Pylone, etc.","ENVTECH", U7="AKTIVCO DEFAUT GE & POWER Cabinet","POWER ISSUE", U7="AKTIVCO Coupure ENEO & Baisse de tension","POWER ISSUE", U7="Coupure ENEO & Baisse de tension","POWER ISSUE", U7="Defaut GE & POWER Cabinet","POWER ISSUE", U7="Sharing","POWER ISSUE", U7="Sites strategiques & DataCenter","POWER ISSUE", U7="Exclu","Exclu", U7="SAT","TX ISSUE", U7="SPARE-ISSUE","SPARE-ISSUE", U7="Fiber CAmtel","TX ISSUE", U7="Fiber AOF","TX ISSUE", U7="Projet OCM (HUAWEI)","TRAVAUX-HUAWEI", U7="Projet OCM (NOKIA)","TRAVAUX -NOKIA", U7="ACCESS-ISSUE","ACCESS-ISSUE", U7="Projet OCM (ZTE, NOKIA, autres projets)","TRAVAUX OCM", U7="No root CAuse","No root cause", U7="ODU HS","TX ISSUE", U7="IP & VLAN","TX ISSUE", U7="Warehouse HUAWEI","SPARE-ISSUE", U7="SPARE-HS","SPARE-ISSUE", U7="Power Telco","RAN ISSUE",U7="no impacts","no impacts" ),"")} -> POWER ISSUE | U7: Defaut GE & Power Cabinet | V7: {=IFERROR(_xlfn.IFS( U7="MPR ISSUE","ACTIVE", U7="BSS Hardware Issue","ACTIVE", U7="Sites strategiques, MLL, Pylone, etc.","PASSIVE", U7="AKTIVCO DEFAUT GE & POWER Cabinet","PASSIVE", U7="AKTIVCO Coupure ENEO & Baisse de tension","PASSIVE", U7="Coupure ENEO & Baisse de tension","PASSIVE", U7="Defaut GE & POWER Cabinet","PASSIVE", U7="Sharing","PASSIVE", U7="Sites strategiques & DataCenter","PASSIVE", U7="Exclu","Exclu", U7="SAT","ACTIVE", U7="SPARE-ISSUE","SPARE-ISSUE", U7="Fiber CAmtel","ACTIVE", U7="Fiber AOF","ACTIVE", U7="Projet OCM (HUAWEI)","PLANNED WORKS", U7="Projet OCM (NOKIA)","PLANNED WORKS", U7="ACCESS-ISSUE","ACCESS-ISSUE", U7="Projet OCM (ZTE, NOKIA, autres projets)","PLANNED WORKS", U7="No root CAuse","No root cause", U7="ODU HS","ACTIVE", U7="IP & VLAN","ACTIVE", U7="Warehouse HUAWEI","SPARE-ISSUE", U7="SPARE-HS","SPARE-ISSUE", U7="Power Telco","ACTIVE", U7="no impacts","no impacts" ),"")} -> PASSIVE | W7: Power Issue | X7: Solve Power Issue on site | Z7: IHS | AA7: Ongoing | AB7: (04/27/2026 top offenders):-27/04/2026 FME mbah hosiah activé ETA=14H UTC 27/04/2026 Power issue evidence transmis a IHS en attente de retour 26/04/2026 OCM_AOF_CTR_242_CTR_524_E-Poste_BONAS-YDE down CDS activated ETA ASAP ..(04/27/2026 ocm ran 17h):-27/04/2026 FME mbah hosiah activé ETA=14H UTC 27/04/2026 Power issue evidence transmis a IHS en attente de retour 26/04/2026 OCM_AOF_CTR_242_CTR_524_E-Poste_BONAS-YDE down CDS activated ETA ASAP ..(04/27/2026 ocm ran 11h):-27/04/2026 Power issue evidence transmis a IHS en attente de retour 26/04/2026 OCM_AOF_CTR_242_CTR_524_E-Poste_BONAS-YDE down CDS activated ETA ASAP | AC7: =_xlfn.XLOOKUP(B7,'INCIDENT-04-27-2026'!E:E,'INCIDENT-04-27-2026'!F:F,"") | AE7: (04/27/2026 top offenders):-27/04/2026 FME mbah hosiah activé ETA=14H UTC 27/04/2026 Power issue evidence transmis a IHS en attente de retour 26/04/2026 OCM_AOF_CTR_242_CTR_524_E-Poste_BONAS-YDE down CDS activated ETA ASAP | AF7: =_xlfn.XLOOKUP(B7,'[13]Input_27-04'!$B:$B,'[13]Input_27-04'!$M:$M,"") | AI7: =_xlfn.XLOOKUP(B7,'[3]Cells Huawei 27042026 10h'!$B:$B,'[3]Cells Huawei 27042026 10h'!$T:$T,"") | AJ7: =_xlfn.XLOOKUP(B7,'[3]Cells Huawei 27042026 15h'!$B:$B,'[3]Cells Huawei 27042026 15h'!$T:$T,"") | AK7: =_xlfn.XLOOKUP(B7,'[4]cells down 27042026 11h28'!$B:$B,'[4]cells down 27042026 11h28'!$R:$R,"") | AL7: =_xlfn.XLOOKUP(B7,'[4]cells down 27042026 18h01'!$B:$B,'[4]cells down 27042026 18h01'!$R:$R,"") | AM7: =_xlfn.XLOOKUP(B7,'[5]cell downs 27042026 11h'!$B:$B,'[5]cell downs 27042026 11h'!$R:$R,"") | AN7: =_xlfn.XLOOKUP(B7,'[5]cell downs 27042026 17h40'!$B:$B,'[5]cell downs 27042026 17h40'!$R:$R,"") | AO7: =_xlfn.XLOOKUP(B7,'[6]ALL SITES DOWN'!$D:$D,'[6]ALL SITES DOWN'!$J:$J,"") -> (04/27/2026 ocm ran 17h):-27/04/2026 FME mbah hosiah activé ETA=14H UTC 27/04/2026 Power issue evidence transmis a IHS en attente de retour 26/04/2026 OCM_AOF_CTR_242_CTR_524_E-Poste_BONAS-YDE down CDS activated ETA ASAP | AP7: =_xlfn.XLOOKUP(B7,'[7]ALL SITES DOWN'!$D:$D,'[7]ALL SITES DOWN'!$J:$J,"") -> (04/27/2026 ocm ran 11h):-27/04/2026 Power issue evidence transmis a IHS en attente de retour 26/04/2026 OCM_AOF_CTR_242_CTR_524_E-Poste_BONAS-YDE down CDS activated ETA ASAP | AQ7: =_xlfn.XLOOKUP(B7,[8]sheet1!$AC:$AC,[8]sheet1!$AF:$AF,"") | AT7: =_xlfn.XLOOKUP(B7,'[9]cell downs 18042026 17h'!$B:$B,'[9]cell downs 18042026 17h'!$B:$B,"") | AU7: =_xlfn.XLOOKUP(B7,'[10]Cells Huawei 19042026 15h'!$B:$B,'[10]Cells Huawei 19042026 15h'!$B:$B,"") | AV7: =_xlfn.XLOOKUP(B7,'[11]cells down 19042026 9H40'!$B:$B,'[11]cells down 19042026 9H40'!$B:$B,"")
A8: Marche-Central-Bonawon-New | B8: LIT_740 | C8: =_xlfn.XLOOKUP(B8,'[1]daily break down'!$D:$D,'[1]daily break down'!$E:$E,"") -> Douala | D8: CAMUSAT | E8: Good Grid no GE - 8h | F8: LITTORAL | G8: Douala | H8: =_xlfn.XLOOKUP(B8,[2]CALCULATION!$B:$B,[2]CALCULATION!$H:$H,"") -> ZTE | I8: 0 | J8: 5.9068709 | K8: 11.730399 | L8: 34.629408 | M8: 30.956952 | N8: 15.409508 | O8: 45.748314 | P8: REPETITIF | Q8: Operationnel | S8: {=IFERROR(_xlfn.IFS( U8="MPR ISSUE","PDH", U8="BSS Hardware Issue","BSS", U8="Sites strategiques, MLL, Pylone, etc.","ENVTECH", U8="AKTIVCO DEFAUT GE & POWER Cabinet","AKTIVCO", U8="AKTIVCO Coupure ENEO & Baisse de tension","AKTIVCO GRID ONLY", U8="Coupure ENEO & Baisse de tension","IHS GRID ONLY", U8="Defaut GE & POWER Cabinet","IHS", U8="Sharing","Partners", U8="Sites strategiques & DataCenter","SST & DC", U8="Exclu","Exclu", U8="SAT","SAT", U8="SPARE-ISSUE","SPARE-ISSUE", U8="Fiber CAmtel","TRANS_FO_CAMTEL", U8="Fiber AOF","Fiber AOF", U8="Projet OCM (HUAWEI)","TRAVAUX-HUAWEI", U8="Projet OCM (NOKIA)","TRAVAUX-NOKIA", U8="ACCESS-ISSUE","ACCESS-ISSUE", U8="Projet OCM (ZTE, NOKIA, autres projets)","TRAVAUX OCM", U8="No root CAuse","No root cause", U8="ODU HS","PDH", U8="IP & VLAN","PDH", U8="Warehouse HUAWEI","SPARE-ISSUE", U8="SPARE-HS","SPARE-ISSUE", U8="Power Telco","BSS",U8="no impacts","no impacts" ),"")} -> AKTIVCO GRID ONLY | T8: {=IFERROR(_xlfn.IFS( U8="MPR ISSUE","TX ISSUE", U8="BSS Hardware Issue","RAN ISSUE", U8="Sites strategiques, MLL, Pylone, etc.","ENVTECH", U8="AKTIVCO DEFAUT GE & POWER Cabinet","POWER ISSUE", U8="AKTIVCO Coupure ENEO & Baisse de tension","POWER ISSUE", U8="Coupure ENEO & Baisse de tension","POWER ISSUE", U8="Defaut GE & POWER Cabinet","POWER ISSUE", U8="Sharing","POWER ISSUE", U8="Sites strategiques & DataCenter","POWER ISSUE", U8="Exclu","Exclu", U8="SAT","TX ISSUE", U8="SPARE-ISSUE","SPARE-ISSUE", U8="Fiber CAmtel","TX ISSUE", U8="Fiber AOF","TX ISSUE", U8="Projet OCM (HUAWEI)","TRAVAUX-HUAWEI", U8="Projet OCM (NOKIA)","TRAVAUX -NOKIA", U8="ACCESS-ISSUE","ACCESS-ISSUE", U8="Projet OCM (ZTE, NOKIA, autres projets)","TRAVAUX OCM", U8="No root CAuse","No root cause", U8="ODU HS","TX ISSUE", U8="IP & VLAN","TX ISSUE", U8="Warehouse HUAWEI","SPARE-ISSUE", U8="SPARE-HS","SPARE-ISSUE", U8="Power Telco","RAN ISSUE",U8="no impacts","no impacts" ),"")} -> POWER ISSUE | U8: AKTIVCO Coupure ENEO & Baisse de tension | V8: {=IFERROR(_xlfn.IFS( U8="MPR ISSUE","ACTIVE", U8="BSS Hardware Issue","ACTIVE", U8="Sites strategiques, MLL, Pylone, etc.","PASSIVE", U8="AKTIVCO DEFAUT GE & POWER Cabinet","PASSIVE", U8="AKTIVCO Coupure ENEO & Baisse de tension","PASSIVE", U8="Coupure ENEO & Baisse de tension","PASSIVE", U8="Defaut GE & POWER Cabinet","PASSIVE", U8="Sharing","PASSIVE", U8="Sites strategiques & DataCenter","PASSIVE", U8="Exclu","Exclu", U8="SAT","ACTIVE", U8="SPARE-ISSUE","SPARE-ISSUE", U8="Fiber CAmtel","ACTIVE", U8="Fiber AOF","ACTIVE", U8="Projet OCM (HUAWEI)","PLANNED WORKS", U8="Projet OCM (NOKIA)","PLANNED WORKS", U8="ACCESS-ISSUE","ACCESS-ISSUE", U8="Projet OCM (ZTE, NOKIA, autres projets)","PLANNED WORKS", U8="No root CAuse","No root cause", U8="ODU HS","ACTIVE", U8="IP & VLAN","ACTIVE", U8="Warehouse HUAWEI","SPARE-ISSUE", U8="SPARE-HS","SPARE-ISSUE", U8="Power Telco","ACTIVE", U8="no impacts","no impacts" ),"")} -> PASSIVE | W8: Grid outage grid only site | X8: Awaiting Grid return | Z8: CAMUSAT | AA8: Ongoing | AB8: (04/27/2026 top offenders):-27/04/2026 : Besoin d'analyse BO RAN..(04/27/2026 cell zte):-27/04/2026 : Besoin d'analyse BO RAN..(04/27/2026 ticket):-INC-20260427-00010265…2026-04-27 15:44:11…Grid outage and grid only site / Grid return awaited | AC8: =_xlfn.XLOOKUP(B8,'INCIDENT-04-27-2026'!E:E,'INCIDENT-04-27-2026'!F:F,"") | AE8: (04/27/2026 top offenders):-27/04/2026 : Besoin d'analyse BO RAN | AF8: =_xlfn.XLOOKUP(B8,'[13]Input_27-04'!$B:$B,'[13]Input_27-04'!$M:$M,"") -> Grid outage, / grid return awaited | AI8: =_xlfn.XLOOKUP(B8,'[3]Cells Huawei 27042026 10h'!$B:$B,'[3]Cells Huawei 27042026 10h'!$T:$T,"") | AJ8: =_xlfn.XLOOKUP(B8,'[3]Cells Huawei 27042026 15h'!$B:$B,'[3]Cells Huawei 27042026 15h'!$T:$T,"") | AK8: =_xlfn.XLOOKUP(B8,'[4]cells down 27042026 11h28'!$B:$B,'[4]cells down 27042026 11h28'!$R:$R,"") -> (04/27/2026 cell zte):-27/04/2026 : Besoin d'analyse BO RAN | AL8: =_xlfn.XLOOKUP(B8,'[4]cells down 27042026 18h01'!$B:$B,'[4]cells down 27042026 18h01'!$R:$R,"") | AM8: =_xlfn.XLOOKUP(B8,'[5]cell downs 27042026 11h'!$B:$B,'[5]cell downs 27042026 11h'!$R:$R,"") | AN8: =_xlfn.XLOOKUP(B8,'[5]cell downs 27042026 17h40'!$B:$B,'[5]cell downs 27042026 17h40'!$R:$R,"") | AO8: =_xlfn.XLOOKUP(B8,'[6]ALL SITES DOWN'!$D:$D,'[6]ALL SITES DOWN'!$J:$J,"") | AP8: =_xlfn.XLOOKUP(B8,'[7]ALL SITES DOWN'!$D:$D,'[7]ALL SITES DOWN'!$J:$J,"") | AQ8: =_xlfn.XLOOKUP(B8,[8]sheet1!$AC:$AC,[8]sheet1!$AF:$AF,"") -> (04/27/2026 ticket):-INC-20260427-00010265…2026-04-27 15:44:11…Grid outage and grid only site / Grid return awaited | AT8: =_xlfn.XLOOKUP(B8,'[9]cell downs 18042026 17h'!$B:$B,'[9]cell downs 18042026 17h'!$B:$B,"") | AU8: =_xlfn.XLOOKUP(B8,'[10]Cells Huawei 19042026 15h'!$B:$B,'[10]Cells Huawei 19042026 15h'!$B:$B,"") | AV8: =_xlfn.XLOOKUP(B8,'[11]cells down 19042026 9H40'!$B:$B,'[11]cells down 19042026 9H40'!$B:$B,"")
A9: Mboppi-New | B9: LIT_736 | C9: =_xlfn.XLOOKUP(B9,'[1]daily break down'!$D:$D,'[1]daily break down'!$E:$E,"") -> Douala | D9: CAMUSAT | E9: Good Grid no GE - 8h | F9: LITTORAL | G9: Douala | H9: =_xlfn.XLOOKUP(B9,[2]CALCULATION!$B:$B,[2]CALCULATION!$H:$H,"") -> ZTE | I9: 0 | J9: 15.895692 | K9: 13.868557 | L9: 13.868557 | M9: 13.868557 | N9: 13.868557 | O9: 45.674423 | P9: REPETITIF | Q9: Operationnel | S9: {=IFERROR(_xlfn.IFS( U9="MPR ISSUE","PDH", U9="BSS Hardware Issue","BSS", U9="Sites strategiques, MLL, Pylone, etc.","ENVTECH", U9="AKTIVCO DEFAUT GE & POWER Cabinet","AKTIVCO", U9="AKTIVCO Coupure ENEO & Baisse de tension","AKTIVCO GRID ONLY", U9="Coupure ENEO & Baisse de tension","IHS GRID ONLY", U9="Defaut GE & POWER Cabinet","IHS", U9="Sharing","Partners", U9="Sites strategiques & DataCenter","SST & DC", U9="Exclu","Exclu", U9="SAT","SAT", U9="SPARE-ISSUE","SPARE-ISSUE", U9="Fiber CAmtel","TRANS_FO_CAMTEL", U9="Fiber AOF","Fiber AOF", U9="Projet OCM (HUAWEI)","TRAVAUX-HUAWEI", U9="Projet OCM (NOKIA)","TRAVAUX-NOKIA", U9="ACCESS-ISSUE","ACCESS-ISSUE", U9="Projet OCM (ZTE, NOKIA, autres projets)","TRAVAUX OCM", U9="No root CAuse","No root cause", U9="ODU HS","PDH", U9="IP & VLAN","PDH", U9="Warehouse HUAWEI","SPARE-ISSUE", U9="SPARE-HS","SPARE-ISSUE", U9="Power Telco","BSS",U9="no impacts","no impacts" ),"")} -> AKTIVCO GRID ONLY | T9: {=IFERROR(_xlfn.IFS( U9="MPR ISSUE","TX ISSUE", U9="BSS Hardware Issue","RAN ISSUE", U9="Sites strategiques, MLL, Pylone, etc.","ENVTECH", U9="AKTIVCO DEFAUT GE & POWER Cabinet","POWER ISSUE", U9="AKTIVCO Coupure ENEO & Baisse de tension","POWER ISSUE", U9="Coupure ENEO & Baisse de tension","POWER ISSUE", U9="Defaut GE & POWER Cabinet","POWER ISSUE", U9="Sharing","POWER ISSUE", U9="Sites strategiques & DataCenter","POWER ISSUE", U9="Exclu","Exclu", U9="SAT","TX ISSUE", U9="SPARE-ISSUE","SPARE-ISSUE", U9="Fiber CAmtel","TX ISSUE", U9="Fiber AOF","TX ISSUE", U9="Projet OCM (HUAWEI)","TRAVAUX-HUAWEI", U9="Projet OCM (NOKIA)","TRAVAUX -NOKIA", U9="ACCESS-ISSUE","ACCESS-ISSUE", U9="Projet OCM (ZTE, NOKIA, autres projets)","TRAVAUX OCM", U9="No root CAuse","No root cause", U9="ODU HS","TX ISSUE", U9="IP & VLAN","TX ISSUE", U9="Warehouse HUAWEI","SPARE-ISSUE", U9="SPARE-HS","SPARE-ISSUE", U9="Power Telco","RAN ISSUE",U9="no impacts","no impacts" ),"")} -> POWER ISSUE | U9: AKTIVCO Coupure ENEO & Baisse de tension | V9: {=IFERROR(_xlfn.IFS( U9="MPR ISSUE","ACTIVE", U9="BSS Hardware Issue","ACTIVE", U9="Sites strategiques, MLL, Pylone, etc.","PASSIVE", U9="AKTIVCO DEFAUT GE & POWER Cabinet","PASSIVE", U9="AKTIVCO Coupure ENEO & Baisse de tension","PASSIVE", U9="Coupure ENEO & Baisse de tension","PASSIVE", U9="Defaut GE & POWER Cabinet","PASSIVE", U9="Sharing","PASSIVE", U9="Sites strategiques & DataCenter","PASSIVE", U9="Exclu","Exclu", U9="SAT","ACTIVE", U9="SPARE-ISSUE","SPARE-ISSUE", U9="Fiber CAmtel","ACTIVE", U9="Fiber AOF","ACTIVE", U9="Projet OCM (HUAWEI)","PLANNED WORKS", U9="Projet OCM (NOKIA)","PLANNED WORKS", U9="ACCESS-ISSUE","ACCESS-ISSUE", U9="Projet OCM (ZTE, NOKIA, autres projets)","PLANNED WORKS", U9="No root CAuse","No root cause", U9="ODU HS","ACTIVE", U9="IP & VLAN","ACTIVE", U9="Warehouse HUAWEI","SPARE-ISSUE", U9="SPARE-HS","SPARE-ISSUE", U9="Power Telco","ACTIVE", U9="no impacts","no impacts" ),"")} -> PASSIVE | W9: Grid outage et batterie frelon dechargee | X9: Awaiting Grid return (Escalade L4) | Z9: CAMUSAT | AA9: Ongoing | AB9: LIT_736_Z_Mboppi-New ,Grid outage et batterie frelon dechargee..(04/27/2026 top offenders):-26/04/2026 ENEO a fini les travaux dans la zone / Pas eu d'accès site pour diagnostiguer / site à l'interieur du marcher sans accès 24.04.26: Grid outage, Grid only site / Grid return awaited - Escalade L4 23.04.26: Grid outage, Grid only site / Grid return awaited - Escalade L4 23.04.26: Grid outage, Grid only site / Grid return awaited - Escalade L3..(04/27/2026 cell zte):-23/04/2026 : Site down..(04/27/2026 ocm ran 11h):-26/04/2026 ENEO a fini les travaux dans la zone / Pas eu d'accès site pour diagnostiguer / site à l'interieur du marcher sans accès 24.04.26: Grid outage, Grid only site / Grid return awaited - Escalade L4 23.04.26: Grid outage, Grid only site / Grid return awaited - Escalade L4 23.04.26: Grid outage, Grid only site / Grid return awaited - Escalade L3 | AC9: =_xlfn.XLOOKUP(B9,'INCIDENT-04-27-2026'!E:E,'INCIDENT-04-27-2026'!F:F,"") -> (04/27/2026 incident ) :impacted by LIT_736_Z_Mboppi-New ,Grid outage et batterie frelon dechargee || Actrion :installation de la betterie Frelon | AD9: LIT_736_Z_Mboppi-New ,Grid outage et batterie frelon dechargee | AE9: (04/27/2026 top offenders):-26/04/2026 ENEO a fini les travaux dans la zone / Pas eu d'accès site pour diagnostiguer / site à l'interieur du marcher sans accès 24.04.26: Grid outage, Grid only site / Grid return awaited - Escalade L4 23.04.26: Grid outage, Grid only site / Grid return awaited - Escalade L4 23.04.26: Grid outage, Grid only site / Grid return awaited - Escalade L3 | AF9: =_xlfn.XLOOKUP(B9,'[13]Input_27-04'!$B:$B,'[13]Input_27-04'!$M:$M,"") -> Grid outage, / grid return awaited | AI9: =_xlfn.XLOOKUP(B9,'[3]Cells Huawei 27042026 10h'!$B:$B,'[3]Cells Huawei 27042026 10h'!$T:$T,"") | AJ9: =_xlfn.XLOOKUP(B9,'[3]Cells Huawei 27042026 15h'!$B:$B,'[3]Cells Huawei 27042026 15h'!$T:$T,"") | AK9: =_xlfn.XLOOKUP(B9,'[4]cells down 27042026 11h28'!$B:$B,'[4]cells down 27042026 11h28'!$R:$R,"") | AL9: =_xlfn.XLOOKUP(B9,'[4]cells down 27042026 18h01'!$B:$B,'[4]cells down 27042026 18h01'!$R:$R,"") -> (04/27/2026 cell zte):-23/04/2026 : Site down | AM9: =_xlfn.XLOOKUP(B9,'[5]cell downs 27042026 11h'!$B:$B,'[5]cell downs 27042026 11h'!$R:$R,"") | AN9: =_xlfn.XLOOKUP(B9,'[5]cell downs 27042026 17h40'!$B:$B,'[5]cell downs 27042026 17h40'!$R:$R,"") | AO9: =_xlfn.XLOOKUP(B9,'[6]ALL SITES DOWN'!$D:$D,'[6]ALL SITES DOWN'!$J:$J,"") | AP9: =_xlfn.XLOOKUP(B9,'[7]ALL SITES DOWN'!$D:$D,'[7]ALL SITES DOWN'!$J:$J,"") -> (04/27/2026 ocm ran 11h):-26/04/2026 ENEO a fini les travaux dans la zone / Pas eu d'accès site pour diagnostiguer / site à l'interieur du marcher sans accès 24.04.26: Grid outage, Grid only site / Grid return awaited - Escalade L4 23.04.26: Grid outage, Grid only site / Grid return awaited - Escalade L4 23.04.26: Grid outage, Grid only site / Grid return awaited - Escalade L3 | AQ9: =_xlfn.XLOOKUP(B9,[8]sheet1!$AC:$AC,[8]sheet1!$AF:$AF,"") | AT9: =_xlfn.XLOOKUP(B9,'[9]cell downs 18042026 17h'!$B:$B,'[9]cell downs 18042026 17h'!$B:$B,"") | AU9: =_xlfn.XLOOKUP(B9,'[10]Cells Huawei 19042026 15h'!$B:$B,'[10]Cells Huawei 19042026 15h'!$B:$B,"") | AV9: =_xlfn.XLOOKUP(B9,'[11]cells down 19042026 9H40'!$B:$B,'[11]cells down 19042026 9H40'!$B:$B,"")
A10: PK5-Auberge | B10: LIT_647 | C10: =_xlfn.XLOOKUP(B10,'[1]daily break down'!$D:$D,'[1]daily break down'!$E:$E,"") -> Douala | D10: CAMUSAT | E10: Good Grid no GE - 12h | F10: LITTORAL | G10: Douala | H10: =_xlfn.XLOOKUP(B10,[2]CALCULATION!$B:$B,[2]CALCULATION!$H:$H,"") -> ZTE | I10: 27.34731 | J10: 43.775326 | K10: 12.738401 | L10: 22.509599 | M10: 21.703864 | N10: 9.2160984 | O10: 44.204366 | P10: REPETITIF | Q10: Operationnel | S10: {=IFERROR(_xlfn.IFS( U10="MPR ISSUE","PDH", U10="BSS Hardware Issue","BSS", U10="Sites strategiques, MLL, Pylone, etc.","ENVTECH", U10="AKTIVCO DEFAUT GE & POWER Cabinet","AKTIVCO", U10="AKTIVCO Coupure ENEO & Baisse de tension","AKTIVCO GRID ONLY", U10="Coupure ENEO & Baisse de tension","IHS GRID ONLY", U10="Defaut GE & POWER Cabinet","IHS", U10="Sharing","Partners", U10="Sites strategiques & DataCenter","SST & DC", U10="Exclu","Exclu", U10="SAT","SAT", U10="SPARE-ISSUE","SPARE-ISSUE", U10="Fiber CAmtel","TRANS_FO_CAMTEL", U10="Fiber AOF","Fiber AOF", U10="Projet OCM (HUAWEI)","TRAVAUX-HUAWEI", U10="Projet OCM (NOKIA)","TRAVAUX-NOKIA", U10="ACCESS-ISSUE","ACCESS-ISSUE", U10="Projet OCM (ZTE, NOKIA, autres projets)","TRAVAUX OCM", U10="No root CAuse","No root cause", U10="ODU HS","PDH", U10="IP & VLAN","PDH", U10="Warehouse HUAWEI","SPARE-ISSUE", U10="SPARE-HS","SPARE-ISSUE", U10="Power Telco","BSS",U10="no impacts","no impacts" ),"")} -> AKTIVCO GRID ONLY | T10: {=IFERROR(_xlfn.IFS( U10="MPR ISSUE","TX ISSUE", U10="BSS Hardware Issue","RAN ISSUE", U10="Sites strategiques, MLL, Pylone, etc.","ENVTECH", U10="AKTIVCO DEFAUT GE & POWER Cabinet","POWER ISSUE", U10="AKTIVCO Coupure ENEO & Baisse de tension","POWER ISSUE", U10="Coupure ENEO & Baisse de tension","POWER ISSUE", U10="Defaut GE & POWER Cabinet","POWER ISSUE", U10="Sharing","POWER ISSUE", U10="Sites strategiques & DataCenter","POWER ISSUE", U10="Exclu","Exclu", U10="SAT","TX ISSUE", U10="SPARE-ISSUE","SPARE-ISSUE", U10="Fiber CAmtel","TX ISSUE", U10="Fiber AOF","TX ISSUE", U10="Projet OCM (HUAWEI)","TRAVAUX-HUAWEI", U10="Projet OCM (NOKIA)","TRAVAUX -NOKIA", U10="ACCESS-ISSUE","ACCESS-ISSUE", U10="Projet OCM (ZTE, NOKIA, autres projets)","TRAVAUX OCM", U10="No root CAuse","No root cause", U10="ODU HS","TX ISSUE", U10="IP & VLAN","TX ISSUE", U10="Warehouse HUAWEI","SPARE-ISSUE", U10="SPARE-HS","SPARE-ISSUE", U10="Power Telco","RAN ISSUE",U10="no impacts","no impacts" ),"")} -> POWER ISSUE | U10: AKTIVCO Coupure ENEO & Baisse de tension | V10: {=IFERROR(_xlfn.IFS( U10="MPR ISSUE","ACTIVE", U10="BSS Hardware Issue","ACTIVE", U10="Sites strategiques, MLL, Pylone, etc.","PASSIVE", U10="AKTIVCO DEFAUT GE & POWER Cabinet","PASSIVE", U10="AKTIVCO Coupure ENEO & Baisse de tension","PASSIVE", U10="Coupure ENEO & Baisse de tension","PASSIVE", U10="Defaut GE & POWER Cabinet","PASSIVE", U10="Sharing","PASSIVE", U10="Sites strategiques & DataCenter","PASSIVE", U10="Exclu","Exclu", U10="SAT","ACTIVE", U10="SPARE-ISSUE","SPARE-ISSUE", U10="Fiber CAmtel","ACTIVE", U10="Fiber AOF","ACTIVE", U10="Projet OCM (HUAWEI)","PLANNED WORKS", U10="Projet OCM (NOKIA)","PLANNED WORKS", U10="ACCESS-ISSUE","ACCESS-ISSUE", U10="Projet OCM (ZTE, NOKIA, autres projets)","PLANNED WORKS", U10="No root CAuse","No root cause", U10="ODU HS","ACTIVE", U10="IP & VLAN","ACTIVE", U10="Warehouse HUAWEI","SPARE-ISSUE", U10="SPARE-HS","SPARE-ISSUE", U10="Power Telco","ACTIVE", U10="no impacts","no impacts" ),"")} -> PASSIVE | W10: Grid Outage | X10: Awaiting Grid return | Z10: CAMUSAT | AA10: Ongoing | AB10: (04/27/2026 top offenders):-power status check ongoing..(04/27/2026 ticket):-INC-20260427-00010172…2026-04-27 15:42:09…Grid outage and grid only site / Grid return awaited | AC10: =_xlfn.XLOOKUP(B10,'INCIDENT-04-27-2026'!E:E,'INCIDENT-04-27-2026'!F:F,"") | AE10: (04/27/2026 top offenders):-power status check ongoing | AF10: =_xlfn.XLOOKUP(B10,'[13]Input_27-04'!$B:$B,'[13]Input_27-04'!$M:$M,"") -> Grid outage, / grid return awaited | AI10: =_xlfn.XLOOKUP(B10,'[3]Cells Huawei 27042026 10h'!$B:$B,'[3]Cells Huawei 27042026 10h'!$T:$T,"") | AJ10: =_xlfn.XLOOKUP(B10,'[3]Cells Huawei 27042026 15h'!$B:$B,'[3]Cells Huawei 27042026 15h'!$T:$T,"") | AK10: =_xlfn.XLOOKUP(B10,'[4]cells down 27042026 11h28'!$B:$B,'[4]cells down 27042026 11h28'!$R:$R,"") | AL10: =_xlfn.XLOOKUP(B10,'[4]cells down 27042026 18h01'!$B:$B,'[4]cells down 27042026 18h01'!$R:$R,"") | AM10: =_xlfn.XLOOKUP(B10,'[5]cell downs 27042026 11h'!$B:$B,'[5]cell downs 27042026 11h'!$R:$R,"") | AN10: =_xlfn.XLOOKUP(B10,'[5]cell downs 27042026 17h40'!$B:$B,'[5]cell downs 27042026 17h40'!$R:$R,"") | AO10: =_xlfn.XLOOKUP(B10,'[6]ALL SITES DOWN'!$D:$D,'[6]ALL SITES DOWN'!$J:$J,"") | AP10: =_xlfn.XLOOKUP(B10,'[7]ALL SITES DOWN'!$D:$D,'[7]ALL SITES DOWN'!$J:$J,"") | AQ10: =_xlfn.XLOOKUP(B10,[8]sheet1!$AC:$AC,[8]sheet1!$AF:$AF,"") -> (04/27/2026 ticket):-INC-20260427-00010172…2026-04-27 15:42:09…Grid outage and grid only site / Grid return awaited | AT10: =_xlfn.XLOOKUP(B10,'[9]cell downs 18042026 17h'!$B:$B,'[9]cell downs 18042026 17h'!$B:$B,"") | AU10: =_xlfn.XLOOKUP(B10,'[10]Cells Huawei 19042026 15h'!$B:$B,'[10]Cells Huawei 19042026 15h'!$B:$B,"") | AV10: =_xlfn.XLOOKUP(B10,'[11]cells down 19042026 9H40'!$B:$B,'[11]cells down 19042026 9H40'!$B:$B,"") -> LIT_647
