Workbook

Sheet RECAP
F4: oprationnel | G4: (All)
B6: oprationnel | C6: (All) | F6: Row Labels | G6: Sum of NUR 22/04/2026
F7: ACCESS-ISSUE | G7: 50.441198
B8: Row Labels | C8: Sum of NUR 21/04/2026 | F8: ENVTECH | G8: 18.491409
B9: ACCESS-ISSUE | C9: 45.65501 | F9: Exclu | G9: 200.88829
B10: ACTIVE | C10: 342.35738 | F10: no impacts | G10: 48.016386
B11: Exclu | C11: 191.61879 | F11: No root cause | G11: 528.70434
B12: no impacts | C12: 663.56424 | F12: POWER ISSUE | G12: 1364.3467
B13: No root cause | C13: 489.8306 | F13: RAN ISSUE | G13: 169.84374
B14: PASSIVE | C14: 855.67351 | F14: SPARE-ISSUE | G14: 151.59937
B15: PLANNED WORKS | C15: 0 | F15: TRAVAUX-HUAWEI | G15: 0
B16: SPARE-ISSUE | C16: 132.50799 | F16: TX ISSUE | G16: 202.77058
B17: Grand Total | C17: 2721.2075 | F17: Grand Total | G17: 2735.102

Sheet daily break down
A1: Nom du Physique | B1: Codesite | C1: CLUSTER | D1: Owner | E1: Topology | F1: Region | G1: Ville | H1: VENDOR | I1: 17/4/2026 | J1: 18/4/2026 | K1: 19/4/2026 | L1: 20/04/2026 | M1: 21/4/2026 | N1: 22/4/2026 | O1: 23/4/2026 | P1: REPETITIF | Q1: oprationnel | R1: Raison d'exclusion | S1: OCM NOMENCLATURE | T1: SUB RCA | U1: CAUSE | V1: CATEGORIE | W1: RCA | X1: Action Plan | Y1: ETR | Z1: Owner | AA1: Status | AB1: Verifications 23/04/2026 | AC1: UPDATE 23/04/2026 | AD1: INCIDENT 23/04/2026 | AE1: top offenders 23/04/2026 | AF1: RETOUR CAMUSAT 23/04/2026 | AG1: RETOUR IHS 23/04/2026 | AH1: Hourly IHS 23/04/2026 | AI1: Cells Huawei 23042026 9h | AJ1: Cells Huawei 23042026 15h | AK1: Cells Huawei 23042026 18h | AL1: cells down 23042026 8h31 | AM1: cells down 23042026 14h33 | AN1: cells down 23042026 16h41 | AO1: cell downs 23042026 8h40 | AP1: cell downs 23042026 12h30 | AQ1: cell downs 23042026 17h | AR1: OCM Ran 23/04/2026 18H | AS1: OCM Ran 23/04/2026 17H | AT1: OCM Ran 23/04/2026 13H | AU1: Ticket 23/04/2026 | AV1: Dashbord suivi TOP OFFENDERS 23/04/2026 | AW1: SITE WITH GPS ISSUE | AX1: nokia number cell | AY1: HUAWEI number cell | AZ1: Incident | BA1: ENEO CRISIS
A2: Nkololoun | B2: LIT_183 | C2: =_xlfn.XLOOKUP(B2,'[1]daily break down'!$D:$D,'[1]daily break down'!$E:$E,"") -> Douala | D2: IHS | E2: GridOnly | F2: LITTORAL | G2: Douala | H2: =_xlfn.XLOOKUP(B2,[2]CALCULATION!$B:$B,[2]CALCULATION!$H:$H,"") -> ZTE | I2: 0 | J2: 27.146255 | K2: 18.560467 | L2: 23.181054 | M2: 7.8696035 | N2: 60.072022 | O2: 12.314212 | P2: REPETITIF | Q2: Operationnel | S2: {=IFERROR(_xlfn.IFS( U2="MPR ISSUE","PDH", U2="BSS Hardware Issue","BSS", U2="Sites strategiques, MLL, Pylone, etc.","ENVTECH", U2="AKTIVCO DEFAUT GE & POWER Cabinet","AKTIVCO", U2="AKTIVCO Coupure ENEO & Baisse de tension","AKTIVCO GRID ONLY", U2="Coupure ENEO & Baisse de tension","IHS GRID ONLY", U2="Defaut GE & POWER Cabinet","IHS", U2="Sharing","Partners", U2="Sites strategiques & DataCenter","SST & DC", U2="Exclu","Exclu", U2="SAT","SAT", U2="SPARE-ISSUE","SPARE-ISSUE", U2="Fiber CAmtel","TRANS_FO_CAMTEL", U2="Fiber AOF","Fiber AOF", U2="Projet OCM (HUAWEI)","TRAVAUX-HUAWEI", U2="Projet OCM (NOKIA)","TRAVAUX-NOKIA", U2="ACCESS-ISSUE","ACCESS-ISSUE", U2="Projet OCM (ZTE, NOKIA, autres projets)","TRAVAUX OCM", U2="No root CAuse","No root cause", U2="ODU HS","PDH", U2="IP & VLAN","PDH", U2="Warehouse HUAWEI","SPARE-ISSUE", U2="SPARE-HS","SPARE-ISSUE", U2="Power Telco","BSS",U2="no impacts","no impacts" ),"")} | T2: {=IFERROR(_xlfn.IFS( U2="MPR ISSUE","TX ISSUE", U2="BSS Hardware Issue","RAN ISSUE", U2="Sites strategiques, MLL, Pylone, etc.","ENVTECH", U2="AKTIVCO DEFAUT GE & POWER Cabinet","POWER ISSUE", U2="AKTIVCO Coupure ENEO & Baisse de tension","POWER ISSUE", U2="Coupure ENEO & Baisse de tension","POWER ISSUE", U2="Defaut GE & POWER Cabinet","POWER ISSUE", U2="Sharing","POWER ISSUE", U2="Sites strategiques & DataCenter","POWER ISSUE", U2="Exclu","Exclu", U2="SAT","TX ISSUE", U2="SPARE-ISSUE","SPARE-ISSUE", U2="Fiber CAmtel","TX ISSUE", U2="Fiber AOF","TX ISSUE", U2="Projet OCM (HUAWEI)","TRAVAUX-HUAWEI", U2="Projet OCM (NOKIA)","TRAVAUX -NOKIA", U2="ACCESS-ISSUE","ACCESS-ISSUE", U2="Projet OCM (ZTE, NOKIA, autres projets)","TRAVAUX OCM", U2="No root CAuse","No root cause", U2="ODU HS","TX ISSUE", U2="IP & VLAN","TX ISSUE", U2="Warehouse HUAWEI","SPARE-ISSUE", U2="SPARE-HS","SPARE-ISSUE", U2="Power Telco","RAN ISSUE",U2="no impacts","no impacts" ),"")} | V2: {=IFERROR(_xlfn.IFS( U2="MPR ISSUE","ACTIVE", U2="BSS Hardware Issue","ACTIVE", U2="Sites strategiques, MLL, Pylone, etc.","PASSIVE", U2="AKTIVCO DEFAUT GE & POWER Cabinet","PASSIVE", U2="AKTIVCO Coupure ENEO & Baisse de tension","PASSIVE", U2="Coupure ENEO & Baisse de tension","PASSIVE", U2="Defaut GE & POWER Cabinet","PASSIVE", U2="Sharing","PASSIVE", U2="Sites strategiques & DataCenter","PASSIVE", U2="Exclu","Exclu", U2="SAT","ACTIVE", U2="SPARE-ISSUE","SPARE-ISSUE", U2="Fiber CAmtel","ACTIVE", U2="Fiber AOF","ACTIVE", U2="Projet OCM (HUAWEI)","PLANNED WORKS", U2="Projet OCM (NOKIA)","PLANNED WORKS", U2="ACCESS-ISSUE","ACCESS-ISSUE", U2="Projet OCM (ZTE, NOKIA, autres projets)","PLANNED WORKS", U2="No root CAuse","No root cause", U2="ODU HS","ACTIVE", U2="IP & VLAN","ACTIVE", U2="Warehouse HUAWEI","SPARE-ISSUE", U2="SPARE-HS","SPARE-ISSUE", U2="Power Telco","ACTIVE", U2="no impacts","no impacts" ),"")} | W2: =_xlfn.XLOOKUP(B2,[3]Sheet2!$B:$B,[3]Sheet2!$S:$S,"") -> Grid only, Grid outage no space | X2: Awaiting Grid return | Z2: IHS | AA2: Ongoing | AB2: (04/23/2026 hourly IHS):-2:51:43-Grid only, no space//awaiting grid return..INC-20260423-00016006…Others Transmission equipement fault | AH2: (04/23/2026 hourly IHS):-2:51:43-Grid only, no space//awaiting grid return | AU2: INC-20260423-00016006…Others Transmission equipement fault | AX2: =_xlfn.XLOOKUP(B2,'[4]cell downs 18042026 17h'!$B:$B,'[4]cell downs 18042026 17h'!$B:$B,"") | AY2: =_xlfn.XLOOKUP(B2,'[5]Cells Huawei 19042026 15h'!$B:$B,'[5]Cells Huawei 19042026 15h'!$B:$B,"") | AZ2: =_xlfn.XLOOKUP(B2,'INCIDENT-04-23-2026'!E:E,'INCIDENT-04-23-2026'!F:F,"") | BA2: =_xlfn.XLOOKUP(B2,'[6]Eneo 17H'!$C:$C,'[6]Eneo 17H'!$I:$I,"") | BC2: =_xlfn.XLOOKUP(B2,'[6]Eneo 17H'!$C:$C,'[6]Eneo 17H'!$I:$I,"") | BD2: =_xlfn.XLOOKUP(B2,'[7]Eneo 12H'!$C:$C,'[7]Eneo 12H'!$I:$I,"") | BE2: Grid only no space // awaiting grid return
A3: SIC-Cacao | B3: LIT_654 | C3: =_xlfn.XLOOKUP(B3,'[1]daily break down'!$D:$D,'[1]daily break down'!$E:$E,"") -> Douala | D3: CAMUSAT | E3: Good Grid no GE - 12h | F3: LITTORAL | G3: Douala | H3: =_xlfn.XLOOKUP(B3,[2]CALCULATION!$B:$B,[2]CALCULATION!$H:$H,"") -> ZTE | I3: 13.069367 | J3: 13.621077 | K3: 12.901592 | L3: 12.210162 | M3: 12.980477 | N3: 45.540695 | O3: 25.477998 | P3: REPETITIF | Q3: Operationnel | S3: {=IFERROR(_xlfn.IFS( U3="MPR ISSUE","PDH", U3="BSS Hardware Issue","BSS", U3="Sites strategiques, MLL, Pylone, etc.","ENVTECH", U3="AKTIVCO DEFAUT GE & POWER Cabinet","AKTIVCO", U3="AKTIVCO Coupure ENEO & Baisse de tension","AKTIVCO GRID ONLY", U3="Coupure ENEO & Baisse de tension","IHS GRID ONLY", U3="Defaut GE & POWER Cabinet","IHS", U3="Sharing","Partners", U3="Sites strategiques & DataCenter","SST & DC", U3="Exclu","Exclu", U3="SAT","SAT", U3="SPARE-ISSUE","SPARE-ISSUE", U3="Fiber CAmtel","TRANS_FO_CAMTEL", U3="Fiber AOF","Fiber AOF", U3="Projet OCM (HUAWEI)","TRAVAUX-HUAWEI", U3="Projet OCM (NOKIA)","TRAVAUX-NOKIA", U3="ACCESS-ISSUE","ACCESS-ISSUE", U3="Projet OCM (ZTE, NOKIA, autres projets)","TRAVAUX OCM", U3="No root CAuse","No root cause", U3="ODU HS","PDH", U3="IP & VLAN","PDH", U3="Warehouse HUAWEI","SPARE-ISSUE", U3="SPARE-HS","SPARE-ISSUE", U3="Power Telco","BSS",U3="no impacts","no impacts" ),"")} | T3: {=IFERROR(_xlfn.IFS( U3="MPR ISSUE","TX ISSUE", U3="BSS Hardware Issue","RAN ISSUE", U3="Sites strategiques, MLL, Pylone, etc.","ENVTECH", U3="AKTIVCO DEFAUT GE & POWER Cabinet","POWER ISSUE", U3="AKTIVCO Coupure ENEO & Baisse de tension","POWER ISSUE", U3="Coupure ENEO & Baisse de tension","POWER ISSUE", U3="Defaut GE & POWER Cabinet","POWER ISSUE", U3="Sharing","POWER ISSUE", U3="Sites strategiques & DataCenter","POWER ISSUE", U3="Exclu","Exclu", U3="SAT","TX ISSUE", U3="SPARE-ISSUE","SPARE-ISSUE", U3="Fiber CAmtel","TX ISSUE", U3="Fiber AOF","TX ISSUE", U3="Projet OCM (HUAWEI)","TRAVAUX-HUAWEI", U3="Projet OCM (NOKIA)","TRAVAUX -NOKIA", U3="ACCESS-ISSUE","ACCESS-ISSUE", U3="Projet OCM (ZTE, NOKIA, autres projets)","TRAVAUX OCM", U3="No root CAuse","No root cause", U3="ODU HS","TX ISSUE", U3="IP & VLAN","TX ISSUE", U3="Warehouse HUAWEI","SPARE-ISSUE", U3="SPARE-HS","SPARE-ISSUE", U3="Power Telco","RAN ISSUE",U3="no impacts","no impacts" ),"")} | V3: {=IFERROR(_xlfn.IFS( U3="MPR ISSUE","ACTIVE", U3="BSS Hardware Issue","ACTIVE", U3="Sites strategiques, MLL, Pylone, etc.","PASSIVE", U3="AKTIVCO DEFAUT GE & POWER Cabinet","PASSIVE", U3="AKTIVCO Coupure ENEO & Baisse de tension","PASSIVE", U3="Coupure ENEO & Baisse de tension","PASSIVE", U3="Defaut GE & POWER Cabinet","PASSIVE", U3="Sharing","PASSIVE", U3="Sites strategiques & DataCenter","PASSIVE", U3="Exclu","Exclu", U3="SAT","ACTIVE", U3="SPARE-ISSUE","SPARE-ISSUE", U3="Fiber CAmtel","ACTIVE", U3="Fiber AOF","ACTIVE", U3="Projet OCM (HUAWEI)","PLANNED WORKS", U3="Projet OCM (NOKIA)","PLANNED WORKS", U3="ACCESS-ISSUE","ACCESS-ISSUE", U3="Projet OCM (ZTE, NOKIA, autres projets)","PLANNED WORKS", U3="No root CAuse","No root cause", U3="ODU HS","ACTIVE", U3="IP & VLAN","ACTIVE", U3="Warehouse HUAWEI","SPARE-ISSUE", U3="SPARE-HS","SPARE-ISSUE", U3="Power Telco","ACTIVE", U3="no impacts","no impacts" ),"")} | W3: Grid outage grid only site | X3: Awaiting Grid return | Z3: IHS | AA3: Ongoing | AB3: (04/23/2026 ocm ran 18h): -Power status check ongoing..INC-20260423-00013352…2026-04-23 21:50:40…grid outage grid only site/Grid return awaited | AR3: (04/23/2026 ocm ran 18h): -Power status check ongoing | AU3: INC-20260423-00013352…2026-04-23 21:50:40…grid outage grid only site/Grid return awaited | AX3: =_xlfn.XLOOKUP(B3,'[4]cell downs 18042026 17h'!$B:$B,'[4]cell downs 18042026 17h'!$B:$B,"") | AY3: =_xlfn.XLOOKUP(B3,'[5]Cells Huawei 19042026 15h'!$B:$B,'[5]Cells Huawei 19042026 15h'!$B:$B,"") | AZ3: =_xlfn.XLOOKUP(B3,'INCIDENT-04-23-2026'!E:E,'INCIDENT-04-23-2026'!F:F,"") | BA3: =_xlfn.XLOOKUP(B3,'[6]Eneo 17H'!$C:$C,'[6]Eneo 17H'!$I:$I,"") | BC3: =_xlfn.XLOOKUP(B3,'[6]Eneo 17H'!$C:$C,'[6]Eneo 17H'!$I:$I,"") | BD3: =_xlfn.XLOOKUP(B3,'[7]Eneo 12H'!$C:$C,'[7]Eneo 12H'!$I:$I,"") | BE3: INC-20260420-00013007…2026-04-20 18:26:20…Grid outage/Grid returns is awaited
A4: PK5-Auberge | B4: LIT_647 | C4: =_xlfn.XLOOKUP(B4,'[1]daily break down'!$D:$D,'[1]daily break down'!$E:$E,"") -> Douala | D4: CAMUSAT | E4: Good Grid no GE - 12h | F4: LITTORAL | G4: Douala | H4: =_xlfn.XLOOKUP(B4,[2]CALCULATION!$B:$B,[2]CALCULATION!$H:$H,"") -> ZTE | I4: 0 | J4: 1.1468134 | K4: 59.436718 | L4: 43.199627 | M4: 27.34731 | N4: 43.775326 | O4: 12.738401 | P4: REPETITIF | Q4: Operationnel | S4: {=IFERROR(_xlfn.IFS( U4="MPR ISSUE","PDH", U4="BSS Hardware Issue","BSS", U4="Sites strategiques, MLL, Pylone, etc.","ENVTECH", U4="AKTIVCO DEFAUT GE & POWER Cabinet","AKTIVCO", U4="AKTIVCO Coupure ENEO & Baisse de tension","AKTIVCO GRID ONLY", U4="Coupure ENEO & Baisse de tension","IHS GRID ONLY", U4="Defaut GE & POWER Cabinet","IHS", U4="Sharing","Partners", U4="Sites strategiques & DataCenter","SST & DC", U4="Exclu","Exclu", U4="SAT","SAT", U4="SPARE-ISSUE","SPARE-ISSUE", U4="Fiber CAmtel","TRANS_FO_CAMTEL", U4="Fiber AOF","Fiber AOF", U4="Projet OCM (HUAWEI)","TRAVAUX-HUAWEI", U4="Projet OCM (NOKIA)","TRAVAUX-NOKIA", U4="ACCESS-ISSUE","ACCESS-ISSUE", U4="Projet OCM (ZTE, NOKIA, autres projets)","TRAVAUX OCM", U4="No root CAuse","No root cause", U4="ODU HS","PDH", U4="IP & VLAN","PDH", U4="Warehouse HUAWEI","SPARE-ISSUE", U4="SPARE-HS","SPARE-ISSUE", U4="Power Telco","BSS",U4="no impacts","no impacts" ),"")} | T4: {=IFERROR(_xlfn.IFS( U4="MPR ISSUE","TX ISSUE", U4="BSS Hardware Issue","RAN ISSUE", U4="Sites strategiques, MLL, Pylone, etc.","ENVTECH", U4="AKTIVCO DEFAUT GE & POWER Cabinet","POWER ISSUE", U4="AKTIVCO Coupure ENEO & Baisse de tension","POWER ISSUE", U4="Coupure ENEO & Baisse de tension","POWER ISSUE", U4="Defaut GE & POWER Cabinet","POWER ISSUE", U4="Sharing","POWER ISSUE", U4="Sites strategiques & DataCenter","POWER ISSUE", U4="Exclu","Exclu", U4="SAT","TX ISSUE", U4="SPARE-ISSUE","SPARE-ISSUE", U4="Fiber CAmtel","TX ISSUE", U4="Fiber AOF","TX ISSUE", U4="Projet OCM (HUAWEI)","TRAVAUX-HUAWEI", U4="Projet OCM (NOKIA)","TRAVAUX -NOKIA", U4="ACCESS-ISSUE","ACCESS-ISSUE", U4="Projet OCM (ZTE, NOKIA, autres projets)","TRAVAUX OCM", U4="No root CAuse","No root cause", U4="ODU HS","TX ISSUE", U4="IP & VLAN","TX ISSUE", U4="Warehouse HUAWEI","SPARE-ISSUE", U4="SPARE-HS","SPARE-ISSUE", U4="Power Telco","RAN ISSUE",U4="no impacts","no impacts" ),"")} | V4: {=IFERROR(_xlfn.IFS( U4="MPR ISSUE","ACTIVE", U4="BSS Hardware Issue","ACTIVE", U4="Sites strategiques, MLL, Pylone, etc.","PASSIVE", U4="AKTIVCO DEFAUT GE & POWER Cabinet","PASSIVE", U4="AKTIVCO Coupure ENEO & Baisse de tension","PASSIVE", U4="Coupure ENEO & Baisse de tension","PASSIVE", U4="Defaut GE & POWER Cabinet","PASSIVE", U4="Sharing","PASSIVE", U4="Sites strategiques & DataCenter","PASSIVE", U4="Exclu","Exclu", U4="SAT","ACTIVE", U4="SPARE-ISSUE","SPARE-ISSUE", U4="Fiber CAmtel","ACTIVE", U4="Fiber AOF","ACTIVE", U4="Projet OCM (HUAWEI)","PLANNED WORKS", U4="Projet OCM (NOKIA)","PLANNED WORKS", U4="ACCESS-ISSUE","ACCESS-ISSUE", U4="Projet OCM (ZTE, NOKIA, autres projets)","PLANNED WORKS", U4="No root CAuse","No root cause", U4="ODU HS","ACTIVE", U4="IP & VLAN","ACTIVE", U4="Warehouse HUAWEI","SPARE-ISSUE", U4="SPARE-HS","SPARE-ISSUE", U4="Power Telco","ACTIVE", U4="no impacts","no impacts" ),"")} | W4: Impacted by LIT_736_Z_Mboppi-New. Grid outage, Grid only site | X4: Awaiting Grid return | Z4: CAMUSAT | AA4: Ongoing | AB4: P2 Incident at Mboppi-New (Power issue). LIT_736_Z_Mboppi-New - Status: Down - Update: Grid outage, Grid only site / Grid return awaited. Good Grid no GE - 8h..P2 Incident at Mboppi-New (Power issue) | AE4: P2 Incident at Mboppi-New (Power issue) | AT4: (04/23/2026 ocm ran 13h): -P2 Incident at Mboppi-New (Power issue) | AU4: INC-20260423-00006742…power issu coupure d'électricité dans la zone en attente du retour secteur site Grid Only …Others Transmission equipement fault | AX4: =_xlfn.XLOOKUP(B4,'[4]cell downs 18042026 17h'!$B:$B,'[4]cell downs 18042026 17h'!$B:$B,"") | AY4: =_xlfn.XLOOKUP(B4,'[5]Cells Huawei 19042026 15h'!$B:$B,'[5]Cells Huawei 19042026 15h'!$B:$B,"") | AZ4: =_xlfn.XLOOKUP(B4,'INCIDENT-04-23-2026'!E:E,'INCIDENT-04-23-2026'!F:F,"") | BA4: =_xlfn.XLOOKUP(B4,'[6]Eneo 17H'!$C:$C,'[6]Eneo 17H'!$I:$I,"") | BB4: =_xlfn.XLOOKUP(B4,[8]ALL!$B:$B,[8]ALL!$M:$M,"") -> P2 Incident at Mboppi-New (Power issue) | BC4: =_xlfn.XLOOKUP(B4,'[6]Eneo 17H'!$C:$C,'[6]Eneo 17H'!$I:$I,"") | BD4: =_xlfn.XLOOKUP(B4,'[7]Eneo 12H'!$C:$C,'[7]Eneo 12H'!$I:$I,"") | BE4: 20.04.26; Camusat; Grid outage, Grid only site / Grid return awaited - L4 19.04.26; Camusat; Grid outage, Grid only site / Grid return awaited - L2..;..;19.04.26; Camusat; Grid outage, Grid only site / Grid return awaited - L2
A5: Batouri | B5: EST_005 | C5: =_xlfn.XLOOKUP(B5,'[1]daily break down'!$D:$D,'[1]daily break down'!$E:$E,"") -> CENTRE | D5: CAMUSAT | E5: Bad Grid + Solar + GE | F5: EST | G5: Batouri | H5: =_xlfn.XLOOKUP(B5,[2]CALCULATION!$B:$B,[2]CALCULATION!$H:$H,"") -> ZTE | I5: 0.0078117643 | J5: 0 | K5: 2.460135 | L5: 21.774348 | M5: 46.768034 | N5: 28.483815 | O5: 28.052616 | P5: REPETITIF | Q5: Operationnel | S5: {=IFERROR(_xlfn.IFS( U5="MPR ISSUE","PDH", U5="BSS Hardware Issue","BSS", U5="Sites strategiques, MLL, Pylone, etc.","ENVTECH", U5="AKTIVCO DEFAUT GE & POWER Cabinet","AKTIVCO", U5="AKTIVCO Coupure ENEO & Baisse de tension","AKTIVCO GRID ONLY", U5="Coupure ENEO & Baisse de tension","IHS GRID ONLY", U5="Defaut GE & POWER Cabinet","IHS", U5="Sharing","Partners", U5="Sites strategiques & DataCenter","SST & DC", U5="Exclu","Exclu", U5="SAT","SAT", U5="SPARE-ISSUE","SPARE-ISSUE", U5="Fiber CAmtel","TRANS_FO_CAMTEL", U5="Fiber AOF","Fiber AOF", U5="Projet OCM (HUAWEI)","TRAVAUX-HUAWEI", U5="Projet OCM (NOKIA)","TRAVAUX-NOKIA", U5="ACCESS-ISSUE","ACCESS-ISSUE", U5="Projet OCM (ZTE, NOKIA, autres projets)","TRAVAUX OCM", U5="No root CAuse","No root cause", U5="ODU HS","PDH", U5="IP & VLAN","PDH", U5="Warehouse HUAWEI","SPARE-ISSUE", U5="SPARE-HS","SPARE-ISSUE", U5="Power Telco","BSS",U5="no impacts","no impacts" ),"")} | T5: {=IFERROR(_xlfn.IFS( U5="MPR ISSUE","TX ISSUE", U5="BSS Hardware Issue","RAN ISSUE", U5="Sites strategiques, MLL, Pylone, etc.","ENVTECH", U5="AKTIVCO DEFAUT GE & POWER Cabinet","POWER ISSUE", U5="AKTIVCO Coupure ENEO & Baisse de tension","POWER ISSUE", U5="Coupure ENEO & Baisse de tension","POWER ISSUE", U5="Defaut GE & POWER Cabinet","POWER ISSUE", U5="Sharing","POWER ISSUE", U5="Sites strategiques & DataCenter","POWER ISSUE", U5="Exclu","Exclu", U5="SAT","TX ISSUE", U5="SPARE-ISSUE","SPARE-ISSUE", U5="Fiber CAmtel","TX ISSUE", U5="Fiber AOF","TX ISSUE", U5="Projet OCM (HUAWEI)","TRAVAUX-HUAWEI", U5="Projet OCM (NOKIA)","TRAVAUX -NOKIA", U5="ACCESS-ISSUE","ACCESS-ISSUE", U5="Projet OCM (ZTE, NOKIA, autres projets)","TRAVAUX OCM", U5="No root CAuse","No root cause", U5="ODU HS","TX ISSUE", U5="IP & VLAN","TX ISSUE", U5="Warehouse HUAWEI","SPARE-ISSUE", U5="SPARE-HS","SPARE-ISSUE", U5="Power Telco","RAN ISSUE",U5="no impacts","no impacts" ),"")} | V5: {=IFERROR(_xlfn.IFS( U5="MPR ISSUE","ACTIVE", U5="BSS Hardware Issue","ACTIVE", U5="Sites strategiques, MLL, Pylone, etc.","PASSIVE", U5="AKTIVCO DEFAUT GE & POWER Cabinet","PASSIVE", U5="AKTIVCO Coupure ENEO & Baisse de tension","PASSIVE", U5="Coupure ENEO & Baisse de tension","PASSIVE", U5="Defaut GE & POWER Cabinet","PASSIVE", U5="Sharing","PASSIVE", U5="Sites strategiques & DataCenter","PASSIVE", U5="Exclu","Exclu", U5="SAT","ACTIVE", U5="SPARE-ISSUE","SPARE-ISSUE", U5="Fiber CAmtel","ACTIVE", U5="Fiber AOF","ACTIVE", U5="Projet OCM (HUAWEI)","PLANNED WORKS", U5="Projet OCM (NOKIA)","PLANNED WORKS", U5="ACCESS-ISSUE","ACCESS-ISSUE", U5="Projet OCM (ZTE, NOKIA, autres projets)","PLANNED WORKS", U5="No root CAuse","No root cause", U5="ODU HS","ACTIVE", U5="IP & VLAN","ACTIVE", U5="Warehouse HUAWEI","SPARE-ISSUE", U5="SPARE-HS","SPARE-ISSUE", U5="Power Telco","ACTIVE", U5="no impacts","no impacts" ),"")} | W5: MPR issue | X5: Check MPR issue | Z5: GNOC | AA5: Ongoing | AB5: EST_211_Z_BATOURI-TRYPANO-MTN-IHS; Besoin d'un FME sur site pour vérifier le statut du MPR; CM-20260423-00002722 | AX5: =_xlfn.XLOOKUP(B5,'[4]cell downs 18042026 17h'!$B:$B,'[4]cell downs 18042026 17h'!$B:$B,"") | AY5: =_xlfn.XLOOKUP(B5,'[5]Cells Huawei 19042026 15h'!$B:$B,'[5]Cells Huawei 19042026 15h'!$B:$B,"") | AZ5: =_xlfn.XLOOKUP(B5,'INCIDENT-04-23-2026'!E:E,'INCIDENT-04-23-2026'!F:F,"") | BA5: =_xlfn.XLOOKUP(B5,'[6]Eneo 17H'!$C:$C,'[6]Eneo 17H'!$I:$I,"") | BC5: =_xlfn.XLOOKUP(B5,'[6]Eneo 17H'!$C:$C,'[6]Eneo 17H'!$I:$I,"") | BD5: =_xlfn.XLOOKUP(B5,'[7]Eneo 12H'!$C:$C,'[7]Eneo 12H'!$I:$I,"") | BE5: 20.04.26; Camusat; Rodrigue is managing with the guard. We will keep you posted..;..;Power status check ongoing..;..;INC-20260420-00010315…2026-04-20 19:46:41…No power issue onsite. according to FME there is transmission issue impacted by Tikonji. Evidences still awaited
A6: Foumbot-Centre-Ville-II | B6: OST_227 | C6: =_xlfn.XLOOKUP(B6,'[1]daily break down'!$D:$D,'[1]daily break down'!$E:$E,"") -> OUEST | D6: CAMUSAT | E6: Medium Grid + GE | F6: OUEST | G6: Foumbot | H6: =_xlfn.XLOOKUP(B6,[2]CALCULATION!$B:$B,[2]CALCULATION!$H:$H,"") -> Huawei | I6: 41.605403 | J6: 41.605671 | K6: 41.605671 | L6: 41.553503 | M6: 41.604066 | N6: 41.520062 | O6: 41.605671 | P6: REPETITIF | Q6: Operationnel | S6: {=IFERROR(_xlfn.IFS( U6="MPR ISSUE","PDH", U6="BSS Hardware Issue","BSS", U6="Sites strategiques, MLL, Pylone, etc.","ENVTECH", U6="AKTIVCO DEFAUT GE & POWER Cabinet","AKTIVCO", U6="AKTIVCO Coupure ENEO & Baisse de tension","AKTIVCO GRID ONLY", U6="Coupure ENEO & Baisse de tension","IHS GRID ONLY", U6="Defaut GE & POWER Cabinet","IHS", U6="Sharing","Partners", U6="Sites strategiques & DataCenter","SST & DC", U6="Exclu","Exclu", U6="SAT","SAT", U6="SPARE-ISSUE","SPARE-ISSUE", U6="Fiber CAmtel","TRANS_FO_CAMTEL", U6="Fiber AOF","Fiber AOF", U6="Projet OCM (HUAWEI)","TRAVAUX-HUAWEI", U6="Projet OCM (NOKIA)","TRAVAUX-NOKIA", U6="ACCESS-ISSUE","ACCESS-ISSUE", U6="Projet OCM (ZTE, NOKIA, autres projets)","TRAVAUX OCM", U6="No root CAuse","No root cause", U6="ODU HS","PDH", U6="IP & VLAN","PDH", U6="Warehouse HUAWEI","SPARE-ISSUE", U6="SPARE-HS","SPARE-ISSUE", U6="Power Telco","BSS",U6="no impacts","no impacts" ),"")} | T6: {=IFERROR(_xlfn.IFS( U6="MPR ISSUE","TX ISSUE", U6="BSS Hardware Issue","RAN ISSUE", U6="Sites strategiques, MLL, Pylone, etc.","ENVTECH", U6="AKTIVCO DEFAUT GE & POWER Cabinet","POWER ISSUE", U6="AKTIVCO Coupure ENEO & Baisse de tension","POWER ISSUE", U6="Coupure ENEO & Baisse de tension","POWER ISSUE", U6="Defaut GE & POWER Cabinet","POWER ISSUE", U6="Sharing","POWER ISSUE", U6="Sites strategiques & DataCenter","POWER ISSUE", U6="Exclu","Exclu", U6="SAT","TX ISSUE", U6="SPARE-ISSUE","SPARE-ISSUE", U6="Fiber CAmtel","TX ISSUE", U6="Fiber AOF","TX ISSUE", U6="Projet OCM (HUAWEI)","TRAVAUX-HUAWEI", U6="Projet OCM (NOKIA)","TRAVAUX -NOKIA", U6="ACCESS-ISSUE","ACCESS-ISSUE", U6="Projet OCM (ZTE, NOKIA, autres projets)","TRAVAUX OCM", U6="No root CAuse","No root cause", U6="ODU HS","TX ISSUE", U6="IP & VLAN","TX ISSUE", U6="Warehouse HUAWEI","SPARE-ISSUE", U6="SPARE-HS","SPARE-ISSUE", U6="Power Telco","RAN ISSUE",U6="no impacts","no impacts" ),"")} | V6: {=IFERROR(_xlfn.IFS( U6="MPR ISSUE","ACTIVE", U6="BSS Hardware Issue","ACTIVE", U6="Sites strategiques, MLL, Pylone, etc.","PASSIVE", U6="AKTIVCO DEFAUT GE & POWER Cabinet","PASSIVE", U6="AKTIVCO Coupure ENEO & Baisse de tension","PASSIVE", U6="Coupure ENEO & Baisse de tension","PASSIVE", U6="Defaut GE & POWER Cabinet","PASSIVE", U6="Sharing","PASSIVE", U6="Sites strategiques & DataCenter","PASSIVE", U6="Exclu","Exclu", U6="SAT","ACTIVE", U6="SPARE-ISSUE","SPARE-ISSUE", U6="Fiber CAmtel","ACTIVE", U6="Fiber AOF","ACTIVE", U6="Projet OCM (HUAWEI)","PLANNED WORKS", U6="Projet OCM (NOKIA)","PLANNED WORKS", U6="ACCESS-ISSUE","ACCESS-ISSUE", U6="Projet OCM (ZTE, NOKIA, autres projets)","PLANNED WORKS", U6="No root CAuse","No root cause", U6="ODU HS","ACTIVE", U6="IP & VLAN","ACTIVE", U6="Warehouse HUAWEI","SPARE-ISSUE", U6="SPARE-HS","SPARE-ISSUE", U6="Power Telco","ACTIVE", U6="no impacts","no impacts" ),"")} | W6: AOF issue | X6: Awaiting BO TX analysis | Z6: GNOC | AA6: Ongoing | AB6: (04/23/2026 cell huawei): -22/04/2026 : Suite des checks de la chaine antennaire en cours par le BO TX 20/04/2026 : Après analyse nous constatons qu’il a eu un souci d’énergie le 16/04/2026 sur le site de FOUMBO-CENTRE-VILLE-II. Aussi l’AOF FOUMBOT_1---- FOUMBO-CENTRE-VILLE-II ne prend pas de trafic. Merci d’impacter CDS pour prise en charge. 20/04/2026 : Escalade en voyee au Manager des BO TX GNOC. Point pris et son feedback attendu 16/04/2026 : Besoin d'analyse BO RAN || All cells down due to SCTP Link Fault . thanks to activate BO TX to check VLAN..(04/23/2026 cell huawei): -22/04/2026 : Suite des checks de la chaine antennaire en cours par le BO TX 20/04/2026 : Après analyse nous constatons qu’il a eu un souci d’énergie le 16/04/2026 sur le site de FOUMBO-CENTRE-VILLE-II. Aussi l’AOF FOUMBOT_1---- FOUMBO-CENTRE-VILLE-II ne prend pas de trafic. Merci d’impacter CDS pour prise en charge. 20/04/2026 : Escalade en voyee au Manager des BO TX GNOC. Point pris et son feedback attendu 16/04/2026 : Besoin d'analyse BO RAN || All cells down due to SCTP Link Fault . thanks to activate BO TX to check VLAN..OST_227..22/04/2026 : Suite des checks de la chaine antennaire en cours par le BO TX 20/04/2026 : Après analyse nous constatons qu’il a eu un souci d’énergie le 16/04/2026 sur le site de FOUMBO-CENTRE-VILLE-II. Aussi l’AOF FOUMBOT_1---- FOUMBO-CENTRE-VILLE-II ne prend pas de trafic. Merci d’impacter CDS pour prise en charge. 20/04/2026 : Escalade en voyee au Manager des BO TX GNOC. Point pris et son feedback attendu 16/04/2026 : Besoin d'analyse BO RAN || All cells down due to SCTP Link Fault . thanks to activate BO TX to check VLAN | AE6: 22/04/2026 : Suite des checks de la chaine antennaire en cours par le BO TX 20/04/2026 : Après analyse nous constatons qu’il a eu un souci d’énergie le 16/04/2026 sur le site de FOUMBO-CENTRE-VILLE-II. Aussi l’AOF FOUMBOT_1---- FOUMBO-CENTRE-VILLE-II ne prend pas de trafic. Merci d’impacter CDS pour prise en charge. 20/04/2026 : Escalade en voyee au Manager des BO TX GNOC. Point pris et son feedback attendu 16/04/2026 : Besoin d'analyse BO RAN || All cells down due to SCTP Link Fault . thanks to activate BO TX to check VLAN | AI6: (04/23/2026 cell huawei): -22/04/2026 : Suite des checks de la chaine antennaire en cours par le BO TX 20/04/2026 : Après analyse nous constatons qu’il a eu un souci d’énergie le 16/04/2026 sur le site de FOUMBO-CENTRE-VILLE-II. Aussi l’AOF FOUMBOT_1---- FOUMBO-CENTRE-VILLE-II ne prend pas de trafic. Merci d’impacter CDS pour prise en charge. 20/04/2026 : Escalade en voyee au Manager des BO TX GNOC. Point pris et son feedback attendu 16/04/2026 : Besoin d'analyse BO RAN || All cells down due to SCTP Link Fault . thanks to activate BO TX to check VLAN | AJ6: (04/23/2026 cell huawei): -22/04/2026 : Suite des checks de la chaine antennaire en cours par le BO TX 20/04/2026 : Après analyse nous constatons qu’il a eu un souci d’énergie le 16/04/2026 sur le site de FOUMBO-CENTRE-VILLE-II. Aussi l’AOF FOUMBOT_1---- FOUMBO-CENTRE-VILLE-II ne prend pas de trafic. Merci d’impacter CDS pour prise en charge. 20/04/2026 : Escalade en voyee au Manager des BO TX GNOC. Point pris et son feedback attendu 16/04/2026 : Besoin d'analyse BO RAN || All cells down due to SCTP Link Fault . thanks to activate BO TX to check VLAN | AX6: =_xlfn.XLOOKUP(B6,'[4]cell downs 18042026 17h'!$B:$B,'[4]cell downs 18042026 17h'!$B:$B,"") | AY6: =_xlfn.XLOOKUP(B6,'[5]Cells Huawei 19042026 15h'!$B:$B,'[5]Cells Huawei 19042026 15h'!$B:$B,"") -> OST_227 | AZ6: =_xlfn.XLOOKUP(B6,'INCIDENT-04-23-2026'!E:E,'INCIDENT-04-23-2026'!F:F,"") | BA6: =_xlfn.XLOOKUP(B6,'[6]Eneo 17H'!$C:$C,'[6]Eneo 17H'!$I:$I,"") | BB6: =_xlfn.XLOOKUP(B6,[8]ALL!$B:$B,[8]ALL!$M:$M,"") -> 22/04/2026 : Suite des checks de la chaine antennaire en cours par le BO TX 20/04/2026 : Après analyse nous constatons qu’il a eu un souci d’énergie le 16/04/2026 sur le site de FOUMBO-CENTRE-VILLE-II. Aussi l’AOF FOUMBOT_1---- FOUMBO-CENTRE-VILLE-II ne prend pas de trafic. Merci d’impacter CDS pour prise en charge. 20/04/2026 : Escalade en voyee au Manager des BO TX GNOC. Point pris et son feedback attendu 16/04/2026 : Besoin d'analyse BO RAN || All cells down due to SCTP Link Fault . thanks to activate BO TX to check VLAN | BC6: =_xlfn.XLOOKUP(B6,'[6]Eneo 17H'!$C:$C,'[6]Eneo 17H'!$I:$I,"") | BD6: =_xlfn.XLOOKUP(B6,'[7]Eneo 12H'!$C:$C,'[7]Eneo 12H'!$I:$I,"") | BE6: 16/04/2026 : Besoin d'analyse BO RAN || All cells down due to SCTP Link Fault . thanks to activate BO TX to check VLAN..;..;20/04/2026 : Escalade en voyee au Manager des BO TX GNOC. Point pris et son feedback attendu 16/04/2026 : Besoin d'analyse BO RAN || All cells down due to SCTP Link Fault . thanks to activate BO TX to check VLAN..;..;16/04/2026 : Besoin d'analyse BO RAN || All cells down due to SCTP Link Fault . thanks to activate BO TX to check VLAN
A7: Ngona | B7: CTR_590 | C7: =_xlfn.XLOOKUP(B7,'[1]daily break down'!$D:$D,'[1]daily break down'!$E:$E,"") -> Yaounde | D7: IHS | E7: Grid-Gen | F7: CENTRE | G7: Yaounde | H7: =_xlfn.XLOOKUP(B7,[2]CALCULATION!$B:$B,[2]CALCULATION!$H:$H,"") -> ZTE | I7: 36.982818 | J7: 36.982818 | K7: 36.982818 | L7: 36.982818 | M7: 36.982818 | N7: 36.982818 | O7: 23.424752 | P7: REPETITIF | Q7: EXCLU | S7: {=IFERROR(_xlfn.IFS( U7="MPR ISSUE","PDH", U7="BSS Hardware Issue","BSS", U7="Sites strategiques, MLL, Pylone, etc.","ENVTECH", U7="AKTIVCO DEFAUT GE & POWER Cabinet","AKTIVCO", U7="AKTIVCO Coupure ENEO & Baisse de tension","AKTIVCO GRID ONLY", U7="Coupure ENEO & Baisse de tension","IHS GRID ONLY", U7="Defaut GE & POWER Cabinet","IHS", U7="Sharing","Partners", U7="Sites strategiques & DataCenter","SST & DC", U7="Exclu","Exclu", U7="SAT","SAT", U7="SPARE-ISSUE","SPARE-ISSUE", U7="Fiber CAmtel","TRANS_FO_CAMTEL", U7="Fiber AOF","Fiber AOF", U7="Projet OCM (HUAWEI)","TRAVAUX-HUAWEI", U7="Projet OCM (NOKIA)","TRAVAUX-NOKIA", U7="ACCESS-ISSUE","ACCESS-ISSUE", U7="Projet OCM (ZTE, NOKIA, autres projets)","TRAVAUX OCM", U7="No root CAuse","No root cause", U7="ODU HS","PDH", U7="IP & VLAN","PDH", U7="Warehouse HUAWEI","SPARE-ISSUE", U7="SPARE-HS","SPARE-ISSUE", U7="Power Telco","BSS",U7="no impacts","no impacts" ),"")} | T7: {=IFERROR(_xlfn.IFS( U7="MPR ISSUE","TX ISSUE", U7="BSS Hardware Issue","RAN ISSUE", U7="Sites strategiques, MLL, Pylone, etc.","ENVTECH", U7="AKTIVCO DEFAUT GE & POWER Cabinet","POWER ISSUE", U7="AKTIVCO Coupure ENEO & Baisse de tension","POWER ISSUE", U7="Coupure ENEO & Baisse de tension","POWER ISSUE", U7="Defaut GE & POWER Cabinet","POWER ISSUE", U7="Sharing","POWER ISSUE", U7="Sites strategiques & DataCenter","POWER ISSUE", U7="Exclu","Exclu", U7="SAT","TX ISSUE", U7="SPARE-ISSUE","SPARE-ISSUE", U7="Fiber CAmtel","TX ISSUE", U7="Fiber AOF","TX ISSUE", U7="Projet OCM (HUAWEI)","TRAVAUX-HUAWEI", U7="Projet OCM (NOKIA)","TRAVAUX -NOKIA", U7="ACCESS-ISSUE","ACCESS-ISSUE", U7="Projet OCM (ZTE, NOKIA, autres projets)","TRAVAUX OCM", U7="No root CAuse","No root cause", U7="ODU HS","TX ISSUE", U7="IP & VLAN","TX ISSUE", U7="Warehouse HUAWEI","SPARE-ISSUE", U7="SPARE-HS","SPARE-ISSUE", U7="Power Telco","RAN ISSUE",U7="no impacts","no impacts" ),"")} | V7: {=IFERROR(_xlfn.IFS( U7="MPR ISSUE","ACTIVE", U7="BSS Hardware Issue","ACTIVE", U7="Sites strategiques, MLL, Pylone, etc.","PASSIVE", U7="AKTIVCO DEFAUT GE & POWER Cabinet","PASSIVE", U7="AKTIVCO Coupure ENEO & Baisse de tension","PASSIVE", U7="Coupure ENEO & Baisse de tension","PASSIVE", U7="Defaut GE & POWER Cabinet","PASSIVE", U7="Sharing","PASSIVE", U7="Sites strategiques & DataCenter","PASSIVE", U7="Exclu","Exclu", U7="SAT","ACTIVE", U7="SPARE-ISSUE","SPARE-ISSUE", U7="Fiber CAmtel","ACTIVE", U7="Fiber AOF","ACTIVE", U7="Projet OCM (HUAWEI)","PLANNED WORKS", U7="Projet OCM (NOKIA)","PLANNED WORKS", U7="ACCESS-ISSUE","ACCESS-ISSUE", U7="Projet OCM (ZTE, NOKIA, autres projets)","PLANNED WORKS", U7="No root CAuse","No root cause", U7="ODU HS","ACTIVE", U7="IP & VLAN","ACTIVE", U7="Warehouse HUAWEI","SPARE-ISSUE", U7="SPARE-HS","SPARE-ISSUE", U7="Power Telco","ACTIVE", U7="no impacts","no impacts" ),"")} | Z7: =_xlfn.XLOOKUP(B7,[9]ALL!$B:$B,[9]ALL!$P:$P,"") -> 0 | AA7: Obs | AB7: (04/23/2026 cell zte): -23/04/2026 : Intervention prevu pour ce jour ETA attendu 22/04/2026 : Spare pas totalement disponible || Reste de Spare en cours d'expedition de douala pour yaounde ce jour 20/04/2026 : Site vendalise..(04/23/2026 cell zte): -23/04/2026 : Intervention prevu pour ce jour ETA attendu || Up apres remplacement de cable vendalise 22/04/2026 : Spare pas totalement disponible || Reste de Spare en cours d'expedition de douala pour yaounde ce jour 20/04/2026 : Site vendalise..CTR_590..23/04/2026 : Intervention prevu pour ce jour ETA attendu || Up apres remplacement de cable vendalise 22/04/2026 : Spare pas totalement disponible || Reste de Spare en cours d'expedition de douala pour yaounde ce jour 20/04/2026 : Site vendalise | AE7: 23/04/2026 : Intervention prevu pour ce jour ETA attendu || Up apres remplacement de cable vendalise 22/04/2026 : Spare pas totalement disponible || Reste de Spare en cours d'expedition de douala pour yaounde ce jour 20/04/2026 : Site vendalise | AL7: (04/23/2026 cell zte): -23/04/2026 : Intervention prevu pour ce jour ETA attendu 22/04/2026 : Spare pas totalement disponible || Reste de Spare en cours d'expedition de douala pour yaounde ce jour 20/04/2026 : Site vendalise | AM7: (04/23/2026 cell zte): -23/04/2026 : Intervention prevu pour ce jour ETA attendu || Up apres remplacement de cable vendalise 22/04/2026 : Spare pas totalement disponible || Reste de Spare en cours d'expedition de douala pour yaounde ce jour 20/04/2026 : Site vendalise | AX7: =_xlfn.XLOOKUP(B7,'[4]cell downs 18042026 17h'!$B:$B,'[4]cell downs 18042026 17h'!$B:$B,"") | AY7: =_xlfn.XLOOKUP(B7,'[5]Cells Huawei 19042026 15h'!$B:$B,'[5]Cells Huawei 19042026 15h'!$B:$B,"") | AZ7: =_xlfn.XLOOKUP(B7,'INCIDENT-04-23-2026'!E:E,'INCIDENT-04-23-2026'!F:F,"") | BA7: =_xlfn.XLOOKUP(B7,'[6]Eneo 17H'!$C:$C,'[6]Eneo 17H'!$I:$I,"") | BB7: =_xlfn.XLOOKUP(B7,[8]ALL!$B:$B,[8]ALL!$M:$M,"") -> 23/04/2026 : Intervention prevu pour ce jour ETA attendu || Up apres remplacement de cable vendalise 22/04/2026 : Spare pas totalement disponible || Reste de Spare en cours d'expedition de douala pour yaounde ce jour 20/04/2026 : Site vendalise | BC7: =_xlfn.XLOOKUP(B7,'[6]Eneo 17H'!$C:$C,'[6]Eneo 17H'!$I:$I,"") | BD7: =_xlfn.XLOOKUP(B7,'[7]Eneo 12H'!$C:$C,'[7]Eneo 12H'!$I:$I,"") | BE7: 20/04/2026 : Besoin d'analyse BO RAN..;..;20/04/2026 : Site vendalise..;..;20/04/2026 : Site vendalise
A8: Lada | B8: CTR_667 | C8: =_xlfn.XLOOKUP(B8,'[1]daily break down'!$D:$D,'[1]daily break down'!$E:$E,"") -> Yaounde | D8: CAMUSAT | E8: Bad Grid + Solar + GE | F8: CENTRE | G8: Lada | H8: =_xlfn.XLOOKUP(B8,[2]CALCULATION!$B:$B,[2]CALCULATION!$H:$H,"") -> ZTE | I8: 1.3079176 | J8: 0 | K8: 4.926441 | L8: 33.85929 | M8: 36.982818 | N8: 36.982604 | O8: 36.982676 | P8: REPETITIF | Q8: Operationnel | S8: {=IFERROR(_xlfn.IFS( U8="MPR ISSUE","PDH", U8="BSS Hardware Issue","BSS", U8="Sites strategiques, MLL, Pylone, etc.","ENVTECH", U8="AKTIVCO DEFAUT GE & POWER Cabinet","AKTIVCO", U8="AKTIVCO Coupure ENEO & Baisse de tension","AKTIVCO GRID ONLY", U8="Coupure ENEO & Baisse de tension","IHS GRID ONLY", U8="Defaut GE & POWER Cabinet","IHS", U8="Sharing","Partners", U8="Sites strategiques & DataCenter","SST & DC", U8="Exclu","Exclu", U8="SAT","SAT", U8="SPARE-ISSUE","SPARE-ISSUE", U8="Fiber CAmtel","TRANS_FO_CAMTEL", U8="Fiber AOF","Fiber AOF", U8="Projet OCM (HUAWEI)","TRAVAUX-HUAWEI", U8="Projet OCM (NOKIA)","TRAVAUX-NOKIA", U8="ACCESS-ISSUE","ACCESS-ISSUE", U8="Projet OCM (ZTE, NOKIA, autres projets)","TRAVAUX OCM", U8="No root CAuse","No root cause", U8="ODU HS","PDH", U8="IP & VLAN","PDH", U8="Warehouse HUAWEI","SPARE-ISSUE", U8="SPARE-HS","SPARE-ISSUE", U8="Power Telco","BSS",U8="no impacts","no impacts" ),"")} | T8: {=IFERROR(_xlfn.IFS( U8="MPR ISSUE","TX ISSUE", U8="BSS Hardware Issue","RAN ISSUE", U8="Sites strategiques, MLL, Pylone, etc.","ENVTECH", U8="AKTIVCO DEFAUT GE & POWER Cabinet","POWER ISSUE", U8="AKTIVCO Coupure ENEO & Baisse de tension","POWER ISSUE", U8="Coupure ENEO & Baisse de tension","POWER ISSUE", U8="Defaut GE & POWER Cabinet","POWER ISSUE", U8="Sharing","POWER ISSUE", U8="Sites strategiques & DataCenter","POWER ISSUE", U8="Exclu","Exclu", U8="SAT","TX ISSUE", U8="SPARE-ISSUE","SPARE-ISSUE", U8="Fiber CAmtel","TX ISSUE", U8="Fiber AOF","TX ISSUE", U8="Projet OCM (HUAWEI)","TRAVAUX-HUAWEI", U8="Projet OCM (NOKIA)","TRAVAUX -NOKIA", U8="ACCESS-ISSUE","ACCESS-ISSUE", U8="Projet OCM (ZTE, NOKIA, autres projets)","TRAVAUX OCM", U8="No root CAuse","No root cause", U8="ODU HS","TX ISSUE", U8="IP & VLAN","TX ISSUE", U8="Warehouse HUAWEI","SPARE-ISSUE", U8="SPARE-HS","SPARE-ISSUE", U8="Power Telco","RAN ISSUE",U8="no impacts","no impacts" ),"")} | V8: {=IFERROR(_xlfn.IFS( U8="MPR ISSUE","ACTIVE", U8="BSS Hardware Issue","ACTIVE", U8="Sites strategiques, MLL, Pylone, etc.","PASSIVE", U8="AKTIVCO DEFAUT GE & POWER Cabinet","PASSIVE", U8="AKTIVCO Coupure ENEO & Baisse de tension","PASSIVE", U8="Coupure ENEO & Baisse de tension","PASSIVE", U8="Defaut GE & POWER Cabinet","PASSIVE", U8="Sharing","PASSIVE", U8="Sites strategiques & DataCenter","PASSIVE", U8="Exclu","Exclu", U8="SAT","ACTIVE", U8="SPARE-ISSUE","SPARE-ISSUE", U8="Fiber CAmtel","ACTIVE", U8="Fiber AOF","ACTIVE", U8="Projet OCM (HUAWEI)","PLANNED WORKS", U8="Projet OCM (NOKIA)","PLANNED WORKS", U8="ACCESS-ISSUE","ACCESS-ISSUE", U8="Projet OCM (ZTE, NOKIA, autres projets)","PLANNED WORKS", U8="No root CAuse","No root cause", U8="ODU HS","ACTIVE", U8="IP & VLAN","ACTIVE", U8="Warehouse HUAWEI","SPARE-ISSUE", U8="SPARE-HS","SPARE-ISSUE", U8="Power Telco","ACTIVE", U8="no impacts","no impacts" ),"")} | W8: Impacted by CTR_315_Z_Bitoto. Grid outage | X8: Awaiting Grid return | Z8: IHS | AA8: Ongoing | AB8: Whatsapp GNOCa Group : Indisponibilité des services mobiles Voix & Data autour de CTR_315_Z_Bitoto Power issue / En attete RCA HIS | AX8: =_xlfn.XLOOKUP(B8,'[4]cell downs 18042026 17h'!$B:$B,'[4]cell downs 18042026 17h'!$B:$B,"") | AY8: =_xlfn.XLOOKUP(B8,'[5]Cells Huawei 19042026 15h'!$B:$B,'[5]Cells Huawei 19042026 15h'!$B:$B,"") | AZ8: =_xlfn.XLOOKUP(B8,'INCIDENT-04-23-2026'!E:E,'INCIDENT-04-23-2026'!F:F,"") -> (04/23/2026 incident ) : impact by CTR_315_Z_Bitoto RCA: Power issue / En attete RCA IHS | BA8: =_xlfn.XLOOKUP(B8,'[6]Eneo 17H'!$C:$C,'[6]Eneo 17H'!$I:$I,"") | BC8: =_xlfn.XLOOKUP(B8,'[6]Eneo 17H'!$C:$C,'[6]Eneo 17H'!$I:$I,"") | BD8: =_xlfn.XLOOKUP(B8,'[7]Eneo 12H'!$C:$C,'[7]Eneo 12H'!$I:$I,"") | BE8: 20/04/2026 : Besoin d'analyse BO RAN..;..;INC-20260420-00000947…2026-04-20 03:13:02…The technician will be on site on the morning for investigation ETA 06h..;..;Impacted by CTR_315_Z_Bitoto (Gen overload)
A9: Kumba-Lutherian-Church-MTN | B9: SUO_054 | C9: =_xlfn.XLOOKUP(B9,'[1]daily break down'!$D:$D,'[1]daily break down'!$E:$E,"") -> SUD-OUEST | D9: IHS | E9: Grid-Gen | F9: SUD-OUEST | G9: Kumba | H9: =_xlfn.XLOOKUP(B9,[2]CALCULATION!$B:$B,[2]CALCULATION!$H:$H,"") -> Huawei | I9: 34.274009 | J9: 34.14779 | K9: 34.268123 | L9: 34.223946 | M9: 34.188971 | N9: 34.212478 | O9: 28.119872 | P9: REPETITIF | Q9: EXCLU | R9: site vandaliser | S9: {=IFERROR(_xlfn.IFS( U9="MPR ISSUE","PDH", U9="BSS Hardware Issue","BSS", U9="Sites strategiques, MLL, Pylone, etc.","ENVTECH", U9="AKTIVCO DEFAUT GE & POWER Cabinet","AKTIVCO", U9="AKTIVCO Coupure ENEO & Baisse de tension","AKTIVCO GRID ONLY", U9="Coupure ENEO & Baisse de tension","IHS GRID ONLY", U9="Defaut GE & POWER Cabinet","IHS", U9="Sharing","Partners", U9="Sites strategiques & DataCenter","SST & DC", U9="Exclu","Exclu", U9="SAT","SAT", U9="SPARE-ISSUE","SPARE-ISSUE", U9="Fiber CAmtel","TRANS_FO_CAMTEL", U9="Fiber AOF","Fiber AOF", U9="Projet OCM (HUAWEI)","TRAVAUX-HUAWEI", U9="Projet OCM (NOKIA)","TRAVAUX-NOKIA", U9="ACCESS-ISSUE","ACCESS-ISSUE", U9="Projet OCM (ZTE, NOKIA, autres projets)","TRAVAUX OCM", U9="No root CAuse","No root cause", U9="ODU HS","PDH", U9="IP & VLAN","PDH", U9="Warehouse HUAWEI","SPARE-ISSUE", U9="SPARE-HS","SPARE-ISSUE", U9="Power Telco","BSS",U9="no impacts","no impacts" ),"")} | T9: {=IFERROR(_xlfn.IFS( U9="MPR ISSUE","TX ISSUE", U9="BSS Hardware Issue","RAN ISSUE", U9="Sites strategiques, MLL, Pylone, etc.","ENVTECH", U9="AKTIVCO DEFAUT GE & POWER Cabinet","POWER ISSUE", U9="AKTIVCO Coupure ENEO & Baisse de tension","POWER ISSUE", U9="Coupure ENEO & Baisse de tension","POWER ISSUE", U9="Defaut GE & POWER Cabinet","POWER ISSUE", U9="Sharing","POWER ISSUE", U9="Sites strategiques & DataCenter","POWER ISSUE", U9="Exclu","Exclu", U9="SAT","TX ISSUE", U9="SPARE-ISSUE","SPARE-ISSUE", U9="Fiber CAmtel","TX ISSUE", U9="Fiber AOF","TX ISSUE", U9="Projet OCM (HUAWEI)","TRAVAUX-HUAWEI", U9="Projet OCM (NOKIA)","TRAVAUX -NOKIA", U9="ACCESS-ISSUE","ACCESS-ISSUE", U9="Projet OCM (ZTE, NOKIA, autres projets)","TRAVAUX OCM", U9="No root CAuse","No root cause", U9="ODU HS","TX ISSUE", U9="IP & VLAN","TX ISSUE", U9="Warehouse HUAWEI","SPARE-ISSUE", U9="SPARE-HS","SPARE-ISSUE", U9="Power Telco","RAN ISSUE",U9="no impacts","no impacts" ),"")} | V9: {=IFERROR(_xlfn.IFS( U9="MPR ISSUE","ACTIVE", U9="BSS Hardware Issue","ACTIVE", U9="Sites strategiques, MLL, Pylone, etc.","PASSIVE", U9="AKTIVCO DEFAUT GE & POWER Cabinet","PASSIVE", U9="AKTIVCO Coupure ENEO & Baisse de tension","PASSIVE", U9="Coupure ENEO & Baisse de tension","PASSIVE", U9="Defaut GE & POWER Cabinet","PASSIVE", U9="Sharing","PASSIVE", U9="Sites strategiques & DataCenter","PASSIVE", U9="Exclu","Exclu", U9="SAT","ACTIVE", U9="SPARE-ISSUE","SPARE-ISSUE", U9="Fiber CAmtel","ACTIVE", U9="Fiber AOF","ACTIVE", U9="Projet OCM (HUAWEI)","PLANNED WORKS", U9="Projet OCM (NOKIA)","PLANNED WORKS", U9="ACCESS-ISSUE","ACCESS-ISSUE", U9="Projet OCM (ZTE, NOKIA, autres projets)","PLANNED WORKS", U9="No root CAuse","No root cause", U9="ODU HS","ACTIVE", U9="IP & VLAN","ACTIVE", U9="Warehouse HUAWEI","SPARE-ISSUE", U9="SPARE-HS","SPARE-ISSUE", U9="Power Telco","ACTIVE", U9="no impacts","no impacts" ),"")} | AB9: SUO_054 | AX9: =_xlfn.XLOOKUP(B9,'[4]cell downs 18042026 17h'!$B:$B,'[4]cell downs 18042026 17h'!$B:$B,"") | AY9: =_xlfn.XLOOKUP(B9,'[5]Cells Huawei 19042026 15h'!$B:$B,'[5]Cells Huawei 19042026 15h'!$B:$B,"") -> SUO_054 | AZ9: =_xlfn.XLOOKUP(B9,'INCIDENT-04-23-2026'!E:E,'INCIDENT-04-23-2026'!F:F,"") | BA9: =_xlfn.XLOOKUP(B9,'[6]Eneo 17H'!$C:$C,'[6]Eneo 17H'!$I:$I,"") | BC9: =_xlfn.XLOOKUP(B9,'[6]Eneo 17H'!$C:$C,'[6]Eneo 17H'!$I:$I,"") | BD9: =_xlfn.XLOOKUP(B9,'[7]Eneo 12H'!$C:$C,'[7]Eneo 12H'!$I:$I,"") | BE9: Besoin d'un FME sur site pour vérifier le statut du MPR; CM-20260413-00005293
A10: Nkolmessing-Abom-MTN | B10: CTR_832 | C10: =_xlfn.XLOOKUP(B10,'[1]daily break down'!$D:$D,'[1]daily break down'!$E:$E,"") -> Yaounde | D10: MTN | F10: CENTRE | G10: Yaounde | H10: =_xlfn.XLOOKUP(B10,[2]CALCULATION!$B:$B,[2]CALCULATION!$H:$H,"") -> ZTE | I10: 32.359966 | J10: 32.359966 | K10: 32.359966 | L10: 32.359966 | M10: 32.359966 | N10: 32.359966 | O10: 24.419343 | P10: REPETITIF | Q10: Operationnel | S10: {=IFERROR(_xlfn.IFS( U10="MPR ISSUE","PDH", U10="BSS Hardware Issue","BSS", U10="Sites strategiques, MLL, Pylone, etc.","ENVTECH", U10="AKTIVCO DEFAUT GE & POWER Cabinet","AKTIVCO", U10="AKTIVCO Coupure ENEO & Baisse de tension","AKTIVCO GRID ONLY", U10="Coupure ENEO & Baisse de tension","IHS GRID ONLY", U10="Defaut GE & POWER Cabinet","IHS", U10="Sharing","Partners", U10="Sites strategiques & DataCenter","SST & DC", U10="Exclu","Exclu", U10="SAT","SAT", U10="SPARE-ISSUE","SPARE-ISSUE", U10="Fiber CAmtel","TRANS_FO_CAMTEL", U10="Fiber AOF","Fiber AOF", U10="Projet OCM (HUAWEI)","TRAVAUX-HUAWEI", U10="Projet OCM (NOKIA)","TRAVAUX-NOKIA", U10="ACCESS-ISSUE","ACCESS-ISSUE", U10="Projet OCM (ZTE, NOKIA, autres projets)","TRAVAUX OCM", U10="No root CAuse","No root cause", U10="ODU HS","PDH", U10="IP & VLAN","PDH", U10="Warehouse HUAWEI","SPARE-ISSUE", U10="SPARE-HS","SPARE-ISSUE", U10="Power Telco","BSS",U10="no impacts","no impacts" ),"")} | T10: {=IFERROR(_xlfn.IFS( U10="MPR ISSUE","TX ISSUE", U10="BSS Hardware Issue","RAN ISSUE", U10="Sites strategiques, MLL, Pylone, etc.","ENVTECH", U10="AKTIVCO DEFAUT GE & POWER Cabinet","POWER ISSUE", U10="AKTIVCO Coupure ENEO & Baisse de tension","POWER ISSUE", U10="Coupure ENEO & Baisse de tension","POWER ISSUE", U10="Defaut GE & POWER Cabinet","POWER ISSUE", U10="Sharing","POWER ISSUE", U10="Sites strategiques & DataCenter","POWER ISSUE", U10="Exclu","Exclu", U10="SAT","TX ISSUE", U10="SPARE-ISSUE","SPARE-ISSUE", U10="Fiber CAmtel","TX ISSUE", U10="Fiber AOF","TX ISSUE", U10="Projet OCM (HUAWEI)","TRAVAUX-HUAWEI", U10="Projet OCM (NOKIA)","TRAVAUX -NOKIA", U10="ACCESS-ISSUE","ACCESS-ISSUE", U10="Projet OCM (ZTE, NOKIA, autres projets)","TRAVAUX OCM", U10="No root CAuse","No root cause", U10="ODU HS","TX ISSUE", U10="IP & VLAN","TX ISSUE", U10="Warehouse HUAWEI","SPARE-ISSUE", U10="SPARE-HS","SPARE-ISSUE", U10="Power Telco","RAN ISSUE",U10="no impacts","no impacts" ),"")} | V10: {=IFERROR(_xlfn.IFS( U10="MPR ISSUE","ACTIVE", U10="BSS Hardware Issue","ACTIVE", U10="Sites strategiques, MLL, Pylone, etc.","PASSIVE", U10="AKTIVCO DEFAUT GE & POWER Cabinet","PASSIVE", U10="AKTIVCO Coupure ENEO & Baisse de tension","PASSIVE", U10="Coupure ENEO & Baisse de tension","PASSIVE", U10="Defaut GE & POWER Cabinet","PASSIVE", U10="Sharing","PASSIVE", U10="Sites strategiques & DataCenter","PASSIVE", U10="Exclu","Exclu", U10="SAT","ACTIVE", U10="SPARE-ISSUE","SPARE-ISSUE", U10="Fiber CAmtel","ACTIVE", U10="Fiber AOF","ACTIVE", U10="Projet OCM (HUAWEI)","PLANNED WORKS", U10="Projet OCM (NOKIA)","PLANNED WORKS", U10="ACCESS-ISSUE","ACCESS-ISSUE", U10="Projet OCM (ZTE, NOKIA, autres projets)","PLANNED WORKS", U10="No root CAuse","No root cause", U10="ODU HS","ACTIVE", U10="IP & VLAN","ACTIVE", U10="Warehouse HUAWEI","SPARE-ISSUE", U10="SPARE-HS","SPARE-ISSUE", U10="Power Telco","ACTIVE", U10="no impacts","no impacts" ),"")} | W10: Impacted by CTR_263_Z_Abom | X10: Coupure AOF, trafic router sur la FH | Z10: GNOC | AA10: Ongoing | AB10: impacted by CTR_263_Z_Abom , Coupure AOF, trafic router sur la FH | AX10: =_xlfn.XLOOKUP(B10,'[4]cell downs 18042026 17h'!$B:$B,'[4]cell downs 18042026 17h'!$B:$B,"") | AY10: =_xlfn.XLOOKUP(B10,'[5]Cells Huawei 19042026 15h'!$B:$B,'[5]Cells Huawei 19042026 15h'!$B:$B,"") | AZ10: =_xlfn.XLOOKUP(B10,'INCIDENT-04-23-2026'!E:E,'INCIDENT-04-23-2026'!F:F,"") | BA10: =_xlfn.XLOOKUP(B10,'[6]Eneo 17H'!$C:$C,'[6]Eneo 17H'!$I:$I,"") | BB10: =_xlfn.XLOOKUP(B2,#REF!,#REF!,"") -> #REF! | BC10: =_xlfn.XLOOKUP(B10,'[6]Eneo 17H'!$C:$C,'[6]Eneo 17H'!$I:$I,"") | BD10: =_xlfn.XLOOKUP(B10,'[7]Eneo 12H'!$C:$C,'[7]Eneo 12H'!$I:$I,"") | BE10: Power issue on site, MTN activated
A11: Ekoumdoum | B11: CTR_259 | C11: =_xlfn.XLOOKUP(B11,'[1]daily break down'!$D:$D,'[1]daily break down'!$E:$E,"") -> Yaounde | D11: CAMUSAT | E11: Grid-Gen | F11: CENTRE | G11: Yaounde | H11: =_xlfn.XLOOKUP(B11,[2]CALCULATION!$B:$B,[2]CALCULATION!$H:$H,"") -> ZTE | I11: 0 | J11: 0 | K11: 0 | L11: 20.349129 | M11: 27.154049 | N11: 32.177549 | O11: 9.2127275 | P11: REPETITIF | Q11: Operationnel | S11: {=IFERROR(_xlfn.IFS( U11="MPR ISSUE","PDH", U11="BSS Hardware Issue","BSS", U11="Sites strategiques, MLL, Pylone, etc.","ENVTECH", U11="AKTIVCO DEFAUT GE & POWER Cabinet","AKTIVCO", U11="AKTIVCO Coupure ENEO & Baisse de tension","AKTIVCO GRID ONLY", U11="Coupure ENEO & Baisse de tension","IHS GRID ONLY", U11="Defaut GE & POWER Cabinet","IHS", U11="Sharing","Partners", U11="Sites strategiques & DataCenter","SST & DC", U11="Exclu","Exclu", U11="SAT","SAT", U11="SPARE-ISSUE","SPARE-ISSUE", U11="Fiber CAmtel","TRANS_FO_CAMTEL", U11="Fiber AOF","Fiber AOF", U11="Projet OCM (HUAWEI)","TRAVAUX-HUAWEI", U11="Projet OCM (NOKIA)","TRAVAUX-NOKIA", U11="ACCESS-ISSUE","ACCESS-ISSUE", U11="Projet OCM (ZTE, NOKIA, autres projets)","TRAVAUX OCM", U11="No root CAuse","No root cause", U11="ODU HS","PDH", U11="IP & VLAN","PDH", U11="Warehouse HUAWEI","SPARE-ISSUE", U11="SPARE-HS","SPARE-ISSUE", U11="Power Telco","BSS",U11="no impacts","no impacts" ),"")} | T11: {=IFERROR(_xlfn.IFS( U11="MPR ISSUE","TX ISSUE", U11="BSS Hardware Issue","RAN ISSUE", U11="Sites strategiques, MLL, Pylone, etc.","ENVTECH", U11="AKTIVCO DEFAUT GE & POWER Cabinet","POWER ISSUE", U11="AKTIVCO Coupure ENEO & Baisse de tension","POWER ISSUE", U11="Coupure ENEO & Baisse de tension","POWER ISSUE", U11="Defaut GE & POWER Cabinet","POWER ISSUE", U11="Sharing","POWER ISSUE", U11="Sites strategiques & DataCenter","POWER ISSUE", U11="Exclu","Exclu", U11="SAT","TX ISSUE", U11="SPARE-ISSUE","SPARE-ISSUE", U11="Fiber CAmtel","TX ISSUE", U11="Fiber AOF","TX ISSUE", U11="Projet OCM (HUAWEI)","TRAVAUX-HUAWEI", U11="Projet OCM (NOKIA)","TRAVAUX -NOKIA", U11="ACCESS-ISSUE","ACCESS-ISSUE", U11="Projet OCM (ZTE, NOKIA, autres projets)","TRAVAUX OCM", U11="No root CAuse","No root cause", U11="ODU HS","TX ISSUE", U11="IP & VLAN","TX ISSUE", U11="Warehouse HUAWEI","SPARE-ISSUE", U11="SPARE-HS","SPARE-ISSUE", U11="Power Telco","RAN ISSUE",U11="no impacts","no impacts" ),"")} | V11: {=IFERROR(_xlfn.IFS( U11="MPR ISSUE","ACTIVE", U11="BSS Hardware Issue","ACTIVE", U11="Sites strategiques, MLL, Pylone, etc.","PASSIVE", U11="AKTIVCO DEFAUT GE & POWER Cabinet","PASSIVE", U11="AKTIVCO Coupure ENEO & Baisse de tension","PASSIVE", U11="Coupure ENEO & Baisse de tension","PASSIVE", U11="Defaut GE & POWER Cabinet","PASSIVE", U11="Sharing","PASSIVE", U11="Sites strategiques & DataCenter","PASSIVE", U11="Exclu","Exclu", U11="SAT","ACTIVE", U11="SPARE-ISSUE","SPARE-ISSUE", U11="Fiber CAmtel","ACTIVE", U11="Fiber AOF","ACTIVE", U11="Projet OCM (HUAWEI)","PLANNED WORKS", U11="Projet OCM (NOKIA)","PLANNED WORKS", U11="ACCESS-ISSUE","ACCESS-ISSUE", U11="Projet OCM (ZTE, NOKIA, autres projets)","PLANNED WORKS", U11="No root CAuse","No root cause", U11="ODU HS","ACTIVE", U11="IP & VLAN","ACTIVE", U11="Warehouse HUAWEI","SPARE-ISSUE", U11="SPARE-HS","SPARE-ISSUE", U11="Power Telco","ACTIVE", U11="no impacts","no impacts" ),"")} | W11: Powercore controller freeze causing site outage | X11: Up after Powercore controller reset, | Z11: CAMUSAT | AA11: Obs | AB11: (04/23/2026 ocm ran 18h): -Power status check ongoing..INC-20260423-00017366…2026-04-23 21:59:27…site was down because the powercore controller froze / Ok after reset…site was down because the powercore controller froze / Ok after reset…Others…site was down because the powercore controller froze / Ok after reset | AR11: (04/23/2026 ocm ran 18h): -Power status check ongoing | AU11: INC-20260423-00017366…2026-04-23 21:59:27…site was down because the powercore controller froze / Ok after reset…site was down because the powercore controller froze / Ok after reset…Others…site was down because the powercore controller froze / Ok after reset | AX11: =_xlfn.XLOOKUP(B11,'[4]cell downs 18042026 17h'!$B:$B,'[4]cell downs 18042026 17h'!$B:$B,"") | AY11: =_xlfn.XLOOKUP(B11,'[5]Cells Huawei 19042026 15h'!$B:$B,'[5]Cells Huawei 19042026 15h'!$B:$B,"") | AZ11: =_xlfn.XLOOKUP(B11,'INCIDENT-04-23-2026'!E:E,'INCIDENT-04-23-2026'!F:F,"") | BA11: =_xlfn.XLOOKUP(B11,'[6]Eneo 17H'!$C:$C,'[6]Eneo 17H'!$I:$I,"") | BC11: =_xlfn.XLOOKUP(B11,'[6]Eneo 17H'!$C:$C,'[6]Eneo 17H'!$I:$I,"") | BD11: =_xlfn.XLOOKUP(B11,'[7]Eneo 12H'!$C:$C,'[7]Eneo 12H'!$I:$I,"") | BE11: Power status check ongoing..;..;INC-20260420-00012653…2026-04-20 17:49:45…FME is onsite working/ More information will be share ASAP
A12: Ngomedzap | B12: CTR_188 | C12: =_xlfn.XLOOKUP(B12,'[1]daily break down'!$D:$D,'[1]daily break down'!$E:$E,"") -> CENTRE | D12: IHS | E12: Grid-Gen | F12: CENTRE | G12: Ngomedzap | H12: =_xlfn.XLOOKUP(B12,[2]CALCULATION!$B:$B,[2]CALCULATION!$H:$H,"") -> NOKIA | I12: 18.490446 | J12: 18.490232 | K12: 18.490553 | L12: 18.490232 | M12: 8.060314 | N12: 0 | O12: 9.9899426 | P12: REPETITIF | Q12: Operationnel | S12: {=IFERROR(_xlfn.IFS( U12="MPR ISSUE","PDH", U12="BSS Hardware Issue","BSS", U12="Sites strategiques, MLL, Pylone, etc.","ENVTECH", U12="AKTIVCO DEFAUT GE & POWER Cabinet","AKTIVCO", U12="AKTIVCO Coupure ENEO & Baisse de tension","AKTIVCO GRID ONLY", U12="Coupure ENEO & Baisse de tension","IHS GRID ONLY", U12="Defaut GE & POWER Cabinet","IHS", U12="Sharing","Partners", U12="Sites strategiques & DataCenter","SST & DC", U12="Exclu","Exclu", U12="SAT","SAT", U12="SPARE-ISSUE","SPARE-ISSUE", U12="Fiber CAmtel","TRANS_FO_CAMTEL", U12="Fiber AOF","Fiber AOF", U12="Projet OCM (HUAWEI)","TRAVAUX-HUAWEI", U12="Projet OCM (NOKIA)","TRAVAUX-NOKIA", U12="ACCESS-ISSUE","ACCESS-ISSUE", U12="Projet OCM (ZTE, NOKIA, autres projets)","TRAVAUX OCM", U12="No root CAuse","No root cause", U12="ODU HS","PDH", U12="IP & VLAN","PDH", U12="Warehouse HUAWEI","SPARE-ISSUE", U12="SPARE-HS","SPARE-ISSUE", U12="Power Telco","BSS",U12="no impacts","no impacts" ),"")} | T12: {=IFERROR(_xlfn.IFS( U12="MPR ISSUE","TX ISSUE", U12="BSS Hardware Issue","RAN ISSUE", U12="Sites strategiques, MLL, Pylone, etc.","ENVTECH", U12="AKTIVCO DEFAUT GE & POWER Cabinet","POWER ISSUE", U12="AKTIVCO Coupure ENEO & Baisse de tension","POWER ISSUE", U12="Coupure ENEO & Baisse de tension","POWER ISSUE", U12="Defaut GE & POWER Cabinet","POWER ISSUE", U12="Sharing","POWER ISSUE", U12="Sites strategiques & DataCenter","POWER ISSUE", U12="Exclu","Exclu", U12="SAT","TX ISSUE", U12="SPARE-ISSUE","SPARE-ISSUE", U12="Fiber CAmtel","TX ISSUE", U12="Fiber AOF","TX ISSUE", U12="Projet OCM (HUAWEI)","TRAVAUX-HUAWEI", U12="Projet OCM (NOKIA)","TRAVAUX -NOKIA", U12="ACCESS-ISSUE","ACCESS-ISSUE", U12="Projet OCM (ZTE, NOKIA, autres projets)","TRAVAUX OCM", U12="No root CAuse","No root cause", U12="ODU HS","TX ISSUE", U12="IP & VLAN","TX ISSUE", U12="Warehouse HUAWEI","SPARE-ISSUE", U12="SPARE-HS","SPARE-ISSUE", U12="Power Telco","RAN ISSUE",U12="no impacts","no impacts" ),"")} | V12: {=IFERROR(_xlfn.IFS( U12="MPR ISSUE","ACTIVE", U12="BSS Hardware Issue","ACTIVE", U12="Sites strategiques, MLL, Pylone, etc.","PASSIVE", U12="AKTIVCO DEFAUT GE & POWER Cabinet","PASSIVE", U12="AKTIVCO Coupure ENEO & Baisse de tension","PASSIVE", U12="Coupure ENEO & Baisse de tension","PASSIVE", U12="Defaut GE & POWER Cabinet","PASSIVE", U12="Sharing","PASSIVE", U12="Sites strategiques & DataCenter","PASSIVE", U12="Exclu","Exclu", U12="SAT","ACTIVE", U12="SPARE-ISSUE","SPARE-ISSUE", U12="Fiber CAmtel","ACTIVE", U12="Fiber AOF","ACTIVE", U12="Projet OCM (HUAWEI)","PLANNED WORKS", U12="Projet OCM (NOKIA)","PLANNED WORKS", U12="ACCESS-ISSUE","ACCESS-ISSUE", U12="Projet OCM (ZTE, NOKIA, autres projets)","PLANNED WORKS", U12="No root CAuse","No root cause", U12="ODU HS","ACTIVE", U12="IP & VLAN","ACTIVE", U12="Warehouse HUAWEI","SPARE-ISSUE", U12="SPARE-HS","SPARE-ISSUE", U12="Power Telco","ACTIVE",U12="no impacts","no impacts" ),"")} | W12: Need BO Tx analysis | X12: Awaiting BO TX analysis | Z12: BO TX | AA12: Ongoing | AB12: (04/23/2026 ocm ran 18h): -Power status check ongoing..INC-20260423-00013327…2026-04-23 18:10:57…No power Issue U=54V, I=23A/No Action Done…Problème de transmission du signal sur l'axe Minka affectant plusieurs sites parmis lesquels Ngomedzap | AR12: (04/23/2026 ocm ran 18h): -Power status check ongoing | AU12: INC-20260423-00013327…2026-04-23 18:10:57…No power Issue U=54V, I=23A/No Action Done…Problème de transmission du signal sur l'axe Minka affectant plusieurs sites parmis lesquels Ngomedzap | AX12: =_xlfn.XLOOKUP(B12,'[4]cell downs 18042026 17h'!$B:$B,'[4]cell downs 18042026 17h'!$B:$B,"") | AY12: =_xlfn.XLOOKUP(B12,'[5]Cells Huawei 19042026 15h'!$B:$B,'[5]Cells Huawei 19042026 15h'!$B:$B,"") | AZ12: =_xlfn.XLOOKUP(B12,'INCIDENT-04-23-2026'!E:E,'INCIDENT-04-23-2026'!F:F,"") | BA12: =_xlfn.XLOOKUP(B12,'[6]Eneo 17H'!$C:$C,'[6]Eneo 17H'!$I:$I,"") | BB12: =_xlfn.XLOOKUP(B12,[8]ALL!$B:$B,[8]ALL!$M:$M,"") | BC12: =_xlfn.XLOOKUP(B12,'[6]Eneo 17H'!$C:$C,'[6]Eneo 17H'!$I:$I,"") | BD12: =_xlfn.XLOOKUP(B12,'[7]Eneo 12H'!$C:$C,'[7]Eneo 12H'!$I:$I,"") | BE12: Not IHS Site..16.04.26; UE Relay site, ETR=mi-juin..16.04.26; UE Relay site, ETR=mi-juin
A13: Nyalla-III | B13: LIT_751 | C13: =_xlfn.XLOOKUP(B13,'[1]daily break down'!$D:$D,'[1]daily break down'!$E:$E,"") -> Douala | D13: CAMUSAT | E13: Good Grid no GE - 8h | F13: LITTORAL | G13: Douala | H13: =_xlfn.XLOOKUP(B13,[2]CALCULATION!$B:$B,[2]CALCULATION!$H:$H,"") -> ZTE | I13: 0 | J13: 0.77509467 | K13: 1.4386309 | L13: 1.9855258 | M13: 3.9221656 | N13: 29.469542 | O13: 13.515672 | P13: REPETITIF | Q13: Operationnel | S13: {=IFERROR(_xlfn.IFS( U13="MPR ISSUE","PDH", U13="BSS Hardware Issue","BSS", U13="Sites strategiques, MLL, Pylone, etc.","ENVTECH", U13="AKTIVCO DEFAUT GE & POWER Cabinet","AKTIVCO", U13="AKTIVCO Coupure ENEO & Baisse de tension","AKTIVCO GRID ONLY", U13="Coupure ENEO & Baisse de tension","IHS GRID ONLY", U13="Defaut GE & POWER Cabinet","IHS", U13="Sharing","Partners", U13="Sites strategiques & DataCenter","SST & DC", U13="Exclu","Exclu", U13="SAT","SAT", U13="SPARE-ISSUE","SPARE-ISSUE", U13="Fiber CAmtel","TRANS_FO_CAMTEL", U13="Fiber AOF","Fiber AOF", U13="Projet OCM (HUAWEI)","TRAVAUX-HUAWEI", U13="Projet OCM (NOKIA)","TRAVAUX-NOKIA", U13="ACCESS-ISSUE","ACCESS-ISSUE", U13="Projet OCM (ZTE, NOKIA, autres projets)","TRAVAUX OCM", U13="No root CAuse","No root cause", U13="ODU HS","PDH", U13="IP & VLAN","PDH", U13="Warehouse HUAWEI","SPARE-ISSUE", U13="SPARE-HS","SPARE-ISSUE", U13="Power Telco","BSS",U13="no impacts","no impacts" ),"")} | T13: {=IFERROR(_xlfn.IFS( U13="MPR ISSUE","TX ISSUE", U13="BSS Hardware Issue","RAN ISSUE", U13="Sites strategiques, MLL, Pylone, etc.","ENVTECH", U13="AKTIVCO DEFAUT GE & POWER Cabinet","POWER ISSUE", U13="AKTIVCO Coupure ENEO & Baisse de tension","POWER ISSUE", U13="Coupure ENEO & Baisse de tension","POWER ISSUE", U13="Defaut GE & POWER Cabinet","POWER ISSUE", U13="Sharing","POWER ISSUE", U13="Sites strategiques & DataCenter","POWER ISSUE", U13="Exclu","Exclu", U13="SAT","TX ISSUE", U13="SPARE-ISSUE","SPARE-ISSUE", U13="Fiber CAmtel","TX ISSUE", U13="Fiber AOF","TX ISSUE", U13="Projet OCM (HUAWEI)","TRAVAUX-HUAWEI", U13="Projet OCM (NOKIA)","TRAVAUX -NOKIA", U13="ACCESS-ISSUE","ACCESS-ISSUE", U13="Projet OCM (ZTE, NOKIA, autres projets)","TRAVAUX OCM", U13="No root CAuse","No root cause", U13="ODU HS","TX ISSUE", U13="IP & VLAN","TX ISSUE", U13="Warehouse HUAWEI","SPARE-ISSUE", U13="SPARE-HS","SPARE-ISSUE", U13="Power Telco","RAN ISSUE",U13="no impacts","no impacts" ),"")} | V13: {=IFERROR(_xlfn.IFS( U13="MPR ISSUE","ACTIVE", U13="BSS Hardware Issue","ACTIVE", U13="Sites strategiques, MLL, Pylone, etc.","PASSIVE", U13="AKTIVCO DEFAUT GE & POWER Cabinet","PASSIVE", U13="AKTIVCO Coupure ENEO & Baisse de tension","PASSIVE", U13="Coupure ENEO & Baisse de tension","PASSIVE", U13="Defaut GE & POWER Cabinet","PASSIVE", U13="Sharing","PASSIVE", U13="Sites strategiques & DataCenter","PASSIVE", U13="Exclu","Exclu", U13="SAT","ACTIVE", U13="SPARE-ISSUE","SPARE-ISSUE", U13="Fiber CAmtel","ACTIVE", U13="Fiber AOF","ACTIVE", U13="Projet OCM (HUAWEI)","PLANNED WORKS", U13="Projet OCM (NOKIA)","PLANNED WORKS", U13="ACCESS-ISSUE","ACCESS-ISSUE", U13="Projet OCM (ZTE, NOKIA, autres projets)","PLANNED WORKS", U13="No root CAuse","No root cause", U13="ODU HS","ACTIVE", U13="IP & VLAN","ACTIVE", U13="Warehouse HUAWEI","SPARE-ISSUE", U13="SPARE-HS","SPARE-ISSUE", U13="Power Telco","ACTIVE", U13="no impacts","no impacts" ),"")} | W13: Grid outage grid only site | X13: Awaiting Grid return | Z13: CAMUSAT | AA13: Ongoing | AB13: INC-20260423-00016215…2026-04-23 21:41:34…grid outage grid only site / awaiting grid return…grid outage grid only site / awaiting grid return…Coupure Secteur…grid outage grid only site / awaiting grid return..23.04.26; Camusat; Grid outage / Grid return awaited - Escalated to L3 | AE13: 23.04.26; Camusat; Grid outage / Grid return awaited - Escalated to L3 | AU13: INC-20260423-00016215…2026-04-23 21:41:34…grid outage grid only site / awaiting grid return…grid outage grid only site / awaiting grid return…Coupure Secteur…grid outage grid only site / awaiting grid return | AX13: =_xlfn.XLOOKUP(B13,'[4]cell downs 18042026 17h'!$B:$B,'[4]cell downs 18042026 17h'!$B:$B,"") | AY13: =_xlfn.XLOOKUP(B13,'[5]Cells Huawei 19042026 15h'!$B:$B,'[5]Cells Huawei 19042026 15h'!$B:$B,"") | AZ13: =_xlfn.XLOOKUP(B13,'INCIDENT-04-23-2026'!E:E,'INCIDENT-04-23-2026'!F:F,"") | BA13: =_xlfn.XLOOKUP(B13,'[6]Eneo 17H'!$C:$C,'[6]Eneo 17H'!$I:$I,"") | BB13: =_xlfn.XLOOKUP(B13,[8]ALL!$B:$B,[8]ALL!$M:$M,"") -> 23.04.26; Camusat; Grid outage / Grid return awaited - Escalated to L3 | BC13: =_xlfn.XLOOKUP(B13,'[6]Eneo 17H'!$C:$C,'[6]Eneo 17H'!$I:$I,"") | BD13: =_xlfn.XLOOKUP(B13,'[7]Eneo 12H'!$C:$C,'[7]Eneo 12H'!$I:$I,"")
