Workbook

Sheet Sheet3
E1: NUR DAILY RECAP - NUR 2326
A2: Row Labels | B2: Sum of NUR 19/04/2026 | D2: Row Labels | E2: Sum of NUR 19/04/2026 | G2: Row Labels | H2: Sum of NUR 19/04/2026
A3: ACTIVE | B3: 473.36713 | D3: ACCESS-ISSUE | E3: 104.28761 | G3: AKTIVCO | H3: 64.628764
A4: No root cause | B4: 804.36194 | D4: No root cause | E4: 804.36194 | G4: AKTIVCO GRID ONLY | H4: 511.03537
A5: PASSIVE | B5: 1175.3774 | D5: POWER ISSUE | E5: 1175.3774 | G5: BSS | H5: 231.6437
A6: Grand Total | B6: 2453.1065 | D6: RAN ISSUE | E6: 231.6437 | G6: IHS | H6: 409.83242
D7: SPARE-ISSUE | E7: 122.4415 | G7: IHS GRID ONLY | H7: 84.392951
D8: TRAVAUX-HUAWEI | E8: 0 | G8: No root cause | H8: 804.36194
D9: TX ISSUE | E9: 241.72343 | G9: PDH | H9: 195.05281
D10: Grand Total | E10: 2679.8356 | G10: Grand Total | H10: 2300.9479

Sheet daily break down
A1: Nom du Physique | B1: Codesite | C1: CLUSTER | D1: Owner | E1: Topology | F1: Region | G1: Ville | H1: Equipementiers | I1: 15/4/2026 | J1: 16/4/2026 | K1: 17/4/2026 | L1: 18/4/2026 | M1: 19/4/2026 | N1: 20/04/2026 | O1: 21/4/2026 | P1: Repetitive | Q1: Statut | R1: Raison d'exclusion | S1: OCM NOMENCLATURE | T1: SUB RCA | U1: CAUSE | V1: CATEGORIE | W1: RCA | X1: Action Plan | Y1: ETR | Z1: Owner | AA1: Status | AB1: Verifications 21/04/2026 | AC1: IHS FEEDBACK 21/04/2026 | AD1: Top Offenders | AE1: UPDATE 21/04/2026 | AF1: INCIDENT 21/04/2026 | AG1: top offenders 21/04/2026 | AH1: RETOUR CAMUSAT 21/04/2026 | AI1: RETOUR IHS 21/04/2026 | AJ1: Hourly IHS 21/04/2026 | AK1: Cells Huawei 21042026 9h | AL1: Cells Huawei 21042026 14h | AM1: Cells Huawei 21042026 18h | AN1: NOKIA cell downs 21042026 8h30 | AO1: cell downs 21042026 13h50 | AP1: cell downs 21042026 17h20 | AQ1: ZTEcells down 21042026 8h24 | AR1: cells down 21042026 13h08 | AS1: cell downs 20042026 17h16 | AT1: OCM Ran 21/04/2026 18H | AU1: OCM Ran 21/04/2026 14H | AV1: Ticket 21/04/2026 | AW1: Dashbord suivi TOP OFFENDERS 21/04/2026 | AX1: SITE WITH GPS ISSUE | AY1: nokia number cell | AZ1: HUAWEI number cell | BA1: ZTE number cell
A2: Batouri | B2: EST_005 | C2: =_xlfn.XLOOKUP(B2,'[1]daily break down'!$D:$D,'[1]daily break down'!$E:$E,"") -> CENTRE | D2: CAMUSAT | E2: Bad Grid + Solar + GE | F2: EST | G2: Batouri | H2: =_xlfn.XLOOKUP(B2,[2]CALCULATION!$B:$B,[2]CALCULATION!$H:$H,"") -> ZTE | I2: 0 | J2: 0 | K2: 0.0078117643 | L2: 0 | M2: 2.460135 | N2: 21.774348 | O2: 46.768034 | P2: REPETITIF | Q2: Operationnel | S2: {=IFERROR(_xlfn.IFS( U2="MPR ISSUE","PDH", U2="BSS Hardware Issue","BSS", U2="Sites strategiques, MLL, Pylone, etc.","ENVTECH", U2="AKTIVCO DEFAUT GE & POWER Cabinet","AKTIVCO", U2="AKTIVCO Coupure ENEO & Baisse de tension","AKTIVCO GRID ONLY", U2="Coupure ENEO & Baisse de tension","IHS GRID ONLY", U2="Defaut GE & POWER Cabinet","IHS", U2="Sharing","Partners", U2="Sites strategiques & DataCenter","SST & DC", U2="Exclu","Exclu", U2="SAT","SAT", U2="SPARE-ISSUE","SPARE-ISSUE", U2="Fiber CAmtel","TRANS_FO_CAMTEL", U2="Fiber AOF","Fiber AOF", U2="Projet OCM (HUAWEI)","TRAVAUX-HUAWEI", U2="Projet OCM (NOKIA)","TRAVAUX-NOKIA", U2="ACCESS-ISSUE","ACCESS-ISSUE", U2="Projet OCM (ZTE, NOKIA, autres projets)","TRAVAUX OCM", U2="No root CAuse","No root cause", U2="ODU HS","PDH", U2="IP & VLAN","PDH", U2="Warehouse HUAWEI","SPARE-ISSUE", U2="SPARE-HS","SPARE-ISSUE", U2="Power Telco","BSS" ),"")} | T2: {=IFERROR(_xlfn.IFS( U2="MPR ISSUE","TX ISSUE", U2="BSS Hardware Issue","RAN ISSUE", U2="Sites strategiques, MLL, Pylone, etc.","ENVTECH", U2="AKTIVCO DEFAUT GE & POWER Cabinet","POWER ISSUE", U2="AKTIVCO Coupure ENEO & Baisse de tension","POWER ISSUE", U2="Coupure ENEO & Baisse de tension","POWER ISSUE", U2="Defaut GE & POWER Cabinet","POWER ISSUE", U2="Sharing","POWER ISSUE", U2="Sites strategiques & DataCenter","POWER ISSUE", U2="Exclu","Exclu", U2="SAT","TX ISSUE", U2="SPARE-ISSUE","SPARE-ISSUE", U2="Fiber CAmtel","TX ISSUE", U2="Fiber AOF","TX ISSUE", U2="Projet OCM (HUAWEI)","TRAVAUX-HUAWEI", U2="Projet OCM (NOKIA)","TRAVAUX -NOKIA", U2="ACCESS-ISSUE","ACCESS-ISSUE", U2="Projet OCM (ZTE, NOKIA, autres projets)","TRAVAUX OCM", U2="No root CAuse","No root cause", U2="ODU HS","TX ISSUE", U2="IP & VLAN","TX ISSUE", U2="Warehouse HUAWEI","SPARE-ISSUE", U2="SPARE-HS","SPARE-ISSUE", U2="Power Telco","RAN ISSUE" ),"")} | V2: {=IFERROR(_xlfn.IFS( U2="MPR ISSUE","ACTIVE", U2="BSS Hardware Issue","ACTIVE", U2="Sites strategiques, MLL, Pylone, etc.","PASSIVE", U2="AKTIVCO DEFAUT GE & POWER Cabinet","PASSIVE", U2="AKTIVCO Coupure ENEO & Baisse de tension","PASSIVE", U2="Coupure ENEO & Baisse de tension","PASSIVE", U2="Defaut GE & POWER Cabinet","PASSIVE", U2="Sharing","PASSIVE", U2="Sites strategiques & DataCenter","PASSIVE", U2="Exclu","Exclu", U2="SAT","ACTIVE", U2="SPARE-ISSUE","SPARE-ISSUE", U2="Fiber CAmtel","ACTIVE", U2="Fiber AOF","ACTIVE", U2="Projet OCM (HUAWEI)","PLANNED WORKS", U2="Projet OCM (NOKIA)","PLANNED WORKS", U2="ACCESS-ISSUE","ACCESS-ISSUE", U2="Projet OCM (ZTE, NOKIA, autres projets)","PLANNED WORKS", U2="No root CAuse","No root cause", U2="ODU HS","ACTIVE", U2="IP & VLAN","ACTIVE", U2="Warehouse HUAWEI","SPARE-ISSUE", U2="SPARE-HS","SPARE-ISSUE", U2="Power Telco","ACTIVE" ),"")} | W2: MPR issue | X2: FME on site to check MPR status | Z2: GNOC | AA2: Ongoing | AB2: 21.04.26; Besoin d'un FME sur site pour vérifier le statut du MPR; FME Hugues activé pour investigations et manage avec le niveau 0, ETA=16H UTC 20/04/2026 Besoin d'un fme sur site pour verifier le status du MPR et la chaine antennaire de l ODU 3/1 20/04/2026 Rodrigue is managing with the guard. We will keep you posted 20.04.26; Camusat; Rodrigue is managing with the guard. We will keep you posted..(04/21/2026-ocm ran incident 14h):-21.04.26; Besoin d'un FME sur site pour vérifier le statut du MPR; FME Hugues activé pour investigations et manage avec le niveau 0, ETA=16H UTC 20/04/2026 Besoin d'un fme sur site pour verifier le status du MPR et la chaine antennaire de l ODU 3/1 20/04/2026 Rodrigue is managing with the guard. We will keep you posted 20.04.26; Camusat; Rodrigue is managing with the guard. We will keep you posted..(04/21/2026 tickect): -INC-20260421-00016076…2026-04-21 23:10:58…unknow / Notre FME a joint le level 0 et qui fait savoir qu'il y a couvre feu dans la nuit. Donc il ne peut pas sortir. l'investigation ne pourra être fait que ce matin autour de 07h | AC2: =_xlfn.XLOOKUP(B2,[4]ALL!$B:$B,[4]ALL!$N:$N,"") | AD2: 21.04.26; Besoin d'un FME sur site pour vérifier le statut du MPR; FME Hugues activé pour investigations et manage avec le niveau 0, ETA=16H UTC 20/04/2026 Besoin d'un fme sur site pour verifier le status du MPR et la chaine antennaire de l ODU 3/1 20/04/2026 Rodrigue is managing with the guard. We will keep you posted 20.04.26; Camusat; Rodrigue is managing with the guard. We will keep you posted | AU2: (04/21/2026-ocm ran incident 14h):-21.04.26; Besoin d'un FME sur site pour vérifier le statut du MPR; FME Hugues activé pour investigations et manage avec le niveau 0, ETA=16H UTC 20/04/2026 Besoin d'un fme sur site pour verifier le status du MPR et la chaine antennaire de l ODU 3/1 20/04/2026 Rodrigue is managing with the guard. We will keep you posted 20.04.26; Camusat; Rodrigue is managing with the guard. We will keep you posted | AV2: (04/21/2026 tickect): -INC-20260421-00016076…2026-04-21 23:10:58…unknow / Notre FME a joint le level 0 et qui fait savoir qu'il y a couvre feu dans la nuit. Donc il ne peut pas sortir. l'investigation ne pourra être fait que ce matin autour de 07h
A3: Superette-Biyem-Assi | B3: CTR_561 | C3: =_xlfn.XLOOKUP(B3,'[1]daily break down'!$D:$D,'[1]daily break down'!$E:$E,"") -> Yaounde | D3: CAMUSAT | E3: Good Grid no GE - 12h | F3: CENTRE | G3: Yaounde | H3: =_xlfn.XLOOKUP(B3,[2]CALCULATION!$B:$B,[2]CALCULATION!$H:$H,"") -> ZTE | I3: 0 | J3: 0 | K3: 0 | L3: 0 | M3: 0 | N3: 53.665323 | O3: 42.695323 | P3: REPETITIF | Q3: Operationnel | S3: {=IFERROR(_xlfn.IFS( U3="MPR ISSUE","PDH", U3="BSS Hardware Issue","BSS", U3="Sites strategiques, MLL, Pylone, etc.","ENVTECH", U3="AKTIVCO DEFAUT GE & POWER Cabinet","AKTIVCO", U3="AKTIVCO Coupure ENEO & Baisse de tension","AKTIVCO GRID ONLY", U3="Coupure ENEO & Baisse de tension","IHS GRID ONLY", U3="Defaut GE & POWER Cabinet","IHS", U3="Sharing","Partners", U3="Sites strategiques & DataCenter","SST & DC", U3="Exclu","Exclu", U3="SAT","SAT", U3="SPARE-ISSUE","SPARE-ISSUE", U3="Fiber CAmtel","TRANS_FO_CAMTEL", U3="Fiber AOF","Fiber AOF", U3="Projet OCM (HUAWEI)","TRAVAUX-HUAWEI", U3="Projet OCM (NOKIA)","TRAVAUX-NOKIA", U3="ACCESS-ISSUE","ACCESS-ISSUE", U3="Projet OCM (ZTE, NOKIA, autres projets)","TRAVAUX OCM", U3="No root CAuse","No root cause", U3="ODU HS","PDH", U3="IP & VLAN","PDH", U3="Warehouse HUAWEI","SPARE-ISSUE", U3="SPARE-HS","SPARE-ISSUE", U3="Power Telco","BSS" ),"")} | T3: {=IFERROR(_xlfn.IFS( U3="MPR ISSUE","TX ISSUE", U3="BSS Hardware Issue","RAN ISSUE", U3="Sites strategiques, MLL, Pylone, etc.","ENVTECH", U3="AKTIVCO DEFAUT GE & POWER Cabinet","POWER ISSUE", U3="AKTIVCO Coupure ENEO & Baisse de tension","POWER ISSUE", U3="Coupure ENEO & Baisse de tension","POWER ISSUE", U3="Defaut GE & POWER Cabinet","POWER ISSUE", U3="Sharing","POWER ISSUE", U3="Sites strategiques & DataCenter","POWER ISSUE", U3="Exclu","Exclu", U3="SAT","TX ISSUE", U3="SPARE-ISSUE","SPARE-ISSUE", U3="Fiber CAmtel","TX ISSUE", U3="Fiber AOF","TX ISSUE", U3="Projet OCM (HUAWEI)","TRAVAUX-HUAWEI", U3="Projet OCM (NOKIA)","TRAVAUX -NOKIA", U3="ACCESS-ISSUE","ACCESS-ISSUE", U3="Projet OCM (ZTE, NOKIA, autres projets)","TRAVAUX OCM", U3="No root CAuse","No root cause", U3="ODU HS","TX ISSUE", U3="IP & VLAN","TX ISSUE", U3="Warehouse HUAWEI","SPARE-ISSUE", U3="SPARE-HS","SPARE-ISSUE", U3="Power Telco","RAN ISSUE" ),"")} | V3: {=IFERROR(_xlfn.IFS( U3="MPR ISSUE","ACTIVE", U3="BSS Hardware Issue","ACTIVE", U3="Sites strategiques, MLL, Pylone, etc.","PASSIVE", U3="AKTIVCO DEFAUT GE & POWER Cabinet","PASSIVE", U3="AKTIVCO Coupure ENEO & Baisse de tension","PASSIVE", U3="Coupure ENEO & Baisse de tension","PASSIVE", U3="Defaut GE & POWER Cabinet","PASSIVE", U3="Sharing","PASSIVE", U3="Sites strategiques & DataCenter","PASSIVE", U3="Exclu","Exclu", U3="SAT","ACTIVE", U3="SPARE-ISSUE","SPARE-ISSUE", U3="Fiber CAmtel","ACTIVE", U3="Fiber AOF","ACTIVE", U3="Projet OCM (HUAWEI)","PLANNED WORKS", U3="Projet OCM (NOKIA)","PLANNED WORKS", U3="ACCESS-ISSUE","ACCESS-ISSUE", U3="Projet OCM (ZTE, NOKIA, autres projets)","PLANNED WORKS", U3="No root CAuse","No root cause", U3="ODU HS","ACTIVE", U3="IP & VLAN","ACTIVE", U3="Warehouse HUAWEI","SPARE-ISSUE", U3="SPARE-HS","SPARE-ISSUE", U3="Power Telco","ACTIVE" ),"")} | W3: Grid outage, Grid only site | X3: Awaiting Grid return | Z3: CAMUSAT | AA3: Ongoing | AB3: 21.04.26; Camusat; Grid outage, Grid only site / Grid return awaited - Escalated to L4 20.04.26; Camusat; Grid outage, Grid only site / Grid return awaited - Escalated to L3..(04/21/2026-ocm ran incident 14h):-21.04.26; Camusat; Grid outage, Grid only site / Grid return awaited - Escalated to L4 20.04.26; Camusat; Grid outage, Grid only site / Grid return awaited - Escalated to L3 | AC3: =_xlfn.XLOOKUP(B3,[4]ALL!$B:$B,[4]ALL!$N:$N,"") | AD3: 21.04.26; Camusat; Grid outage, Grid only site / Grid return awaited - Escalated to L4 20.04.26; Camusat; Grid outage, Grid only site / Grid return awaited - Escalated to L3 | AU3: (04/21/2026-ocm ran incident 14h):-21.04.26; Camusat; Grid outage, Grid only site / Grid return awaited - Escalated to L4 20.04.26; Camusat; Grid outage, Grid only site / Grid return awaited - Escalated to L3
A4: Foumbot-Centre-Ville-II | B4: OST_227 | C4: =_xlfn.XLOOKUP(B4,'[1]daily break down'!$D:$D,'[1]daily break down'!$E:$E,"") -> OUEST | D4: CAMUSAT | E4: Medium Grid + GE | F4: OUEST | G4: Foumbot | H4: =_xlfn.XLOOKUP(B4,[2]CALCULATION!$B:$B,[2]CALCULATION!$H:$H,"") -> Huawei | I4: 0 | J4: 37.82829 | K4: 41.605403 | L4: 41.605671 | M4: 41.605671 | N4: 41.553503 | O4: 41.604066 | P4: REPETITIF | Q4: Operationnel | S4: {=IFERROR(_xlfn.IFS( U4="MPR ISSUE","PDH", U4="BSS Hardware Issue","BSS", U4="Sites strategiques, MLL, Pylone, etc.","ENVTECH", U4="AKTIVCO DEFAUT GE & POWER Cabinet","AKTIVCO", U4="AKTIVCO Coupure ENEO & Baisse de tension","AKTIVCO GRID ONLY", U4="Coupure ENEO & Baisse de tension","IHS GRID ONLY", U4="Defaut GE & POWER Cabinet","IHS", U4="Sharing","Partners", U4="Sites strategiques & DataCenter","SST & DC", U4="Exclu","Exclu", U4="SAT","SAT", U4="SPARE-ISSUE","SPARE-ISSUE", U4="Fiber CAmtel","TRANS_FO_CAMTEL", U4="Fiber AOF","Fiber AOF", U4="Projet OCM (HUAWEI)","TRAVAUX-HUAWEI", U4="Projet OCM (NOKIA)","TRAVAUX-NOKIA", U4="ACCESS-ISSUE","ACCESS-ISSUE", U4="Projet OCM (ZTE, NOKIA, autres projets)","TRAVAUX OCM", U4="No root CAuse","No root cause", U4="ODU HS","PDH", U4="IP & VLAN","PDH", U4="Warehouse HUAWEI","SPARE-ISSUE", U4="SPARE-HS","SPARE-ISSUE", U4="Power Telco","BSS" ),"")} | T4: {=IFERROR(_xlfn.IFS( U4="MPR ISSUE","TX ISSUE", U4="BSS Hardware Issue","RAN ISSUE", U4="Sites strategiques, MLL, Pylone, etc.","ENVTECH", U4="AKTIVCO DEFAUT GE & POWER Cabinet","POWER ISSUE", U4="AKTIVCO Coupure ENEO & Baisse de tension","POWER ISSUE", U4="Coupure ENEO & Baisse de tension","POWER ISSUE", U4="Defaut GE & POWER Cabinet","POWER ISSUE", U4="Sharing","POWER ISSUE", U4="Sites strategiques & DataCenter","POWER ISSUE", U4="Exclu","Exclu", U4="SAT","TX ISSUE", U4="SPARE-ISSUE","SPARE-ISSUE", U4="Fiber CAmtel","TX ISSUE", U4="Fiber AOF","TX ISSUE", U4="Projet OCM (HUAWEI)","TRAVAUX-HUAWEI", U4="Projet OCM (NOKIA)","TRAVAUX -NOKIA", U4="ACCESS-ISSUE","ACCESS-ISSUE", U4="Projet OCM (ZTE, NOKIA, autres projets)","TRAVAUX OCM", U4="No root CAuse","No root cause", U4="ODU HS","TX ISSUE", U4="IP & VLAN","TX ISSUE", U4="Warehouse HUAWEI","SPARE-ISSUE", U4="SPARE-HS","SPARE-ISSUE", U4="Power Telco","RAN ISSUE" ),"")} | V4: {=IFERROR(_xlfn.IFS( U4="MPR ISSUE","ACTIVE", U4="BSS Hardware Issue","ACTIVE", U4="Sites strategiques, MLL, Pylone, etc.","PASSIVE", U4="AKTIVCO DEFAUT GE & POWER Cabinet","PASSIVE", U4="AKTIVCO Coupure ENEO & Baisse de tension","PASSIVE", U4="Coupure ENEO & Baisse de tension","PASSIVE", U4="Defaut GE & POWER Cabinet","PASSIVE", U4="Sharing","PASSIVE", U4="Sites strategiques & DataCenter","PASSIVE", U4="Exclu","Exclu", U4="SAT","ACTIVE", U4="SPARE-ISSUE","SPARE-ISSUE", U4="Fiber CAmtel","ACTIVE", U4="Fiber AOF","ACTIVE", U4="Projet OCM (HUAWEI)","PLANNED WORKS", U4="Projet OCM (NOKIA)","PLANNED WORKS", U4="ACCESS-ISSUE","ACCESS-ISSUE", U4="Projet OCM (ZTE, NOKIA, autres projets)","PLANNED WORKS", U4="No root CAuse","No root cause", U4="ODU HS","ACTIVE", U4="IP & VLAN","ACTIVE", U4="Warehouse HUAWEI","SPARE-ISSUE", U4="SPARE-HS","SPARE-ISSUE", U4="Power Telco","ACTIVE" ),"")} | W4: SCTP link fault due to AOF link issue | X4: Follow up with CDS for AOF recovery | Z4: GNOC | AA4: Ongoing | AB4: 20/04/2026 : Après analyse nous constatons qu’il a eu un souci d’énergie le 16/04/2026 sur le site de FOUMBO-CENTRE-VILLE-II. Aussi l’AOF FOUMBOT_1---- FOUMBO-CENTRE-VILLE-II ne prend pas de trafic. Merci d’impacter CDS pour prise en charge. 20/04/2026 : Escalade en voyee au Manager des BO TX GNOC. Point pris et son feedback attendu 16/04/2026 : Besoin d'analyse BO RAN || All cells down due to SCTP Link Fault . thanks to activate BO TX to check VLAN..(04/21/2026 cell huawei):-20/04/2026 : Après analyse nous constatons qu’il a eu un souci d’énergie le 16/04/2026 sur le site de FOUMBO-CENTRE-VILLE-II. Aussi l’AOF FOUMBOT_1---- FOUMBO-CENTRE-VILLE-II ne prend pas de trafic. Merci d’impacter CDS pour prise en charge. 20/04/2026 : Escalade en voyee au Manager des BO TX GNOC. Point pris et son feedback attendu 16/04/2026 : Besoin d'analyse BO RAN || All cells down due to SCTP Link Fault . thanks to activate BO TX to check VLAN..(04/21/2026 cell huawei):-20/04/2026 : Après analyse nous constatons qu’il a eu un souci d’énergie le 16/04/2026 sur le site de FOUMBO-CENTRE-VILLE-II. Aussi l’AOF FOUMBOT_1---- FOUMBO-CENTRE-VILLE-II ne prend pas de trafic. Merci d’impacter CDS pour prise en charge. 20/04/2026 : Escalade en voyee au Manager des BO TX GNOC. Point pris et son feedback attendu 16/04/2026 : Besoin d'analyse BO RAN || All cells down due to SCTP Link Fault . thanks to activate BO TX to check VLAN..(04/21/2026 cell huawei):-20/04/2026 : Après analyse nous constatons qu’il a eu un souci d’énergie le 16/04/2026 sur le site de FOUMBO-CENTRE-VILLE-II. Aussi l’AOF FOUMBOT_1---- FOUMBO-CENTRE-VILLE-II ne prend pas de trafic. Merci d’impacter CDS pour prise en charge. 20/04/2026 : Escalade en voyee au Manager des BO TX GNOC. Point pris et son feedback attendu 16/04/2026 : Besoin d'analyse BO RAN || All cells down due to SCTP Link Fault . thanks to activate BO TX to check VLAN..OST_227 | AC4: =_xlfn.XLOOKUP(B4,[4]ALL!$B:$B,[4]ALL!$N:$N,"") | AD4: 20/04/2026 : Après analyse nous constatons qu’il a eu un souci d’énergie le 16/04/2026 sur le site de FOUMBO-CENTRE-VILLE-II. Aussi l’AOF FOUMBOT_1---- FOUMBO-CENTRE-VILLE-II ne prend pas de trafic. Merci d’impacter CDS pour prise en charge. 20/04/2026 : Escalade en voyee au Manager des BO TX GNOC. Point pris et son feedback attendu 16/04/2026 : Besoin d'analyse BO RAN || All cells down due to SCTP Link Fault . thanks to activate BO TX to check VLAN | AK4: (04/21/2026 cell huawei):-20/04/2026 : Après analyse nous constatons qu’il a eu un souci d’énergie le 16/04/2026 sur le site de FOUMBO-CENTRE-VILLE-II. Aussi l’AOF FOUMBOT_1---- FOUMBO-CENTRE-VILLE-II ne prend pas de trafic. Merci d’impacter CDS pour prise en charge. 20/04/2026 : Escalade en voyee au Manager des BO TX GNOC. Point pris et son feedback attendu 16/04/2026 : Besoin d'analyse BO RAN || All cells down due to SCTP Link Fault . thanks to activate BO TX to check VLAN | AL4: (04/21/2026 cell huawei):-20/04/2026 : Après analyse nous constatons qu’il a eu un souci d’énergie le 16/04/2026 sur le site de FOUMBO-CENTRE-VILLE-II. Aussi l’AOF FOUMBOT_1---- FOUMBO-CENTRE-VILLE-II ne prend pas de trafic. Merci d’impacter CDS pour prise en charge. 20/04/2026 : Escalade en voyee au Manager des BO TX GNOC. Point pris et son feedback attendu 16/04/2026 : Besoin d'analyse BO RAN || All cells down due to SCTP Link Fault . thanks to activate BO TX to check VLAN | AM4: (04/21/2026 cell huawei):-20/04/2026 : Après analyse nous constatons qu’il a eu un souci d’énergie le 16/04/2026 sur le site de FOUMBO-CENTRE-VILLE-II. Aussi l’AOF FOUMBOT_1---- FOUMBO-CENTRE-VILLE-II ne prend pas de trafic. Merci d’impacter CDS pour prise en charge. 20/04/2026 : Escalade en voyee au Manager des BO TX GNOC. Point pris et son feedback attendu 16/04/2026 : Besoin d'analyse BO RAN || All cells down due to SCTP Link Fault . thanks to activate BO TX to check VLAN | AZ4: OST_227
A5: Hopital-General | B5: LIT_248 | C5: =_xlfn.XLOOKUP(B5,'[1]daily break down'!$D:$D,'[1]daily break down'!$E:$E,"") -> Douala | D5: IHS | E5: Grid-Gen | F5: LITTORAL | G5: Douala | H5: =_xlfn.XLOOKUP(B5,[2]CALCULATION!$B:$B,[2]CALCULATION!$H:$H,"") -> ZTE | I5: 0 | J5: 0 | K5: 0 | L5: 0 | M5: 0 | N5: 7.1571278 | O5: 37.663619 | P5: REPETITIF | Q5: Operationnel | S5: {=IFERROR(_xlfn.IFS( U5="MPR ISSUE","PDH", U5="BSS Hardware Issue","BSS", U5="Sites strategiques, MLL, Pylone, etc.","ENVTECH", U5="AKTIVCO DEFAUT GE & POWER Cabinet","AKTIVCO", U5="AKTIVCO Coupure ENEO & Baisse de tension","AKTIVCO GRID ONLY", U5="Coupure ENEO & Baisse de tension","IHS GRID ONLY", U5="Defaut GE & POWER Cabinet","IHS", U5="Sharing","Partners", U5="Sites strategiques & DataCenter","SST & DC", U5="Exclu","Exclu", U5="SAT","SAT", U5="SPARE-ISSUE","SPARE-ISSUE", U5="Fiber CAmtel","TRANS_FO_CAMTEL", U5="Fiber AOF","Fiber AOF", U5="Projet OCM (HUAWEI)","TRAVAUX-HUAWEI", U5="Projet OCM (NOKIA)","TRAVAUX-NOKIA", U5="ACCESS-ISSUE","ACCESS-ISSUE", U5="Projet OCM (ZTE, NOKIA, autres projets)","TRAVAUX OCM", U5="No root CAuse","No root cause", U5="ODU HS","PDH", U5="IP & VLAN","PDH", U5="Warehouse HUAWEI","SPARE-ISSUE", U5="SPARE-HS","SPARE-ISSUE", U5="Power Telco","BSS" ),"")} | T5: {=IFERROR(_xlfn.IFS( U5="MPR ISSUE","TX ISSUE", U5="BSS Hardware Issue","RAN ISSUE", U5="Sites strategiques, MLL, Pylone, etc.","ENVTECH", U5="AKTIVCO DEFAUT GE & POWER Cabinet","POWER ISSUE", U5="AKTIVCO Coupure ENEO & Baisse de tension","POWER ISSUE", U5="Coupure ENEO & Baisse de tension","POWER ISSUE", U5="Defaut GE & POWER Cabinet","POWER ISSUE", U5="Sharing","POWER ISSUE", U5="Sites strategiques & DataCenter","POWER ISSUE", U5="Exclu","Exclu", U5="SAT","TX ISSUE", U5="SPARE-ISSUE","SPARE-ISSUE", U5="Fiber CAmtel","TX ISSUE", U5="Fiber AOF","TX ISSUE", U5="Projet OCM (HUAWEI)","TRAVAUX-HUAWEI", U5="Projet OCM (NOKIA)","TRAVAUX -NOKIA", U5="ACCESS-ISSUE","ACCESS-ISSUE", U5="Projet OCM (ZTE, NOKIA, autres projets)","TRAVAUX OCM", U5="No root CAuse","No root cause", U5="ODU HS","TX ISSUE", U5="IP & VLAN","TX ISSUE", U5="Warehouse HUAWEI","SPARE-ISSUE", U5="SPARE-HS","SPARE-ISSUE", U5="Power Telco","RAN ISSUE" ),"")} | V5: {=IFERROR(_xlfn.IFS( U5="MPR ISSUE","ACTIVE", U5="BSS Hardware Issue","ACTIVE", U5="Sites strategiques, MLL, Pylone, etc.","PASSIVE", U5="AKTIVCO DEFAUT GE & POWER Cabinet","PASSIVE", U5="AKTIVCO Coupure ENEO & Baisse de tension","PASSIVE", U5="Coupure ENEO & Baisse de tension","PASSIVE", U5="Defaut GE & POWER Cabinet","PASSIVE", U5="Sharing","PASSIVE", U5="Sites strategiques & DataCenter","PASSIVE", U5="Exclu","Exclu", U5="SAT","ACTIVE", U5="SPARE-ISSUE","SPARE-ISSUE", U5="Fiber CAmtel","ACTIVE", U5="Fiber AOF","ACTIVE", U5="Projet OCM (HUAWEI)","PLANNED WORKS", U5="Projet OCM (NOKIA)","PLANNED WORKS", U5="ACCESS-ISSUE","ACCESS-ISSUE", U5="Projet OCM (ZTE, NOKIA, autres projets)","PLANNED WORKS", U5="No root CAuse","No root cause", U5="ODU HS","ACTIVE", U5="IP & VLAN","ACTIVE", U5="Warehouse HUAWEI","SPARE-ISSUE", U5="SPARE-HS","SPARE-ISSUE", U5="Power Telco","ACTIVE" ),"")} | W5: MPR issue | X5: Dispatch FME on site to reset MPR | Z5: GNOC | AA5: Ongoing | AB5: Not IHS Site..21.04.26; Besoin d'un FME sur site pour reset du MPR et si NOK, tsoot avec le BO TX; CM-20260420-00005639; FME Beauclair activé pour investigations, ETA=11H30 UTC | AC5: =_xlfn.XLOOKUP(B5,[4]ALL!$B:$B,[4]ALL!$N:$N,"") -> Not IHS Site | AD5: 21.04.26; Besoin d'un FME sur site pour reset du MPR et si NOK, tsoot avec le BO TX; CM-20260420-00005639; FME Beauclair activé pour investigations, ETA=11H30 UTC
A6: Ngona | B6: CTR_590 | C6: =_xlfn.XLOOKUP(B6,'[1]daily break down'!$D:$D,'[1]daily break down'!$E:$E,"") -> Yaounde | D6: IHS | E6: Grid-Gen | F6: CENTRE | G6: Yaounde | H6: =_xlfn.XLOOKUP(B6,[2]CALCULATION!$B:$B,[2]CALCULATION!$H:$H,"") -> ZTE | I6: 36.982818 | J6: 36.982818 | K6: 36.982818 | L6: 36.982818 | M6: 36.982818 | N6: 36.982818 | O6: 36.982818 | P6: REPETITIF | Q6: =_xlfn.XLOOKUP(B6,'[1]daily break down'!$D:$D,'[1]daily break down'!$O:$O,"") -> EXCLU | S6: {=IFERROR(_xlfn.IFS( U6="MPR ISSUE","PDH", U6="BSS Hardware Issue","BSS", U6="Sites strategiques, MLL, Pylone, etc.","ENVTECH", U6="AKTIVCO DEFAUT GE & POWER Cabinet","AKTIVCO", U6="AKTIVCO Coupure ENEO & Baisse de tension","AKTIVCO GRID ONLY", U6="Coupure ENEO & Baisse de tension","IHS GRID ONLY", U6="Defaut GE & POWER Cabinet","IHS", U6="Sharing","Partners", U6="Sites strategiques & DataCenter","SST & DC", U6="Exclu","Exclu", U6="SAT","SAT", U6="SPARE-ISSUE","SPARE-ISSUE", U6="Fiber CAmtel","TRANS_FO_CAMTEL", U6="Fiber AOF","Fiber AOF", U6="Projet OCM (HUAWEI)","TRAVAUX-HUAWEI", U6="Projet OCM (NOKIA)","TRAVAUX-NOKIA", U6="ACCESS-ISSUE","ACCESS-ISSUE", U6="Projet OCM (ZTE, NOKIA, autres projets)","TRAVAUX OCM", U6="No root CAuse","No root cause", U6="ODU HS","PDH", U6="IP & VLAN","PDH", U6="Warehouse HUAWEI","SPARE-ISSUE", U6="SPARE-HS","SPARE-ISSUE", U6="Power Telco","BSS" ),"")} | T6: {=IFERROR(_xlfn.IFS( U6="MPR ISSUE","TX ISSUE", U6="BSS Hardware Issue","RAN ISSUE", U6="Sites strategiques, MLL, Pylone, etc.","ENVTECH", U6="AKTIVCO DEFAUT GE & POWER Cabinet","POWER ISSUE", U6="AKTIVCO Coupure ENEO & Baisse de tension","POWER ISSUE", U6="Coupure ENEO & Baisse de tension","POWER ISSUE", U6="Defaut GE & POWER Cabinet","POWER ISSUE", U6="Sharing","POWER ISSUE", U6="Sites strategiques & DataCenter","POWER ISSUE", U6="Exclu","Exclu", U6="SAT","TX ISSUE", U6="SPARE-ISSUE","SPARE-ISSUE", U6="Fiber CAmtel","TX ISSUE", U6="Fiber AOF","TX ISSUE", U6="Projet OCM (HUAWEI)","TRAVAUX-HUAWEI", U6="Projet OCM (NOKIA)","TRAVAUX -NOKIA", U6="ACCESS-ISSUE","ACCESS-ISSUE", U6="Projet OCM (ZTE, NOKIA, autres projets)","TRAVAUX OCM", U6="No root CAuse","No root cause", U6="ODU HS","TX ISSUE", U6="IP & VLAN","TX ISSUE", U6="Warehouse HUAWEI","SPARE-ISSUE", U6="SPARE-HS","SPARE-ISSUE", U6="Power Telco","RAN ISSUE" ),"")} | V6: {=IFERROR(_xlfn.IFS( U6="MPR ISSUE","ACTIVE", U6="BSS Hardware Issue","ACTIVE", U6="Sites strategiques, MLL, Pylone, etc.","PASSIVE", U6="AKTIVCO DEFAUT GE & POWER Cabinet","PASSIVE", U6="AKTIVCO Coupure ENEO & Baisse de tension","PASSIVE", U6="Coupure ENEO & Baisse de tension","PASSIVE", U6="Defaut GE & POWER Cabinet","PASSIVE", U6="Sharing","PASSIVE", U6="Sites strategiques & DataCenter","PASSIVE", U6="Exclu","Exclu", U6="SAT","ACTIVE", U6="SPARE-ISSUE","SPARE-ISSUE", U6="Fiber CAmtel","ACTIVE", U6="Fiber AOF","ACTIVE", U6="Projet OCM (HUAWEI)","PLANNED WORKS", U6="Projet OCM (NOKIA)","PLANNED WORKS", U6="ACCESS-ISSUE","ACCESS-ISSUE", U6="Projet OCM (ZTE, NOKIA, autres projets)","PLANNED WORKS", U6="No root CAuse","No root cause", U6="ODU HS","ACTIVE", U6="IP & VLAN","ACTIVE", U6="Warehouse HUAWEI","SPARE-ISSUE", U6="SPARE-HS","SPARE-ISSUE", U6="Power Telco","ACTIVE" ),"")} | AB6: No Power issue..20/04/2026 : Site vendalise..(04/21/2026 cell zte):-20/04/2026 : Site vendalise..(04/21/2026 cell zte):-20/04/2026 : Site vendalise..(04/21/2026 cell zte):-20/04/2026 : Site vendalise..CTR_590 | AC6: =_xlfn.XLOOKUP(B6,[4]ALL!$B:$B,[4]ALL!$N:$N,"") -> No Power issue | AD6: 20/04/2026 : Site vendalise | AQ6: (04/21/2026 cell zte):-20/04/2026 : Site vendalise | AR6: (04/21/2026 cell zte):-20/04/2026 : Site vendalise | AS6: (04/21/2026 cell zte):-20/04/2026 : Site vendalise | BA6: CTR_590
A7: Lada | B7: CTR_667 | C7: =_xlfn.XLOOKUP(B7,'[1]daily break down'!$D:$D,'[1]daily break down'!$E:$E,"") -> Yaounde | D7: CAMUSAT | E7: Bad Grid + Solar + GE | F7: CENTRE | G7: Lada | H7: =_xlfn.XLOOKUP(B7,[2]CALCULATION!$B:$B,[2]CALCULATION!$H:$H,"") -> ZTE | I7: 8.6248299 | J7: 8.5509213 | K7: 1.3079176 | L7: 0 | M7: 4.926441 | N7: 33.85929 | O7: 36.982818 | P7: REPETITIF | Q7: Operationnel | S7: {=IFERROR(_xlfn.IFS( U7="MPR ISSUE","PDH", U7="BSS Hardware Issue","BSS", U7="Sites strategiques, MLL, Pylone, etc.","ENVTECH", U7="AKTIVCO DEFAUT GE & POWER Cabinet","AKTIVCO", U7="AKTIVCO Coupure ENEO & Baisse de tension","AKTIVCO GRID ONLY", U7="Coupure ENEO & Baisse de tension","IHS GRID ONLY", U7="Defaut GE & POWER Cabinet","IHS", U7="Sharing","Partners", U7="Sites strategiques & DataCenter","SST & DC", U7="Exclu","Exclu", U7="SAT","SAT", U7="SPARE-ISSUE","SPARE-ISSUE", U7="Fiber CAmtel","TRANS_FO_CAMTEL", U7="Fiber AOF","Fiber AOF", U7="Projet OCM (HUAWEI)","TRAVAUX-HUAWEI", U7="Projet OCM (NOKIA)","TRAVAUX-NOKIA", U7="ACCESS-ISSUE","ACCESS-ISSUE", U7="Projet OCM (ZTE, NOKIA, autres projets)","TRAVAUX OCM", U7="No root CAuse","No root cause", U7="ODU HS","PDH", U7="IP & VLAN","PDH", U7="Warehouse HUAWEI","SPARE-ISSUE", U7="SPARE-HS","SPARE-ISSUE", U7="Power Telco","BSS" ),"")} | T7: {=IFERROR(_xlfn.IFS( U7="MPR ISSUE","TX ISSUE", U7="BSS Hardware Issue","RAN ISSUE", U7="Sites strategiques, MLL, Pylone, etc.","ENVTECH", U7="AKTIVCO DEFAUT GE & POWER Cabinet","POWER ISSUE", U7="AKTIVCO Coupure ENEO & Baisse de tension","POWER ISSUE", U7="Coupure ENEO & Baisse de tension","POWER ISSUE", U7="Defaut GE & POWER Cabinet","POWER ISSUE", U7="Sharing","POWER ISSUE", U7="Sites strategiques & DataCenter","POWER ISSUE", U7="Exclu","Exclu", U7="SAT","TX ISSUE", U7="SPARE-ISSUE","SPARE-ISSUE", U7="Fiber CAmtel","TX ISSUE", U7="Fiber AOF","TX ISSUE", U7="Projet OCM (HUAWEI)","TRAVAUX-HUAWEI", U7="Projet OCM (NOKIA)","TRAVAUX -NOKIA", U7="ACCESS-ISSUE","ACCESS-ISSUE", U7="Projet OCM (ZTE, NOKIA, autres projets)","TRAVAUX OCM", U7="No root CAuse","No root cause", U7="ODU HS","TX ISSUE", U7="IP & VLAN","TX ISSUE", U7="Warehouse HUAWEI","SPARE-ISSUE", U7="SPARE-HS","SPARE-ISSUE", U7="Power Telco","RAN ISSUE" ),"")} | V7: {=IFERROR(_xlfn.IFS( U7="MPR ISSUE","ACTIVE", U7="BSS Hardware Issue","ACTIVE", U7="Sites strategiques, MLL, Pylone, etc.","PASSIVE", U7="AKTIVCO DEFAUT GE & POWER Cabinet","PASSIVE", U7="AKTIVCO Coupure ENEO & Baisse de tension","PASSIVE", U7="Coupure ENEO & Baisse de tension","PASSIVE", U7="Defaut GE & POWER Cabinet","PASSIVE", U7="Sharing","PASSIVE", U7="Sites strategiques & DataCenter","PASSIVE", U7="Exclu","Exclu", U7="SAT","ACTIVE", U7="SPARE-ISSUE","SPARE-ISSUE", U7="Fiber CAmtel","ACTIVE", U7="Fiber AOF","ACTIVE", U7="Projet OCM (HUAWEI)","PLANNED WORKS", U7="Projet OCM (NOKIA)","PLANNED WORKS", U7="ACCESS-ISSUE","ACCESS-ISSUE", U7="Projet OCM (ZTE, NOKIA, autres projets)","PLANNED WORKS", U7="No root CAuse","No root cause", U7="ODU HS","ACTIVE", U7="IP & VLAN","ACTIVE", U7="Warehouse HUAWEI","SPARE-ISSUE", U7="SPARE-HS","SPARE-ISSUE", U7="Power Telco","ACTIVE" ),"")} | W7: impacted by bitoto. Need BO TX analysis | X7: Awaiting BO TX analysis | Z7: BO TX | AA7: Ongoing | AC7: =_xlfn.XLOOKUP(B7,[4]ALL!$B:$B,[4]ALL!$N:$N,"")
A8: Kumba-Lutherian-Church-MTN | B8: SUO_054 | C8: =_xlfn.XLOOKUP(B8,'[1]daily break down'!$D:$D,'[1]daily break down'!$E:$E,"") -> SUD-OUEST | D8: IHS | E8: Grid-Gen | F8: SUD-OUEST | G8: Kumba | H8: =_xlfn.XLOOKUP(B8,[2]CALCULATION!$B:$B,[2]CALCULATION!$H:$H,"") -> Huawei | I8: 34.213691 | J8: 34.282409 | K8: 34.274009 | L8: 34.14779 | M8: 34.268123 | N8: 34.223946 | O8: 34.188971 | P8: REPETITIF | Q8: EXCLU | S8: {=IFERROR(_xlfn.IFS( U8="MPR ISSUE","PDH", U8="BSS Hardware Issue","BSS", U8="Sites strategiques, MLL, Pylone, etc.","ENVTECH", U8="AKTIVCO DEFAUT GE & POWER Cabinet","AKTIVCO", U8="AKTIVCO Coupure ENEO & Baisse de tension","AKTIVCO GRID ONLY", U8="Coupure ENEO & Baisse de tension","IHS GRID ONLY", U8="Defaut GE & POWER Cabinet","IHS", U8="Sharing","Partners", U8="Sites strategiques & DataCenter","SST & DC", U8="Exclu","Exclu", U8="SAT","SAT", U8="SPARE-ISSUE","SPARE-ISSUE", U8="Fiber CAmtel","TRANS_FO_CAMTEL", U8="Fiber AOF","Fiber AOF", U8="Projet OCM (HUAWEI)","TRAVAUX-HUAWEI", U8="Projet OCM (NOKIA)","TRAVAUX-NOKIA", U8="ACCESS-ISSUE","ACCESS-ISSUE", U8="Projet OCM (ZTE, NOKIA, autres projets)","TRAVAUX OCM", U8="No root CAuse","No root cause", U8="ODU HS","PDH", U8="IP & VLAN","PDH", U8="Warehouse HUAWEI","SPARE-ISSUE", U8="SPARE-HS","SPARE-ISSUE", U8="Power Telco","BSS" ),"")} | T8: {=IFERROR(_xlfn.IFS( U8="MPR ISSUE","TX ISSUE", U8="BSS Hardware Issue","RAN ISSUE", U8="Sites strategiques, MLL, Pylone, etc.","ENVTECH", U8="AKTIVCO DEFAUT GE & POWER Cabinet","POWER ISSUE", U8="AKTIVCO Coupure ENEO & Baisse de tension","POWER ISSUE", U8="Coupure ENEO & Baisse de tension","POWER ISSUE", U8="Defaut GE & POWER Cabinet","POWER ISSUE", U8="Sharing","POWER ISSUE", U8="Sites strategiques & DataCenter","POWER ISSUE", U8="Exclu","Exclu", U8="SAT","TX ISSUE", U8="SPARE-ISSUE","SPARE-ISSUE", U8="Fiber CAmtel","TX ISSUE", U8="Fiber AOF","TX ISSUE", U8="Projet OCM (HUAWEI)","TRAVAUX-HUAWEI", U8="Projet OCM (NOKIA)","TRAVAUX -NOKIA", U8="ACCESS-ISSUE","ACCESS-ISSUE", U8="Projet OCM (ZTE, NOKIA, autres projets)","TRAVAUX OCM", U8="No root CAuse","No root cause", U8="ODU HS","TX ISSUE", U8="IP & VLAN","TX ISSUE", U8="Warehouse HUAWEI","SPARE-ISSUE", U8="SPARE-HS","SPARE-ISSUE", U8="Power Telco","RAN ISSUE" ),"")} | V8: {=IFERROR(_xlfn.IFS( U8="MPR ISSUE","ACTIVE", U8="BSS Hardware Issue","ACTIVE", U8="Sites strategiques, MLL, Pylone, etc.","PASSIVE", U8="AKTIVCO DEFAUT GE & POWER Cabinet","PASSIVE", U8="AKTIVCO Coupure ENEO & Baisse de tension","PASSIVE", U8="Coupure ENEO & Baisse de tension","PASSIVE", U8="Defaut GE & POWER Cabinet","PASSIVE", U8="Sharing","PASSIVE", U8="Sites strategiques & DataCenter","PASSIVE", U8="Exclu","Exclu", U8="SAT","ACTIVE", U8="SPARE-ISSUE","SPARE-ISSUE", U8="Fiber CAmtel","ACTIVE", U8="Fiber AOF","ACTIVE", U8="Projet OCM (HUAWEI)","PLANNED WORKS", U8="Projet OCM (NOKIA)","PLANNED WORKS", U8="ACCESS-ISSUE","ACCESS-ISSUE", U8="Projet OCM (ZTE, NOKIA, autres projets)","PLANNED WORKS", U8="No root CAuse","No root cause", U8="ODU HS","ACTIVE", U8="IP & VLAN","ACTIVE", U8="Warehouse HUAWEI","SPARE-ISSUE", U8="SPARE-HS","SPARE-ISSUE", U8="Power Telco","ACTIVE" ),"")} | AB8: No Power issue..SUO_054 | AC8: =_xlfn.XLOOKUP(B8,[4]ALL!$B:$B,[4]ALL!$N:$N,"") -> No Power issue | AZ8: SUO_054
A9: Nkolmesseng-H-Pyramides | B9: CTR_771 | C9: =_xlfn.XLOOKUP(B9,'[1]daily break down'!$D:$D,'[1]daily break down'!$E:$E,"") -> Yaounde | D9: CAMUSAT | E9: Good Grid no GE - 8h | F9: CENTRE | G9: Yaounde | H9: =_xlfn.XLOOKUP(B9,[2]CALCULATION!$B:$B,[2]CALCULATION!$H:$H,"") -> ZTE | I9: 0 | J9: 0 | K9: 0 | L9: 0 | M9: 0 | N9: 4.1508826 | O9: 33.897493 | P9: REPETITIF | Q9: Operationnel | S9: {=IFERROR(_xlfn.IFS( U9="MPR ISSUE","PDH", U9="BSS Hardware Issue","BSS", U9="Sites strategiques, MLL, Pylone, etc.","ENVTECH", U9="AKTIVCO DEFAUT GE & POWER Cabinet","AKTIVCO", U9="AKTIVCO Coupure ENEO & Baisse de tension","AKTIVCO GRID ONLY", U9="Coupure ENEO & Baisse de tension","IHS GRID ONLY", U9="Defaut GE & POWER Cabinet","IHS", U9="Sharing","Partners", U9="Sites strategiques & DataCenter","SST & DC", U9="Exclu","Exclu", U9="SAT","SAT", U9="SPARE-ISSUE","SPARE-ISSUE", U9="Fiber CAmtel","TRANS_FO_CAMTEL", U9="Fiber AOF","Fiber AOF", U9="Projet OCM (HUAWEI)","TRAVAUX-HUAWEI", U9="Projet OCM (NOKIA)","TRAVAUX-NOKIA", U9="ACCESS-ISSUE","ACCESS-ISSUE", U9="Projet OCM (ZTE, NOKIA, autres projets)","TRAVAUX OCM", U9="No root CAuse","No root cause", U9="ODU HS","PDH", U9="IP & VLAN","PDH", U9="Warehouse HUAWEI","SPARE-ISSUE", U9="SPARE-HS","SPARE-ISSUE", U9="Power Telco","BSS" ),"")} | T9: {=IFERROR(_xlfn.IFS( U9="MPR ISSUE","TX ISSUE", U9="BSS Hardware Issue","RAN ISSUE", U9="Sites strategiques, MLL, Pylone, etc.","ENVTECH", U9="AKTIVCO DEFAUT GE & POWER Cabinet","POWER ISSUE", U9="AKTIVCO Coupure ENEO & Baisse de tension","POWER ISSUE", U9="Coupure ENEO & Baisse de tension","POWER ISSUE", U9="Defaut GE & POWER Cabinet","POWER ISSUE", U9="Sharing","POWER ISSUE", U9="Sites strategiques & DataCenter","POWER ISSUE", U9="Exclu","Exclu", U9="SAT","TX ISSUE", U9="SPARE-ISSUE","SPARE-ISSUE", U9="Fiber CAmtel","TX ISSUE", U9="Fiber AOF","TX ISSUE", U9="Projet OCM (HUAWEI)","TRAVAUX-HUAWEI", U9="Projet OCM (NOKIA)","TRAVAUX -NOKIA", U9="ACCESS-ISSUE","ACCESS-ISSUE", U9="Projet OCM (ZTE, NOKIA, autres projets)","TRAVAUX OCM", U9="No root CAuse","No root cause", U9="ODU HS","TX ISSUE", U9="IP & VLAN","TX ISSUE", U9="Warehouse HUAWEI","SPARE-ISSUE", U9="SPARE-HS","SPARE-ISSUE", U9="Power Telco","RAN ISSUE" ),"")} | V9: {=IFERROR(_xlfn.IFS( U9="MPR ISSUE","ACTIVE", U9="BSS Hardware Issue","ACTIVE", U9="Sites strategiques, MLL, Pylone, etc.","PASSIVE", U9="AKTIVCO DEFAUT GE & POWER Cabinet","PASSIVE", U9="AKTIVCO Coupure ENEO & Baisse de tension","PASSIVE", U9="Coupure ENEO & Baisse de tension","PASSIVE", U9="Defaut GE & POWER Cabinet","PASSIVE", U9="Sharing","PASSIVE", U9="Sites strategiques & DataCenter","PASSIVE", U9="Exclu","Exclu", U9="SAT","ACTIVE", U9="SPARE-ISSUE","SPARE-ISSUE", U9="Fiber CAmtel","ACTIVE", U9="Fiber AOF","ACTIVE", U9="Projet OCM (HUAWEI)","PLANNED WORKS", U9="Projet OCM (NOKIA)","PLANNED WORKS", U9="ACCESS-ISSUE","ACCESS-ISSUE", U9="Projet OCM (ZTE, NOKIA, autres projets)","PLANNED WORKS", U9="No root CAuse","No root cause", U9="ODU HS","ACTIVE", U9="IP & VLAN","ACTIVE", U9="Warehouse HUAWEI","SPARE-ISSUE", U9="SPARE-HS","SPARE-ISSUE", U9="Power Telco","ACTIVE" ),"")} | W9: Grid outage, Grid only site | X9: Awaiting Grid return | Z9: CAMUSAT | AA9: Ongoing | AB9: 21/04/2026 Camusat: grid outage grid only site / awaiting grid return..(04/21/2026-ocm ran incident 18h):-21/04/2026 grid outage, grid only / grid return awaited - Escalated to L3 20/04/2026 grid outage, grid only / grid return awaited..(04/21/2026-ocm ran incident 14h):-21/04/2026 grid outage, grid only / grid return awaited - Escalated to L3 20/04/2026 grid outage, grid only / grid return awaited..(04/21/2026 tickect): -INC-20260421-00014742…2026-04-21 23:48:04…Grid outage and grid only site / Grid return awaited | AC9: =_xlfn.XLOOKUP(B9,[4]ALL!$B:$B,[4]ALL!$N:$N,"") | AD9: 21/04/2026 Camusat: grid outage grid only site / awaiting grid return | AT9: (04/21/2026-ocm ran incident 18h):-21/04/2026 grid outage, grid only / grid return awaited - Escalated to L3 20/04/2026 grid outage, grid only / grid return awaited | AU9: (04/21/2026-ocm ran incident 14h):-21/04/2026 grid outage, grid only / grid return awaited - Escalated to L3 20/04/2026 grid outage, grid only / grid return awaited | AV9: (04/21/2026 tickect): -INC-20260421-00014742…2026-04-21 23:48:04…Grid outage and grid only site / Grid return awaited
A10: Koweit-City | B10: CTR_258 | C10: =_xlfn.XLOOKUP(B10,'[1]daily break down'!$D:$D,'[1]daily break down'!$E:$E,"") -> Yaounde | D10: CAMUSAT | E10: Good Grid + GE | F10: CENTRE | G10: Yaounde | H10: =_xlfn.XLOOKUP(B10,[2]CALCULATION!$B:$B,[2]CALCULATION!$H:$H,"") -> ZTE | I10: 22.084607 | J10: 17.864239 | K10: 7.9206475 | L10: 12.382485 | M10: 12.046668 | N10: 33.366168 | O10: 33.624901 | P10: REPETITIF | Q10: Operationnel | S10: {=IFERROR(_xlfn.IFS( U10="MPR ISSUE","PDH", U10="BSS Hardware Issue","BSS", U10="Sites strategiques, MLL, Pylone, etc.","ENVTECH", U10="AKTIVCO DEFAUT GE & POWER Cabinet","AKTIVCO", U10="AKTIVCO Coupure ENEO & Baisse de tension","AKTIVCO GRID ONLY", U10="Coupure ENEO & Baisse de tension","IHS GRID ONLY", U10="Defaut GE & POWER Cabinet","IHS", U10="Sharing","Partners", U10="Sites strategiques & DataCenter","SST & DC", U10="Exclu","Exclu", U10="SAT","SAT", U10="SPARE-ISSUE","SPARE-ISSUE", U10="Fiber CAmtel","TRANS_FO_CAMTEL", U10="Fiber AOF","Fiber AOF", U10="Projet OCM (HUAWEI)","TRAVAUX-HUAWEI", U10="Projet OCM (NOKIA)","TRAVAUX-NOKIA", U10="ACCESS-ISSUE","ACCESS-ISSUE", U10="Projet OCM (ZTE, NOKIA, autres projets)","TRAVAUX OCM", U10="No root CAuse","No root cause", U10="ODU HS","PDH", U10="IP & VLAN","PDH", U10="Warehouse HUAWEI","SPARE-ISSUE", U10="SPARE-HS","SPARE-ISSUE", U10="Power Telco","BSS" ),"")} | T10: {=IFERROR(_xlfn.IFS( U10="MPR ISSUE","TX ISSUE", U10="BSS Hardware Issue","RAN ISSUE", U10="Sites strategiques, MLL, Pylone, etc.","ENVTECH", U10="AKTIVCO DEFAUT GE & POWER Cabinet","POWER ISSUE", U10="AKTIVCO Coupure ENEO & Baisse de tension","POWER ISSUE", U10="Coupure ENEO & Baisse de tension","POWER ISSUE", U10="Defaut GE & POWER Cabinet","POWER ISSUE", U10="Sharing","POWER ISSUE", U10="Sites strategiques & DataCenter","POWER ISSUE", U10="Exclu","Exclu", U10="SAT","TX ISSUE", U10="SPARE-ISSUE","SPARE-ISSUE", U10="Fiber CAmtel","TX ISSUE", U10="Fiber AOF","TX ISSUE", U10="Projet OCM (HUAWEI)","TRAVAUX-HUAWEI", U10="Projet OCM (NOKIA)","TRAVAUX -NOKIA", U10="ACCESS-ISSUE","ACCESS-ISSUE", U10="Projet OCM (ZTE, NOKIA, autres projets)","TRAVAUX OCM", U10="No root CAuse","No root cause", U10="ODU HS","TX ISSUE", U10="IP & VLAN","TX ISSUE", U10="Warehouse HUAWEI","SPARE-ISSUE", U10="SPARE-HS","SPARE-ISSUE", U10="Power Telco","RAN ISSUE" ),"")} | V10: {=IFERROR(_xlfn.IFS( U10="MPR ISSUE","ACTIVE", U10="BSS Hardware Issue","ACTIVE", U10="Sites strategiques, MLL, Pylone, etc.","PASSIVE", U10="AKTIVCO DEFAUT GE & POWER Cabinet","PASSIVE", U10="AKTIVCO Coupure ENEO & Baisse de tension","PASSIVE", U10="Coupure ENEO & Baisse de tension","PASSIVE", U10="Defaut GE & POWER Cabinet","PASSIVE", U10="Sharing","PASSIVE", U10="Sites strategiques & DataCenter","PASSIVE", U10="Exclu","Exclu", U10="SAT","ACTIVE", U10="SPARE-ISSUE","SPARE-ISSUE", U10="Fiber CAmtel","ACTIVE", U10="Fiber AOF","ACTIVE", U10="Projet OCM (HUAWEI)","PLANNED WORKS", U10="Projet OCM (NOKIA)","PLANNED WORKS", U10="ACCESS-ISSUE","ACCESS-ISSUE", U10="Projet OCM (ZTE, NOKIA, autres projets)","PLANNED WORKS", U10="No root CAuse","No root cause", U10="ODU HS","ACTIVE", U10="IP & VLAN","ACTIVE", U10="Warehouse HUAWEI","SPARE-ISSUE", U10="SPARE-HS","SPARE-ISSUE", U10="Power Telco","ACTIVE" ),"")} | W10: Need BO RAN analysis | X10: Awaiting BO RAN analysis | Z10: BO RAN | AA10: Ongoing | AB10: 21/04/2026 : Besoin d'analyse BO RAN..(04/21/2026 cell zte):-21/04/2026 : Besoin d'analyse BO RAN..(04/21/2026 cell zte):-21/04/2026 : Besoin d'analyse BO RAN | AC10: =_xlfn.XLOOKUP(B10,[4]ALL!$B:$B,[4]ALL!$N:$N,"") | AD10: 21/04/2026 : Besoin d'analyse BO RAN | AR10: (04/21/2026 cell zte):-21/04/2026 : Besoin d'analyse BO RAN | AS10: (04/21/2026 cell zte):-21/04/2026 : Besoin d'analyse BO RAN
A11: Nkolmessing-Abom-MTN | B11: CTR_832 | C11: =_xlfn.XLOOKUP(B11,'[1]daily break down'!$D:$D,'[1]daily break down'!$E:$E,"") -> Yaounde | D11: MTN | F11: CENTRE | G11: Yaounde | H11: =_xlfn.XLOOKUP(B11,[2]CALCULATION!$B:$B,[2]CALCULATION!$H:$H,"") -> ZTE | I11: 32.359966 | J11: 32.359966 | K11: 32.359966 | L11: 32.359966 | M11: 32.359966 | N11: 32.359966 | O11: 32.359966 | P11: REPETITIF | Q11: Operationnel | S11: {=IFERROR(_xlfn.IFS( U11="MPR ISSUE","PDH", U11="BSS Hardware Issue","BSS", U11="Sites strategiques, MLL, Pylone, etc.","ENVTECH", U11="AKTIVCO DEFAUT GE & POWER Cabinet","AKTIVCO", U11="AKTIVCO Coupure ENEO & Baisse de tension","AKTIVCO GRID ONLY", U11="Coupure ENEO & Baisse de tension","IHS GRID ONLY", U11="Defaut GE & POWER Cabinet","IHS", U11="Sharing","Partners", U11="Sites strategiques & DataCenter","SST & DC", U11="Exclu","Exclu", U11="SAT","SAT", U11="SPARE-ISSUE","SPARE-ISSUE", U11="Fiber CAmtel","TRANS_FO_CAMTEL", U11="Fiber AOF","Fiber AOF", U11="Projet OCM (HUAWEI)","TRAVAUX-HUAWEI", U11="Projet OCM (NOKIA)","TRAVAUX-NOKIA", U11="ACCESS-ISSUE","ACCESS-ISSUE", U11="Projet OCM (ZTE, NOKIA, autres projets)","TRAVAUX OCM", U11="No root CAuse","No root cause", U11="ODU HS","PDH", U11="IP & VLAN","PDH", U11="Warehouse HUAWEI","SPARE-ISSUE", U11="SPARE-HS","SPARE-ISSUE", U11="Power Telco","BSS" ),"")} | T11: {=IFERROR(_xlfn.IFS( U11="MPR ISSUE","TX ISSUE", U11="BSS Hardware Issue","RAN ISSUE", U11="Sites strategiques, MLL, Pylone, etc.","ENVTECH", U11="AKTIVCO DEFAUT GE & POWER Cabinet","POWER ISSUE", U11="AKTIVCO Coupure ENEO & Baisse de tension","POWER ISSUE", U11="Coupure ENEO & Baisse de tension","POWER ISSUE", U11="Defaut GE & POWER Cabinet","POWER ISSUE", U11="Sharing","POWER ISSUE", U11="Sites strategiques & DataCenter","POWER ISSUE", U11="Exclu","Exclu", U11="SAT","TX ISSUE", U11="SPARE-ISSUE","SPARE-ISSUE", U11="Fiber CAmtel","TX ISSUE", U11="Fiber AOF","TX ISSUE", U11="Projet OCM (HUAWEI)","TRAVAUX-HUAWEI", U11="Projet OCM (NOKIA)","TRAVAUX -NOKIA", U11="ACCESS-ISSUE","ACCESS-ISSUE", U11="Projet OCM (ZTE, NOKIA, autres projets)","TRAVAUX OCM", U11="No root CAuse","No root cause", U11="ODU HS","TX ISSUE", U11="IP & VLAN","TX ISSUE", U11="Warehouse HUAWEI","SPARE-ISSUE", U11="SPARE-HS","SPARE-ISSUE", U11="Power Telco","RAN ISSUE" ),"")} | V11: {=IFERROR(_xlfn.IFS( U11="MPR ISSUE","ACTIVE", U11="BSS Hardware Issue","ACTIVE", U11="Sites strategiques, MLL, Pylone, etc.","PASSIVE", U11="AKTIVCO DEFAUT GE & POWER Cabinet","PASSIVE", U11="AKTIVCO Coupure ENEO & Baisse de tension","PASSIVE", U11="Coupure ENEO & Baisse de tension","PASSIVE", U11="Defaut GE & POWER Cabinet","PASSIVE", U11="Sharing","PASSIVE", U11="Sites strategiques & DataCenter","PASSIVE", U11="Exclu","Exclu", U11="SAT","ACTIVE", U11="SPARE-ISSUE","SPARE-ISSUE", U11="Fiber CAmtel","ACTIVE", U11="Fiber AOF","ACTIVE", U11="Projet OCM (HUAWEI)","PLANNED WORKS", U11="Projet OCM (NOKIA)","PLANNED WORKS", U11="ACCESS-ISSUE","ACCESS-ISSUE", U11="Projet OCM (ZTE, NOKIA, autres projets)","PLANNED WORKS", U11="No root CAuse","No root cause", U11="ODU HS","ACTIVE", U11="IP & VLAN","ACTIVE", U11="Warehouse HUAWEI","SPARE-ISSUE", U11="SPARE-HS","SPARE-ISSUE", U11="Power Telco","ACTIVE" ),"")} | W11: Power issue | X11: Awaiting BO TX analysis | Z11: BO TX | AA11: Ongoing | AB11: CTR_832 | AC11: =_xlfn.XLOOKUP(B11,[4]ALL!$B:$B,[4]ALL!$N:$N,"") | BA11: CTR_832
A12: Tropicana-New | B12: CTR_833 | C12: =_xlfn.XLOOKUP(B12,'[1]daily break down'!$D:$D,'[1]daily break down'!$E:$E,"") -> Yaounde | D12: CAMUSAT | E12: Good Grid + GE | F12: CENTRE | G12: Yaounde | H12: =_xlfn.XLOOKUP(B12,[2]CALCULATION!$B:$B,[2]CALCULATION!$H:$H,"") -> ZTE | I12: 3.4924829 | J12: 0.7168453 | K12: 0 | L12: 1.4686117 | M12: 17.352318 | N12: 6.2770915 | O12: 31.937275 | P12: REPETITIF | Q12: Operationnel | S12: {=IFERROR(_xlfn.IFS( U12="MPR ISSUE","PDH", U12="BSS Hardware Issue","BSS", U12="Sites strategiques, MLL, Pylone, etc.","ENVTECH", U12="AKTIVCO DEFAUT GE & POWER Cabinet","AKTIVCO", U12="AKTIVCO Coupure ENEO & Baisse de tension","AKTIVCO GRID ONLY", U12="Coupure ENEO & Baisse de tension","IHS GRID ONLY", U12="Defaut GE & POWER Cabinet","IHS", U12="Sharing","Partners", U12="Sites strategiques & DataCenter","SST & DC", U12="Exclu","Exclu", U12="SAT","SAT", U12="SPARE-ISSUE","SPARE-ISSUE", U12="Fiber CAmtel","TRANS_FO_CAMTEL", U12="Fiber AOF","Fiber AOF", U12="Projet OCM (HUAWEI)","TRAVAUX-HUAWEI", U12="Projet OCM (NOKIA)","TRAVAUX-NOKIA", U12="ACCESS-ISSUE","ACCESS-ISSUE", U12="Projet OCM (ZTE, NOKIA, autres projets)","TRAVAUX OCM", U12="No root CAuse","No root cause", U12="ODU HS","PDH", U12="IP & VLAN","PDH", U12="Warehouse HUAWEI","SPARE-ISSUE", U12="SPARE-HS","SPARE-ISSUE", U12="Power Telco","BSS" ),"")} | T12: {=IFERROR(_xlfn.IFS( U12="MPR ISSUE","TX ISSUE", U12="BSS Hardware Issue","RAN ISSUE", U12="Sites strategiques, MLL, Pylone, etc.","ENVTECH", U12="AKTIVCO DEFAUT GE & POWER Cabinet","POWER ISSUE", U12="AKTIVCO Coupure ENEO & Baisse de tension","POWER ISSUE", U12="Coupure ENEO & Baisse de tension","POWER ISSUE", U12="Defaut GE & POWER Cabinet","POWER ISSUE", U12="Sharing","POWER ISSUE", U12="Sites strategiques & DataCenter","POWER ISSUE", U12="Exclu","Exclu", U12="SAT","TX ISSUE", U12="SPARE-ISSUE","SPARE-ISSUE", U12="Fiber CAmtel","TX ISSUE", U12="Fiber AOF","TX ISSUE", U12="Projet OCM (HUAWEI)","TRAVAUX-HUAWEI", U12="Projet OCM (NOKIA)","TRAVAUX -NOKIA", U12="ACCESS-ISSUE","ACCESS-ISSUE", U12="Projet OCM (ZTE, NOKIA, autres projets)","TRAVAUX OCM", U12="No root CAuse","No root cause", U12="ODU HS","TX ISSUE", U12="IP & VLAN","TX ISSUE", U12="Warehouse HUAWEI","SPARE-ISSUE", U12="SPARE-HS","SPARE-ISSUE", U12="Power Telco","RAN ISSUE" ),"")} | V12: {=IFERROR(_xlfn.IFS( U12="MPR ISSUE","ACTIVE", U12="BSS Hardware Issue","ACTIVE", U12="Sites strategiques, MLL, Pylone, etc.","PASSIVE", U12="AKTIVCO DEFAUT GE & POWER Cabinet","PASSIVE", U12="AKTIVCO Coupure ENEO & Baisse de tension","PASSIVE", U12="Coupure ENEO & Baisse de tension","PASSIVE", U12="Defaut GE & POWER Cabinet","PASSIVE", U12="Sharing","PASSIVE", U12="Sites strategiques & DataCenter","PASSIVE", U12="Exclu","Exclu", U12="SAT","ACTIVE", U12="SPARE-ISSUE","SPARE-ISSUE", U12="Fiber CAmtel","ACTIVE", U12="Fiber AOF","ACTIVE", U12="Projet OCM (HUAWEI)","PLANNED WORKS", U12="Projet OCM (NOKIA)","PLANNED WORKS", U12="ACCESS-ISSUE","ACCESS-ISSUE", U12="Projet OCM (ZTE, NOKIA, autres projets)","PLANNED WORKS", U12="No root CAuse","No root cause", U12="ODU HS","ACTIVE", U12="IP & VLAN","ACTIVE", U12="Warehouse HUAWEI","SPARE-ISSUE", U12="SPARE-HS","SPARE-ISSUE", U12="Power Telco","ACTIVE" ),"")} | W12: Grid outage | X12: Awaiting Grid return | Z12: CAMUSAT | AA12: Ongoing | AB12: 21.04.26; Camusat; FME is on the way ETA 15H30..(04/21/2026-ocm ran incident 14h):-21.04.26; Camusat; FME is on the way ETA 15H30..(04/21/2026 tickect): -INC-20260421-00006727…2026-04-21 13:13:58…FME is on the way ETA 15H30 | AC12: =_xlfn.XLOOKUP(B12,[4]ALL!$B:$B,[4]ALL!$N:$N,"") | AD12: 21.04.26; Camusat; FME is on the way ETA 15H30 | AU12: (04/21/2026-ocm ran incident 14h):-21.04.26; Camusat; FME is on the way ETA 15H30 | AV12: (04/21/2026 tickect): -INC-20260421-00006727…2026-04-21 13:13:58…FME is on the way ETA 15H30
A13: Lendi-II | B13: LIT_582 | C13: =_xlfn.XLOOKUP(B13,'[1]daily break down'!$D:$D,'[1]daily break down'!$E:$E,"") -> Douala | D13: CAMUSAT | E13: Good Grid + GE | F13: LITTORAL | G13: Douala | H13: =_xlfn.XLOOKUP(B13,[2]CALCULATION!$B:$B,[2]CALCULATION!$H:$H,"") -> ZTE | I13: 0 | J13: 0 | K13: 0 | L13: 0 | M13: 4.2905313 | N13: 13.868557 | O13: 29.798885 | P13: REPETITIF | Q13: Operationnel | S13: {=IFERROR(_xlfn.IFS( U13="MPR ISSUE","PDH", U13="BSS Hardware Issue","BSS", U13="Sites strategiques, MLL, Pylone, etc.","ENVTECH", U13="AKTIVCO DEFAUT GE & POWER Cabinet","AKTIVCO", U13="AKTIVCO Coupure ENEO & Baisse de tension","AKTIVCO GRID ONLY", U13="Coupure ENEO & Baisse de tension","IHS GRID ONLY", U13="Defaut GE & POWER Cabinet","IHS", U13="Sharing","Partners", U13="Sites strategiques & DataCenter","SST & DC", U13="Exclu","Exclu", U13="SAT","SAT", U13="SPARE-ISSUE","SPARE-ISSUE", U13="Fiber CAmtel","TRANS_FO_CAMTEL", U13="Fiber AOF","Fiber AOF", U13="Projet OCM (HUAWEI)","TRAVAUX-HUAWEI", U13="Projet OCM (NOKIA)","TRAVAUX-NOKIA", U13="ACCESS-ISSUE","ACCESS-ISSUE", U13="Projet OCM (ZTE, NOKIA, autres projets)","TRAVAUX OCM", U13="No root CAuse","No root cause", U13="ODU HS","PDH", U13="IP & VLAN","PDH", U13="Warehouse HUAWEI","SPARE-ISSUE", U13="SPARE-HS","SPARE-ISSUE", U13="Power Telco","BSS" ),"")} | T13: {=IFERROR(_xlfn.IFS( U13="MPR ISSUE","TX ISSUE", U13="BSS Hardware Issue","RAN ISSUE", U13="Sites strategiques, MLL, Pylone, etc.","ENVTECH", U13="AKTIVCO DEFAUT GE & POWER Cabinet","POWER ISSUE", U13="AKTIVCO Coupure ENEO & Baisse de tension","POWER ISSUE", U13="Coupure ENEO & Baisse de tension","POWER ISSUE", U13="Defaut GE & POWER Cabinet","POWER ISSUE", U13="Sharing","POWER ISSUE", U13="Sites strategiques & DataCenter","POWER ISSUE", U13="Exclu","Exclu", U13="SAT","TX ISSUE", U13="SPARE-ISSUE","SPARE-ISSUE", U13="Fiber CAmtel","TX ISSUE", U13="Fiber AOF","TX ISSUE", U13="Projet OCM (HUAWEI)","TRAVAUX-HUAWEI", U13="Projet OCM (NOKIA)","TRAVAUX -NOKIA", U13="ACCESS-ISSUE","ACCESS-ISSUE", U13="Projet OCM (ZTE, NOKIA, autres projets)","TRAVAUX OCM", U13="No root CAuse","No root cause", U13="ODU HS","TX ISSUE", U13="IP & VLAN","TX ISSUE", U13="Warehouse HUAWEI","SPARE-ISSUE", U13="SPARE-HS","SPARE-ISSUE", U13="Power Telco","RAN ISSUE" ),"")} | V13: {=IFERROR(_xlfn.IFS( U13="MPR ISSUE","ACTIVE", U13="BSS Hardware Issue","ACTIVE", U13="Sites strategiques, MLL, Pylone, etc.","PASSIVE", U13="AKTIVCO DEFAUT GE & POWER Cabinet","PASSIVE", U13="AKTIVCO Coupure ENEO & Baisse de tension","PASSIVE", U13="Coupure ENEO & Baisse de tension","PASSIVE", U13="Defaut GE & POWER Cabinet","PASSIVE", U13="Sharing","PASSIVE", U13="Sites strategiques & DataCenter","PASSIVE", U13="Exclu","Exclu", U13="SAT","ACTIVE", U13="SPARE-ISSUE","SPARE-ISSUE", U13="Fiber CAmtel","ACTIVE", U13="Fiber AOF","ACTIVE", U13="Projet OCM (HUAWEI)","PLANNED WORKS", U13="Projet OCM (NOKIA)","PLANNED WORKS", U13="ACCESS-ISSUE","ACCESS-ISSUE", U13="Projet OCM (ZTE, NOKIA, autres projets)","PLANNED WORKS", U13="No root CAuse","No root cause", U13="ODU HS","ACTIVE", U13="IP & VLAN","ACTIVE", U13="Warehouse HUAWEI","SPARE-ISSUE", U13="SPARE-HS","SPARE-ISSUE", U13="Power Telco","ACTIVE" ),"")} | W13: =_xlfn.XLOOKUP($B13,Sheet1!$C:$C,Sheet1!E:E,"") -> Impacted by LIT_774_Z_Lendi-Chefferie. MPR issue | X13: =_xlfn.XLOOKUP($B13,Sheet1!$C:$C,Sheet1!F:F,"") -> Dispatch FME on site to check MPR status | Z13: =_xlfn.XLOOKUP($B13,Sheet1!$C:$C,Sheet1!H:H,"") -> GNOC | AA13: Ongoing | AB13: 20.04.26; FME sur site mais injoignable, escalade faite au RM, update ASAP 20.04.26; Besoin d'un FME sur site pour vérifier la chaine antennaire de l'ODU 3.1; FME Etaba activé pour investigations, FME sur site et travaux en cours Impacted by LIT_774_Z_Lendi-Chefferie (TX issue) | AC13: =_xlfn.XLOOKUP(B13,[4]ALL!$B:$B,[4]ALL!$N:$N,"") | AD13: 20.04.26; FME sur site mais injoignable, escalade faite au RM, update ASAP 20.04.26; Besoin d'un FME sur site pour vérifier la chaine antennaire de l'ODU 3.1; FME Etaba activé pour investigations, FME sur site et travaux en cours Impacted by LIT_774_Z_Lendi-Chefferie (TX issue)
A14: Lendi-Chefferie | B14: LIT_774 | C14: =_xlfn.XLOOKUP(B14,'[1]daily break down'!$D:$D,'[1]daily break down'!$E:$E,"") -> Douala | D14: CAMUSAT | E14: Good Grid + GE | F14: LITTORAL | G14: Douala | H14: =_xlfn.XLOOKUP(B14,[2]CALCULATION!$B:$B,[2]CALCULATION!$H:$H,"") -> ZTE | I14: 0 | J14: 0 | K14: 0 | L14: 0 | M14: 4.2900497 | N14: 56.485334 | O14: 29.798225 | P14: REPETITIF | Q14: Operationnel | S14: {=IFERROR(_xlfn.IFS( U14="MPR ISSUE","PDH", U14="BSS Hardware Issue","BSS", U14="Sites strategiques, MLL, Pylone, etc.","ENVTECH", U14="AKTIVCO DEFAUT GE & POWER Cabinet","AKTIVCO", U14="AKTIVCO Coupure ENEO & Baisse de tension","AKTIVCO GRID ONLY", U14="Coupure ENEO & Baisse de tension","IHS GRID ONLY", U14="Defaut GE & POWER Cabinet","IHS", U14="Sharing","Partners", U14="Sites strategiques & DataCenter","SST & DC", U14="Exclu","Exclu", U14="SAT","SAT", U14="SPARE-ISSUE","SPARE-ISSUE", U14="Fiber CAmtel","TRANS_FO_CAMTEL", U14="Fiber AOF","Fiber AOF", U14="Projet OCM (HUAWEI)","TRAVAUX-HUAWEI", U14="Projet OCM (NOKIA)","TRAVAUX-NOKIA", U14="ACCESS-ISSUE","ACCESS-ISSUE", U14="Projet OCM (ZTE, NOKIA, autres projets)","TRAVAUX OCM", U14="No root CAuse","No root cause", U14="ODU HS","PDH", U14="IP & VLAN","PDH", U14="Warehouse HUAWEI","SPARE-ISSUE", U14="SPARE-HS","SPARE-ISSUE", U14="Power Telco","BSS" ),"")} | T14: {=IFERROR(_xlfn.IFS( U14="MPR ISSUE","TX ISSUE", U14="BSS Hardware Issue","RAN ISSUE", U14="Sites strategiques, MLL, Pylone, etc.","ENVTECH", U14="AKTIVCO DEFAUT GE & POWER Cabinet","POWER ISSUE", U14="AKTIVCO Coupure ENEO & Baisse de tension","POWER ISSUE", U14="Coupure ENEO & Baisse de tension","POWER ISSUE", U14="Defaut GE & POWER Cabinet","POWER ISSUE", U14="Sharing","POWER ISSUE", U14="Sites strategiques & DataCenter","POWER ISSUE", U14="Exclu","Exclu", U14="SAT","TX ISSUE", U14="SPARE-ISSUE","SPARE-ISSUE", U14="Fiber CAmtel","TX ISSUE", U14="Fiber AOF","TX ISSUE", U14="Projet OCM (HUAWEI)","TRAVAUX-HUAWEI", U14="Projet OCM (NOKIA)","TRAVAUX -NOKIA", U14="ACCESS-ISSUE","ACCESS-ISSUE", U14="Projet OCM (ZTE, NOKIA, autres projets)","TRAVAUX OCM", U14="No root CAuse","No root cause", U14="ODU HS","TX ISSUE", U14="IP & VLAN","TX ISSUE", U14="Warehouse HUAWEI","SPARE-ISSUE", U14="SPARE-HS","SPARE-ISSUE", U14="Power Telco","RAN ISSUE" ),"")} | V14: {=IFERROR(_xlfn.IFS( U14="MPR ISSUE","ACTIVE", U14="BSS Hardware Issue","ACTIVE", U14="Sites strategiques, MLL, Pylone, etc.","PASSIVE", U14="AKTIVCO DEFAUT GE & POWER Cabinet","PASSIVE", U14="AKTIVCO Coupure ENEO & Baisse de tension","PASSIVE", U14="Coupure ENEO & Baisse de tension","PASSIVE", U14="Defaut GE & POWER Cabinet","PASSIVE", U14="Sharing","PASSIVE", U14="Sites strategiques & DataCenter","PASSIVE", U14="Exclu","Exclu", U14="SAT","ACTIVE", U14="SPARE-ISSUE","SPARE-ISSUE", U14="Fiber CAmtel","ACTIVE", U14="Fiber AOF","ACTIVE", U14="Projet OCM (HUAWEI)","PLANNED WORKS", U14="Projet OCM (NOKIA)","PLANNED WORKS", U14="ACCESS-ISSUE","ACCESS-ISSUE", U14="Projet OCM (ZTE, NOKIA, autres projets)","PLANNED WORKS", U14="No root CAuse","No root cause", U14="ODU HS","ACTIVE", U14="IP & VLAN","ACTIVE", U14="Warehouse HUAWEI","SPARE-ISSUE", U14="SPARE-HS","SPARE-ISSUE", U14="Power Telco","ACTIVE" ),"")} | W14: MPR issue | X14: Dispatch FME on site to check MPR status | Z14: GNOC | AA14: Ongoing | AB14: 20/04/2026 Besoin d'un fme sur site pour verifier le status du MPR | AC14: =_xlfn.XLOOKUP(B14,[4]ALL!$B:$B,[4]ALL!$N:$N,"") | AD14: 20/04/2026 Besoin d'un fme sur site pour verifier le status du MPR
A15: Fin-goudron-Mbangue | B15: LIT_844 | C15: =_xlfn.XLOOKUP(B15,'[1]daily break down'!$D:$D,'[1]daily break down'!$E:$E,"") -> Douala | D15: CAMUSAT | E15: Bad-Grid-GE | F15: LITTORAL | G15: Douala | H15: =_xlfn.XLOOKUP(B15,[2]CALCULATION!$B:$B,[2]CALCULATION!$H:$H,"") -> ZTE | I15: 0 | J15: 0 | K15: 41.248933 | L15: 0.2306254 | M15: 3.535947 | N15: 0.11619554 | O15: 29.782441 | P15: REPETITIF | Q15: Operationnel | S15: {=IFERROR(_xlfn.IFS( U15="MPR ISSUE","PDH", U15="BSS Hardware Issue","BSS", U15="Sites strategiques, MLL, Pylone, etc.","ENVTECH", U15="AKTIVCO DEFAUT GE & POWER Cabinet","AKTIVCO", U15="AKTIVCO Coupure ENEO & Baisse de tension","AKTIVCO GRID ONLY", U15="Coupure ENEO & Baisse de tension","IHS GRID ONLY", U15="Defaut GE & POWER Cabinet","IHS", U15="Sharing","Partners", U15="Sites strategiques & DataCenter","SST & DC", U15="Exclu","Exclu", U15="SAT","SAT", U15="SPARE-ISSUE","SPARE-ISSUE", U15="Fiber CAmtel","TRANS_FO_CAMTEL", U15="Fiber AOF","Fiber AOF", U15="Projet OCM (HUAWEI)","TRAVAUX-HUAWEI", U15="Projet OCM (NOKIA)","TRAVAUX-NOKIA", U15="ACCESS-ISSUE","ACCESS-ISSUE", U15="Projet OCM (ZTE, NOKIA, autres projets)","TRAVAUX OCM", U15="No root CAuse","No root cause", U15="ODU HS","PDH", U15="IP & VLAN","PDH", U15="Warehouse HUAWEI","SPARE-ISSUE", U15="SPARE-HS","SPARE-ISSUE", U15="Power Telco","BSS" ),"")} | T15: {=IFERROR(_xlfn.IFS( U15="MPR ISSUE","TX ISSUE", U15="BSS Hardware Issue","RAN ISSUE", U15="Sites strategiques, MLL, Pylone, etc.","ENVTECH", U15="AKTIVCO DEFAUT GE & POWER Cabinet","POWER ISSUE", U15="AKTIVCO Coupure ENEO & Baisse de tension","POWER ISSUE", U15="Coupure ENEO & Baisse de tension","POWER ISSUE", U15="Defaut GE & POWER Cabinet","POWER ISSUE", U15="Sharing","POWER ISSUE", U15="Sites strategiques & DataCenter","POWER ISSUE", U15="Exclu","Exclu", U15="SAT","TX ISSUE", U15="SPARE-ISSUE","SPARE-ISSUE", U15="Fiber CAmtel","TX ISSUE", U15="Fiber AOF","TX ISSUE", U15="Projet OCM (HUAWEI)","TRAVAUX-HUAWEI", U15="Projet OCM (NOKIA)","TRAVAUX -NOKIA", U15="ACCESS-ISSUE","ACCESS-ISSUE", U15="Projet OCM (ZTE, NOKIA, autres projets)","TRAVAUX OCM", U15="No root CAuse","No root cause", U15="ODU HS","TX ISSUE", U15="IP & VLAN","TX ISSUE", U15="Warehouse HUAWEI","SPARE-ISSUE", U15="SPARE-HS","SPARE-ISSUE", U15="Power Telco","RAN ISSUE" ),"")} | V15: {=IFERROR(_xlfn.IFS( U15="MPR ISSUE","ACTIVE", U15="BSS Hardware Issue","ACTIVE", U15="Sites strategiques, MLL, Pylone, etc.","PASSIVE", U15="AKTIVCO DEFAUT GE & POWER Cabinet","PASSIVE", U15="AKTIVCO Coupure ENEO & Baisse de tension","PASSIVE", U15="Coupure ENEO & Baisse de tension","PASSIVE", U15="Defaut GE & POWER Cabinet","PASSIVE", U15="Sharing","PASSIVE", U15="Sites strategiques & DataCenter","PASSIVE", U15="Exclu","Exclu", U15="SAT","ACTIVE", U15="SPARE-ISSUE","SPARE-ISSUE", U15="Fiber CAmtel","ACTIVE", U15="Fiber AOF","ACTIVE", U15="Projet OCM (HUAWEI)","PLANNED WORKS", U15="Projet OCM (NOKIA)","PLANNED WORKS", U15="ACCESS-ISSUE","ACCESS-ISSUE", U15="Projet OCM (ZTE, NOKIA, autres projets)","PLANNED WORKS", U15="No root CAuse","No root cause", U15="ODU HS","ACTIVE", U15="IP & VLAN","ACTIVE", U15="Warehouse HUAWEI","SPARE-ISSUE", U15="SPARE-HS","SPARE-ISSUE", U15="Power Telco","ACTIVE" ),"")} | W15: =_xlfn.XLOOKUP(B15,Sheet1!$C:$C,Sheet1!$E:$E,"") -> Impacted by LIT_657_Z_Kotto-Denver. Grid outage | X15: =_xlfn.XLOOKUP($B15,Sheet1!$C:$C,Sheet1!F:F,"") -> Awaiting Grid return | Z15: =_xlfn.XLOOKUP($B15,Sheet1!$C:$C,Sheet1!H:H,"") -> CAMUSAT | AA15: Ongoing | AB15: Impacted by LIT_657_Z_Kotto-Denver (Power issue)..(04/21/2026-ocm ran incident 18h):-Impacted by LIT_657_Z_Kotto-Denver (Power issue)..(04/21/2026-ocm ran incident 14h):-Impacted by LIT_657_Z_Kotto-Denver (Power issue) | AC15: =_xlfn.XLOOKUP(B15,[4]ALL!$B:$B,[4]ALL!$N:$N,"") | AD15: Impacted by LIT_657_Z_Kotto-Denver (Power issue) | AT15: (04/21/2026-ocm ran incident 18h):-Impacted by LIT_657_Z_Kotto-Denver (Power issue) | AU15: (04/21/2026-ocm ran incident 14h):-Impacted by LIT_657_Z_Kotto-Denver (Power issue)
