Workbook
Name camusat_ocm: '[1]CAMUSAT OCM DB'!$A$1:$G$431
Name ihs_ocm: '[1]IHS OCM DB'!$A$1:$U$1703

Sheet BREACKDOWN
A2: NOKIA SITES FOLOW-UP
B3: INCIDENTS ONGOING | M3: Vendor | N3: Nokia
A5: Owner Group | B5: Owner | C5: T<1H | D5: 1H<T<2H | E5: 2H<T<4H | F5: 4H<T<8H | G5: 8H<T<16H | H5: 16H<T<24H | I5: 24H<T<48H | J5: T>48H | K5: Grand Total | M5: Row Labels | N5: Count of Site ID
A6: GNOCa | B6: HW SPMS | C6: =COUNTIFS('ALL SITES DOWN'!$O:$O,"NOKIA", 'ALL SITES DOWN'!$M:$M,BREACKDOWN!$B6,'ALL SITES DOWN'!$P:$P,BREACKDOWN!C$5) -> 0 | D6: =COUNTIFS('ALL SITES DOWN'!$O:$O,"NOKIA", 'ALL SITES DOWN'!$M:$M,BREACKDOWN!$B6,'ALL SITES DOWN'!$P:$P,BREACKDOWN!D$5) -> 0 | E6: =COUNTIFS('ALL SITES DOWN'!$O:$O,"NOKIA", 'ALL SITES DOWN'!$M:$M,BREACKDOWN!$B6,'ALL SITES DOWN'!$P:$P,BREACKDOWN!E$5) -> 0 | F6: =COUNTIFS('ALL SITES DOWN'!$O:$O,"NOKIA", 'ALL SITES DOWN'!$M:$M,BREACKDOWN!$B6,'ALL SITES DOWN'!$P:$P,BREACKDOWN!F$5) -> 0 | G6: =COUNTIFS('ALL SITES DOWN'!$O:$O,"NOKIA", 'ALL SITES DOWN'!$M:$M,BREACKDOWN!$B6,'ALL SITES DOWN'!$P:$P,BREACKDOWN!G$5) -> 0 | H6: =COUNTIFS('ALL SITES DOWN'!$O:$O,"NOKIA", 'ALL SITES DOWN'!$M:$M,BREACKDOWN!$B6,'ALL SITES DOWN'!$P:$P,BREACKDOWN!H$5) -> 0 | I6: =COUNTIFS('ALL SITES DOWN'!$O:$O,"NOKIA", 'ALL SITES DOWN'!$M:$M,BREACKDOWN!$B6,'ALL SITES DOWN'!$P:$P,BREACKDOWN!I$5) -> 0 | J6: =COUNTIFS('ALL SITES DOWN'!$O:$O,"NOKIA", 'ALL SITES DOWN'!$M:$M,BREACKDOWN!$B6,'ALL SITES DOWN'!$P:$P,BREACKDOWN!J$5) -> 0 | K6: =SUM(C6:J6) -> 0 | M6: camusat | N6: 1
B7: BO TRANS | C7: =COUNTIFS('ALL SITES DOWN'!$O:$O,"NOKIA", 'ALL SITES DOWN'!$M:$M,BREACKDOWN!$B7,'ALL SITES DOWN'!$P:$P,BREACKDOWN!C$5) -> 0 | D7: =COUNTIFS('ALL SITES DOWN'!$O:$O,"NOKIA", 'ALL SITES DOWN'!$M:$M,BREACKDOWN!$B7,'ALL SITES DOWN'!$P:$P,BREACKDOWN!D$5) -> 0 | E7: =COUNTIFS('ALL SITES DOWN'!$O:$O,"NOKIA", 'ALL SITES DOWN'!$M:$M,BREACKDOWN!$B7,'ALL SITES DOWN'!$P:$P,BREACKDOWN!E$5) -> 0 | F7: =COUNTIFS('ALL SITES DOWN'!$O:$O,"NOKIA", 'ALL SITES DOWN'!$M:$M,BREACKDOWN!$B7,'ALL SITES DOWN'!$P:$P,BREACKDOWN!F$5) -> 0 | G7: =COUNTIFS('ALL SITES DOWN'!$O:$O,"NOKIA", 'ALL SITES DOWN'!$M:$M,BREACKDOWN!$B7,'ALL SITES DOWN'!$P:$P,BREACKDOWN!G$5) -> 0 | H7: =COUNTIFS('ALL SITES DOWN'!$O:$O,"NOKIA", 'ALL SITES DOWN'!$M:$M,BREACKDOWN!$B7,'ALL SITES DOWN'!$P:$P,BREACKDOWN!H$5) -> 0 | I7: =COUNTIFS('ALL SITES DOWN'!$O:$O,"NOKIA", 'ALL SITES DOWN'!$M:$M,BREACKDOWN!$B7,'ALL SITES DOWN'!$P:$P,BREACKDOWN!I$5) -> 0 | J7: =COUNTIFS('ALL SITES DOWN'!$O:$O,"NOKIA", 'ALL SITES DOWN'!$M:$M,BREACKDOWN!$B7,'ALL SITES DOWN'!$P:$P,BREACKDOWN!J$5) -> 0 | K7: =SUM(C7:J7) -> 0 | M7: #N/A | N7: 1
B8: BO RAN | C8: =COUNTIFS('ALL SITES DOWN'!$O:$O,"NOKIA", 'ALL SITES DOWN'!$M:$M,BREACKDOWN!$B8,'ALL SITES DOWN'!$P:$P,BREACKDOWN!C$5) -> 0 | D8: =COUNTIFS('ALL SITES DOWN'!$O:$O,"NOKIA", 'ALL SITES DOWN'!$M:$M,BREACKDOWN!$B8,'ALL SITES DOWN'!$P:$P,BREACKDOWN!D$5) -> 0 | E8: =COUNTIFS('ALL SITES DOWN'!$O:$O,"NOKIA", 'ALL SITES DOWN'!$M:$M,BREACKDOWN!$B8,'ALL SITES DOWN'!$P:$P,BREACKDOWN!E$5) -> 0 | F8: =COUNTIFS('ALL SITES DOWN'!$O:$O,"NOKIA", 'ALL SITES DOWN'!$M:$M,BREACKDOWN!$B8,'ALL SITES DOWN'!$P:$P,BREACKDOWN!F$5) -> 0 | G8: =COUNTIFS('ALL SITES DOWN'!$O:$O,"NOKIA", 'ALL SITES DOWN'!$M:$M,BREACKDOWN!$B8,'ALL SITES DOWN'!$P:$P,BREACKDOWN!G$5) -> 0 | H8: =COUNTIFS('ALL SITES DOWN'!$O:$O,"NOKIA", 'ALL SITES DOWN'!$M:$M,BREACKDOWN!$B8,'ALL SITES DOWN'!$P:$P,BREACKDOWN!H$5) -> 0 | I8: =COUNTIFS('ALL SITES DOWN'!$O:$O,"NOKIA", 'ALL SITES DOWN'!$M:$M,BREACKDOWN!$B8,'ALL SITES DOWN'!$P:$P,BREACKDOWN!I$5) -> 0 | J8: =COUNTIFS('ALL SITES DOWN'!$O:$O,"NOKIA", 'ALL SITES DOWN'!$M:$M,BREACKDOWN!$B8,'ALL SITES DOWN'!$P:$P,BREACKDOWN!J$5) -> 0 | K8: =SUM(C8:J8) -> 0 | M8: HW SPMS | N8: 3
B9: BO IP | C9: =COUNTIFS('ALL SITES DOWN'!$O:$O,"NOKIA", 'ALL SITES DOWN'!$M:$M,BREACKDOWN!$B9,'ALL SITES DOWN'!$P:$P,BREACKDOWN!C$5) -> 0 | D9: =COUNTIFS('ALL SITES DOWN'!$O:$O,"NOKIA", 'ALL SITES DOWN'!$M:$M,BREACKDOWN!$B9,'ALL SITES DOWN'!$P:$P,BREACKDOWN!D$5) -> 0 | E9: =COUNTIFS('ALL SITES DOWN'!$O:$O,"NOKIA", 'ALL SITES DOWN'!$M:$M,BREACKDOWN!$B9,'ALL SITES DOWN'!$P:$P,BREACKDOWN!E$5) -> 0 | F9: =COUNTIFS('ALL SITES DOWN'!$O:$O,"NOKIA", 'ALL SITES DOWN'!$M:$M,BREACKDOWN!$B9,'ALL SITES DOWN'!$P:$P,BREACKDOWN!F$5) -> 0 | G9: =COUNTIFS('ALL SITES DOWN'!$O:$O,"NOKIA", 'ALL SITES DOWN'!$M:$M,BREACKDOWN!$B9,'ALL SITES DOWN'!$P:$P,BREACKDOWN!G$5) -> 0 | H9: =COUNTIFS('ALL SITES DOWN'!$O:$O,"NOKIA", 'ALL SITES DOWN'!$M:$M,BREACKDOWN!$B9,'ALL SITES DOWN'!$P:$P,BREACKDOWN!H$5) -> 0 | I9: =COUNTIFS('ALL SITES DOWN'!$O:$O,"NOKIA", 'ALL SITES DOWN'!$M:$M,BREACKDOWN!$B9,'ALL SITES DOWN'!$P:$P,BREACKDOWN!I$5) -> 0 | J9: =COUNTIFS('ALL SITES DOWN'!$O:$O,"NOKIA", 'ALL SITES DOWN'!$M:$M,BREACKDOWN!$B9,'ALL SITES DOWN'!$P:$P,BREACKDOWN!J$5) -> 0 | K9: =SUM(C9:J9) -> 0 | M9: Teleinfra | N9: 4
B10: FO | C10: =COUNTIFS('ALL SITES DOWN'!$O:$O,"NOKIA", 'ALL SITES DOWN'!$M:$M,BREACKDOWN!$B10,'ALL SITES DOWN'!$P:$P,BREACKDOWN!C$5) -> 0 | D10: =COUNTIFS('ALL SITES DOWN'!$O:$O,"NOKIA", 'ALL SITES DOWN'!$M:$M,BREACKDOWN!$B10,'ALL SITES DOWN'!$P:$P,BREACKDOWN!D$5) -> 0 | E10: =COUNTIFS('ALL SITES DOWN'!$O:$O,"NOKIA", 'ALL SITES DOWN'!$M:$M,BREACKDOWN!$B10,'ALL SITES DOWN'!$P:$P,BREACKDOWN!E$5) -> 0 | F10: =COUNTIFS('ALL SITES DOWN'!$O:$O,"NOKIA", 'ALL SITES DOWN'!$M:$M,BREACKDOWN!$B10,'ALL SITES DOWN'!$P:$P,BREACKDOWN!F$5) -> 0 | G10: =COUNTIFS('ALL SITES DOWN'!$O:$O,"NOKIA", 'ALL SITES DOWN'!$M:$M,BREACKDOWN!$B10,'ALL SITES DOWN'!$P:$P,BREACKDOWN!G$5) -> 0 | H10: =COUNTIFS('ALL SITES DOWN'!$O:$O,"NOKIA", 'ALL SITES DOWN'!$M:$M,BREACKDOWN!$B10,'ALL SITES DOWN'!$P:$P,BREACKDOWN!H$5) -> 0 | I10: =COUNTIFS('ALL SITES DOWN'!$O:$O,"NOKIA", 'ALL SITES DOWN'!$M:$M,BREACKDOWN!$B10,'ALL SITES DOWN'!$P:$P,BREACKDOWN!I$5) -> 0 | J10: =COUNTIFS('ALL SITES DOWN'!$O:$O,"NOKIA", 'ALL SITES DOWN'!$M:$M,BREACKDOWN!$B10,'ALL SITES DOWN'!$P:$P,BREACKDOWN!J$5) -> 0 | K10: =SUM(C10:J10) -> 0 | M10: AFRO | N10: 5
A11: Huawei SBC | B11: TELEINFRA | C11: =COUNTIFS('ALL SITES DOWN'!$O:$O,"NOKIA", 'ALL SITES DOWN'!$M:$M,BREACKDOWN!$B11,'ALL SITES DOWN'!$P:$P,BREACKDOWN!C$5) -> 0 | D11: =COUNTIFS('ALL SITES DOWN'!$O:$O,"NOKIA", 'ALL SITES DOWN'!$M:$M,BREACKDOWN!$B11,'ALL SITES DOWN'!$P:$P,BREACKDOWN!D$5) -> 0 | E11: =COUNTIFS('ALL SITES DOWN'!$O:$O,"NOKIA", 'ALL SITES DOWN'!$M:$M,BREACKDOWN!$B11,'ALL SITES DOWN'!$P:$P,BREACKDOWN!E$5) -> 0 | F11: =COUNTIFS('ALL SITES DOWN'!$O:$O,"NOKIA", 'ALL SITES DOWN'!$M:$M,BREACKDOWN!$B11,'ALL SITES DOWN'!$P:$P,BREACKDOWN!F$5) -> 0 | G11: =COUNTIFS('ALL SITES DOWN'!$O:$O,"NOKIA", 'ALL SITES DOWN'!$M:$M,BREACKDOWN!$B11,'ALL SITES DOWN'!$P:$P,BREACKDOWN!G$5) -> 0 | H11: =COUNTIFS('ALL SITES DOWN'!$O:$O,"NOKIA", 'ALL SITES DOWN'!$M:$M,BREACKDOWN!$B11,'ALL SITES DOWN'!$P:$P,BREACKDOWN!H$5) -> 0 | I11: =COUNTIFS('ALL SITES DOWN'!$O:$O,"NOKIA", 'ALL SITES DOWN'!$M:$M,BREACKDOWN!$B11,'ALL SITES DOWN'!$P:$P,BREACKDOWN!I$5) -> 0 | J11: =COUNTIFS('ALL SITES DOWN'!$O:$O,"NOKIA", 'ALL SITES DOWN'!$M:$M,BREACKDOWN!$B11,'ALL SITES DOWN'!$P:$P,BREACKDOWN!J$5) -> 0 | K11: =SUM(C11:J11) -> 0 | M11: OCM SPMS | N11: 5
B12: H-TELI | C12: =COUNTIFS('ALL SITES DOWN'!$O:$O,"NOKIA", 'ALL SITES DOWN'!$M:$M,BREACKDOWN!$B12,'ALL SITES DOWN'!$P:$P,BREACKDOWN!C$5) -> 0 | D12: =COUNTIFS('ALL SITES DOWN'!$O:$O,"NOKIA", 'ALL SITES DOWN'!$M:$M,BREACKDOWN!$B12,'ALL SITES DOWN'!$P:$P,BREACKDOWN!D$5) -> 0 | E12: =COUNTIFS('ALL SITES DOWN'!$O:$O,"NOKIA", 'ALL SITES DOWN'!$M:$M,BREACKDOWN!$B12,'ALL SITES DOWN'!$P:$P,BREACKDOWN!E$5) -> 0 | F12: =COUNTIFS('ALL SITES DOWN'!$O:$O,"NOKIA", 'ALL SITES DOWN'!$M:$M,BREACKDOWN!$B12,'ALL SITES DOWN'!$P:$P,BREACKDOWN!F$5) -> 0 | G12: =COUNTIFS('ALL SITES DOWN'!$O:$O,"NOKIA", 'ALL SITES DOWN'!$M:$M,BREACKDOWN!$B12,'ALL SITES DOWN'!$P:$P,BREACKDOWN!G$5) -> 0 | H12: =COUNTIFS('ALL SITES DOWN'!$O:$O,"NOKIA", 'ALL SITES DOWN'!$M:$M,BREACKDOWN!$B12,'ALL SITES DOWN'!$P:$P,BREACKDOWN!H$5) -> 0 | I12: =COUNTIFS('ALL SITES DOWN'!$O:$O,"NOKIA", 'ALL SITES DOWN'!$M:$M,BREACKDOWN!$B12,'ALL SITES DOWN'!$P:$P,BREACKDOWN!I$5) -> 0 | J12: =COUNTIFS('ALL SITES DOWN'!$O:$O,"NOKIA", 'ALL SITES DOWN'!$M:$M,BREACKDOWN!$B12,'ALL SITES DOWN'!$P:$P,BREACKDOWN!J$5) -> 0 | K12: =SUM(C12:J12) -> 0 | M12: Hammer | N12: 10
B13: I-ENG | C13: =COUNTIFS('ALL SITES DOWN'!$O:$O,"NOKIA", 'ALL SITES DOWN'!$M:$M,BREACKDOWN!$B13,'ALL SITES DOWN'!$P:$P,BREACKDOWN!C$5) -> 0 | D13: =COUNTIFS('ALL SITES DOWN'!$O:$O,"NOKIA", 'ALL SITES DOWN'!$M:$M,BREACKDOWN!$B13,'ALL SITES DOWN'!$P:$P,BREACKDOWN!D$5) -> 0 | E13: =COUNTIFS('ALL SITES DOWN'!$O:$O,"NOKIA", 'ALL SITES DOWN'!$M:$M,BREACKDOWN!$B13,'ALL SITES DOWN'!$P:$P,BREACKDOWN!E$5) -> 0 | F13: =COUNTIFS('ALL SITES DOWN'!$O:$O,"NOKIA", 'ALL SITES DOWN'!$M:$M,BREACKDOWN!$B13,'ALL SITES DOWN'!$P:$P,BREACKDOWN!F$5) -> 0 | G13: =COUNTIFS('ALL SITES DOWN'!$O:$O,"NOKIA", 'ALL SITES DOWN'!$M:$M,BREACKDOWN!$B13,'ALL SITES DOWN'!$P:$P,BREACKDOWN!G$5) -> 0 | H13: =COUNTIFS('ALL SITES DOWN'!$O:$O,"NOKIA", 'ALL SITES DOWN'!$M:$M,BREACKDOWN!$B13,'ALL SITES DOWN'!$P:$P,BREACKDOWN!H$5) -> 0 | I13: =COUNTIFS('ALL SITES DOWN'!$O:$O,"NOKIA", 'ALL SITES DOWN'!$M:$M,BREACKDOWN!$B13,'ALL SITES DOWN'!$P:$P,BREACKDOWN!I$5) -> 0 | J13: =COUNTIFS('ALL SITES DOWN'!$O:$O,"NOKIA", 'ALL SITES DOWN'!$M:$M,BREACKDOWN!$B13,'ALL SITES DOWN'!$P:$P,BREACKDOWN!J$5) -> 0 | K13: =SUM(C13:J13) -> 0 | M13: OCM ING | N13: 10
B14: CDS | C14: =COUNTIFS('ALL SITES DOWN'!$O:$O,"NOKIA", 'ALL SITES DOWN'!$M:$M,BREACKDOWN!$B14,'ALL SITES DOWN'!$P:$P,BREACKDOWN!C$5) -> 0 | D14: =COUNTIFS('ALL SITES DOWN'!$O:$O,"NOKIA", 'ALL SITES DOWN'!$M:$M,BREACKDOWN!$B14,'ALL SITES DOWN'!$P:$P,BREACKDOWN!D$5) -> 0 | E14: =COUNTIFS('ALL SITES DOWN'!$O:$O,"NOKIA", 'ALL SITES DOWN'!$M:$M,BREACKDOWN!$B14,'ALL SITES DOWN'!$P:$P,BREACKDOWN!E$5) -> 0 | F14: =COUNTIFS('ALL SITES DOWN'!$O:$O,"NOKIA", 'ALL SITES DOWN'!$M:$M,BREACKDOWN!$B14,'ALL SITES DOWN'!$P:$P,BREACKDOWN!F$5) -> 0 | G14: =COUNTIFS('ALL SITES DOWN'!$O:$O,"NOKIA", 'ALL SITES DOWN'!$M:$M,BREACKDOWN!$B14,'ALL SITES DOWN'!$P:$P,BREACKDOWN!G$5) -> 0 | H14: =COUNTIFS('ALL SITES DOWN'!$O:$O,"NOKIA", 'ALL SITES DOWN'!$M:$M,BREACKDOWN!$B14,'ALL SITES DOWN'!$P:$P,BREACKDOWN!H$5) -> 0 | I14: =COUNTIFS('ALL SITES DOWN'!$O:$O,"NOKIA", 'ALL SITES DOWN'!$M:$M,BREACKDOWN!$B14,'ALL SITES DOWN'!$P:$P,BREACKDOWN!I$5) -> 0 | J14: =COUNTIFS('ALL SITES DOWN'!$O:$O,"NOKIA", 'ALL SITES DOWN'!$M:$M,BREACKDOWN!$B14,'ALL SITES DOWN'!$P:$P,BREACKDOWN!J$5) -> 0 | K14: =SUM(C14:J14) -> 0 | M14: IHS | N14: 11
A15: 3PP | B15: IHS | C15: =COUNTIFS('ALL SITES DOWN'!$O:$O,"NOKIA", 'ALL SITES DOWN'!$M:$M,BREACKDOWN!$B15,'ALL SITES DOWN'!$P:$P,BREACKDOWN!C$5) -> 0 | D15: =COUNTIFS('ALL SITES DOWN'!$O:$O,"NOKIA", 'ALL SITES DOWN'!$M:$M,BREACKDOWN!$B15,'ALL SITES DOWN'!$P:$P,BREACKDOWN!D$5) -> 0 | E15: =COUNTIFS('ALL SITES DOWN'!$O:$O,"NOKIA", 'ALL SITES DOWN'!$M:$M,BREACKDOWN!$B15,'ALL SITES DOWN'!$P:$P,BREACKDOWN!E$5) -> 0 | F15: =COUNTIFS('ALL SITES DOWN'!$O:$O,"NOKIA", 'ALL SITES DOWN'!$M:$M,BREACKDOWN!$B15,'ALL SITES DOWN'!$P:$P,BREACKDOWN!F$5) -> 0 | G15: =COUNTIFS('ALL SITES DOWN'!$O:$O,"NOKIA", 'ALL SITES DOWN'!$M:$M,BREACKDOWN!$B15,'ALL SITES DOWN'!$P:$P,BREACKDOWN!G$5) -> 0 | H15: =COUNTIFS('ALL SITES DOWN'!$O:$O,"NOKIA", 'ALL SITES DOWN'!$M:$M,BREACKDOWN!$B15,'ALL SITES DOWN'!$P:$P,BREACKDOWN!H$5) -> 0 | I15: =COUNTIFS('ALL SITES DOWN'!$O:$O,"NOKIA", 'ALL SITES DOWN'!$M:$M,BREACKDOWN!$B15,'ALL SITES DOWN'!$P:$P,BREACKDOWN!I$5) -> 0 | J15: =COUNTIFS('ALL SITES DOWN'!$O:$O,"NOKIA", 'ALL SITES DOWN'!$M:$M,BREACKDOWN!$B15,'ALL SITES DOWN'!$P:$P,BREACKDOWN!J$5) -> 0 | K15: =SUM(C15:J15) -> 0 | M15: Grand Total | N15: 50
B16: CAMUSAT | C16: =COUNTIFS('ALL SITES DOWN'!$O:$O,"NOKIA", 'ALL SITES DOWN'!$M:$M,BREACKDOWN!$B16,'ALL SITES DOWN'!$P:$P,BREACKDOWN!C$5) -> 0 | D16: =COUNTIFS('ALL SITES DOWN'!$O:$O,"NOKIA", 'ALL SITES DOWN'!$M:$M,BREACKDOWN!$B16,'ALL SITES DOWN'!$P:$P,BREACKDOWN!D$5) -> 0 | E16: =COUNTIFS('ALL SITES DOWN'!$O:$O,"NOKIA", 'ALL SITES DOWN'!$M:$M,BREACKDOWN!$B16,'ALL SITES DOWN'!$P:$P,BREACKDOWN!E$5) -> 0 | F16: =COUNTIFS('ALL SITES DOWN'!$O:$O,"NOKIA", 'ALL SITES DOWN'!$M:$M,BREACKDOWN!$B16,'ALL SITES DOWN'!$P:$P,BREACKDOWN!F$5) -> 0 | G16: =COUNTIFS('ALL SITES DOWN'!$O:$O,"NOKIA", 'ALL SITES DOWN'!$M:$M,BREACKDOWN!$B16,'ALL SITES DOWN'!$P:$P,BREACKDOWN!G$5) -> 0 | H16: =COUNTIFS('ALL SITES DOWN'!$O:$O,"NOKIA", 'ALL SITES DOWN'!$M:$M,BREACKDOWN!$B16,'ALL SITES DOWN'!$P:$P,BREACKDOWN!H$5) -> 0 | I16: =COUNTIFS('ALL SITES DOWN'!$O:$O,"NOKIA", 'ALL SITES DOWN'!$M:$M,BREACKDOWN!$B16,'ALL SITES DOWN'!$P:$P,BREACKDOWN!I$5) -> 0 | J16: =COUNTIFS('ALL SITES DOWN'!$O:$O,"NOKIA", 'ALL SITES DOWN'!$M:$M,BREACKDOWN!$B16,'ALL SITES DOWN'!$P:$P,BREACKDOWN!J$5) -> 0 | K16: =SUM(C16:J16) -> 0
B17: MTN | C17: =COUNTIFS('ALL SITES DOWN'!$O:$O,"NOKIA", 'ALL SITES DOWN'!$M:$M,BREACKDOWN!$B17,'ALL SITES DOWN'!$P:$P,BREACKDOWN!C$5) -> 0 | D17: =COUNTIFS('ALL SITES DOWN'!$O:$O,"NOKIA", 'ALL SITES DOWN'!$M:$M,BREACKDOWN!$B17,'ALL SITES DOWN'!$P:$P,BREACKDOWN!D$5) -> 0 | E17: =COUNTIFS('ALL SITES DOWN'!$O:$O,"NOKIA", 'ALL SITES DOWN'!$M:$M,BREACKDOWN!$B17,'ALL SITES DOWN'!$P:$P,BREACKDOWN!E$5) -> 0 | F17: =COUNTIFS('ALL SITES DOWN'!$O:$O,"NOKIA", 'ALL SITES DOWN'!$M:$M,BREACKDOWN!$B17,'ALL SITES DOWN'!$P:$P,BREACKDOWN!F$5) -> 0 | G17: =COUNTIFS('ALL SITES DOWN'!$O:$O,"NOKIA", 'ALL SITES DOWN'!$M:$M,BREACKDOWN!$B17,'ALL SITES DOWN'!$P:$P,BREACKDOWN!G$5) -> 0 | H17: =COUNTIFS('ALL SITES DOWN'!$O:$O,"NOKIA", 'ALL SITES DOWN'!$M:$M,BREACKDOWN!$B17,'ALL SITES DOWN'!$P:$P,BREACKDOWN!H$5) -> 0 | I17: =COUNTIFS('ALL SITES DOWN'!$O:$O,"NOKIA", 'ALL SITES DOWN'!$M:$M,BREACKDOWN!$B17,'ALL SITES DOWN'!$P:$P,BREACKDOWN!I$5) -> 0 | J17: =COUNTIFS('ALL SITES DOWN'!$O:$O,"NOKIA", 'ALL SITES DOWN'!$M:$M,BREACKDOWN!$B17,'ALL SITES DOWN'!$P:$P,BREACKDOWN!J$5) -> 0 | K17: =SUM(C17:J17) -> 0
B18: Camtel | C18: =COUNTIFS('ALL SITES DOWN'!$O:$O,"NOKIA", 'ALL SITES DOWN'!$M:$M,BREACKDOWN!$B18,'ALL SITES DOWN'!$P:$P,BREACKDOWN!C$5) -> 0 | D18: =COUNTIFS('ALL SITES DOWN'!$O:$O,"NOKIA", 'ALL SITES DOWN'!$M:$M,BREACKDOWN!$B18,'ALL SITES DOWN'!$P:$P,BREACKDOWN!D$5) -> 0 | E18: =COUNTIFS('ALL SITES DOWN'!$O:$O,"NOKIA", 'ALL SITES DOWN'!$M:$M,BREACKDOWN!$B18,'ALL SITES DOWN'!$P:$P,BREACKDOWN!E$5) -> 0 | F18: =COUNTIFS('ALL SITES DOWN'!$O:$O,"NOKIA", 'ALL SITES DOWN'!$M:$M,BREACKDOWN!$B18,'ALL SITES DOWN'!$P:$P,BREACKDOWN!F$5) -> 0 | G18: =COUNTIFS('ALL SITES DOWN'!$O:$O,"NOKIA", 'ALL SITES DOWN'!$M:$M,BREACKDOWN!$B18,'ALL SITES DOWN'!$P:$P,BREACKDOWN!G$5) -> 0 | H18: =COUNTIFS('ALL SITES DOWN'!$O:$O,"NOKIA", 'ALL SITES DOWN'!$M:$M,BREACKDOWN!$B18,'ALL SITES DOWN'!$P:$P,BREACKDOWN!H$5) -> 0 | I18: =COUNTIFS('ALL SITES DOWN'!$O:$O,"NOKIA", 'ALL SITES DOWN'!$M:$M,BREACKDOWN!$B18,'ALL SITES DOWN'!$P:$P,BREACKDOWN!I$5) -> 0 | J18: =COUNTIFS('ALL SITES DOWN'!$O:$O,"NOKIA", 'ALL SITES DOWN'!$M:$M,BREACKDOWN!$B18,'ALL SITES DOWN'!$P:$P,BREACKDOWN!J$5) -> 0 | K18: =SUM(C18:J18) -> 0
A19: OCM | B19: OCM ING | C19: =COUNTIFS('ALL SITES DOWN'!$O:$O,"NOKIA", 'ALL SITES DOWN'!$M:$M,BREACKDOWN!$B19,'ALL SITES DOWN'!$P:$P,BREACKDOWN!C$5) -> 0 | D19: =COUNTIFS('ALL SITES DOWN'!$O:$O,"NOKIA", 'ALL SITES DOWN'!$M:$M,BREACKDOWN!$B19,'ALL SITES DOWN'!$P:$P,BREACKDOWN!D$5) -> 0 | E19: =COUNTIFS('ALL SITES DOWN'!$O:$O,"NOKIA", 'ALL SITES DOWN'!$M:$M,BREACKDOWN!$B19,'ALL SITES DOWN'!$P:$P,BREACKDOWN!E$5) -> 0 | F19: =COUNTIFS('ALL SITES DOWN'!$O:$O,"NOKIA", 'ALL SITES DOWN'!$M:$M,BREACKDOWN!$B19,'ALL SITES DOWN'!$P:$P,BREACKDOWN!F$5) -> 0 | G19: =COUNTIFS('ALL SITES DOWN'!$O:$O,"NOKIA", 'ALL SITES DOWN'!$M:$M,BREACKDOWN!$B19,'ALL SITES DOWN'!$P:$P,BREACKDOWN!G$5) -> 0 | H19: =COUNTIFS('ALL SITES DOWN'!$O:$O,"NOKIA", 'ALL SITES DOWN'!$M:$M,BREACKDOWN!$B19,'ALL SITES DOWN'!$P:$P,BREACKDOWN!H$5) -> 0 | I19: =COUNTIFS('ALL SITES DOWN'!$O:$O,"NOKIA", 'ALL SITES DOWN'!$M:$M,BREACKDOWN!$B19,'ALL SITES DOWN'!$P:$P,BREACKDOWN!I$5) -> 0 | J19: =COUNTIFS('ALL SITES DOWN'!$O:$O,"NOKIA", 'ALL SITES DOWN'!$M:$M,BREACKDOWN!$B19,'ALL SITES DOWN'!$P:$P,BREACKDOWN!J$5) -> 0 | K19: =SUM(C19:J19) -> 0
B20: OCM OPS | C20: =COUNTIFS('ALL SITES DOWN'!$O:$O,"NOKIA", 'ALL SITES DOWN'!$M:$M,BREACKDOWN!$B20,'ALL SITES DOWN'!$P:$P,BREACKDOWN!C$5) -> 0 | D20: =COUNTIFS('ALL SITES DOWN'!$O:$O,"NOKIA", 'ALL SITES DOWN'!$M:$M,BREACKDOWN!$B20,'ALL SITES DOWN'!$P:$P,BREACKDOWN!D$5) -> 0 | E20: =COUNTIFS('ALL SITES DOWN'!$O:$O,"NOKIA", 'ALL SITES DOWN'!$M:$M,BREACKDOWN!$B20,'ALL SITES DOWN'!$P:$P,BREACKDOWN!E$5) -> 0 | F20: =COUNTIFS('ALL SITES DOWN'!$O:$O,"NOKIA", 'ALL SITES DOWN'!$M:$M,BREACKDOWN!$B20,'ALL SITES DOWN'!$P:$P,BREACKDOWN!F$5) -> 0 | G20: =COUNTIFS('ALL SITES DOWN'!$O:$O,"NOKIA", 'ALL SITES DOWN'!$M:$M,BREACKDOWN!$B20,'ALL SITES DOWN'!$P:$P,BREACKDOWN!G$5) -> 0 | H20: =COUNTIFS('ALL SITES DOWN'!$O:$O,"NOKIA", 'ALL SITES DOWN'!$M:$M,BREACKDOWN!$B20,'ALL SITES DOWN'!$P:$P,BREACKDOWN!H$5) -> 0 | I20: =COUNTIFS('ALL SITES DOWN'!$O:$O,"NOKIA", 'ALL SITES DOWN'!$M:$M,BREACKDOWN!$B20,'ALL SITES DOWN'!$P:$P,BREACKDOWN!I$5) -> 0 | J20: =COUNTIFS('ALL SITES DOWN'!$O:$O,"NOKIA", 'ALL SITES DOWN'!$M:$M,BREACKDOWN!$B20,'ALL SITES DOWN'!$P:$P,BREACKDOWN!J$5) -> 0 | K20: =SUM(C20:J20) -> 0
B21: OCM SPMS | C21: =COUNTIFS('ALL SITES DOWN'!$O:$O,"NOKIA", 'ALL SITES DOWN'!$M:$M,BREACKDOWN!$B21,'ALL SITES DOWN'!$P:$P,BREACKDOWN!C$5) -> 0 | D21: =COUNTIFS('ALL SITES DOWN'!$O:$O,"NOKIA", 'ALL SITES DOWN'!$M:$M,BREACKDOWN!$B21,'ALL SITES DOWN'!$P:$P,BREACKDOWN!D$5) -> 0 | E21: =COUNTIFS('ALL SITES DOWN'!$O:$O,"NOKIA", 'ALL SITES DOWN'!$M:$M,BREACKDOWN!$B21,'ALL SITES DOWN'!$P:$P,BREACKDOWN!E$5) -> 0 | F21: =COUNTIFS('ALL SITES DOWN'!$O:$O,"NOKIA", 'ALL SITES DOWN'!$M:$M,BREACKDOWN!$B21,'ALL SITES DOWN'!$P:$P,BREACKDOWN!F$5) -> 0 | G21: =COUNTIFS('ALL SITES DOWN'!$O:$O,"NOKIA", 'ALL SITES DOWN'!$M:$M,BREACKDOWN!$B21,'ALL SITES DOWN'!$P:$P,BREACKDOWN!G$5) -> 0 | H21: =COUNTIFS('ALL SITES DOWN'!$O:$O,"NOKIA", 'ALL SITES DOWN'!$M:$M,BREACKDOWN!$B21,'ALL SITES DOWN'!$P:$P,BREACKDOWN!H$5) -> 0 | I21: =COUNTIFS('ALL SITES DOWN'!$O:$O,"NOKIA", 'ALL SITES DOWN'!$M:$M,BREACKDOWN!$B21,'ALL SITES DOWN'!$P:$P,BREACKDOWN!I$5) -> 0 | J21: =COUNTIFS('ALL SITES DOWN'!$O:$O,"NOKIA", 'ALL SITES DOWN'!$M:$M,BREACKDOWN!$B21,'ALL SITES DOWN'!$P:$P,BREACKDOWN!J$5) -> 0 | K21: =SUM(C21:J21) -> 0
A22: Vendor | B22: Nokia | C22: =COUNTIFS('ALL SITES DOWN'!$O:$O,"NOKIA", 'ALL SITES DOWN'!$M:$M,BREACKDOWN!$B22,'ALL SITES DOWN'!$P:$P,BREACKDOWN!C$5) -> 0 | D22: =COUNTIFS('ALL SITES DOWN'!$O:$O,"NOKIA", 'ALL SITES DOWN'!$M:$M,BREACKDOWN!$B22,'ALL SITES DOWN'!$P:$P,BREACKDOWN!D$5) -> 0 | E22: =COUNTIFS('ALL SITES DOWN'!$O:$O,"NOKIA", 'ALL SITES DOWN'!$M:$M,BREACKDOWN!$B22,'ALL SITES DOWN'!$P:$P,BREACKDOWN!E$5) -> 0 | F22: =COUNTIFS('ALL SITES DOWN'!$O:$O,"NOKIA", 'ALL SITES DOWN'!$M:$M,BREACKDOWN!$B22,'ALL SITES DOWN'!$P:$P,BREACKDOWN!F$5) -> 0 | G22: =COUNTIFS('ALL SITES DOWN'!$O:$O,"NOKIA", 'ALL SITES DOWN'!$M:$M,BREACKDOWN!$B22,'ALL SITES DOWN'!$P:$P,BREACKDOWN!G$5) -> 0 | H22: =COUNTIFS('ALL SITES DOWN'!$O:$O,"NOKIA", 'ALL SITES DOWN'!$M:$M,BREACKDOWN!$B22,'ALL SITES DOWN'!$P:$P,BREACKDOWN!H$5) -> 0 | I22: =COUNTIFS('ALL SITES DOWN'!$O:$O,"NOKIA", 'ALL SITES DOWN'!$M:$M,BREACKDOWN!$B22,'ALL SITES DOWN'!$P:$P,BREACKDOWN!I$5) -> 0 | J22: =COUNTIFS('ALL SITES DOWN'!$O:$O,"NOKIA", 'ALL SITES DOWN'!$M:$M,BREACKDOWN!$B22,'ALL SITES DOWN'!$P:$P,BREACKDOWN!J$5) -> 0 | K22: =SUM(C22:J22) -> 0
B23: Huawei_Project | C23: =COUNTIFS('ALL SITES DOWN'!$O:$O,"NOKIA", 'ALL SITES DOWN'!$M:$M,BREACKDOWN!$B23,'ALL SITES DOWN'!$P:$P,BREACKDOWN!C$5) -> 0 | D23: =COUNTIFS('ALL SITES DOWN'!$O:$O,"NOKIA", 'ALL SITES DOWN'!$M:$M,BREACKDOWN!$B23,'ALL SITES DOWN'!$P:$P,BREACKDOWN!D$5) -> 0 | E23: =COUNTIFS('ALL SITES DOWN'!$O:$O,"NOKIA", 'ALL SITES DOWN'!$M:$M,BREACKDOWN!$B23,'ALL SITES DOWN'!$P:$P,BREACKDOWN!E$5) -> 0 | F23: =COUNTIFS('ALL SITES DOWN'!$O:$O,"NOKIA", 'ALL SITES DOWN'!$M:$M,BREACKDOWN!$B23,'ALL SITES DOWN'!$P:$P,BREACKDOWN!F$5) -> 0 | G23: =COUNTIFS('ALL SITES DOWN'!$O:$O,"NOKIA", 'ALL SITES DOWN'!$M:$M,BREACKDOWN!$B23,'ALL SITES DOWN'!$P:$P,BREACKDOWN!G$5) -> 0 | H23: =COUNTIFS('ALL SITES DOWN'!$O:$O,"NOKIA", 'ALL SITES DOWN'!$M:$M,BREACKDOWN!$B23,'ALL SITES DOWN'!$P:$P,BREACKDOWN!H$5) -> 0 | I23: =COUNTIFS('ALL SITES DOWN'!$O:$O,"NOKIA", 'ALL SITES DOWN'!$M:$M,BREACKDOWN!$B23,'ALL SITES DOWN'!$P:$P,BREACKDOWN!I$5) -> 0 | J23: =COUNTIFS('ALL SITES DOWN'!$O:$O,"NOKIA", 'ALL SITES DOWN'!$M:$M,BREACKDOWN!$B23,'ALL SITES DOWN'!$P:$P,BREACKDOWN!J$5) -> 0 | K23: =SUM(C23:J23) -> 0
B24: ZTE | C24: =COUNTIFS('ALL SITES DOWN'!$O:$O,"NOKIA", 'ALL SITES DOWN'!$M:$M,BREACKDOWN!$B24,'ALL SITES DOWN'!$P:$P,BREACKDOWN!C$5) -> 0 | D24: =COUNTIFS('ALL SITES DOWN'!$O:$O,"NOKIA", 'ALL SITES DOWN'!$M:$M,BREACKDOWN!$B24,'ALL SITES DOWN'!$P:$P,BREACKDOWN!D$5) -> 0 | E24: =COUNTIFS('ALL SITES DOWN'!$O:$O,"NOKIA", 'ALL SITES DOWN'!$M:$M,BREACKDOWN!$B24,'ALL SITES DOWN'!$P:$P,BREACKDOWN!E$5) -> 0 | F24: =COUNTIFS('ALL SITES DOWN'!$O:$O,"NOKIA", 'ALL SITES DOWN'!$M:$M,BREACKDOWN!$B24,'ALL SITES DOWN'!$P:$P,BREACKDOWN!F$5) -> 0 | G24: =COUNTIFS('ALL SITES DOWN'!$O:$O,"NOKIA", 'ALL SITES DOWN'!$M:$M,BREACKDOWN!$B24,'ALL SITES DOWN'!$P:$P,BREACKDOWN!G$5) -> 0 | H24: =COUNTIFS('ALL SITES DOWN'!$O:$O,"NOKIA", 'ALL SITES DOWN'!$M:$M,BREACKDOWN!$B24,'ALL SITES DOWN'!$P:$P,BREACKDOWN!H$5) -> 0 | I24: =COUNTIFS('ALL SITES DOWN'!$O:$O,"NOKIA", 'ALL SITES DOWN'!$M:$M,BREACKDOWN!$B24,'ALL SITES DOWN'!$P:$P,BREACKDOWN!I$5) -> 0 | J24: =COUNTIFS('ALL SITES DOWN'!$O:$O,"NOKIA", 'ALL SITES DOWN'!$M:$M,BREACKDOWN!$B24,'ALL SITES DOWN'!$P:$P,BREACKDOWN!J$5) -> 0 | K24: =SUM(C24:J24) -> 0
A25: Major Incidents | B25: P1 Child | C25: =COUNTIFS('ALL SITES DOWN'!$O:$O,"NOKIA", 'ALL SITES DOWN'!$M:$M,BREACKDOWN!$B25,'ALL SITES DOWN'!$P:$P,BREACKDOWN!C$5) -> 0 | D25: =COUNTIFS('ALL SITES DOWN'!$O:$O,"NOKIA", 'ALL SITES DOWN'!$M:$M,BREACKDOWN!$B25,'ALL SITES DOWN'!$P:$P,BREACKDOWN!D$5) -> 0 | E25: =COUNTIFS('ALL SITES DOWN'!$O:$O,"NOKIA", 'ALL SITES DOWN'!$M:$M,BREACKDOWN!$B25,'ALL SITES DOWN'!$P:$P,BREACKDOWN!E$5) -> 0 | F25: =COUNTIFS('ALL SITES DOWN'!$O:$O,"NOKIA", 'ALL SITES DOWN'!$M:$M,BREACKDOWN!$B25,'ALL SITES DOWN'!$P:$P,BREACKDOWN!F$5) -> 0 | G25: =COUNTIFS('ALL SITES DOWN'!$O:$O,"NOKIA", 'ALL SITES DOWN'!$M:$M,BREACKDOWN!$B25,'ALL SITES DOWN'!$P:$P,BREACKDOWN!G$5) -> 0 | H25: =COUNTIFS('ALL SITES DOWN'!$O:$O,"NOKIA", 'ALL SITES DOWN'!$M:$M,BREACKDOWN!$B25,'ALL SITES DOWN'!$P:$P,BREACKDOWN!H$5) -> 0 | I25: =COUNTIFS('ALL SITES DOWN'!$O:$O,"NOKIA", 'ALL SITES DOWN'!$M:$M,BREACKDOWN!$B25,'ALL SITES DOWN'!$P:$P,BREACKDOWN!I$5) -> 0 | J25: =COUNTIFS('ALL SITES DOWN'!$O:$O,"NOKIA", 'ALL SITES DOWN'!$M:$M,BREACKDOWN!$B25,'ALL SITES DOWN'!$P:$P,BREACKDOWN!J$5) -> 0 | K25: =SUM(C25:J25) -> 0
B26: P2 Child | C26: =COUNTIFS('ALL SITES DOWN'!$O:$O,"NOKIA", 'ALL SITES DOWN'!$M:$M,BREACKDOWN!$B26,'ALL SITES DOWN'!$P:$P,BREACKDOWN!C$5) -> 0 | D26: =COUNTIFS('ALL SITES DOWN'!$O:$O,"NOKIA", 'ALL SITES DOWN'!$M:$M,BREACKDOWN!$B26,'ALL SITES DOWN'!$P:$P,BREACKDOWN!D$5) -> 0 | E26: =COUNTIFS('ALL SITES DOWN'!$O:$O,"NOKIA", 'ALL SITES DOWN'!$M:$M,BREACKDOWN!$B26,'ALL SITES DOWN'!$P:$P,BREACKDOWN!E$5) -> 0 | F26: =COUNTIFS('ALL SITES DOWN'!$O:$O,"NOKIA", 'ALL SITES DOWN'!$M:$M,BREACKDOWN!$B26,'ALL SITES DOWN'!$P:$P,BREACKDOWN!F$5) -> 0 | G26: =COUNTIFS('ALL SITES DOWN'!$O:$O,"NOKIA", 'ALL SITES DOWN'!$M:$M,BREACKDOWN!$B26,'ALL SITES DOWN'!$P:$P,BREACKDOWN!G$5) -> 0 | H26: =COUNTIFS('ALL SITES DOWN'!$O:$O,"NOKIA", 'ALL SITES DOWN'!$M:$M,BREACKDOWN!$B26,'ALL SITES DOWN'!$P:$P,BREACKDOWN!H$5) -> 0 | I26: =COUNTIFS('ALL SITES DOWN'!$O:$O,"NOKIA", 'ALL SITES DOWN'!$M:$M,BREACKDOWN!$B26,'ALL SITES DOWN'!$P:$P,BREACKDOWN!I$5) -> 0 | J26: =COUNTIFS('ALL SITES DOWN'!$O:$O,"NOKIA", 'ALL SITES DOWN'!$M:$M,BREACKDOWN!$B26,'ALL SITES DOWN'!$P:$P,BREACKDOWN!J$5) -> 0 | K26: =SUM(C26:J26) -> 0
A27: Grand Total | C27: =SUM(C6:C24) -> 0 | D27: =SUM(D6:D24) -> 0 | E27: =SUM(E6:E24) -> 0 | F27: =SUM(F6:F24) -> 0 | G27: =SUM(G6:G24) -> 0 | H27: =SUM(H6:H24) -> 0 | I27: =SUM(I6:I24) -> 0 | J27: =SUM(J6:J24) -> 0 | K27: =SUM(K6:K24) -> 0
A31: ZTE SITES FOLOW-UP
B32: INCIDENTS ONGOING | M32: Vendor | N32: Nokia
A33: Owner Group | B33: Owner | C33: T<1H | D33: 1H<T<2H | E33: 2H<T<4H | F33: 4H<T<8H | G33: 8H<T<16H | H33: 16H<T<24H | I33: 24H<T<48H | J33: T>48H | K33: Grand Total
A34: GNOCa | B34: HW SPMS | C34: =COUNTIFS('ALL SITES DOWN'!$O:$O,"ZTE", 'ALL SITES DOWN'!$M:$M,BREACKDOWN!$B34,'ALL SITES DOWN'!$P:$P,BREACKDOWN!C$33) -> 0 | D34: =COUNTIFS('ALL SITES DOWN'!$O:$O,"ZTE", 'ALL SITES DOWN'!$M:$M,BREACKDOWN!$B34,'ALL SITES DOWN'!$P:$P,BREACKDOWN!D$33) -> 0 | E34: =COUNTIFS('ALL SITES DOWN'!$O:$O,"ZTE", 'ALL SITES DOWN'!$M:$M,BREACKDOWN!$B34,'ALL SITES DOWN'!$P:$P,BREACKDOWN!E$33) -> 0 | F34: =COUNTIFS('ALL SITES DOWN'!$O:$O,"ZTE", 'ALL SITES DOWN'!$M:$M,BREACKDOWN!$B34,'ALL SITES DOWN'!$P:$P,BREACKDOWN!F$33) -> 0 | G34: =COUNTIFS('ALL SITES DOWN'!$O:$O,"ZTE", 'ALL SITES DOWN'!$M:$M,BREACKDOWN!$B34,'ALL SITES DOWN'!$P:$P,BREACKDOWN!G$33) -> 0 | H34: =COUNTIFS('ALL SITES DOWN'!$O:$O,"ZTE", 'ALL SITES DOWN'!$M:$M,BREACKDOWN!$B34,'ALL SITES DOWN'!$P:$P,BREACKDOWN!H$33) -> 0 | I34: =COUNTIFS('ALL SITES DOWN'!$O:$O,"ZTE", 'ALL SITES DOWN'!$M:$M,BREACKDOWN!$B34,'ALL SITES DOWN'!$P:$P,BREACKDOWN!I$33) -> 0 | J34: =COUNTIFS('ALL SITES DOWN'!$O:$O,"ZTE", 'ALL SITES DOWN'!$M:$M,BREACKDOWN!$B34,'ALL SITES DOWN'!$P:$P,BREACKDOWN!J$33) -> 0 | K34: =SUM(C34:J34) -> 0 | M34: Row Labels | N34: Count of Site ID
B35: BO TRANS | C35: =COUNTIFS('ALL SITES DOWN'!$O:$O,"ZTE", 'ALL SITES DOWN'!$M:$M,BREACKDOWN!$B35,'ALL SITES DOWN'!$P:$P,BREACKDOWN!C$33) -> 0 | D35: =COUNTIFS('ALL SITES DOWN'!$O:$O,"ZTE", 'ALL SITES DOWN'!$M:$M,BREACKDOWN!$B35,'ALL SITES DOWN'!$P:$P,BREACKDOWN!D$33) -> 0 | E35: =COUNTIFS('ALL SITES DOWN'!$O:$O,"ZTE", 'ALL SITES DOWN'!$M:$M,BREACKDOWN!$B35,'ALL SITES DOWN'!$P:$P,BREACKDOWN!E$33) -> 0 | F35: =COUNTIFS('ALL SITES DOWN'!$O:$O,"ZTE", 'ALL SITES DOWN'!$M:$M,BREACKDOWN!$B35,'ALL SITES DOWN'!$P:$P,BREACKDOWN!F$33) -> 0 | G35: =COUNTIFS('ALL SITES DOWN'!$O:$O,"ZTE", 'ALL SITES DOWN'!$M:$M,BREACKDOWN!$B35,'ALL SITES DOWN'!$P:$P,BREACKDOWN!G$33) -> 0 | H35: =COUNTIFS('ALL SITES DOWN'!$O:$O,"ZTE", 'ALL SITES DOWN'!$M:$M,BREACKDOWN!$B35,'ALL SITES DOWN'!$P:$P,BREACKDOWN!H$33) -> 0 | I35: =COUNTIFS('ALL SITES DOWN'!$O:$O,"ZTE", 'ALL SITES DOWN'!$M:$M,BREACKDOWN!$B35,'ALL SITES DOWN'!$P:$P,BREACKDOWN!I$33) -> 0 | J35: =COUNTIFS('ALL SITES DOWN'!$O:$O,"ZTE", 'ALL SITES DOWN'!$M:$M,BREACKDOWN!$B35,'ALL SITES DOWN'!$P:$P,BREACKDOWN!J$33) -> 0 | K35: =SUM(C35:J35) -> 0 | M35: camusat | N35: 1
B36: BO RAN | C36: =COUNTIFS('ALL SITES DOWN'!$O:$O,"ZTE", 'ALL SITES DOWN'!$M:$M,BREACKDOWN!$B36,'ALL SITES DOWN'!$P:$P,BREACKDOWN!C$33) -> 0 | D36: =COUNTIFS('ALL SITES DOWN'!$O:$O,"ZTE", 'ALL SITES DOWN'!$M:$M,BREACKDOWN!$B36,'ALL SITES DOWN'!$P:$P,BREACKDOWN!D$33) -> 0 | E36: =COUNTIFS('ALL SITES DOWN'!$O:$O,"ZTE", 'ALL SITES DOWN'!$M:$M,BREACKDOWN!$B36,'ALL SITES DOWN'!$P:$P,BREACKDOWN!E$33) -> 0 | F36: =COUNTIFS('ALL SITES DOWN'!$O:$O,"ZTE", 'ALL SITES DOWN'!$M:$M,BREACKDOWN!$B36,'ALL SITES DOWN'!$P:$P,BREACKDOWN!F$33) -> 0 | G36: =COUNTIFS('ALL SITES DOWN'!$O:$O,"ZTE", 'ALL SITES DOWN'!$M:$M,BREACKDOWN!$B36,'ALL SITES DOWN'!$P:$P,BREACKDOWN!G$33) -> 0 | H36: =COUNTIFS('ALL SITES DOWN'!$O:$O,"ZTE", 'ALL SITES DOWN'!$M:$M,BREACKDOWN!$B36,'ALL SITES DOWN'!$P:$P,BREACKDOWN!H$33) -> 0 | I36: =COUNTIFS('ALL SITES DOWN'!$O:$O,"ZTE", 'ALL SITES DOWN'!$M:$M,BREACKDOWN!$B36,'ALL SITES DOWN'!$P:$P,BREACKDOWN!I$33) -> 0 | J36: =COUNTIFS('ALL SITES DOWN'!$O:$O,"ZTE", 'ALL SITES DOWN'!$M:$M,BREACKDOWN!$B36,'ALL SITES DOWN'!$P:$P,BREACKDOWN!J$33) -> 0 | K36: =SUM(C36:J36) -> 0 | M36: #N/A | N36: 1
B37: BO IP | C37: =COUNTIFS('ALL SITES DOWN'!$O:$O,"ZTE", 'ALL SITES DOWN'!$M:$M,BREACKDOWN!$B37,'ALL SITES DOWN'!$P:$P,BREACKDOWN!C$33) -> 0 | D37: =COUNTIFS('ALL SITES DOWN'!$O:$O,"ZTE", 'ALL SITES DOWN'!$M:$M,BREACKDOWN!$B37,'ALL SITES DOWN'!$P:$P,BREACKDOWN!D$33) -> 0 | E37: =COUNTIFS('ALL SITES DOWN'!$O:$O,"ZTE", 'ALL SITES DOWN'!$M:$M,BREACKDOWN!$B37,'ALL SITES DOWN'!$P:$P,BREACKDOWN!E$33) -> 0 | F37: =COUNTIFS('ALL SITES DOWN'!$O:$O,"ZTE", 'ALL SITES DOWN'!$M:$M,BREACKDOWN!$B37,'ALL SITES DOWN'!$P:$P,BREACKDOWN!F$33) -> 0 | G37: =COUNTIFS('ALL SITES DOWN'!$O:$O,"ZTE", 'ALL SITES DOWN'!$M:$M,BREACKDOWN!$B37,'ALL SITES DOWN'!$P:$P,BREACKDOWN!G$33) -> 0 | H37: =COUNTIFS('ALL SITES DOWN'!$O:$O,"ZTE", 'ALL SITES DOWN'!$M:$M,BREACKDOWN!$B37,'ALL SITES DOWN'!$P:$P,BREACKDOWN!H$33) -> 0 | I37: =COUNTIFS('ALL SITES DOWN'!$O:$O,"ZTE", 'ALL SITES DOWN'!$M:$M,BREACKDOWN!$B37,'ALL SITES DOWN'!$P:$P,BREACKDOWN!I$33) -> 0 | J37: =COUNTIFS('ALL SITES DOWN'!$O:$O,"ZTE", 'ALL SITES DOWN'!$M:$M,BREACKDOWN!$B37,'ALL SITES DOWN'!$P:$P,BREACKDOWN!J$33) -> 0 | K37: =SUM(C37:J37) -> 0 | M37: HW SPMS | N37: 3
B38: FO | C38: =COUNTIFS('ALL SITES DOWN'!$O:$O,"ZTE", 'ALL SITES DOWN'!$M:$M,BREACKDOWN!$B38,'ALL SITES DOWN'!$P:$P,BREACKDOWN!C$33) -> 0 | D38: =COUNTIFS('ALL SITES DOWN'!$O:$O,"ZTE", 'ALL SITES DOWN'!$M:$M,BREACKDOWN!$B38,'ALL SITES DOWN'!$P:$P,BREACKDOWN!D$33) -> 0 | E38: =COUNTIFS('ALL SITES DOWN'!$O:$O,"ZTE", 'ALL SITES DOWN'!$M:$M,BREACKDOWN!$B38,'ALL SITES DOWN'!$P:$P,BREACKDOWN!E$33) -> 0 | F38: =COUNTIFS('ALL SITES DOWN'!$O:$O,"ZTE", 'ALL SITES DOWN'!$M:$M,BREACKDOWN!$B38,'ALL SITES DOWN'!$P:$P,BREACKDOWN!F$33) -> 0 | G38: =COUNTIFS('ALL SITES DOWN'!$O:$O,"ZTE", 'ALL SITES DOWN'!$M:$M,BREACKDOWN!$B38,'ALL SITES DOWN'!$P:$P,BREACKDOWN!G$33) -> 0 | H38: =COUNTIFS('ALL SITES DOWN'!$O:$O,"ZTE", 'ALL SITES DOWN'!$M:$M,BREACKDOWN!$B38,'ALL SITES DOWN'!$P:$P,BREACKDOWN!H$33) -> 0 | I38: =COUNTIFS('ALL SITES DOWN'!$O:$O,"ZTE", 'ALL SITES DOWN'!$M:$M,BREACKDOWN!$B38,'ALL SITES DOWN'!$P:$P,BREACKDOWN!I$33) -> 0 | J38: =COUNTIFS('ALL SITES DOWN'!$O:$O,"ZTE", 'ALL SITES DOWN'!$M:$M,BREACKDOWN!$B38,'ALL SITES DOWN'!$P:$P,BREACKDOWN!J$33) -> 0 | K38: =SUM(C38:J38) -> 0 | M38: Teleinfra | N38: 4
A39: Huawei SBC | B39: TELEINFRA | C39: =COUNTIFS('ALL SITES DOWN'!$O:$O,"ZTE", 'ALL SITES DOWN'!$M:$M,BREACKDOWN!$B39,'ALL SITES DOWN'!$P:$P,BREACKDOWN!C$33) -> 0 | D39: =COUNTIFS('ALL SITES DOWN'!$O:$O,"ZTE", 'ALL SITES DOWN'!$M:$M,BREACKDOWN!$B39,'ALL SITES DOWN'!$P:$P,BREACKDOWN!D$33) -> 0 | E39: =COUNTIFS('ALL SITES DOWN'!$O:$O,"ZTE", 'ALL SITES DOWN'!$M:$M,BREACKDOWN!$B39,'ALL SITES DOWN'!$P:$P,BREACKDOWN!E$33) -> 0 | F39: =COUNTIFS('ALL SITES DOWN'!$O:$O,"ZTE", 'ALL SITES DOWN'!$M:$M,BREACKDOWN!$B39,'ALL SITES DOWN'!$P:$P,BREACKDOWN!F$33) -> 0 | G39: =COUNTIFS('ALL SITES DOWN'!$O:$O,"ZTE", 'ALL SITES DOWN'!$M:$M,BREACKDOWN!$B39,'ALL SITES DOWN'!$P:$P,BREACKDOWN!G$33) -> 0 | H39: =COUNTIFS('ALL SITES DOWN'!$O:$O,"ZTE", 'ALL SITES DOWN'!$M:$M,BREACKDOWN!$B39,'ALL SITES DOWN'!$P:$P,BREACKDOWN!H$33) -> 0 | I39: =COUNTIFS('ALL SITES DOWN'!$O:$O,"ZTE", 'ALL SITES DOWN'!$M:$M,BREACKDOWN!$B39,'ALL SITES DOWN'!$P:$P,BREACKDOWN!I$33) -> 0 | J39: =COUNTIFS('ALL SITES DOWN'!$O:$O,"ZTE", 'ALL SITES DOWN'!$M:$M,BREACKDOWN!$B39,'ALL SITES DOWN'!$P:$P,BREACKDOWN!J$33) -> 0 | K39: =SUM(C39:J39) -> 0 | M39: AFRO | N39: 5
B40: H-TELI | C40: =COUNTIFS('ALL SITES DOWN'!$O:$O,"ZTE", 'ALL SITES DOWN'!$M:$M,BREACKDOWN!$B40,'ALL SITES DOWN'!$P:$P,BREACKDOWN!C$33) -> 0 | D40: =COUNTIFS('ALL SITES DOWN'!$O:$O,"ZTE", 'ALL SITES DOWN'!$M:$M,BREACKDOWN!$B40,'ALL SITES DOWN'!$P:$P,BREACKDOWN!D$33) -> 0 | E40: =COUNTIFS('ALL SITES DOWN'!$O:$O,"ZTE", 'ALL SITES DOWN'!$M:$M,BREACKDOWN!$B40,'ALL SITES DOWN'!$P:$P,BREACKDOWN!E$33) -> 0 | F40: =COUNTIFS('ALL SITES DOWN'!$O:$O,"ZTE", 'ALL SITES DOWN'!$M:$M,BREACKDOWN!$B40,'ALL SITES DOWN'!$P:$P,BREACKDOWN!F$33) -> 0 | G40: =COUNTIFS('ALL SITES DOWN'!$O:$O,"ZTE", 'ALL SITES DOWN'!$M:$M,BREACKDOWN!$B40,'ALL SITES DOWN'!$P:$P,BREACKDOWN!G$33) -> 0 | H40: =COUNTIFS('ALL SITES DOWN'!$O:$O,"ZTE", 'ALL SITES DOWN'!$M:$M,BREACKDOWN!$B40,'ALL SITES DOWN'!$P:$P,BREACKDOWN!H$33) -> 0 | I40: =COUNTIFS('ALL SITES DOWN'!$O:$O,"ZTE", 'ALL SITES DOWN'!$M:$M,BREACKDOWN!$B40,'ALL SITES DOWN'!$P:$P,BREACKDOWN!I$33) -> 0 | J40: =COUNTIFS('ALL SITES DOWN'!$O:$O,"ZTE", 'ALL SITES DOWN'!$M:$M,BREACKDOWN!$B40,'ALL SITES DOWN'!$P:$P,BREACKDOWN!J$33) -> 0 | K40: =SUM(C40:J40) -> 0 | M40: OCM SPMS | N40: 5
B41: I-ENG | C41: =COUNTIFS('ALL SITES DOWN'!$O:$O,"ZTE", 'ALL SITES DOWN'!$M:$M,BREACKDOWN!$B41,'ALL SITES DOWN'!$P:$P,BREACKDOWN!C$33) -> 0 | D41: =COUNTIFS('ALL SITES DOWN'!$O:$O,"ZTE", 'ALL SITES DOWN'!$M:$M,BREACKDOWN!$B41,'ALL SITES DOWN'!$P:$P,BREACKDOWN!D$33) -> 0 | E41: =COUNTIFS('ALL SITES DOWN'!$O:$O,"ZTE", 'ALL SITES DOWN'!$M:$M,BREACKDOWN!$B41,'ALL SITES DOWN'!$P:$P,BREACKDOWN!E$33) -> 0 | F41: =COUNTIFS('ALL SITES DOWN'!$O:$O,"ZTE", 'ALL SITES DOWN'!$M:$M,BREACKDOWN!$B41,'ALL SITES DOWN'!$P:$P,BREACKDOWN!F$33) -> 0 | G41: =COUNTIFS('ALL SITES DOWN'!$O:$O,"ZTE", 'ALL SITES DOWN'!$M:$M,BREACKDOWN!$B41,'ALL SITES DOWN'!$P:$P,BREACKDOWN!G$33) -> 0 | H41: =COUNTIFS('ALL SITES DOWN'!$O:$O,"ZTE", 'ALL SITES DOWN'!$M:$M,BREACKDOWN!$B41,'ALL SITES DOWN'!$P:$P,BREACKDOWN!H$33) -> 0 | I41: =COUNTIFS('ALL SITES DOWN'!$O:$O,"ZTE", 'ALL SITES DOWN'!$M:$M,BREACKDOWN!$B41,'ALL SITES DOWN'!$P:$P,BREACKDOWN!I$33) -> 0 | J41: =COUNTIFS('ALL SITES DOWN'!$O:$O,"ZTE", 'ALL SITES DOWN'!$M:$M,BREACKDOWN!$B41,'ALL SITES DOWN'!$P:$P,BREACKDOWN!J$33) -> 0 | K41: =SUM(C41:J41) -> 0 | M41: Hammer | N41: 10
B42: CDS | C42: =COUNTIFS('ALL SITES DOWN'!$O:$O,"ZTE", 'ALL SITES DOWN'!$M:$M,BREACKDOWN!$B42,'ALL SITES DOWN'!$P:$P,BREACKDOWN!C$33) -> 0 | D42: =COUNTIFS('ALL SITES DOWN'!$O:$O,"ZTE", 'ALL SITES DOWN'!$M:$M,BREACKDOWN!$B42,'ALL SITES DOWN'!$P:$P,BREACKDOWN!D$33) -> 0 | E42: =COUNTIFS('ALL SITES DOWN'!$O:$O,"ZTE", 'ALL SITES DOWN'!$M:$M,BREACKDOWN!$B42,'ALL SITES DOWN'!$P:$P,BREACKDOWN!E$33) -> 0 | F42: =COUNTIFS('ALL SITES DOWN'!$O:$O,"ZTE", 'ALL SITES DOWN'!$M:$M,BREACKDOWN!$B42,'ALL SITES DOWN'!$P:$P,BREACKDOWN!F$33) -> 0 | G42: =COUNTIFS('ALL SITES DOWN'!$O:$O,"ZTE", 'ALL SITES DOWN'!$M:$M,BREACKDOWN!$B42,'ALL SITES DOWN'!$P:$P,BREACKDOWN!G$33) -> 0 | H42: =COUNTIFS('ALL SITES DOWN'!$O:$O,"ZTE", 'ALL SITES DOWN'!$M:$M,BREACKDOWN!$B42,'ALL SITES DOWN'!$P:$P,BREACKDOWN!H$33) -> 0 | I42: =COUNTIFS('ALL SITES DOWN'!$O:$O,"ZTE", 'ALL SITES DOWN'!$M:$M,BREACKDOWN!$B42,'ALL SITES DOWN'!$P:$P,BREACKDOWN!I$33) -> 0 | J42: =COUNTIFS('ALL SITES DOWN'!$O:$O,"ZTE", 'ALL SITES DOWN'!$M:$M,BREACKDOWN!$B42,'ALL SITES DOWN'!$P:$P,BREACKDOWN!J$33) -> 0 | K42: =SUM(C42:J42) -> 0 | M42: OCM ING | N42: 10
A43: 3PP | B43: IHS | C43: =COUNTIFS('ALL SITES DOWN'!$O:$O,"ZTE", 'ALL SITES DOWN'!$M:$M,BREACKDOWN!$B43,'ALL SITES DOWN'!$P:$P,BREACKDOWN!C$33) -> 0 | D43: =COUNTIFS('ALL SITES DOWN'!$O:$O,"ZTE", 'ALL SITES DOWN'!$M:$M,BREACKDOWN!$B43,'ALL SITES DOWN'!$P:$P,BREACKDOWN!D$33) -> 0 | E43: =COUNTIFS('ALL SITES DOWN'!$O:$O,"ZTE", 'ALL SITES DOWN'!$M:$M,BREACKDOWN!$B43,'ALL SITES DOWN'!$P:$P,BREACKDOWN!E$33) -> 0 | F43: =COUNTIFS('ALL SITES DOWN'!$O:$O,"ZTE", 'ALL SITES DOWN'!$M:$M,BREACKDOWN!$B43,'ALL SITES DOWN'!$P:$P,BREACKDOWN!F$33) -> 0 | G43: =COUNTIFS('ALL SITES DOWN'!$O:$O,"ZTE", 'ALL SITES DOWN'!$M:$M,BREACKDOWN!$B43,'ALL SITES DOWN'!$P:$P,BREACKDOWN!G$33) -> 0 | H43: =COUNTIFS('ALL SITES DOWN'!$O:$O,"ZTE", 'ALL SITES DOWN'!$M:$M,BREACKDOWN!$B43,'ALL SITES DOWN'!$P:$P,BREACKDOWN!H$33) -> 0 | I43: =COUNTIFS('ALL SITES DOWN'!$O:$O,"ZTE", 'ALL SITES DOWN'!$M:$M,BREACKDOWN!$B43,'ALL SITES DOWN'!$P:$P,BREACKDOWN!I$33) -> 0 | J43: =COUNTIFS('ALL SITES DOWN'!$O:$O,"ZTE", 'ALL SITES DOWN'!$M:$M,BREACKDOWN!$B43,'ALL SITES DOWN'!$P:$P,BREACKDOWN!J$33) -> 0 | K43: =SUM(C43:J43) -> 0 | M43: IHS | N43: 11
B44: CAMUSAT | C44: =COUNTIFS('ALL SITES DOWN'!$O:$O,"ZTE", 'ALL SITES DOWN'!$M:$M,BREACKDOWN!$B44,'ALL SITES DOWN'!$P:$P,BREACKDOWN!C$33) -> 0 | D44: =COUNTIFS('ALL SITES DOWN'!$O:$O,"ZTE", 'ALL SITES DOWN'!$M:$M,BREACKDOWN!$B44,'ALL SITES DOWN'!$P:$P,BREACKDOWN!D$33) -> 0 | E44: =COUNTIFS('ALL SITES DOWN'!$O:$O,"ZTE", 'ALL SITES DOWN'!$M:$M,BREACKDOWN!$B44,'ALL SITES DOWN'!$P:$P,BREACKDOWN!E$33) -> 0 | F44: =COUNTIFS('ALL SITES DOWN'!$O:$O,"ZTE", 'ALL SITES DOWN'!$M:$M,BREACKDOWN!$B44,'ALL SITES DOWN'!$P:$P,BREACKDOWN!F$33) -> 0 | G44: =COUNTIFS('ALL SITES DOWN'!$O:$O,"ZTE", 'ALL SITES DOWN'!$M:$M,BREACKDOWN!$B44,'ALL SITES DOWN'!$P:$P,BREACKDOWN!G$33) -> 0 | H44: =COUNTIFS('ALL SITES DOWN'!$O:$O,"ZTE", 'ALL SITES DOWN'!$M:$M,BREACKDOWN!$B44,'ALL SITES DOWN'!$P:$P,BREACKDOWN!H$33) -> 0 | I44: =COUNTIFS('ALL SITES DOWN'!$O:$O,"ZTE", 'ALL SITES DOWN'!$M:$M,BREACKDOWN!$B44,'ALL SITES DOWN'!$P:$P,BREACKDOWN!I$33) -> 0 | J44: =COUNTIFS('ALL SITES DOWN'!$O:$O,"ZTE", 'ALL SITES DOWN'!$M:$M,BREACKDOWN!$B44,'ALL SITES DOWN'!$P:$P,BREACKDOWN!J$33) -> 0 | K44: =SUM(C44:J44) -> 0 | M44: Grand Total | N44: 50
B45: MTN | C45: =COUNTIFS('ALL SITES DOWN'!$O:$O,"ZTE", 'ALL SITES DOWN'!$M:$M,BREACKDOWN!$B45,'ALL SITES DOWN'!$P:$P,BREACKDOWN!C$33) -> 0 | D45: =COUNTIFS('ALL SITES DOWN'!$O:$O,"ZTE", 'ALL SITES DOWN'!$M:$M,BREACKDOWN!$B45,'ALL SITES DOWN'!$P:$P,BREACKDOWN!D$33) -> 0 | E45: =COUNTIFS('ALL SITES DOWN'!$O:$O,"ZTE", 'ALL SITES DOWN'!$M:$M,BREACKDOWN!$B45,'ALL SITES DOWN'!$P:$P,BREACKDOWN!E$33) -> 0 | F45: =COUNTIFS('ALL SITES DOWN'!$O:$O,"ZTE", 'ALL SITES DOWN'!$M:$M,BREACKDOWN!$B45,'ALL SITES DOWN'!$P:$P,BREACKDOWN!F$33) -> 0 | G45: =COUNTIFS('ALL SITES DOWN'!$O:$O,"ZTE", 'ALL SITES DOWN'!$M:$M,BREACKDOWN!$B45,'ALL SITES DOWN'!$P:$P,BREACKDOWN!G$33) -> 0 | H45: =COUNTIFS('ALL SITES DOWN'!$O:$O,"ZTE", 'ALL SITES DOWN'!$M:$M,BREACKDOWN!$B45,'ALL SITES DOWN'!$P:$P,BREACKDOWN!H$33) -> 0 | I45: =COUNTIFS('ALL SITES DOWN'!$O:$O,"ZTE", 'ALL SITES DOWN'!$M:$M,BREACKDOWN!$B45,'ALL SITES DOWN'!$P:$P,BREACKDOWN!I$33) -> 0 | J45: =COUNTIFS('ALL SITES DOWN'!$O:$O,"ZTE", 'ALL SITES DOWN'!$M:$M,BREACKDOWN!$B45,'ALL SITES DOWN'!$P:$P,BREACKDOWN!J$33) -> 0 | K45: =SUM(C45:J45) -> 0
...

Sheet ALL SITES DOWN
A1: Priority | B1: Ticket ID | C1: Site Name | D1: Site ID | E1: PowerCO | F1: TOPOLOGIE | G1: Date de début | H1: Durée | I1: Causes | J1: Actions en cours | K1: Owner | L1: Vendor | M1: TEMPS | N1: Alarm Name | O1: Action attendue | P1: FME Name | Q1: AREA | R1: SBC | S1: CONCAT | T1: PMO | U1: RUA | V1: For NSB | W1: Ville
C2: NRO_073_N_Tatum_G | D2: NRO_073 | E2: =VLOOKUP(D2,[2]ACTIF!$A:$D,4,0) -> IHS | F2: =VLOOKUP(D2,[2]ACTIF!$A:$C,3,0) -> Hybrid Gen | G2: =VLOOKUP(Table4[[#This Row],[Site ID]],Extract!D:G,4,0) -> 45931.933 | H2: =NOW() - G2 + TIME(1,0,0) -> 208.89904 | I2: TX MW / security | J2: 21.04.26; Dementellement des ODUs en cours pour MAD à Huawei, update ASAP 09.03.2026: ODU 3DB20858AC/AB et 3DB20859AC/AB MPT 8Ghz pas disponible chez Huawei. Commande passee a OCM. Compte tenu des Swaps NGOKOLO en cours, le site de Tatum impacté bénéficiera des ODUs retours sites. A noter que swap du Lien TX Mah<>Tatum est planifié dans le cadre des swaps TX NOSO avec Huawei et les matériels Huawei ne sont pas encore arrivés | K2: OCM SPMS | L2: =IF(NOT(ISERROR(SEARCH("_URH_",Table4[[#This Row],[Site Name]]))), "Huawei_Rural", IF(NOT(ISERROR(SEARCH("_H_",Table4[[#This Row],[Site Name]]))), "Huawei",IF(NOT(ISERROR(SEARCH("_Z_",Table4[[#This Row],[Site Name]]))), "ZTE","Nokia"))) -> Nokia | M2: =IF(H2 < 1/24, "T<1H", IF(AND(H2<2/24, H2>1/24), "1H<T<2H", IF(AND(H2<4/24, H2>2/24), "2H<T<4H", IF(AND(H2<8/24, H2>4/24), "4H<T<8H", IF(AND(H2<16/24, H2>8/24), "8H<T<16H",IF(AND(H2<24/24, H2>16/24),"16H<T<24H", IF(AND(H2<48/24, H2>24/24),"24H<T<48H", "T>48H"))))))) -> T>48H | N2: BTS O&M LINK FAILURE | O2: =IF(J2="Power Status check Ongoing", "En Attente status Power", IF(J2<>"Power Status check Ongoing", _xlfn.CONCAT(K2, " ", "Ongoing"))) -> OCM SPMS Ongoing | P2: =VLOOKUP(D2,'[3]SBC And PowerCO Info'!A:C,3,0) -> NRO | Q2: =LEFT(D2,3) -> NRO | R2: =VLOOKUP(D2,'[4]SBC And PowerCO Info'!A:N,12,0) -> I-ENG | S2: =_xlfn.CONCAT(Table4[[#This Row],[Site Name]], ": ", IF(ISNUMBER(SEARCH(CHAR(10),J2)), LEFT(J2, SEARCH(CHAR(10),J2)-1), J2)) -> NRO_073_N_Tatum_G: 21.04.26; Dementellement des ODUs en cours pour MAD à Huawei, update ASAP | T2: =IF(ISNA(VLOOKUP([5]!Table4[[#This Row],[Site ID]],[5]PMO!A:A,1,0)),"No","Yes") -> Yes | U2: =VLOOKUP(Table4[[#This Row],[Site ID]],'[6]URH & URZ'!$A:$C,3,0) -> #N/A | V2: =VLOOKUP(Table4[[#This Row],[Site ID]],[6]NSB!$A:$C,3,0) -> #N/A | W2: =VLOOKUP(Table4[[#This Row],[Site ID]],[7]OCTOBRE_25!$J:$L,3,0) -> Tatum
C3: CTR_1053_Z_Okolo-Kilombo-MTN-IHS | D3: CTR_1053 | E3: =VLOOKUP(D3,[2]ACTIF!$A:$D,4,0) -> #N/A | F3: =VLOOKUP(D3,[2]ACTIF!$A:$C,3,0) -> #N/A | G3: =VLOOKUP(Table4[[#This Row],[Site ID]],Extract!D:G,4,0) -> 2026-02-10 10:29:08 | H3: =NOW() - G3 + TIME(1,0,0) -> 77.394969 | I3: New site | J3: New site not yet transferred to MSP | K3: OCM ING | L3: =IF(NOT(ISERROR(SEARCH("_URH_",Table4[[#This Row],[Site Name]]))), "Huawei_Rural", IF(NOT(ISERROR(SEARCH("_H_",Table4[[#This Row],[Site Name]]))), "Huawei",IF(NOT(ISERROR(SEARCH("_Z_",Table4[[#This Row],[Site Name]]))), "ZTE","Nokia"))) -> ZTE | M3: =IF(H3 < 1/24, "T<1H", IF(AND(H3<2/24, H3>1/24), "1H<T<2H", IF(AND(H3<4/24, H3>2/24), "2H<T<4H", IF(AND(H3<8/24, H3>4/24), "4H<T<8H", IF(AND(H3<16/24, H3>8/24), "8H<T<16H",IF(AND(H3<24/24, H3>16/24),"16H<T<24H", IF(AND(H3<48/24, H3>24/24),"24H<T<48H", "T>48H"))))))) -> T>48H | O3: =IF(J3="Power Status check Ongoing", "En Attente status Power", IF(J3<>"Power Status check Ongoing", _xlfn.CONCAT(K3, " ", "Ongoing"))) -> OCM ING Ongoing | P3: =VLOOKUP(D3,'[3]SBC And PowerCO Info'!A:C,3,0) -> #N/A | Q3: =LEFT(D3,3) -> CTR | R3: =VLOOKUP(D3,'[4]SBC And PowerCO Info'!A:N,12,0) -> #N/A | S3: =_xlfn.CONCAT(Table4[[#This Row],[Site Name]], ": ", IF(ISNUMBER(SEARCH(CHAR(10),J3)), LEFT(J3, SEARCH(CHAR(10),J3)-1), J3)) -> CTR_1053_Z_Okolo-Kilombo-MTN-IHS: New site not yet transferred to MSP | T3: =IF(ISNA(VLOOKUP([5]!Table4[[#This Row],[Site ID]],[5]PMO!A:A,1,0)),"No","Yes") -> Yes | U3: =VLOOKUP(Table4[[#This Row],[Site ID]],'[6]URH & URZ'!$A:$C,3,0) -> #N/A | V3: =VLOOKUP(Table4[[#This Row],[Site ID]],[6]NSB!$A:$C,3,0) -> Not Transferred | W3: =VLOOKUP(Table4[[#This Row],[Site ID]],[7]OCTOBRE_25!$J:$L,3,0) -> #N/A
C4: Nkolmeyang-IHS_G9_CTR_442 | D4: CTR_442 | E4: =VLOOKUP(D4,[2]ACTIF!$A:$D,4,0) -> IHS | F4: =VLOOKUP(D4,[2]ACTIF!$A:$C,3,0) -> Hybrid Gen | G4: =VLOOKUP(Table4[[#This Row],[Site ID]],Extract!D:G,4,0) -> 46080.026 | H4: =NOW() - G4 + TIME(1,0,0) -> 60.805663 | I4: UE Relay | J4: 13/04/2026 ETR mi-juin 07/04/2026 Ce site prendra aussi sa transmission sur Tiga. Finalisation du site de Tiga ETR:09/04/2026 09.03.2026: Ce site prendra aussi sa transmission sur Tiga. Finalisation du site de Tiga (Fin Mars 26). ETR: Fin Mars 26 04/03/2026 OCM: installation de la liaison NKOMEYANG <> TIGA ETR=FIN MARS 28.02.26; Site UE Relay, plusieurs reset effectués sans succès (Technologie pas maîtrisée) 27.02.26; FME Rodrigue activer manage avec le level 0. Update ASAP (Plusieurs reset effectués sans succès) BO TX; Site UE-RELAY. Cells L700 de son Donor Nkolbewae UP. Besoin d'un FME sur site pour: Reset Physique du HMC si NOK, Check des Antennes Yagui(Deconnection et reconnection) | K4: OCM ING | L4: =IF(NOT(ISERROR(SEARCH("_URH_",Table4[[#This Row],[Site Name]]))), "Huawei_Rural", IF(NOT(ISERROR(SEARCH("_H_",Table4[[#This Row],[Site Name]]))), "Huawei",IF(NOT(ISERROR(SEARCH("_Z_",Table4[[#This Row],[Site Name]]))), "ZTE","Nokia"))) -> Nokia | M4: =IF(H4 < 1/24, "T<1H", IF(AND(H4<2/24, H4>1/24), "1H<T<2H", IF(AND(H4<4/24, H4>2/24), "2H<T<4H", IF(AND(H4<8/24, H4>4/24), "4H<T<8H", IF(AND(H4<16/24, H4>8/24), "8H<T<16H",IF(AND(H4<24/24, H4>16/24),"16H<T<24H", IF(AND(H4<48/24, H4>24/24),"24H<T<48H", "T>48H"))))))) -> T>48H | N4: NE3SWS AGENT NOT RESPONDING TO REQUESTS | O4: =IF(J4="Power Status check Ongoing", "En Attente status Power", IF(J4<>"Power Status check Ongoing", _xlfn.CONCAT(K4, " ", "Ongoing"))) -> OCM ING Ongoing | P4: =VLOOKUP(D4,'[3]SBC And PowerCO Info'!A:C,3,0) -> CTR | Q4: =LEFT(D4,3) -> CTR | R4: =VLOOKUP(D4,'[4]SBC And PowerCO Info'!A:N,12,0) -> AFRO | S4: =_xlfn.CONCAT(Table4[[#This Row],[Site Name]], ": ", IF(ISNUMBER(SEARCH(CHAR(10),J4)), LEFT(J4, SEARCH(CHAR(10),J4)-1), J4)) -> Nkolmeyang-IHS_G9_CTR_442: 13/04/2026 ETR mi-juin | T4: =IF(ISNA(VLOOKUP([5]!Table4[[#This Row],[Site ID]],[5]PMO!A:A,1,0)),"No","Yes") -> Yes | U4: =VLOOKUP(Table4[[#This Row],[Site ID]],'[6]URH & URZ'!$A:$C,3,0) -> #N/A | V4: =VLOOKUP(Table4[[#This Row],[Site ID]],[6]NSB!$A:$C,3,0) -> #N/A | W4: =VLOOKUP(Table4[[#This Row],[Site ID]],[7]OCTOBRE_25!$J:$L,3,0) -> Nkolmeyang
C5: Balissa_MTN-IHS_G9U9U21_CTR_170 | D5: CTR_170 | E5: =VLOOKUP(D5,[2]ACTIF!$A:$D,4,0) -> IHS | F5: =VLOOKUP(D5,[2]ACTIF!$A:$C,3,0) -> Solar-Gen-Lithium | G5: =VLOOKUP(Table4[[#This Row],[Site ID]],Extract!D:G,4,0) -> 46093.014 | H5: =NOW() - G5 + TIME(1,0,0) -> 47.817781 | I5: TX MW | J5: 02.04.2026: ODU3DB20859AC (MPT-7-8Ghz) Recu faulty nouvelle commande en cours chez OCM car spare pas dispo chez Huawei 02.04.2026: FME en route ETA=30 MIN 01/04/2026 FME a la Gare pour la recuperation du Materiel ETA=15H UTC 31/03/2026 ODU recu Ngaoundéré expedition ngaoundal ETD=31/03/2026 30/03/2026 ODU recu Ngaoundéré expedition ngaoundal ETD=30/03/2026 28.03.2: ODU mis à disposition expédition Ngaoundéré, ETD=30.03.26 26.03.26; ODU mis à disposition ce jour et expédition ce jour vers Ngaoundéré, ETD=30.03.26 14/03/2026 FME en route ETA=10H UTC // FME sur site ODU 3DB20859AC (MPT-7-8Ghz) fautlty commande pas disponible au WH point transmisa OCM en attente de retour 13.03.26; FME en route pour le site, ETA=17H UTC (escalade faite au FM manager) 12.03.26; Level 0 sur site et investigations en cours 12.03.26; Level 0 en route pour le site, ETA=16H30 UTC 12.02.26; Besoin d'un FME sur site pour vérifier le statut du MPR; FME manage avec le niveau 0 | K5: OCM SPMS | L5: =IF(NOT(ISERROR(SEARCH("_URH_",Table4[[#This Row],[Site Name]]))), "Huawei_Rural", IF(NOT(ISERROR(SEARCH("_H_",Table4[[#This Row],[Site Name]]))), "Huawei",IF(NOT(ISERROR(SEARCH("_Z_",Table4[[#This Row],[Site Name]]))), "ZTE","Nokia"))) -> Nokia | M5: =IF(H5 < 1/24, "T<1H", IF(AND(H5<2/24, H5>1/24), "1H<T<2H", IF(AND(H5<4/24, H5>2/24), "2H<T<4H", IF(AND(H5<8/24, H5>4/24), "4H<T<8H", IF(AND(H5<16/24, H5>8/24), "8H<T<16H",IF(AND(H5<24/24, H5>16/24),"16H<T<24H", IF(AND(H5<48/24, H5>24/24),"24H<T<48H", "T>48H"))))))) -> T>48H | N5: NE3SWS AGENT NOT RESPONDING TO REQUESTS | O5: =IF(J5="Power Status check Ongoing", "En Attente status Power", IF(J5<>"Power Status check Ongoing", _xlfn.CONCAT(K5, " ", "Ongoing"))) -> OCM SPMS Ongoing | P5: =VLOOKUP(D5,'[3]SBC And PowerCO Info'!A:C,3,0) -> CTR | Q5: =LEFT(D5,3) -> CTR | R5: =VLOOKUP(D5,'[4]SBC And PowerCO Info'!A:N,12,0) -> AFRO | S5: =_xlfn.CONCAT(Table4[[#This Row],[Site Name]], ": ", IF(ISNUMBER(SEARCH(CHAR(10),J5)), LEFT(J5, SEARCH(CHAR(10),J5)-1), J5)) -> Balissa_MTN-IHS_G9U9U21_CTR_170: | T5: =IF(ISNA(VLOOKUP([5]!Table4[[#This Row],[Site ID]],[5]PMO!A:A,1,0)),"No","Yes") -> Yes | U5: =VLOOKUP(Table4[[#This Row],[Site ID]],'[6]URH & URZ'!$A:$C,3,0) -> #N/A | V5: =VLOOKUP(Table4[[#This Row],[Site ID]],[6]NSB!$A:$C,3,0) -> #N/A | W5: =VLOOKUP(Table4[[#This Row],[Site ID]],[7]OCTOBRE_25!$J:$L,3,0) -> Balissa
C6: ADM_215_H_NGD-UNIVERSITY-CAMTEL_U, LogicRNCID=387 | D6: ADM_215 | E6: =VLOOKUP(D6,[2]ACTIF!$A:$D,4,0) -> #N/A | F6: =VLOOKUP(D6,[2]ACTIF!$A:$C,3,0) -> #N/A | G6: =VLOOKUP(Table4[[#This Row],[Site ID]],Extract!D:G,4,0) -> 2026-03-12 03:51:43 | H6: =NOW() - G6 + TIME(1,0,0) -> 47.670952 | I6: New site | J6: New site not yet transferred to MSP | K6: OCM ING | L6: =IF(NOT(ISERROR(SEARCH("_URH_",Table4[[#This Row],[Site Name]]))), "Huawei_Rural", IF(NOT(ISERROR(SEARCH("_H_",Table4[[#This Row],[Site Name]]))), "Huawei",IF(NOT(ISERROR(SEARCH("_Z_",Table4[[#This Row],[Site Name]]))), "ZTE","Nokia"))) -> Huawei | M6: =IF(H6 < 1/24, "T<1H", IF(AND(H6<2/24, H6>1/24), "1H<T<2H", IF(AND(H6<4/24, H6>2/24), "2H<T<4H", IF(AND(H6<8/24, H6>4/24), "4H<T<8H", IF(AND(H6<16/24, H6>8/24), "8H<T<16H",IF(AND(H6<24/24, H6>16/24),"16H<T<24H", IF(AND(H6<48/24, H6>24/24),"24H<T<48H", "T>48H"))))))) -> T>48H | N6: NodeB Unavailable | O6: =IF(J6="Power Status check Ongoing", "En Attente status Power", IF(J6<>"Power Status check Ongoing", _xlfn.CONCAT(K6, " ", "Ongoing"))) -> OCM ING Ongoing | P6: =VLOOKUP(D6,'[3]SBC And PowerCO Info'!A:C,3,0) -> #N/A | Q6: =LEFT(D6,3) -> ADM | R6: =VLOOKUP(D6,'[4]SBC And PowerCO Info'!A:N,12,0) -> #N/A | S6: =_xlfn.CONCAT(Table4[[#This Row],[Site Name]], ": ", IF(ISNUMBER(SEARCH(CHAR(10),J6)), LEFT(J6, SEARCH(CHAR(10),J6)-1), J6)) -> ADM_215_H_NGD-UNIVERSITY-CAMTEL_U, LogicRNCID=387: New site not yet transferred to MSP | T6: =IF(ISNA(VLOOKUP([5]!Table4[[#This Row],[Site ID]],[5]PMO!A:A,1,0)),"No","Yes") -> Yes | U6: =VLOOKUP(Table4[[#This Row],[Site ID]],'[6]URH & URZ'!$A:$C,3,0) -> #N/A | V6: =VLOOKUP(Table4[[#This Row],[Site ID]],[6]NSB!$A:$C,3,0) -> Not Transferred | W6: =VLOOKUP(Table4[[#This Row],[Site ID]],[7]OCTOBRE_25!$J:$L,3,0) -> #N/A
C7: ADM_233_H_NGD-BURKINA-CENTENAIRE_U, LogicRNCID=387 | D7: ADM_233 | E7: =VLOOKUP(D7,[2]ACTIF!$A:$D,4,0) -> #N/A | F7: =VLOOKUP(D7,[2]ACTIF!$A:$C,3,0) -> #N/A | G7: =VLOOKUP(Table4[[#This Row],[Site ID]],Extract!D:G,4,0) -> 2026-03-12 03:51:43 | H7: =NOW() - G7 + TIME(1,0,0) -> 47.670952 | I7: New site | J7: New site not yet transferred to MSP | K7: OCM ING | L7: =IF(NOT(ISERROR(SEARCH("_URH_",Table4[[#This Row],[Site Name]]))), "Huawei_Rural", IF(NOT(ISERROR(SEARCH("_H_",Table4[[#This Row],[Site Name]]))), "Huawei",IF(NOT(ISERROR(SEARCH("_Z_",Table4[[#This Row],[Site Name]]))), "ZTE","Nokia"))) -> Huawei | M7: =IF(H7 < 1/24, "T<1H", IF(AND(H7<2/24, H7>1/24), "1H<T<2H", IF(AND(H7<4/24, H7>2/24), "2H<T<4H", IF(AND(H7<8/24, H7>4/24), "4H<T<8H", IF(AND(H7<16/24, H7>8/24), "8H<T<16H",IF(AND(H7<24/24, H7>16/24),"16H<T<24H", IF(AND(H7<48/24, H7>24/24),"24H<T<48H", "T>48H"))))))) -> T>48H | N7: NodeB Unavailable | O7: =IF(J7="Power Status check Ongoing", "En Attente status Power", IF(J7<>"Power Status check Ongoing", _xlfn.CONCAT(K7, " ", "Ongoing"))) -> OCM ING Ongoing | P7: =VLOOKUP(D7,'[3]SBC And PowerCO Info'!A:C,3,0) -> #N/A | Q7: =LEFT(D7,3) -> ADM | R7: =VLOOKUP(D7,'[4]SBC And PowerCO Info'!A:N,12,0) -> #N/A | S7: =_xlfn.CONCAT(Table4[[#This Row],[Site Name]], ": ", IF(ISNUMBER(SEARCH(CHAR(10),J7)), LEFT(J7, SEARCH(CHAR(10),J7)-1), J7)) -> ADM_233_H_NGD-BURKINA-CENTENAIRE_U, LogicRNCID=387: New site not yet transferred to MSP | T7: =IF(ISNA(VLOOKUP([5]!Table4[[#This Row],[Site ID]],[5]PMO!A:A,1,0)),"No","Yes") -> Yes | U7: =VLOOKUP(Table4[[#This Row],[Site ID]],'[6]URH & URZ'!$A:$C,3,0) -> #N/A | V7: =VLOOKUP(Table4[[#This Row],[Site ID]],[6]NSB!$A:$C,3,0) -> Not Transferred | W7: =VLOOKUP(Table4[[#This Row],[Site ID]],[7]OCTOBRE_25!$J:$L,3,0) -> #N/A
C8: ADM_216_H_Mawi | D8: ADM_216 | E8: =VLOOKUP(D8,[2]ACTIF!$A:$D,4,0) -> #N/A | F8: =VLOOKUP(D8,[2]ACTIF!$A:$C,3,0) -> #N/A | G8: =VLOOKUP(Table4[[#This Row],[Site ID]],Extract!D:G,4,0) -> 2026-03-19 17:24:32 | H8: =NOW() - G8 + TIME(1,0,0) -> 40.106496 | I8: New site | J8: New site not yet transferred to MSP | K8: OCM ING | L8: =IF(NOT(ISERROR(SEARCH("_URH_",Table4[[#This Row],[Site Name]]))), "Huawei_Rural", IF(NOT(ISERROR(SEARCH("_H_",Table4[[#This Row],[Site Name]]))), "Huawei",IF(NOT(ISERROR(SEARCH("_Z_",Table4[[#This Row],[Site Name]]))), "ZTE","Nokia"))) -> Huawei | M8: =IF(H8 < 1/24, "T<1H", IF(AND(H8<2/24, H8>1/24), "1H<T<2H", IF(AND(H8<4/24, H8>2/24), "2H<T<4H", IF(AND(H8<8/24, H8>4/24), "4H<T<8H", IF(AND(H8<16/24, H8>8/24), "8H<T<16H",IF(AND(H8<24/24, H8>16/24),"16H<T<24H", IF(AND(H8<48/24, H8>24/24),"24H<T<48H", "T>48H"))))))) -> T>48H | N8: NE Is Disconnected | O8: =IF(J8="Power Status check Ongoing", "En Attente status Power", IF(J8<>"Power Status check Ongoing", _xlfn.CONCAT(K8, " ", "Ongoing"))) -> OCM ING Ongoing | P8: =VLOOKUP(D8,'[3]SBC And PowerCO Info'!A:C,3,0) -> #N/A | Q8: =LEFT(D8,3) -> ADM | R8: =VLOOKUP(D8,'[4]SBC And PowerCO Info'!A:N,12,0) -> #N/A | S8: =_xlfn.CONCAT(Table4[[#This Row],[Site Name]], ": ", IF(ISNUMBER(SEARCH(CHAR(10),J8)), LEFT(J8, SEARCH(CHAR(10),J8)-1), J8)) -> ADM_216_H_Mawi: New site not yet transferred to MSP | T8: =IF(ISNA(VLOOKUP([5]!Table4[[#This Row],[Site ID]],[5]PMO!A:A,1,0)),"No","Yes") -> Yes | U8: =VLOOKUP(Table4[[#This Row],[Site ID]],'[6]URH & URZ'!$A:$C,3,0) -> #N/A | V8: =VLOOKUP(Table4[[#This Row],[Site ID]],[6]NSB!$A:$C,3,0) -> Not Transferred | W8: =VLOOKUP(Table4[[#This Row],[Site ID]],[7]OCTOBRE_25!$J:$L,3,0) -> #N/A
C9: EXN_394_URH_MAGAM_KOTOKO | D9: EXN_394 | E9: Teleinfra | F9: Solar Only | G9: =VLOOKUP(Table4[[#This Row],[Site ID]],Extract!D:G,4,0) -> 2026-03-28 09:34:51 | H9: =NOW() - G9 + TIME(1,0,0) -> 31.432665 | I9: New site | J9: New site not yet transferred to MSP | K9: OCM ING | L9: =IF(NOT(ISERROR(SEARCH("_URH_",Table4[[#This Row],[Site Name]]))), "Huawei_Rural", IF(NOT(ISERROR(SEARCH("_H_",Table4[[#This Row],[Site Name]]))), "Huawei",IF(NOT(ISERROR(SEARCH("_Z_",Table4[[#This Row],[Site Name]]))), "ZTE","Nokia"))) -> Huawei_Rural | M9: =IF(H9 < 1/24, "T<1H", IF(AND(H9<2/24, H9>1/24), "1H<T<2H", IF(AND(H9<4/24, H9>2/24), "2H<T<4H", IF(AND(H9<8/24, H9>4/24), "4H<T<8H", IF(AND(H9<16/24, H9>8/24), "8H<T<16H",IF(AND(H9<24/24, H9>16/24),"16H<T<24H", IF(AND(H9<48/24, H9>24/24),"24H<T<48H", "T>48H"))))))) -> T>48H | N9: CSL Fault | O9: =IF(J9="Power Status check Ongoing", "En Attente status Power", IF(J9<>"Power Status check Ongoing", _xlfn.CONCAT(K9, " ", "Ongoing"))) -> OCM ING Ongoing | P9: =VLOOKUP(D9,'[3]SBC And PowerCO Info'!A:C,3,0) -> #N/A | Q9: =LEFT(D9,3) -> EXN | R9: =VLOOKUP(D9,'[4]SBC And PowerCO Info'!A:N,12,0) -> #N/A | S9: =_xlfn.CONCAT(Table4[[#This Row],[Site Name]], ": ", IF(ISNUMBER(SEARCH(CHAR(10),J9)), LEFT(J9, SEARCH(CHAR(10),J9)-1), J9)) -> EXN_394_URH_MAGAM_KOTOKO: New site not yet transferred to MSP | T9: =IF(ISNA(VLOOKUP([5]!Table4[[#This Row],[Site ID]],[5]PMO!A:A,1,0)),"No","Yes") -> Yes | U9: =VLOOKUP(Table4[[#This Row],[Site ID]],'[6]URH & URZ'!$A:$C,3,0) -> #N/A | V9: =VLOOKUP(Table4[[#This Row],[Site ID]],[6]NSB!$A:$C,3,0) -> #N/A | W9: =VLOOKUP(Table4[[#This Row],[Site ID]],[7]OCTOBRE_25!$J:$L,3,0) -> #N/A
C10: EXN_300_URH_KARENA | D10: EXN_300 | E10: Teleinfra | F10: Solar Only | G10: =VLOOKUP(Table4[[#This Row],[Site ID]],Extract!D:G,4,0) -> 2026-03-28 09:34:54 | H10: =NOW() - G10 + TIME(1,0,0) -> 31.432631 | I10: VENDALIZED | J10: 28.04.2026: Karena à nouveau entièrement vandalisé la nuit 25/04/2026. Rapport D'intervention envoye a OCM pour MAD du materiel 26/04/2026 Karena à nouveau entièrement vandalisé cette nuit. 26/04/2026 suite remplacement des PV et batteries ce jour, ETR 18H 25/04/2026 FME sur site suite des travaux en cours 24.04.26: Travaux de restoration en cours ce jour, ETR=14H UTC 23.04.26: PV et Batteries reçus à Kousseri, remplacement ce 24/04/2026 22.04.26; PV et Batteries confiés à un nouveau transporteur pour KOUSSERI, ETD=22/04/2026 21.04.26; PV et Batteries confiés à un nouveau transporteur pour KOUSSERI, ETD=22/04/2026 20.04.26; we are facing transport issues from Maroua to Kousseri due to the very bad road. We finally found a workaround to go through Chad. The ETA 23rd April, approximation as we do not have mastery of this route. 19.04.26; Soucis de transport du matériel (car matériel délicat à transporter). Expédition de Maroua pour Kousseri ce jour, ETD à préciser 18.04.26; Négociations de l'escorte en cours pour Makary, update ASAP 17/04/2026 le Materiel est arrive a Kousseri, l'equipe negocie l'acces pour Makary, zone insecurisee. Update asap 15/04/2026 Apres l'arrivee des Panneaux solaires et battéries à Maroua. l'expedition de Maroua vers Kousseri sur une route tres mauvaise et ensuite de Kousseri vers Makary avec des panneaux solaire de 2m chacun et donc assez delicat a transporter. Nouvel ETD pour Kousseri 16/04/2026 08/04/2026 KARENA : Apres l'arrivee des Panneaux solaires et battéries à Maroua. l'expedition continue demain de Maroua vers Kousseri sur une route tres mauvaise et ensuite de Kousseri vers Makary avec des panneaux solaire de 2m chacun et donc assez delicat a transporter. ETD pour Makary ETD 14.04.2026 et ETR 15.04.2026 06.04.26; Panneaux solaires et battéries à Maroua et recherche d'une solution pour expédition vers Kousseri puis vers Makary, ETD=08.04.26 04/04/2026 Karena etant un site situé dans le cluster de Makari, nous essayons de procéder au transfert de ces spare vers kousseri afin qu'elle soient acheminée sur Makari...Nous vous reviendrons pour l'ETD sur Kousseri car vu l'heure le départ pour Kousseri n'est pas pour ce jour. 02/04/2026 Expedition toujours en cours Retards du transporteur a cause d'une panne de vehicule Nouvelle ETD=03/04/2026 25.03.26; Tous les restes de matériels attendus, panneaux, batteries, Fibre optique a été livré ce jour. ETD 01/04 09.03.2026: Le reste du materiel(Panneau solaire. Qté:3. PN: 52240364 Batterie 48 Volts Huawei ESM-48100B1. Qté: 3. PN: 01074746-010, Cosses de 35 Qté: 6 PN:56464200056, Câble bleu de section 35 mm2 pour le câblage des batteries. Longueur:10m. PN:25030741, Câble noir de section 35 mm2 pour le câblage des batteries. Longueur:10m. PN:25030742 , Câble rouge de section 16 mm2 pour le câblage des PV. Longueur:10m. PN:25035221 ) Sera mis a dispostion de Huawei ce 13.03.2026 05.03.2026: 05.03.2026: 700m de cable 2*16 et 500m de cable 2*25 ont ete deja fournit a Huawei. Il ne reste que les cable 2*35, les panneaux solaire, les Batteries et Fibre Optiques qui sont attendus de OCM 25.02.26; Site vendalisé, inventaire du matériel pour restauration transmis à OCM, en attente de la mise à disposition 24/02/2026 Site vandalise, requete de spare en cours vers OCM pour restauration 24.02.26; Rapport sur le vendalisme transmis et vérifications du SPM en cours | K10: Teleinfra | L10: =IF(NOT(ISERROR(SEARCH("_URH_",Table4[[#This Row],[Site Name]]))), "Huawei_Rural", IF(NOT(ISERROR(SEARCH("_H_",Table4[[#This Row],[Site Name]]))), "Huawei",IF(NOT(ISERROR(SEARCH("_Z_",Table4[[#This Row],[Site Name]]))), "ZTE","Nokia"))) -> Huawei_Rural | M10: =IF(H10 < 1/24, "T<1H", IF(AND(H10<2/24, H10>1/24), "1H<T<2H", IF(AND(H10<4/24, H10>2/24), "2H<T<4H", IF(AND(H10<8/24, H10>4/24), "4H<T<8H", IF(AND(H10<16/24, H10>8/24), "8H<T<16H",IF(AND(H10<24/24, H10>16/24),"16H<T<24H", IF(AND(H10<48/24, H10>24/24),"24H<T<48H", "T>48H"))))))) -> T>48H | N10: CSL Fault | O10: =IF(J10="Power Status check Ongoing", "En Attente status Power", IF(J10<>"Power Status check Ongoing", _xlfn.CONCAT(K10, " ", "Ongoing"))) -> Teleinfra Ongoing | P10: =VLOOKUP(D10,'[3]SBC And PowerCO Info'!A:C,3,0) -> EXN | Q10: =LEFT(D10,3) -> EXN | R10: =VLOOKUP(D10,'[4]SBC And PowerCO Info'!A:N,12,0) -> TIF NORD | S10: =_xlfn.CONCAT(Table4[[#This Row],[Site Name]], ": ", IF(ISNUMBER(SEARCH(CHAR(10),J10)), LEFT(J10, SEARCH(CHAR(10),J10)-1), J10)) -> EXN_300_URH_KARENA: 28.04.2026: Karena à nouveau entièrement vandalisé la nuit 25/04/2026. Rapport D'intervention envoye a OCM pour MAD du materiel | T10: =IF(ISNA(VLOOKUP([5]!Table4[[#This Row],[Site ID]],[5]PMO!A:A,1,0)),"No","Yes") -> Yes | U10: =VLOOKUP(Table4[[#This Row],[Site ID]],'[6]URH & URZ'!$A:$C,3,0) -> transfered | V10: =VLOOKUP(Table4[[#This Row],[Site ID]],[6]NSB!$A:$C,3,0) -> #N/A | W10: =VLOOKUP(Table4[[#This Row],[Site ID]],[7]OCTOBRE_25!$J:$L,3,0) -> #N/A
