Workbook
Name camusat_ocm: '[1]CAMUSAT OCM DB'!$A$1:$G$431
Name ihs_ocm: '[1]IHS OCM DB'!$A$1:$U$1703

Sheet cell downs 01062026 8h16
A1: Controlling Object Name | B1: site code | C1: Tickets | D1: Type | E1: User Additional Information | F1: Powerco | G1: Topo energy | H1: Alarm Time | I1: Duration | J1: Technology | K1: Problem | L1: AP | M1: Supplementary Information | N1: Diagnostic Info | O1: Action PLAN | P1: Action de resolution | Q1: Date de resolution | R1: Comment | S1: Porteur | T1: RCA | U1: Causes | V1: SBC | W1: Ville | X1: Regoin | Y1: Temps | Z1: Nombre | AA1: STATUT Cells | AB1: Ages Cells | AC1: Jour d'extraction | AD1: SEMAINE | AE1: ETD,ETA,
A2: Batchenga_G9U9U21L8L7L18L26_CTR_032_MRBTS1 | B2: CTR_032 | E2: faulty_cells=GSM:2937 | F2: =VLOOKUP(B2,'[2]Power '!$A:$C,3,0) -> #N/A | G2: =VLOOKUP(B2,'[2]Power '!$A:$D,4,0) -> #N/A | H2: 46161.849 | I2: =NOW()-H2 -> 18.820081 | M2: TRX initialization failure | N2: 2400 supplAlarmInfo=Not enough DSP resources available to allocate the TRX additionalFaultID=2400 | R2: 01/06/2026: : Need BO TX analysis || 29/05/2026 : Feedback BO RAN : Il y a deux soucis sur ce site : RAN et TX || TX : packet loss, instabilité Bien vouloir faire analyser par un BO TX 25/05/2026 : Un mail a ete envoyer au BO pour plus d'analyse. | S2: BO TX | T2: RCA unknown | U2: RCA unknown | V2: =VLOOKUP(B2,[2]Overall!$A:$D,4,0) -> TELEINFRA CENTRE | W2: =VLOOKUP(B2,[3]Sheet1!$A:$B,2,0) -> Batchenga | X2: =LEFT('[4]cell downs 21052026 8h34'!B84,3) -> SUO | Y2: =IF(I2 < 1/24, "T<1H", IF(AND(I2<2/24, I2>1/24), "1H<T<2H", IF(AND(I2<4/24, I2>2/24), "2H<T<4H", IF(AND(I2<8/24, I2>4/24), "4H<T<8H", IF(AND(I2<16/24, I2>8/24), "8H<T<16H",IF(AND(I2<24/24, I2>16/24),"16H<T<24H", IF(AND(I2<48/24, I2>24/24),"24H<T<48H",IF(AND(I2<72/24, I2>24/24),"48H<T<72H", "T>72H")))))))) -> T>72H | Z2: =IF(OR(E2="", E2="affected_cells=unknown"), "", LEN(E2)-LEN(SUBSTITUTE(E2, ",", "")) + LEN(E2)-LEN(SUBSTITUTE(E2, ";", "")) + 1) -> 1 | AA2: DOWN | AB2: Old case | AC2: 01/06/2026 8h16 | AD2: W23
A3: Batchenga_G9U9U21L8L7L18L26_CTR_032_MRBTS1 | B3: CTR_032 | E3: faulty_cells=GSM:2936 | F3: =VLOOKUP(B3,'[2]Power '!$A:$C,3,0) -> #N/A | G3: =VLOOKUP(B3,'[2]Power '!$A:$D,4,0) -> #N/A | H3: 46161.849 | I3: =NOW()-H3 -> 18.820081 | M3: TRX initialization failure | N3: 2400 supplAlarmInfo=Not enough DSP resources available to allocate the TRX additionalFaultID=2400 | R3: 01/06/2026: : Need BO TX analysis || 29/05/2026 : Feedback BO RAN : Il y a deux soucis sur ce site : RAN et TX || TX : packet loss, instabilité Bien vouloir faire analyser par un BO TX 25/05/2026 : Un mail a ete envoyer au BO pour plus d'analyse. | S3: BO TX | T3: RCA unknown | U3: RCA unknown | V3: =VLOOKUP(B3,[2]Overall!$A:$D,4,0) -> TELEINFRA CENTRE | W3: =VLOOKUP(B3,[3]Sheet1!$A:$B,2,0) -> Batchenga | X3: =LEFT('[4]cell downs 21052026 8h34'!B85,3) -> SUO | Y3: =IF(I3 < 1/24, "T<1H", IF(AND(I3<2/24, I3>1/24), "1H<T<2H", IF(AND(I3<4/24, I3>2/24), "2H<T<4H", IF(AND(I3<8/24, I3>4/24), "4H<T<8H", IF(AND(I3<16/24, I3>8/24), "8H<T<16H",IF(AND(I3<24/24, I3>16/24),"16H<T<24H", IF(AND(I3<48/24, I3>24/24),"24H<T<48H",IF(AND(I3<72/24, I3>24/24),"48H<T<72H", "T>72H")))))))) -> T>72H | Z3: =IF(OR(E3="", E3="affected_cells=unknown"), "", LEN(E3)-LEN(SUBSTITUTE(E3, ",", "")) + LEN(E3)-LEN(SUBSTITUTE(E3, ";", "")) + 1) -> 1 | AA3: DOWN | AB3: Old case | AC3: 01/06/2026 8h16 | AD3: W23
A4: Batchenga_G9U9U21L8L7L18L26_CTR_032_MRBTS1 | B4: CTR_032 | E4: faulty_cells=GSM:2938 | F4: =VLOOKUP(B4,'[2]Power '!$A:$C,3,0) -> #N/A | G4: =VLOOKUP(B4,'[2]Power '!$A:$D,4,0) -> #N/A | H4: 46161.849 | I4: =NOW()-H4 -> 18.820081 | M4: TRX initialization failure | N4: 2400 supplAlarmInfo=Not enough DSP resources available to allocate the TRX additionalFaultID=2400 | R4: 01/06/2026: : Need BO TX analysis || 29/05/2026 : Feedback BO RAN : Il y a deux soucis sur ce site : RAN et TX || TX : packet loss, instabilité Bien vouloir faire analyser par un BO TX 25/05/2026 : Un mail a ete envoyer au BO pour plus d'analyse. | S4: BO TX | T4: RCA unknown | U4: RCA unknown | V4: =VLOOKUP(B4,[2]Overall!$A:$D,4,0) -> TELEINFRA CENTRE | W4: =VLOOKUP(B4,[3]Sheet1!$A:$B,2,0) -> Batchenga | X4: =LEFT('[4]cell downs 21052026 8h34'!B86,3) -> ADM | Y4: =IF(I4 < 1/24, "T<1H", IF(AND(I4<2/24, I4>1/24), "1H<T<2H", IF(AND(I4<4/24, I4>2/24), "2H<T<4H", IF(AND(I4<8/24, I4>4/24), "4H<T<8H", IF(AND(I4<16/24, I4>8/24), "8H<T<16H",IF(AND(I4<24/24, I4>16/24),"16H<T<24H", IF(AND(I4<48/24, I4>24/24),"24H<T<48H",IF(AND(I4<72/24, I4>24/24),"48H<T<72H", "T>72H")))))))) -> T>72H | Z4: =IF(OR(E4="", E4="affected_cells=unknown"), "", LEN(E4)-LEN(SUBSTITUTE(E4, ",", "")) + LEN(E4)-LEN(SUBSTITUTE(E4, ";", "")) + 1) -> 1 | AA4: DOWN | AB4: Old case | AC4: 01/06/2026 8h16 | AD4: W23
A5: Martap_G18L18L8_ADM_060_sBTS2 | B5: ADM_060 | E5: faulty_cells=LTE:13 | F5: =VLOOKUP(B5,'[2]Power '!$A:$C,3,0) -> TowerCo | G5: =VLOOKUP(B5,'[2]Power '!$A:$D,4,0) -> Solar-Gen | H5: 46163.5 | I5: =NOW()-H5 -> 17.168692 | M5: TX out of order | N5: 1907 unitName=FRMF path=/SMOD_R-1/eif2_rf6/RMOD_R-3 serial_no=AS181700926 additionalFaultID=1907 | R5: 01/06/2026 : Besoin transfere a OCM || Feedback OCM : DN attendu pour recuperation de la SPARE 30/05/2026 : FRMF pas disponible dans les Grd-nord || MAil de cde envoye a hw spare 29/05/2026 : Check disponibilite FRMF dans les WH du grand Nord. 28/05/2026: Intervetion prevue ce jour ||ETA: 11h||intervention en cour||Configuaration et remplcament de la SFP module||FRMF faulty 27/05/2026 : Fme actuellment sur le site de Dir pourra intervenir sur le site de Martap apres. 26/05/2026:Feedback RM : Intervention le 27/05/2026 après remplacement FRMF sur Goro ce jour 25/05/2026 : Forte pluie dans la zone. Evidences partagees 22/05/2026 ; Feedback Warehouse ; La spare na pas pu ete transferer faute des agents de l'agence||ETD : demain matin 20/05/2026 : FRMF transfere sur ngaoundere || Expedition pour Ngaoudal || ETD 21052026 18/05/2026 ; La spare quitte Maroua pour NDE aujourd'hui ETD : 20052026 17/05/2026 : Check breaker and interconnection (sfp, optical fiber) between system and radio module, swap its if needed||FME active ||Cmd de la radio FRMF en cour chez le warehouse de NDE. | S5: OCM SPMS | T5: FRMF faulty | U5: FRMF faulty | V5: =VLOOKUP(B5,[2]Overall!$A:$D,4,0) -> TELEINFRA NORD | W5: =VLOOKUP(B5,[3]Sheet1!$A:$B,2,0) -> Martap | X5: =LEFT('[4]cell downs 21052026 8h34'!B87,3) -> SUD | Y5: =IF(I5 < 1/24, "T<1H", IF(AND(I5<2/24, I5>1/24), "1H<T<2H", IF(AND(I5<4/24, I5>2/24), "2H<T<4H", IF(AND(I5<8/24, I5>4/24), "4H<T<8H", IF(AND(I5<16/24, I5>8/24), "8H<T<16H",IF(AND(I5<24/24, I5>16/24),"16H<T<24H", IF(AND(I5<48/24, I5>24/24),"24H<T<48H",IF(AND(I5<72/24, I5>24/24),"48H<T<72H", "T>72H")))))))) -> T>72H | Z5: =IF(OR(E5="", E5="affected_cells=unknown"), "", LEN(E5)-LEN(SUBSTITUTE(E5, ",", "")) + LEN(E5)-LEN(SUBSTITUTE(E5, ";", "")) + 1) -> 1 | AA5: DOWN | AB5: Old case | AC5: 01/06/2026 8h16 | AD5: W23
A6: Kembong_G9U9U21_NRO_026_MRBTS1 | B6: NRO_026 | E6: faulty_cells=WCDMA:500601;degraded_cells=WCDMA:500614 | F6: =VLOOKUP(B6,'[2]Power '!$A:$C,3,0) -> TowerCo | G6: =VLOOKUP(B6,'[2]Power '!$A:$D,4,0) -> Grid-Gen | H6: 46163.574 | I6: =NOW()-H6 -> 17.094387 | M6: VSWR major alarm | N6: 1837 unitName=AntennaLine path=/SMOD_R-1/rf_ext3/RMOD_R-2/ant1 additionalFaultID=1837 | R6: 01/06/2026: GHOST TOWN 31/05/2026 : Access issue || Negociation en cours 30/05/2026: Feedback PM: Panel Antenna replacement planned today 30.05.2026 29.05.2025: Intervention planned by today if acces OK 28/05/2026:Feedback PM||Panel Antenna replacemen planned on 29.05.2025 25/05/2026 : GHOST TOWN 22/05/2026 : Action avec le level non productive || Look down dans la zone || Feedback PM : Intevenion planned 24.05.2025 while waiting acces to be granted by local resident 21/05/2026: Access isssue || Action evec le level 0 en cours || Si l'action n'aboutti pas le FME interveindra demain si l'access est possible 19/05/2026:LOCK DOWN 18/05/2026 : GHOST TOWN 17/05/2026 : No access for this site for now we keep tryin 16/05/2026 : No access for this site for now we keep trying 15/05/2026 : No access for this site for now we keep trying 14/05/2026 : Feedback RM :No access for this site for now we keep trying 12/05/2026: Fme should check and clean jumper, port 1 || Insecurity zone: Access clearance negotiation on site for intervention 11/05/2026 : Ghost town 09/05/2026 : Need BO RAN analysis||Fme should check and clean jumper, port 1 | S6: HAMMER_OU-NO | T6: Pannel faulty | U6: Pannel faulty | V6: =VLOOKUP(B6,[2]Overall!$A:$D,4,0) -> I-ENG | W6: =VLOOKUP(B6,[3]Sheet1!$A:$B,2,0) -> Kembong | X6: =LEFT('[4]cell downs 21052026 8h34'!B85,3) -> SUO | Y6: =IF(I6 < 1/24, "T<1H", IF(AND(I6<2/24, I6>1/24), "1H<T<2H", IF(AND(I6<4/24, I6>2/24), "2H<T<4H", IF(AND(I6<8/24, I6>4/24), "4H<T<8H", IF(AND(I6<16/24, I6>8/24), "8H<T<16H",IF(AND(I6<24/24, I6>16/24),"16H<T<24H", IF(AND(I6<48/24, I6>24/24),"24H<T<48H",IF(AND(I6<72/24, I6>24/24),"48H<T<72H", "T>72H")))))))) -> T>72H | Z6: =IF(OR(E6="", E6="affected_cells=unknown"), "", LEN(E6)-LEN(SUBSTITUTE(E6, ",", "")) + LEN(E6)-LEN(SUBSTITUTE(E6, ";", "")) + 1) -> 2 | AA6: DOWN | AB6: Old case | AC6: 01/06/2026 8h16 | AD6: W23
A7: Songbong_L18L8_CTR_311_MRBTS2 | B7: CTR_311 | E7: faulty_cells=LTE:11,12,13,22 | F7: =VLOOKUP(B7,'[2]Power '!$A:$C,3,0) -> TowerCo | G7: =VLOOKUP(B7,'[2]Power '!$A:$D,4,0) -> Solar-Gen | H7: 46167.751 | I7: =NOW()-H7 -> 12.917304 | M7: FSP overheating | N7: 4077 unitName=FBBC path=/SMOD_R-1/bbext1/BBMOD_R-1 serial_no=GA224200184 additionalFaultID=4077 | R7: 01/06/2026 : Relance faite ce jour 29/05/2026 : GEN Overload d'apres HIS || The plan will be shared ASAP 28/05/2026 : Excalade l3 ce jour 26/05/2026 : Need BO RAN analysis || Cell was down due to power || Mail sent to IHS | S7: IHS | T7: GEN Overload | U7: Power issue | V7: =VLOOKUP(B7,[2]Overall!$A:$D,4,0) -> TELEINFRA CENTRE | W7: =VLOOKUP(B7,[3]Sheet1!$A:$B,2,0) -> Song-Bong | X7: =LEFT('[4]cell downs 21052026 8h34'!B87,3) -> SUD | Y7: =IF(I7 < 1/24, "T<1H", IF(AND(I7<2/24, I7>1/24), "1H<T<2H", IF(AND(I7<4/24, I7>2/24), "2H<T<4H", IF(AND(I7<8/24, I7>4/24), "4H<T<8H", IF(AND(I7<16/24, I7>8/24), "8H<T<16H",IF(AND(I7<24/24, I7>16/24),"16H<T<24H", IF(AND(I7<48/24, I7>24/24),"24H<T<48H",IF(AND(I7<72/24, I7>24/24),"48H<T<72H", "T>72H")))))))) -> T>72H | Z7: =IF(OR(E7="", E7="affected_cells=unknown"), "", LEN(E7)-LEN(SUBSTITUTE(E7, ",", "")) + LEN(E7)-LEN(SUBSTITUTE(E7, ";", "")) + 1) -> 4 | AA7: DOWN | AB7: New case | AC7: 01/06/2026 8h16 | AD7: W23
A8: Songbong_L18L8_CTR_311_MRBTS2 | B8: CTR_311 | E8: faulty_cells=LTE:21,23 | F8: =VLOOKUP(B8,'[2]Power '!$A:$C,3,0) -> TowerCo | G8: =VLOOKUP(B8,'[2]Power '!$A:$D,4,0) -> Solar-Gen | H8: 46167.766 | I8: =NOW()-H8 -> 12.90272 | M8: FSP overheating | N8: 4077 unitName=FSMF path=/SMOD_R-1 serial_no=AS180751192 additionalFaultID=4077 | R8: 01/06/2026 : Relance faite ce jour 29/05/2026 : GEN Overload d'apres HIS || The plan will be shared ASAP 28/05/2026 : Excalade l3 ce jour 26/05/2026 : Need BO RAN analysis || Cell was down due to power || Mail sent to IHS | S8: IHS | T8: GEN Overload | U8: Power issue | V8: =VLOOKUP(B8,[2]Overall!$A:$D,4,0) -> TELEINFRA CENTRE | W8: =VLOOKUP(B8,[3]Sheet1!$A:$B,2,0) -> Song-Bong | X8: =LEFT('[4]cell downs 21052026 8h34'!B85,3) -> SUO | Y8: =IF(I8 < 1/24, "T<1H", IF(AND(I8<2/24, I8>1/24), "1H<T<2H", IF(AND(I8<4/24, I8>2/24), "2H<T<4H", IF(AND(I8<8/24, I8>4/24), "4H<T<8H", IF(AND(I8<16/24, I8>8/24), "8H<T<16H",IF(AND(I8<24/24, I8>16/24),"16H<T<24H", IF(AND(I8<48/24, I8>24/24),"24H<T<48H",IF(AND(I8<72/24, I8>24/24),"48H<T<72H", "T>72H")))))))) -> T>72H | Z8: =IF(OR(E8="", E8="affected_cells=unknown"), "", LEN(E8)-LEN(SUBSTITUTE(E8, ",", "")) + LEN(E8)-LEN(SUBSTITUTE(E8, ";", "")) + 1) -> 2 | AA8: DOWN | AB8: New case | AC8: 01/06/2026 8h16 | AD8: W23
A9: Dogba-IHS_G18L18L8_EXN_171_MRBTS2 | B9: EXN_171 | E9: faulty_cells=GSM:all;LTE:21,22,23 | F9: =VLOOKUP(B9,'[2]Power '!$A:$C,3,0) -> TowerCo | G9: =VLOOKUP(B9,'[2]Power '!$A:$D,4,0) -> Gen Only | H9: 46168.171 | I9: =NOW()-H9 -> 12.497859 | M9: No connection to unit | N9: 10 unitName=FXED path=/SMOD_R-1/rf_ext1/RMOD_R-1 serial_no=1M164643187 additionalFaultID=10 | R9: 01/06/2026 : ETA 14H 31/05/2026: FO faulty || ETD: 01/06/2026 30/05/2026 ; Intervention prevu ce jour||ET 13H 29/05/2026 : Check breaker and interconnection (sfp, optical fiber) between system and radio module, swap its if needed||Intervetion prevue pour demain | S9: TELEINFRA | T9: RCA unknown | U9: RCA unknown | V9: =VLOOKUP(B9,[2]Overall!$A:$D,4,0) -> TELEINFRA NORD | W9: =VLOOKUP(B9,[3]Sheet1!$A:$B,2,0) -> Dogba | X9: =LEFT('[4]cell downs 21052026 8h34'!B85,3) -> SUO | Y9: =IF(I9 < 1/24, "T<1H", IF(AND(I9<2/24, I9>1/24), "1H<T<2H", IF(AND(I9<4/24, I9>2/24), "2H<T<4H", IF(AND(I9<8/24, I9>4/24), "4H<T<8H", IF(AND(I9<16/24, I9>8/24), "8H<T<16H",IF(AND(I9<24/24, I9>16/24),"16H<T<24H", IF(AND(I9<48/24, I9>24/24),"24H<T<48H",IF(AND(I9<72/24, I9>24/24),"48H<T<72H", "T>72H")))))))) -> T>72H | Z9: =IF(OR(E9="", E9="affected_cells=unknown"), "", LEN(E9)-LEN(SUBSTITUTE(E9, ",", "")) + LEN(E9)-LEN(SUBSTITUTE(E9, ";", "")) + 1) -> 4 | AA9: DOWN | AB9: Old case | AC9: 01/06/2026 8h16 | AD9: W23
A10: Dogba-IHS_G18L18L8_EXN_171_MRBTS2 | B10: EXN_171 | E10: faulty_cells=LTE:11,12,13 | F10: =VLOOKUP(B10,'[2]Power '!$A:$C,3,0) -> TowerCo | G10: =VLOOKUP(B10,'[2]Power '!$A:$D,4,0) -> Gen Only | H10: 46168.171 | I10: =NOW()-H10 -> 12.497859 | M10: No connection to unit | N10: 10 unitName=FRMF path=/SMOD_R-1/eif2_rf6/RMOD_R-2 serial_no=F7182927057 additionalFaultID=10 | R10: 01/06/2026 : ETA 14H 31/05/2026: FO faulty || ETD: 01/06/2026 30/05/2026 ; Intervention prevu ce jour||ET 13H 29/05/2026 : Check breaker and interconnection (sfp, optical fiber) between system and radio module, swap its if needed||Intervetion prevue pour demain | S10: TELEINFRA | T10: RCA unknown | U10: RCA unknown | V10: =VLOOKUP(B10,[2]Overall!$A:$D,4,0) -> TELEINFRA NORD | W10: =VLOOKUP(B10,[3]Sheet1!$A:$B,2,0) -> Dogba | X10: =LEFT('[4]cell downs 21052026 8h34'!B85,3) -> SUO | Y10: =IF(I10 < 1/24, "T<1H", IF(AND(I10<2/24, I10>1/24), "1H<T<2H", IF(AND(I10<4/24, I10>2/24), "2H<T<4H", IF(AND(I10<8/24, I10>4/24), "4H<T<8H", IF(AND(I10<16/24, I10>8/24), "8H<T<16H",IF(AND(I10<24/24, I10>16/24),"16H<T<24H", IF(AND(I10<48/24, I10>24/24),"24H<T<48H",IF(AND(I10<72/24, I10>24/24),"48H<T<72H", "T>72H")))))))) -> T>72H | Z10: =IF(OR(E10="", E10="affected_cells=unknown"), "", LEN(E10)-LEN(SUBSTITUTE(E10, ",", "")) + LEN(E10)-LEN(SUBSTITUTE(E10, ";", "")) + 1) -> 3 | AA10: DOWN | AB10: Old case | AC10: 01/06/2026 8h16 | AD10: W23
A11: Zigague_G9U9_EXN_034_MRBTS1 | B11: EXN_034 | E11: faulty_cells=WCDMA:all | F11: =VLOOKUP(B11,'[2]Power '!$A:$C,3,0) -> TowerCo | G11: =VLOOKUP(B11,'[2]Power '!$A:$D,4,0) -> Solar-Grid-Gen | H11: 46168.536 | I11: =NOW()-H11 -> 12.132581 | M11: Antenna link is down | N11: 476 unitName=FBBC path=/SMOD_R-1/bbext1/BBMOD_R-1 serial_no=EA204520538 additionalFaultID=476 | R11: 30/05/2026: Feedback FME: Negociation escorte en cours 29/05/2026 : Negociation escorte en cours 28/05/2026 : Zone rouge || Action avec Level 0 en cour 27/05/2026 : Need BO RAN analysis||Check and replace FBBC if needed | S11: TELEINFRA | T11: RCA unknown | U11: RCA unknown | V11: =VLOOKUP(B11,[2]Overall!$A:$D,4,0) -> TELEINFRA NORD | W11: =VLOOKUP(B11,[3]Sheet1!$A:$B,2,0) -> Zigague | X11: =LEFT('[4]cell downs 21052026 8h34'!B86,3) -> ADM | Y11: =IF(I11 < 1/24, "T<1H", IF(AND(I11<2/24, I11>1/24), "1H<T<2H", IF(AND(I11<4/24, I11>2/24), "2H<T<4H", IF(AND(I11<8/24, I11>4/24), "4H<T<8H", IF(AND(I11<16/24, I11>8/24), "8H<T<16H",IF(AND(I11<24/24, I11>16/24),"16H<T<24H", IF(AND(I11<48/24, I11>24/24),"24H<T<48H",IF(AND(I11<72/24, I11>24/24),"48H<T<72H", "T>72H")))))))) -> T>72H | Z11: =IF(OR(E11="", E11="affected_cells=unknown"), "", LEN(E11)-LEN(SUBSTITUTE(E11, ",", "")) + LEN(E11)-LEN(SUBSTITUTE(E11, ";", "")) + 1) -> 1 | AA11: DOWN | AB11: Old case | AC11: 01/06/2026 8h16 | AD11: W23
A12: Ebonji-IHS_G9U9U21_SUO_101_MRBTS1 | B12: SUO_101 | E12: faulty_cells=WCDMA:all | F12: =VLOOKUP(B12,'[2]Power '!$A:$C,3,0) -> TowerCo | G12: =VLOOKUP(B12,'[2]Power '!$A:$D,4,0) -> Grid-Gen | H12: 46168.908 | I12: =NOW()-H12 -> 11.760359 | M12: FSP subunit lost | N12: 4341 unitName=FBBC path=/SMOD_R-1/bbext1/BBMOD_R-1 serial_no=GA223600523 additionalFaultID=4341 | R12: 31/052026: FBBC recu. Access Issues. || ETA: 02/06/2026. 30/05/2026:Attente du feedback du RM 28/05/2026: FBBC commandee || Expedition demain 29052026 || ETD/ETA 30052026 27/05/2026 : Need BO RAN analysis||Check and replace FBBC if needed||Fme activer || | S12: HAMMER_LT-SW | T12: FBBC faulty | U12: FBBC faulty | V12: =VLOOKUP(B12,[2]Overall!$A:$D,4,0) -> H-TELI | W12: =VLOOKUP(B12,[3]Sheet1!$A:$B,2,0) -> Ebonji | X12: =LEFT('[4]cell downs 21052026 8h34'!B87,3) -> SUD | Y12: =IF(I12 < 1/24, "T<1H", IF(AND(I12<2/24, I12>1/24), "1H<T<2H", IF(AND(I12<4/24, I12>2/24), "2H<T<4H", IF(AND(I12<8/24, I12>4/24), "4H<T<8H", IF(AND(I12<16/24, I12>8/24), "8H<T<16H",IF(AND(I12<24/24, I12>16/24),"16H<T<24H", IF(AND(I12<48/24, I12>24/24),"24H<T<48H",IF(AND(I12<72/24, I12>24/24),"48H<T<72H", "T>72H")))))))) -> T>72H | Z12: =IF(OR(E12="", E12="affected_cells=unknown"), "", LEN(E12)-LEN(SUBSTITUTE(E12, ",", "")) + LEN(E12)-LEN(SUBSTITUTE(E12, ";", "")) + 1) -> 1 | AA12: DOWN | AB12: Old case | AC12: 01/06/2026 8h16 | AD12: W23
A13: Salapoumbe-Ville-MTN-IHS_G9L8_EST_103_MRBTS1 | B13: EST_103 | E13: faulty_cells=GSM:2101,2102 | F13: =VLOOKUP(B13,'[2]Power '!$A:$C,3,0) -> TowerCo | G13: =VLOOKUP(B13,'[2]Power '!$A:$D,4,0) -> Hybrid-Gen | H13: 46169.26 | I13: =NOW()-H13 -> 11.408276 | M13: RF Module filter input power missing | N13: 1910 unitName=FXDB path=/SMOD_R-1/rf_ext1/RMOD_R-1 serial_no=F7162803993 additionalFaultID=1910 | R13: 01/06/2026:FME interviendra sur le site de Yokadouma ce jour|| Intervention prevue pour le 02062026 31/05/2026: Toujour en attente de la Radio FXDB 30/05/2026:Cmd de la FXDB en cour||La radio quitte Bertoua pour Batouri ce jour||ETD: demain 31052026 28/05/2026 : Need BO RAN analysis || Check power cable of FXDB || Escalade faite au RM || En attente de son feedback | S13: AFRO | T13: RCA unknown | U13: RCA unknown | V13: =VLOOKUP(B13,[2]Overall!$A:$D,4,0) -> TELEINFRA CENTRE | W13: =VLOOKUP(B13,[3]Sheet1!$A:$B,2,0) -> SALAPOUMBE | X13: =LEFT(B3,3) -> CTR | Y13: =IF(I13 < 1/24, "T<1H", IF(AND(I13<2/24, I13>1/24), "1H<T<2H", IF(AND(I13<4/24, I13>2/24), "2H<T<4H", IF(AND(I13<8/24, I13>4/24), "4H<T<8H", IF(AND(I13<16/24, I13>8/24), "8H<T<16H",IF(AND(I13<24/24, I13>16/24),"16H<T<24H", IF(AND(I13<48/24, I13>24/24),"24H<T<48H",IF(AND(I13<72/24, I13>24/24),"48H<T<72H", "T>72H")))))))) -> T>72H | Z13: =IF(OR(E13="", E13="affected_cells=unknown"), "", LEN(E13)-LEN(SUBSTITUTE(E13, ",", "")) + LEN(E13)-LEN(SUBSTITUTE(E13, ";", "")) + 1) -> 2 | AA13: DOWN | AB13: Old case | AC13: 01/06/2026 8h16 | AD13: W23
A14: Bafmeng_L18L8_NRO_047_MRBTS2 | B14: NRO_047 | E14: faulty_cells=LTE:11,12,13 | F14: =VLOOKUP(B14,'[2]Power '!$A:$C,3,0) -> TowerCo | G14: =VLOOKUP(B14,'[2]Power '!$A:$D,4,0) -> Hybrid-Gen | H14: 46169.53 | I14: =NOW()-H14 -> 11.138831 | M14: No connection to unit | N14: 10 unitName=FR path=/SMOD_R-1/eif2_rf6/RMOD_R-2 additionalFaultID=10 | R14: 01/06/2026: GHOST TOWN 30/05/2026:New case access clearance negotiation on site ongoing 29//05/2026:New case access clearance negotiation on site ongoing 28/05/'2026; Feeedback PM : New case access clearance negotiation on site ongoing 26/05/2026 : Check breaker and interconnection (sfp, optical fiber) between system and radio module, swap its if needed || FME active | S14: HAMMER_OU-NO | T14: RCA unknown | U14: RCA unknown | V14: =VLOOKUP(B14,[2]Overall!$A:$D,4,0) -> I-ENG | W14: =VLOOKUP(B14,[3]Sheet1!$A:$B,2,0) -> Bafmeng | X14: =LEFT(B4,3) -> CTR | Y14: =IF(I14 < 1/24, "T<1H", IF(AND(I14<2/24, I14>1/24), "1H<T<2H", IF(AND(I14<4/24, I14>2/24), "2H<T<4H", IF(AND(I14<8/24, I14>4/24), "4H<T<8H", IF(AND(I14<16/24, I14>8/24), "8H<T<16H",IF(AND(I14<24/24, I14>16/24),"16H<T<24H", IF(AND(I14<48/24, I14>24/24),"24H<T<48H",IF(AND(I14<72/24, I14>24/24),"48H<T<72H", "T>72H")))))))) -> T>72H | Z14: =IF(OR(E14="", E14="affected_cells=unknown"), "", LEN(E14)-LEN(SUBSTITUTE(E14, ",", "")) + LEN(E14)-LEN(SUBSTITUTE(E14, ";", "")) + 1) -> 3 | AA14: DOWN | AB14: New case | AC14: 01/06/2026 8h16 | AD14: W23
A15: Yokadouma_G18L18L8L26_EST_013_MRBTS2 | B15: EST_013 | E15: faulty_cells=LTE:11,12,13 | F15: =VLOOKUP(B15,'[2]Power '!$A:$C,3,0) -> ESCO | G15: =VLOOKUP(B15,'[2]Power '!$A:$D,4,0) -> Good Grid + Solar + GE | H15: 46170.251 | I15: =NOW()-H15 -> 10.417304 | M15: No connection to unit | N15: 10 unitName=ARMA path=/SMOD_R-1/BBMOD_R-2(Left_Middle)/rf6/RMOD_R-2 serial_no=1M222545494 supplAlarmInfo=RU connection was lost in runtime additionalFaultID=10 | R15: 01/06/2026: FME activer|| ETA: 15h 31/05/2026: Toujour en attente de la Radio ARMA 30/05/2026:La radio quitte Bertoua pour Batouri ce jour||ETD: demain 31052026 29/05/2026:Cmd de la ARMA en cour 28/05/2026: FME should Check and replace ARMA||FME activer pour investigation||ETA: Demain 27/05/2026 : Need BO RAN analysis | S15: AFRO | T15: RCA unknown | U15: RCA unknown | V15: =VLOOKUP(B15,[2]Overall!$A:$D,4,0) -> TELEINFRA CENTRE | W15: =VLOOKUP(B15,[3]Sheet1!$A:$B,2,0) -> Yokadouma | X15: =LEFT(B5,3) -> ADM | Y15: =IF(I15 < 1/24, "T<1H", IF(AND(I15<2/24, I15>1/24), "1H<T<2H", IF(AND(I15<4/24, I15>2/24), "2H<T<4H", IF(AND(I15<8/24, I15>4/24), "4H<T<8H", IF(AND(I15<16/24, I15>8/24), "8H<T<16H",IF(AND(I15<24/24, I15>16/24),"16H<T<24H", IF(AND(I15<48/24, I15>24/24),"24H<T<48H",IF(AND(I15<72/24, I15>24/24),"48H<T<72H", "T>72H")))))))) -> T>72H | Z15: =IF(OR(E15="", E15="affected_cells=unknown"), "", LEN(E15)-LEN(SUBSTITUTE(E15, ",", "")) + LEN(E15)-LEN(SUBSTITUTE(E15, ";", "")) + 1) -> 3 | AA15: DOWN | AB15: Old case | AC15: 01/06/2026 8h16 | AD15: W23
A16: Martap_G9U9U21_ADM_060_MRBTS1 | B16: ADM_060 | E16: faulty_cells=LTE:13 | F16: =VLOOKUP(B16,'[2]Power '!$A:$C,3,0) -> TowerCo | G16: =VLOOKUP(B16,'[2]Power '!$A:$D,4,0) -> Solar-Gen | H16: 46170.731 | I16: =NOW()-H16 -> 9.9374425 | M16: TX out of order | N16: 1907 unitName=FRMF path=/SMOD_R-1/eif2_rf6/RMOD_R-4 serial_no=AS181700926 additionalFaultID=1907 | R16: 01/06/2026 : Besoin transfere a OCM || Feedback OCM : DN attendu pour recuperation de la SPARE 30/05/2026 : FRMF pas disponible dans les Grd-nord || MAil de cde envoye a hw spare 29/05/2026 : Check disponibilite FRMF dans les WH du grand Nord. 28/05/2026: Intervetion prevue ce jour ||ETA: 11h||intervention en cour||Configuaration et remplcament de la SFP module||FRMF faulty 27/05/2026 : Fme actuellment sur le site de Dir pourra intervenir sur le site de Martap apres. 26/05/2026:Feedback RM : Intervention le 27/05/2026 après remplacement FRMF sur Goro ce jour 25/05/2026 : Forte pluie dans la zone. Evidences partagees 22/05/2026 ; Feedback Warehouse ; La spare na pas pu ete transferer faute des agents de l'agence||ETD : demain matin 20/05/2026 : FRMF transfere sur ngaoundere || Expedition pour Ngaoudal || ETD 21052026 18/05/2026 ; La spare quitte Maroua pour NDE aujourd'hui ETD : 20052026 17/05/2026 : Check breaker and interconnection (sfp, optical fiber) between system and radio module, swap its if needed||FME active ||Cmd de la radio FRMF en cour chez le warehouse de NDE. | S16: OCM SPMS | T16: FRMF faulty | U16: FRMF faulty | V16: =VLOOKUP(B16,[2]Overall!$A:$D,4,0) -> TELEINFRA NORD | W16: =VLOOKUP(B16,[3]Sheet1!$A:$B,2,0) -> Martap | X16: =LEFT(B6,3) -> NRO | Y16: =IF(I16 < 1/24, "T<1H", IF(AND(I16<2/24, I16>1/24), "1H<T<2H", IF(AND(I16<4/24, I16>2/24), "2H<T<4H", IF(AND(I16<8/24, I16>4/24), "4H<T<8H", IF(AND(I16<16/24, I16>8/24), "8H<T<16H",IF(AND(I16<24/24, I16>16/24),"16H<T<24H", IF(AND(I16<48/24, I16>24/24),"24H<T<48H",IF(AND(I16<72/24, I16>24/24),"48H<T<72H", "T>72H")))))))) -> T>72H | Z16: =IF(OR(E16="", E16="affected_cells=unknown"), "", LEN(E16)-LEN(SUBSTITUTE(E16, ",", "")) + LEN(E16)-LEN(SUBSTITUTE(E16, ";", "")) + 1) -> 1 | AA16: DOWN | AB16: Old case | AC16: 01/06/2026 8h16 | AD16: W23
A17: Mayo-Nonde-IHS_G9U9U21_NRD_106_MRBTS1 | B17: NRD_106 | E17: faulty_cells=WCDMA:520701,520714,520727 | F17: =VLOOKUP(B17,'[2]Power '!$A:$C,3,0) -> TowerCo | G17: =VLOOKUP(B17,'[2]Power '!$A:$D,4,0) -> Solar-Gen | H17: 46170.776 | I17: =NOW()-H17 -> 9.8923036 | M17: TX out of order | N17: 1907 unitName=FRGU path=/SMOD_R-1/rf_ext3/RMOD_R-2 serial_no=K9181304673 additionalFaultID=1907 | R17: 01/06/2026 : Feedback HW SPMS attendu 30/05/2026 : FRGU pas disponible dans les Grd-nord || MAil de cde envoye a HW spare 29/05/2026 : Check disponibilite FRGU dans les WH du grand Nord 28/05/2026 : Need BO RAN analysis ||close aafter reset | S17: HW SPMS | T17: FRGU faulty | U17: FRGU faulty | V17: =VLOOKUP(B17,[2]Overall!$A:$D,4,0) -> TELEINFRA NORD | W17: =VLOOKUP(B17,[3]Sheet1!$A:$B,2,0) -> Mayo-Nonde | X17: =LEFT(B7,3) -> CTR | Y17: =IF(I17 < 1/24, "T<1H", IF(AND(I17<2/24, I17>1/24), "1H<T<2H", IF(AND(I17<4/24, I17>2/24), "2H<T<4H", IF(AND(I17<8/24, I17>4/24), "4H<T<8H", IF(AND(I17<16/24, I17>8/24), "8H<T<16H",IF(AND(I17<24/24, I17>16/24),"16H<T<24H", IF(AND(I17<48/24, I17>24/24),"24H<T<48H",IF(AND(I17<72/24, I17>24/24),"48H<T<72H", "T>72H")))))))) -> T>72H | Z17: =IF(OR(E17="", E17="affected_cells=unknown"), "", LEN(E17)-LEN(SUBSTITUTE(E17, ",", "")) + LEN(E17)-LEN(SUBSTITUTE(E17, ";", "")) + 1) -> 3 | AA17: DOWN | AB17: Old case | AC17: 01/06/2026 8h16 | AD17: W23
A18: Sabongari-NRO_L18L8_NRO_230_MRBTS2 | B18: NRO_230 | E18: faulty_cells=LTE:13;degraded_cells=LTE:12 | F18: =VLOOKUP(B18,'[2]Power '!$A:$C,3,0) -> TowerCo | G18: =VLOOKUP(B18,'[2]Power '!$A:$D,4,0) -> Hybrid-Gen | H18: 46171.704 | I18: =NOW()-H18 -> 8.9645258 | M18: TX out of order | N18: 1907 unitName=FRMF path=/SMOD_R-1/eif2_rf6/RMOD_R-2 serial_no=AS202001126 additionalFaultID=1907 | P18: UP without action | Q18: 46028 | R18: 31/05/2026 : Need BO RAN analysis | S18: BO RAN | T18: RCA unknown | U18: RCA unknown | V18: =VLOOKUP(B18,[2]Overall!$A:$D,4,0) -> I-ENG | W18: =VLOOKUP(B18,[3]Sheet1!$A:$B,2,0) -> Sabongari | X18: =LEFT(B3,3) -> CTR | Y18: =IF(I18 < 1/24, "T<1H", IF(AND(I18<2/24, I18>1/24), "1H<T<2H", IF(AND(I18<4/24, I18>2/24), "2H<T<4H", IF(AND(I18<8/24, I18>4/24), "4H<T<8H", IF(AND(I18<16/24, I18>8/24), "8H<T<16H",IF(AND(I18<24/24, I18>16/24),"16H<T<24H", IF(AND(I18<48/24, I18>24/24),"24H<T<48H",IF(AND(I18<72/24, I18>24/24),"48H<T<72H", "T>72H")))))))) -> T>72H | Z18: =IF(OR(E18="", E18="affected_cells=unknown"), "", LEN(E18)-LEN(SUBSTITUTE(E18, ",", "")) + LEN(E18)-LEN(SUBSTITUTE(E18, ";", "")) + 1) -> 2 | AA18: UP | AB18: Old case | AC18: 01/06/2026 8h16 | AD18: W23
A19: Batibo_L18L8L26_NRO_010_MRBTS2 | B19: NRO_010 | E19: faulty_cells=LTE:51 | F19: =VLOOKUP(B19,'[2]Power '!$A:$C,3,0) -> TowerCo | G19: =VLOOKUP(B19,'[2]Power '!$A:$D,4,0) -> Grid-Gen | H19: 46172.45 | I19: =NOW()-H19 -> 8.2186925 | M19: BTS configuration error (not enough HW for LCR) | N19: 1868 supplAlarmInfo=Uplane calculation failure due to not enough cabling throughput additionalFaultID=1868 LNCEL-51 | R19: 01/06/2026: GHOST TOWN 30/05/2026; Feedbck PM:Intervention planned by today / Alarm on Fiber to replace 30.05.2026 29/05/2026: Intervention planned by today||Intervention en cour||Remplacemennt de la AZHA ET Power connector OK ce jour, mais a constate que la FO faulty. | S19: HAMMER_OU-NO | T19: FO faulty | U19: FO faulty | V19: =VLOOKUP(B19,[2]Overall!$A:$D,4,0) -> I-ENG | W19: =VLOOKUP(B19,[3]Sheet1!$A:$B,2,0) -> Batibo | X19: =LEFT(B9,3) -> EXN | Y19: =IF(I19 < 1/24, "T<1H", IF(AND(I19<2/24, I19>1/24), "1H<T<2H", IF(AND(I19<4/24, I19>2/24), "2H<T<4H", IF(AND(I19<8/24, I19>4/24), "4H<T<8H", IF(AND(I19<16/24, I19>8/24), "8H<T<16H",IF(AND(I19<24/24, I19>16/24),"16H<T<24H", IF(AND(I19<48/24, I19>24/24),"24H<T<48H",IF(AND(I19<72/24, I19>24/24),"48H<T<72H", "T>72H")))))))) -> T>72H | Z19: =IF(OR(E19="", E19="affected_cells=unknown"), "", LEN(E19)-LEN(SUBSTITUTE(E19, ",", "")) + LEN(E19)-LEN(SUBSTITUTE(E19, ";", "")) + 1) -> 1 | AA19: DOWN | AB19: Old case | AC19: 01/06/2026 8h16 | AD19: W23
A20: Mazera_G18L18L8_EXN_226_MRBTS2 | B20: EXN_226 | E20: faulty_cells=GSM:all | F20: =VLOOKUP(B20,'[2]Power '!$A:$C,3,0) -> TowerCo | G20: =VLOOKUP(B20,'[2]Power '!$A:$D,4,0) -> Hybrid-Gen | H20: 46172.534 | I20: =NOW()-H20 -> 8.1346647 | M20: OMU signaling connection failure in Abis interface | N20: 2412 unitName=FSMF additionalFaultID=2412 MRBTS-30182 | R20: 31/05/2026 : Acess issue 30/05/2026 : Need BO RAN analysis ||Check and replace FXBD | S20: TELEINFRA | T20: RCA unknown | U20: RCA unknown | V20: =VLOOKUP(B20,[2]Overall!$A:$D,4,0) -> TELEINFRA NORD | W20: =VLOOKUP(B20,[3]Sheet1!$A:$B,2,0) -> Mazera | X20: =LEFT(B10,3) -> EXN | Y20: =IF(I20 < 1/24, "T<1H", IF(AND(I20<2/24, I20>1/24), "1H<T<2H", IF(AND(I20<4/24, I20>2/24), "2H<T<4H", IF(AND(I20<8/24, I20>4/24), "4H<T<8H", IF(AND(I20<16/24, I20>8/24), "8H<T<16H",IF(AND(I20<24/24, I20>16/24),"16H<T<24H", IF(AND(I20<48/24, I20>24/24),"24H<T<48H",IF(AND(I20<72/24, I20>24/24),"48H<T<72H", "T>72H")))))))) -> T>72H | Z20: =IF(OR(E20="", E20="affected_cells=unknown"), "", LEN(E20)-LEN(SUBSTITUTE(E20, ",", "")) + LEN(E20)-LEN(SUBSTITUTE(E20, ";", "")) + 1) -> 1 | AA20: DOWN | AB20: Old case | AC20: 01/06/2026 8h16 | AD20: W23
A21: Mbidou-IHS_G9U9U21_ADM_079_MRBTS1 | B21: ADM_079 | E21: faulty_cells=GSM:all;WCDMA:4633901,4634002 | F21: =VLOOKUP(B21,'[2]Power '!$A:$C,3,0) -> TowerCo | G21: =VLOOKUP(B21,'[2]Power '!$A:$D,4,0) -> Grid-Gen | H21: 46172.581 | I21: =NOW()-H21 -> 8.0881369 | M21: No connection to unit | N21: 10 unitName=FXDB path=/SMOD_R-1/rf_ext2/RMOD_R-1 serial_no=F7170246168 additionalFaultID=10 | R21: 31/05/2026 : Escalade faite au RM || En attente de son feedback 30/05/26:Intervention prevue pour demain 31/05/26||le Fme sur le site de Lewa puis sur likok 29/05/2026 : Check breaker and interconnection (sfp, optical fiber) between system and radio module, swap its if needed | S21: TELEINFRA | T21: RCA unknown | U21: RCA unknown | V21: =VLOOKUP(B21,[2]Overall!$A:$D,4,0) -> TELEINFRA NORD | W21: =VLOOKUP(B21,[3]Sheet1!$A:$B,2,0) -> Mbidou | X21: =LEFT(B11,3) -> EXN | Y21: =IF(I21 < 1/24, "T<1H", IF(AND(I21<2/24, I21>1/24), "1H<T<2H", IF(AND(I21<4/24, I21>2/24), "2H<T<4H", IF(AND(I21<8/24, I21>4/24), "4H<T<8H", IF(AND(I21<16/24, I21>8/24), "8H<T<16H",IF(AND(I21<24/24, I21>16/24),"16H<T<24H", IF(AND(I21<48/24, I21>24/24),"24H<T<48H",IF(AND(I21<72/24, I21>24/24),"48H<T<72H", "T>72H")))))))) -> T>72H | Z21: =IF(OR(E21="", E21="affected_cells=unknown"), "", LEN(E21)-LEN(SUBSTITUTE(E21, ",", "")) + LEN(E21)-LEN(SUBSTITUTE(E21, ";", "")) + 1) -> 3 | AA21: DOWN | AB21: Old case | AC21: 01/06/2026 8h16 | AD21: W23
A22: Mbidou-IHS_G9U9U21_ADM_079_MRBTS1 | B22: ADM_079 | E22: faulty_cells=GSM:all;WCDMA:4633901,4634002 | F22: =VLOOKUP(B22,'[2]Power '!$A:$C,3,0) -> TowerCo | G22: =VLOOKUP(B22,'[2]Power '!$A:$D,4,0) -> Grid-Gen | H22: 46172.588 | I22: =NOW()-H22 -> 8.080498 | M22: Optical Interface faulty | N22: 2000 unitName=LANE path=/SMOD_R-1/rf_ext2/SFP_R-2/LANE_R-1 additionalFaultID=2000 | R22: 31/05/2026 : Escalade faite au RM || En attente de son feedback 30/05/26:Intervention prevue pour demain 31/05/26||le Fme sur le site de Lewa puis sur likok 29/05/2026 : Check breaker and interconnection (sfp, optical fiber) between system and radio module, swap its if needed | S22: TELEINFRA | T22: RCA unknown | U22: RCA unknown | V22: =VLOOKUP(B22,[2]Overall!$A:$D,4,0) -> TELEINFRA NORD | W22: =VLOOKUP(B22,[3]Sheet1!$A:$B,2,0) -> Mbidou | X22: =LEFT(B12,3) -> SUO | Y22: =IF(I22 < 1/24, "T<1H", IF(AND(I22<2/24, I22>1/24), "1H<T<2H", IF(AND(I22<4/24, I22>2/24), "2H<T<4H", IF(AND(I22<8/24, I22>4/24), "4H<T<8H", IF(AND(I22<16/24, I22>8/24), "8H<T<16H",IF(AND(I22<24/24, I22>16/24),"16H<T<24H", IF(AND(I22<48/24, I22>24/24),"24H<T<48H",IF(AND(I22<72/24, I22>24/24),"48H<T<72H", "T>72H")))))))) -> T>72H | Z22: =IF(OR(E22="", E22="affected_cells=unknown"), "", LEN(E22)-LEN(SUBSTITUTE(E22, ",", "")) + LEN(E22)-LEN(SUBSTITUTE(E22, ";", "")) + 1) -> 3 | AA22: DOWN | AB22: Old case | AC22: 01/06/2026 8h16 | AD22: W23
A23: Badjonre-IHS_G9G18U9U21L18L8_EXN_152_MRBTS1 | B23: EXN_152 | E23: faulty_cells=LTE:23 | F23: =VLOOKUP(B23,'[2]Power '!$A:$C,3,0) -> TowerCo | G23: =VLOOKUP(B23,'[2]Power '!$A:$D,4,0) -> Solar-Gen | H23: 46172.679 | I23: =NOW()-H23 -> 7.9895258 | M23: BTS configuration error (not enough HW for LCR) | N23: 1868 supplAlarmInfo=Uplane calculation failure due to not enough cabling throughput additionalFaultID=1868 LNCEL-23 | R23: 01/062026: Reception de la SPARE ce jour || ETD:14h||intervention prevue pour ce jour|| ETA:16h 31/05/2026: Toujour en attente de la FCOP|| ETD: Demain 28/05/2026: Cmd de la FCOP || ETD 30052026 . ETA 31052026 27/05/2026: Investigation en cour ||FCOP faulty 26/05/2026: FME activé, ETA 12H || UP apres reset physique 25/05/2026 : Closed afted reset || check statut of carte ABIA 24/05/2026 : Need BO RAN analysis | S23: TELEINFRA | T23: FCOP faulty | U23: FCOP faulty | V23: =VLOOKUP(B23,[2]Overall!$A:$D,4,0) -> TELEINFRA NORD | W23: =VLOOKUP(B23,[3]Sheet1!$A:$B,2,0) -> Badjonre | X23: =LEFT(B13,3) -> EST | Y23: =IF(I23 < 1/24, "T<1H", IF(AND(I23<2/24, I23>1/24), "1H<T<2H", IF(AND(I23<4/24, I23>2/24), "2H<T<4H", IF(AND(I23<8/24, I23>4/24), "4H<T<8H", IF(AND(I23<16/24, I23>8/24), "8H<T<16H",IF(AND(I23<24/24, I23>16/24),"16H<T<24H", IF(AND(I23<48/24, I23>24/24),"24H<T<48H",IF(AND(I23<72/24, I23>24/24),"48H<T<72H", "T>72H")))))))) -> T>72H | Z23: =IF(OR(E23="", E23="affected_cells=unknown"), "", LEN(E23)-LEN(SUBSTITUTE(E23, ",", "")) + LEN(E23)-LEN(SUBSTITUTE(E23, ";", "")) + 1) -> 1 | AA23: DOWN | AB23: Old case | AC23: 01/06/2026 8h16 | AD23: W23
A24: Hamalade-IHS_G9G18U9U21L18L8_NRD_111_MRBTS1 | B24: NRD_111 | E24: faulty_cells=GSM:871,872,873 | F24: =VLOOKUP(B24,'[2]Power '!$A:$C,3,0) -> TowerCo | G24: =VLOOKUP(B24,'[2]Power '!$A:$D,4,0) -> Solar-Gen | H24: 46172.719 | I24: =NOW()-H24 -> 7.949248 | M24: No connection to unit | N24: 10 unitName=FR path=/SMOD_R-1/BBMOD_R-3(Left_Bottom)/rf1/RMOD_R-2 supplAlarmInfo=RU not detected after BTS startup additionalFaultID=10 | R24: 01/06/2026 : Recherche du fond de chassis en cours dans les WH du l'ANEN 30/05/2026 ;Fme deja en route ||ETA 12H || Le FME a remplace plusieurs cartes, mais sans chanegement || Il faut replacet le fond de chassis 29/05/2026 : Intervention repoussee pour cause de pluie || ETA 30052026 28/05/2026: Intervention prevue pour demain 29052026 27/05/2026 : FME etait sur site hier il a effectuer le remplacement de la ABIA. A cause du maonque de supervision le BO n'a pas pu mener les actions. Lepoin est actuellemt suivi par le BO RAN 26/05/2026:En attente du feedbck RM ||Feedback RM : FME en route, ETA 12H || fme sur site || Intervention en cours || remplacement de la ABIAeffectuer ce jour.Site reste en observetion 25/05/2026: Intervention prevu pour ce jour ||ETA : 16h|| Forte pluie dans la zone evidence envoyer dans le groupe.||Intervention reporte pour demain 23/05/2026 : Check breaker and interconnection (sfp, optical fiber) between system and radio module, swap its if needed | S24: TELEINFRA | T24: RCA unknown | U24: RCA unknown | V24: =VLOOKUP(B24,[2]Overall!$A:$D,4,0) -> TELEINFRA NORD | W24: =VLOOKUP(B24,[3]Sheet1!$A:$B,2,0) -> Hamalade | X24: =LEFT(B14,3) -> NRO | Y24: =IF(I24 < 1/24, "T<1H", IF(AND(I24<2/24, I24>1/24), "1H<T<2H", IF(AND(I24<4/24, I24>2/24), "2H<T<4H", IF(AND(I24<8/24, I24>4/24), "4H<T<8H", IF(AND(I24<16/24, I24>8/24), "8H<T<16H",IF(AND(I24<24/24, I24>16/24),"16H<T<24H", IF(AND(I24<48/24, I24>24/24),"24H<T<48H",IF(AND(I24<72/24, I24>24/24),"48H<T<72H", "T>72H")))))))) -> T>72H | Z24: =IF(OR(E24="", E24="affected_cells=unknown"), "", LEN(E24)-LEN(SUBSTITUTE(E24, ",", "")) + LEN(E24)-LEN(SUBSTITUTE(E24, ";", "")) + 1) -> 3 | AA24: DOWN | AB24: Old case | AC24: 01/06/2026 8h16 | AD24: W23
A25: Hamalade-IHS_G9G18U9U21L18L8_NRD_111_MRBTS1 | B25: NRD_111 | E25: faulty_cells=LTE:11,12,13 | F25: =VLOOKUP(B25,'[2]Power '!$A:$C,3,0) -> TowerCo | G25: =VLOOKUP(B25,'[2]Power '!$A:$D,4,0) -> Solar-Gen | H25: 46172.719 | I25: =NOW()-H25 -> 7.949248 | M25: No connection to unit | N25: 10 unitName=FR path=/SMOD_R-1/BBMOD_R-2(Left_Middle)/rf6/RMOD_R-4 supplAlarmInfo=RU not detected after BTS startup additionalFaultID=10 | R25: 01/06/2026 : Recherche du fond de chassis en cours dans les WH du l'ANEN 30/05/2026 ;Fme deja en route ||ETA 12H || Le FME a remplace plusieurs cartes, mais sans chanegement || Il faut replacet le fond de chassis 29/05/2026 : Intervention repoussee pour cause de pluie || ETA 30052026 28/05/2026: Intervention prevue pour demain 29052026 27/05/2026 : FME etait sur site hier il a effectuer le remplacement de la ABIA. A cause du maonque de supervision le BO n'a pas pu mener les actions. Lepoin est actuellemt suivi par le BO RAN 26/05/2026:En attente du feedbck RM ||Feedback RM : FME en route, ETA 12H || fme sur site || Intervention en cours || remplacement de la ABIAeffectuer ce jour.Site reste en observetion 25/05/2026: Intervention prevu pour ce jour ||ETA : 16h|| Forte pluie dans la zone evidence envoyer dans le groupe.||Intervention reporte pour demain 23/05/2026 : Check breaker and interconnection (sfp, optical fiber) between system and radio module, swap its if needed | S25: TELEINFRA | T25: RCA unknown | U25: RCA unknown | V25: =VLOOKUP(B25,[2]Overall!$A:$D,4,0) -> TELEINFRA NORD | W25: =VLOOKUP(B25,[3]Sheet1!$A:$B,2,0) -> Hamalade | X25: =LEFT(B15,3) -> EST | Y25: =IF(I25 < 1/24, "T<1H", IF(AND(I25<2/24, I25>1/24), "1H<T<2H", IF(AND(I25<4/24, I25>2/24), "2H<T<4H", IF(AND(I25<8/24, I25>4/24), "4H<T<8H", IF(AND(I25<16/24, I25>8/24), "8H<T<16H",IF(AND(I25<24/24, I25>16/24),"16H<T<24H", IF(AND(I25<48/24, I25>24/24),"24H<T<48H",IF(AND(I25<72/24, I25>24/24),"48H<T<72H", "T>72H")))))))) -> T>72H | Z25: =IF(OR(E25="", E25="affected_cells=unknown"), "", LEN(E25)-LEN(SUBSTITUTE(E25, ",", "")) + LEN(E25)-LEN(SUBSTITUTE(E25, ";", "")) + 1) -> 3 | AA25: DOWN | AB25: Old case | AC25: 01/06/2026 8h16 | AD25: W23
A26: Hamalade-IHS_G9G18U9U21L18L8_NRD_111_MRBTS1 | B26: NRD_111 | E26: faulty_cells=GSM:872 | F26: =VLOOKUP(B26,'[2]Power '!$A:$C,3,0) -> TowerCo | G26: =VLOOKUP(B26,'[2]Power '!$A:$D,4,0) -> Solar-Gen | H26: 46172.724 | I26: =NOW()-H26 -> 7.9443869 | M26: TRX initialization failure | N26: 2400 supplAlarmInfo=Not enough DSP resources available to allocate the TRX additionalFaultID=2400 | R26: 01/06/2026 : Recherche du fond de chassis en cours dans les WH du l'ANEN 30/05/2026 ;Fme deja en route ||ETA 12H || Le FME a remplace plusieurs cartes, mais sans chanegement || Il faut replacet le fond de chassis 29/05/2026 : Intervention repoussee pour cause de pluie || ETA 30052026 28/05/2026: Intervention prevue pour demain 29052026 27/05/2026 : FME etait sur site hier il a effectuer le remplacement de la ABIA. A cause du maonque de supervision le BO n'a pas pu mener les actions. Lepoin est actuellemt suivi par le BO RAN 26/05/2026:En attente du feedbck RM ||Feedback RM : FME en route, ETA 12H || fme sur site || Intervention en cours || remplacement de la ABIAeffectuer ce jour.Site reste en observetion 25/05/2026: Intervention prevu pour ce jour ||ETA : 16h|| Forte pluie dans la zone evidence envoyer dans le groupe.||Intervention reporte pour demain 23/05/2026 : Check breaker and interconnection (sfp, optical fiber) between system and radio module, swap its if needed | S26: TELEINFRA | T26: RCA unknown | U26: RCA unknown | V26: =VLOOKUP(B26,[2]Overall!$A:$D,4,0) -> TELEINFRA NORD | W26: =VLOOKUP(B26,[3]Sheet1!$A:$B,2,0) -> Hamalade | X26: =LEFT(B16,3) -> ADM | Y26: =IF(I26 < 1/24, "T<1H", IF(AND(I26<2/24, I26>1/24), "1H<T<2H", IF(AND(I26<4/24, I26>2/24), "2H<T<4H", IF(AND(I26<8/24, I26>4/24), "4H<T<8H", IF(AND(I26<16/24, I26>8/24), "8H<T<16H",IF(AND(I26<24/24, I26>16/24),"16H<T<24H", IF(AND(I26<48/24, I26>24/24),"24H<T<48H",IF(AND(I26<72/24, I26>24/24),"48H<T<72H", "T>72H")))))))) -> T>72H | Z26: =IF(OR(E26="", E26="affected_cells=unknown"), "", LEN(E26)-LEN(SUBSTITUTE(E26, ",", "")) + LEN(E26)-LEN(SUBSTITUTE(E26, ";", "")) + 1) -> 1 | AA26: DOWN | AB26: Old case | AC26: 01/06/2026 8h16 | AD26: W23
A27: Hamalade-IHS_G9G18U9U21L18L8_NRD_111_MRBTS1 | B27: NRD_111 | E27: faulty_cells=GSM:871 | F27: =VLOOKUP(B27,'[2]Power '!$A:$C,3,0) -> TowerCo | G27: =VLOOKUP(B27,'[2]Power '!$A:$D,4,0) -> Solar-Gen | H27: 46172.724 | I27: =NOW()-H27 -> 7.9443869 | M27: TRX initialization failure | N27: 2400 supplAlarmInfo=Not enough DSP resources available to allocate the TRX additionalFaultID=2400 | R27: 01/06/2026 : Recherche du fond de chassis en cours dans les WH du l'ANEN 30/05/2026 ;Fme deja en route ||ETA 12H || Le FME a remplace plusieurs cartes, mais sans chanegement || Il faut replacet le fond de chassis 29/05/2026 : Intervention repoussee pour cause de pluie || ETA 30052026 28/05/2026: Intervention prevue pour demain 29052026 27/05/2026 : FME etait sur site hier il a effectuer le remplacement de la ABIA. A cause du maonque de supervision le BO n'a pas pu mener les actions. Lepoin est actuellemt suivi par le BO RAN 26/05/2026:En attente du feedbck RM ||Feedback RM : FME en route, ETA 12H || fme sur site || Intervention en cours || remplacement de la ABIAeffectuer ce jour.Site reste en observetion 25/05/2026: Intervention prevu pour ce jour ||ETA : 16h|| Forte pluie dans la zone evidence envoyer dans le groupe.||Intervention reporte pour demain 23/05/2026 : Check breaker and interconnection (sfp, optical fiber) between system and radio module, swap its if needed | S27: TELEINFRA | T27: RCA unknown | U27: RCA unknown | V27: =VLOOKUP(B27,[2]Overall!$A:$D,4,0) -> TELEINFRA NORD | W27: =VLOOKUP(B27,[3]Sheet1!$A:$B,2,0) -> Hamalade | X27: =LEFT(B17,3) -> NRD | Y27: =IF(I27 < 1/24, "T<1H", IF(AND(I27<2/24, I27>1/24), "1H<T<2H", IF(AND(I27<4/24, I27>2/24), "2H<T<4H", IF(AND(I27<8/24, I27>4/24), "4H<T<8H", IF(AND(I27<16/24, I27>8/24), "8H<T<16H",IF(AND(I27<24/24, I27>16/24),"16H<T<24H", IF(AND(I27<48/24, I27>24/24),"24H<T<48H",IF(AND(I27<72/24, I27>24/24),"48H<T<72H", "T>72H")))))))) -> T>72H | Z27: =IF(OR(E27="", E27="affected_cells=unknown"), "", LEN(E27)-LEN(SUBSTITUTE(E27, ",", "")) + LEN(E27)-LEN(SUBSTITUTE(E27, ";", "")) + 1) -> 1 | AA27: DOWN | AB27: Old case | AC27: 01/06/2026 8h16 | AD27: W23
A28: Hamalade-IHS_G9G18U9U21L18L8_NRD_111_MRBTS1 | B28: NRD_111 | E28: faulty_cells=GSM:873 | F28: =VLOOKUP(B28,'[2]Power '!$A:$C,3,0) -> TowerCo | G28: =VLOOKUP(B28,'[2]Power '!$A:$D,4,0) -> Solar-Gen | H28: 46172.724 | I28: =NOW()-H28 -> 7.9443869 | M28: TRX initialization failure | N28: 2400 supplAlarmInfo=Not enough DSP resources available to allocate the TRX additionalFaultID=2400 | R28: 01/06/2026 : Recherche du fond de chassis en cours dans les WH du l'ANEN 30/05/2026 ;Fme deja en route ||ETA 12H || Le FME a remplace plusieurs cartes, mais sans chanegement || Il faut replacet le fond de chassis 29/05/2026 : Intervention repoussee pour cause de pluie || ETA 30052026 28/05/2026: Intervention prevue pour demain 29052026 27/05/2026 : FME etait sur site hier il a effectuer le remplacement de la ABIA. A cause du maonque de supervision le BO n'a pas pu mener les actions. Lepoin est actuellemt suivi par le BO RAN 26/05/2026:En attente du feedbck RM ||Feedback RM : FME en route, ETA 12H || fme sur site || Intervention en cours || remplacement de la ABIAeffectuer ce jour.Site reste en observetion 25/05/2026: Intervention prevu pour ce jour ||ETA : 16h|| Forte pluie dans la zone evidence envoyer dans le groupe.||Intervention reporte pour demain 23/05/2026 : Check breaker and interconnection (sfp, optical fiber) between system and radio module, swap its if needed | S28: TELEINFRA | T28: RCA unknown | U28: RCA unknown | V28: =VLOOKUP(B28,[2]Overall!$A:$D,4,0) -> TELEINFRA NORD | W28: =VLOOKUP(B28,[3]Sheet1!$A:$B,2,0) -> Hamalade | X28: =LEFT(B18,3) -> NRO | Y28: =IF(I28 < 1/24, "T<1H", IF(AND(I28<2/24, I28>1/24), "1H<T<2H", IF(AND(I28<4/24, I28>2/24), "2H<T<4H", IF(AND(I28<8/24, I28>4/24), "4H<T<8H", IF(AND(I28<16/24, I28>8/24), "8H<T<16H",IF(AND(I28<24/24, I28>16/24),"16H<T<24H", IF(AND(I28<48/24, I28>24/24),"24H<T<48H",IF(AND(I28<72/24, I28>24/24),"48H<T<72H", "T>72H")))))))) -> T>72H | Z28: =IF(OR(E28="", E28="affected_cells=unknown"), "", LEN(E28)-LEN(SUBSTITUTE(E28, ",", "")) + LEN(E28)-LEN(SUBSTITUTE(E28, ";", "")) + 1) -> 1 | AA28: DOWN | AB28: Old case | AC28: 01/06/2026 8h16 | AD28: W23
A29: Mbakong-MTN_G9U9U21_NRO_255_MRBTS1 | B29: NRO_255 | E29: faulty_cells=WCDMA:504127;degraded_cells=WCDMA:504114 | F29: =VLOOKUP(B29,'[2]Power '!$A:$C,3,0) -> TowerCo | G29: =VLOOKUP(B29,'[2]Power '!$A:$D,4,0) -> Hybrid-Gen | H29: 46172.767 | I29: =NOW()-H29 -> 7.9013314 | M29: VSWR major alarm | N29: 1837 unitName=AntennaLine path=/SMOD_R-1/rf_ext3/RMOD_R-3/ant2 additionalFaultID=1837 | R29: 01/06/2026: GHOST TOWN 31/05/2026:New case access clearance negotiation on site ongoing 30/05/2026:New case access clearance negotiation on site ongoing 29/05/2026 : Acces issue 28/05/2026: Intervention prevue pour demain 29052026 27/05/2026 : FME etait sur site hier il a effectuer le remplacement de la ABIA. A cause du maonque de supervision le BO n'a pas pu mener les actions. Lepoin est actuellemt suivi par le BO RAN 26/05/2026:En attente du feedbck RM ||Feedback RM : FME en route, ETA 12H || fme sur site || Intervention en cours || remplacement de la ABIAeffectuer ce jour.Site reste en observetion 25/05/2026: Intervention prevu pour ce jour ||ETA : 16h|| Forte pluie dans la zone evidence envoyer dans le groupe.||Intervention reporte pour demain 23/05/2026 : Check breaker and interconnection (sfp, optical fiber) between system and radio module, swap its if needed | S29: HAMMER_OU-NO | T29: RCA unknown | U29: RCA unknown | V29: =VLOOKUP(B29,[2]Overall!$A:$D,4,0) -> I-ENG | W29: =VLOOKUP(B29,[3]Sheet1!$A:$B,2,0) -> Mbakong | X29: =LEFT(B19,3) -> NRO | Y29: =IF(I29 < 1/24, "T<1H", IF(AND(I29<2/24, I29>1/24), "1H<T<2H", IF(AND(I29<4/24, I29>2/24), "2H<T<4H", IF(AND(I29<8/24, I29>4/24), "4H<T<8H", IF(AND(I29<16/24, I29>8/24), "8H<T<16H",IF(AND(I29<24/24, I29>16/24),"16H<T<24H", IF(AND(I29<48/24, I29>24/24),"24H<T<48H",IF(AND(I29<72/24, I29>24/24),"48H<T<72H", "T>72H")))))))) -> T>72H | Z29: =IF(OR(E29="", E29="affected_cells=unknown"), "", LEN(E29)-LEN(SUBSTITUTE(E29, ",", "")) + LEN(E29)-LEN(SUBSTITUTE(E29, ";", "")) + 1) -> 2 | AA29: DOWN | AB29: Old case | AC29: 01/06/2026 8h16 | AD29: W23
A30: Widikum_L18L8_NRO_219_MRBTS | B30: NRO_219 | E30: faulty_cells=LTE:23,22 | F30: =VLOOKUP(B30,'[2]Power '!$A:$C,3,0) -> TowerCo | G30: =VLOOKUP(B30,'[2]Power '!$A:$D,4,0) -> Vandalized | H30: 46173.003 | I30: =NOW()-H30 -> 7.6652203 | M30: TX out of order | N30: 1907 unitName=FXED path=/SMOD_R-1/rf_ext1/RMOD_R-1 serial_no=F7170309627 additionalFaultID=1907 | R30: 30/05/2026 : Need BO RAN analysis | S30: BO RAN | T30: RCA unknown | U30: RCA unknown | V30: =VLOOKUP(B30,[2]Overall!$A:$D,4,0) -> I-ENG | W30: =VLOOKUP(B30,[3]Sheet1!$A:$B,2,0) -> Widikum | X30: =LEFT(B15,3) -> EST | Y30: =IF(I30 < 1/24, "T<1H", IF(AND(I30<2/24, I30>1/24), "1H<T<2H", IF(AND(I30<4/24, I30>2/24), "2H<T<4H", IF(AND(I30<8/24, I30>4/24), "4H<T<8H", IF(AND(I30<16/24, I30>8/24), "8H<T<16H",IF(AND(I30<24/24, I30>16/24),"16H<T<24H", IF(AND(I30<48/24, I30>24/24),"24H<T<48H",IF(AND(I30<72/24, I30>24/24),"48H<T<72H", "T>72H")))))))) -> T>72H | Z30: =IF(OR(E30="", E30="affected_cells=unknown"), "", LEN(E30)-LEN(SUBSTITUTE(E30, ",", "")) + LEN(E30)-LEN(SUBSTITUTE(E30, ";", "")) + 1) -> 2 | AA30: DOWN | AB30: Old case | AC30: 01/06/2026 8h16 | AD30: W23
A31: Gaba_G9U9U21_NRD_155_MRBTS1 | B31: NRD_155 | E31: faulty_cells=WCDMA:4642303 | F31: =VLOOKUP(B31,'[2]Power '!$A:$C,3,0) -> ESCO | G31: =VLOOKUP(B31,'[2]Power '!$A:$D,4,0) -> Hybrid Solar - S3 | H31: 46173.006 | I31: =NOW()-H31 -> 7.6631369 | M31: Unit RNW configuration failure | N31: 110 unitName=FXDB path=/SMOD_R-1/rf_ext2/RMOD_R-2 serial_no=1M171227601 additionalFaultID=110 | P31: UP without action | Q31: 46028 | R31: 01/06/2026 : Need BO RAN analysis | S31: BO RAN | T31: RCA unknown | U31: RCA unknown | V31: =VLOOKUP(B31,[2]Overall!$A:$D,4,0) -> TELEINFRA NORD | W31: =VLOOKUP(B31,[3]Sheet1!$A:$B,2,0) -> Gaba | X31: =LEFT(B16,3) -> ADM | Y31: =IF(I31 < 1/24, "T<1H", IF(AND(I31<2/24, I31>1/24), "1H<T<2H", IF(AND(I31<4/24, I31>2/24), "2H<T<4H", IF(AND(I31<8/24, I31>4/24), "4H<T<8H", IF(AND(I31<16/24, I31>8/24), "8H<T<16H",IF(AND(I31<24/24, I31>16/24),"16H<T<24H", IF(AND(I31<48/24, I31>24/24),"24H<T<48H",IF(AND(I31<72/24, I31>24/24),"48H<T<72H", "T>72H")))))))) -> T>72H | Z31: =IF(OR(E31="", E31="affected_cells=unknown"), "", LEN(E31)-LEN(SUBSTITUTE(E31, ",", "")) + LEN(E31)-LEN(SUBSTITUTE(E31, ";", "")) + 1) -> 1 | AA31: UP | AB31: New case | AC31: 01/06/2026 8h16 | AD31: W23
A32: Telo-MTN-IHS_G9U21_ADM_108_MRBTS1 | B32: ADM_108 | E32: faulty_cells=GSM:all | F32: =VLOOKUP(B32,'[2]Power '!$A:$C,3,0) -> TowerCo | G32: =VLOOKUP(B32,'[2]Power '!$A:$D,4,0) -> Grid-Hybrid-Gen | H32: 46173.336 | I32: =NOW()-H32 -> 7.3325814 | M32: No connection to unit | N32: 10 unitName=FXDB path=/SMOD_R-1/rf_ext2/RMOD_R-1 serial_no=1M172903408 additionalFaultID=10 | R32: 30/05/2026 : Need BO RAN analysis || | S32: BO RAN | T32: RCA unknown | U32: RCA unknown | V32: =VLOOKUP(B32,[2]Overall!$A:$D,4,0) -> TELEINFRA NORD | W32: =VLOOKUP(B32,[3]Sheet1!$A:$B,2,0) -> Telo | X32: =LEFT(B17,3) -> NRD | Y32: =IF(I32 < 1/24, "T<1H", IF(AND(I32<2/24, I32>1/24), "1H<T<2H", IF(AND(I32<4/24, I32>2/24), "2H<T<4H", IF(AND(I32<8/24, I32>4/24), "4H<T<8H", IF(AND(I32<16/24, I32>8/24), "8H<T<16H",IF(AND(I32<24/24, I32>16/24),"16H<T<24H", IF(AND(I32<48/24, I32>24/24),"24H<T<48H",IF(AND(I32<72/24, I32>24/24),"48H<T<72H", "T>72H")))))))) -> T>72H | Z32: =IF(OR(E32="", E32="affected_cells=unknown"), "", LEN(E32)-LEN(SUBSTITUTE(E32, ",", "")) + LEN(E32)-LEN(SUBSTITUTE(E32, ";", "")) + 1) -> 1 | AA32: DOWN | AB32: Old case | AC32: 01/06/2026 8h16 | AD32: W23
A33: Babessi_L18L8_NRO_024_MRBTS2 | B33: NRO_024 | E33: faulty_cells=LTE:11,12,13 | F33: =VLOOKUP(B33,'[2]Power '!$A:$C,3,0) -> TowerCo | G33: =VLOOKUP(B33,'[2]Power '!$A:$D,4,0) -> Grid-Gen | H33: 46173.667 | I33: =NOW()-H33 -> 7.0013314 | M33: No connection to unit | N33: 10 unitName=FRMF path=/SMOD_R-1/eif2_rf6/RMOD_R-3 serial_no=AS201908645 additionalFaultID=10 | R33: 01/06/2026 : Check breaker and interconnection (sfp, optical fiber) between system and radio module, swap its if needed||GHOST TOWN | S33: HAMMER_OU-NO | T33: RCA unknown | U33: RCA unknown | V33: =VLOOKUP(B33,[2]Overall!$A:$D,4,0) -> I-ENG | W33: =VLOOKUP(B33,[3]Sheet1!$A:$B,2,0) -> Babessi | X33: =LEFT(B23,3) -> EXN | Y33: =IF(I33 < 1/24, "T<1H", IF(AND(I33<2/24, I33>1/24), "1H<T<2H", IF(AND(I33<4/24, I33>2/24), "2H<T<4H", IF(AND(I33<8/24, I33>4/24), "4H<T<8H", IF(AND(I33<16/24, I33>8/24), "8H<T<16H",IF(AND(I33<24/24, I33>16/24),"16H<T<24H", IF(AND(I33<48/24, I33>24/24),"24H<T<48H",IF(AND(I33<72/24, I33>24/24),"48H<T<72H", "T>72H")))))))) -> T>72H | Z33: =IF(OR(E33="", E33="affected_cells=unknown"), "", LEN(E33)-LEN(SUBSTITUTE(E33, ",", "")) + LEN(E33)-LEN(SUBSTITUTE(E33, ";", "")) + 1) -> 3 | AA33: DOWN | AB33: New case | AC33: 01/06/2026 8h16 | AD33: W23
A34: Makor_G9U21_ADM_015_MRBTS1 | B34: ADM_015 | E34: faulty_cells=GSM:1042 | F34: =VLOOKUP(B34,'[2]Power '!$A:$C,3,0) -> #N/A | G34: =VLOOKUP(B34,'[2]Power '!$A:$D,4,0) -> #N/A | H34: 46173.718 | I34: =NOW()-H34 -> 6.9506369 | M34: BTS configuration error (not enough HW for LCR) | N34: 1868 supplAlarmInfo=Not enough link capacity on fronthaul or internal connections or SFP(s) for cell detected additionalFaultID=1868 | P34: UP without action | Q34: 46028 | R34: 01/06/2026 : Need BO RAN analysis | S34: BO RAN | T34: RCA unknown | U34: RCA unknown | V34: =VLOOKUP(B34,[2]Overall!$A:$D,4,0) -> TELEINFRA NORD | W34: =VLOOKUP(B34,[3]Sheet1!$A:$B,2,0) -> Makor | X34: =LEFT(B19,3) -> NRO | Y34: =IF(I34 < 1/24, "T<1H", IF(AND(I34<2/24, I34>1/24), "1H<T<2H", IF(AND(I34<4/24, I34>2/24), "2H<T<4H", IF(AND(I34<8/24, I34>4/24), "4H<T<8H", IF(AND(I34<16/24, I34>8/24), "8H<T<16H",IF(AND(I34<24/24, I34>16/24),"16H<T<24H", IF(AND(I34<48/24, I34>24/24),"24H<T<48H",IF(AND(I34<72/24, I34>24/24),"48H<T<72H", "T>72H")))))))) -> T>72H | Z34: =IF(OR(E34="", E34="affected_cells=unknown"), "", LEN(E34)-LEN(SUBSTITUTE(E34, ",", "")) + LEN(E34)-LEN(SUBSTITUTE(E34, ";", "")) + 1) -> 1 | AA34: UP | AB34: New case | AC34: 01/06/2026 8h16 | AD34: W23
A35: Makor_G9U21_ADM_015_MRBTS1 | B35: ADM_015 | E35: faulty_cells=GSM:1043 | F35: =VLOOKUP(B35,'[2]Power '!$A:$C,3,0) -> #N/A | G35: =VLOOKUP(B35,'[2]Power '!$A:$D,4,0) -> #N/A | H35: 46173.718 | I35: =NOW()-H35 -> 6.9506369 | M35: BTS configuration error (not enough HW for LCR) | N35: 1868 supplAlarmInfo=Not enough link capacity on fronthaul or internal connections or SFP(s) for cell detected additionalFaultID=1868 | P35: UP without action | Q35: 46028 | R35: 01/06/2026 : Need BO RAN analysis | S35: BO RAN | T35: RCA unknown | U35: RCA unknown | V35: =VLOOKUP(B35,[2]Overall!$A:$D,4,0) -> TELEINFRA NORD | W35: =VLOOKUP(B35,[3]Sheet1!$A:$B,2,0) -> Makor | X35: =LEFT(B20,3) -> EXN | Y35: =IF(I35 < 1/24, "T<1H", IF(AND(I35<2/24, I35>1/24), "1H<T<2H", IF(AND(I35<4/24, I35>2/24), "2H<T<4H", IF(AND(I35<8/24, I35>4/24), "4H<T<8H", IF(AND(I35<16/24, I35>8/24), "8H<T<16H",IF(AND(I35<24/24, I35>16/24),"16H<T<24H", IF(AND(I35<48/24, I35>24/24),"24H<T<48H",IF(AND(I35<72/24, I35>24/24),"48H<T<72H", "T>72H")))))))) -> T>72H | Z35: =IF(OR(E35="", E35="affected_cells=unknown"), "", LEN(E35)-LEN(SUBSTITUTE(E35, ",", "")) + LEN(E35)-LEN(SUBSTITUTE(E35, ";", "")) + 1) -> 1 | AA35: UP | AB35: New case | AC35: 01/06/2026 8h16 | AD35: W23
A36: Makor_G9U21_ADM_015_MRBTS1 | B36: ADM_015 | E36: faulty_cells=WCDMA:4878501 | F36: =VLOOKUP(B36,'[2]Power '!$A:$C,3,0) -> #N/A | G36: =VLOOKUP(B36,'[2]Power '!$A:$D,4,0) -> #N/A | H36: 46173.718 | I36: =NOW()-H36 -> 6.9506369 | M36: BTS configuration error (not enough HW for LCR) | N36: 1868 supplAlarmInfo=Not enough link capacity on fronthaul or internal connections or SFP(s) for cell detected additionalFaultID=1868 | P36: UP without action | Q36: 46028 | R36: 01/06/2026 : Need BO RAN analysis | S36: BO RAN | T36: RCA unknown | U36: RCA unknown | V36: =VLOOKUP(B36,[2]Overall!$A:$D,4,0) -> TELEINFRA NORD | W36: =VLOOKUP(B36,[3]Sheet1!$A:$B,2,0) -> Makor | X36: =LEFT(B21,3) -> ADM | Y36: =IF(I36 < 1/24, "T<1H", IF(AND(I36<2/24, I36>1/24), "1H<T<2H", IF(AND(I36<4/24, I36>2/24), "2H<T<4H", IF(AND(I36<8/24, I36>4/24), "4H<T<8H", IF(AND(I36<16/24, I36>8/24), "8H<T<16H",IF(AND(I36<24/24, I36>16/24),"16H<T<24H", IF(AND(I36<48/24, I36>24/24),"24H<T<48H",IF(AND(I36<72/24, I36>24/24),"48H<T<72H", "T>72H")))))))) -> T>72H | Z36: =IF(OR(E36="", E36="affected_cells=unknown"), "", LEN(E36)-LEN(SUBSTITUTE(E36, ",", "")) + LEN(E36)-LEN(SUBSTITUTE(E36, ";", "")) + 1) -> 1 | AA36: UP | AB36: New case | AC36: 01/06/2026 8h16 | AD36: W23
A37: Makor_G9U21_ADM_015_MRBTS1 | B37: ADM_015 | E37: faulty_cells=WCDMA:4878703 | F37: =VLOOKUP(B37,'[2]Power '!$A:$C,3,0) -> #N/A | G37: =VLOOKUP(B37,'[2]Power '!$A:$D,4,0) -> #N/A | H37: 46173.718 | I37: =NOW()-H37 -> 6.9506369 | M37: BTS configuration error (not enough HW for LCR) | N37: 1868 supplAlarmInfo=Not enough link capacity on fronthaul or internal connections or SFP(s) for cell detected additionalFaultID=1868 | P37: UP without action | Q37: 46028 | R37: 01/06/2026 : Need BO RAN analysis | S37: BO RAN | T37: RCA unknown | U37: RCA unknown | V37: =VLOOKUP(B37,[2]Overall!$A:$D,4,0) -> TELEINFRA NORD | W37: =VLOOKUP(B37,[3]Sheet1!$A:$B,2,0) -> Makor | X37: =LEFT(B22,3) -> ADM | Y37: =IF(I37 < 1/24, "T<1H", IF(AND(I37<2/24, I37>1/24), "1H<T<2H", IF(AND(I37<4/24, I37>2/24), "2H<T<4H", IF(AND(I37<8/24, I37>4/24), "4H<T<8H", IF(AND(I37<16/24, I37>8/24), "8H<T<16H",IF(AND(I37<24/24, I37>16/24),"16H<T<24H", IF(AND(I37<48/24, I37>24/24),"24H<T<48H",IF(AND(I37<72/24, I37>24/24),"48H<T<72H", "T>72H")))))))) -> T>72H | Z37: =IF(OR(E37="", E37="affected_cells=unknown"), "", LEN(E37)-LEN(SUBSTITUTE(E37, ",", "")) + LEN(E37)-LEN(SUBSTITUTE(E37, ";", "")) + 1) -> 1 | AA37: UP | AB37: New case | AC37: 01/06/2026 8h16 | AD37: W23
A38: Makor_G9U21_ADM_015_MRBTS1 | B38: ADM_015 | E38: faulty_cells=GSM:1041 | F38: =VLOOKUP(B38,'[2]Power '!$A:$C,3,0) -> #N/A | G38: =VLOOKUP(B38,'[2]Power '!$A:$D,4,0) -> #N/A | H38: 46173.718 | I38: =NOW()-H38 -> 6.9506369 | M38: BTS configuration error (not enough HW for LCR) | N38: 1868 supplAlarmInfo=Not enough link capacity on fronthaul or internal connections or SFP(s) for cell detected additionalFaultID=1868 | P38: UP without action | Q38: 46028 | R38: 01/06/2026 : Need BO RAN analysis | S38: BO RAN | T38: RCA unknown | U38: RCA unknown | V38: =VLOOKUP(B38,[2]Overall!$A:$D,4,0) -> TELEINFRA NORD | W38: =VLOOKUP(B38,[3]Sheet1!$A:$B,2,0) -> Makor | X38: =LEFT(B23,3) -> EXN | Y38: =IF(I38 < 1/24, "T<1H", IF(AND(I38<2/24, I38>1/24), "1H<T<2H", IF(AND(I38<4/24, I38>2/24), "2H<T<4H", IF(AND(I38<8/24, I38>4/24), "4H<T<8H", IF(AND(I38<16/24, I38>8/24), "8H<T<16H",IF(AND(I38<24/24, I38>16/24),"16H<T<24H", IF(AND(I38<48/24, I38>24/24),"24H<T<48H",IF(AND(I38<72/24, I38>24/24),"48H<T<72H", "T>72H")))))))) -> T>72H | Z38: =IF(OR(E38="", E38="affected_cells=unknown"), "", LEN(E38)-LEN(SUBSTITUTE(E38, ",", "")) + LEN(E38)-LEN(SUBSTITUTE(E38, ";", "")) + 1) -> 1 | AA38: UP | AB38: New case | AC38: 01/06/2026 8h16 | AD38: W23
A39: Makor_G9U21_ADM_015_MRBTS1 | B39: ADM_015 | E39: faulty_cells=WCDMA:4878602 | F39: =VLOOKUP(B39,'[2]Power '!$A:$C,3,0) -> #N/A | G39: =VLOOKUP(B39,'[2]Power '!$A:$D,4,0) -> #N/A | H39: 46173.718 | I39: =NOW()-H39 -> 6.9506369 | M39: BTS configuration error (not enough HW for LCR) | N39: 1868 supplAlarmInfo=Not enough link capacity on fronthaul or internal connections or SFP(s) for cell detected additionalFaultID=1868 | P39: UP without action | Q39: 46028 | R39: 01/06/2026 : Need BO RAN analysis | S39: BO RAN | T39: RCA unknown | U39: RCA unknown | V39: =VLOOKUP(B39,[2]Overall!$A:$D,4,0) -> TELEINFRA NORD | W39: =VLOOKUP(B39,[3]Sheet1!$A:$B,2,0) -> Makor | X39: =LEFT(B24,3) -> NRD | Y39: =IF(I39 < 1/24, "T<1H", IF(AND(I39<2/24, I39>1/24), "1H<T<2H", IF(AND(I39<4/24, I39>2/24), "2H<T<4H", IF(AND(I39<8/24, I39>4/24), "4H<T<8H", IF(AND(I39<16/24, I39>8/24), "8H<T<16H",IF(AND(I39<24/24, I39>16/24),"16H<T<24H", IF(AND(I39<48/24, I39>24/24),"24H<T<48H",IF(AND(I39<72/24, I39>24/24),"48H<T<72H", "T>72H")))))))) -> T>72H | Z39: =IF(OR(E39="", E39="affected_cells=unknown"), "", LEN(E39)-LEN(SUBSTITUTE(E39, ",", "")) + LEN(E39)-LEN(SUBSTITUTE(E39, ";", "")) + 1) -> 1 | AA39: UP | AB39: New case | AC39: 01/06/2026 8h16 | AD39: W23
