Workbook

Sheet RAPPORT
G10: oprationnel | H10: Operationnel
D12: oprationnel | E12: Operationnel | G12: Row Labels | H12: Sum of NUR DU 05/03/2026
G13: ACCESS-ISSUE | H13: 21.736591
A14: oprationnel | B14: Operationnel | D14: Row Labels | E14: Sum of NUR DU 05/03/2026 | G14: AKTIVCO | H14: 204.99122
D15: ACCESS-ISSUE | E15: 21.736591 | G15: AKTIVCO GRID ONLY | H15: 358.67596
A16: Row Labels | B16: Sum of NUR DU 05/03/2026 | D16: ENVTECH | E16: 23.112121 | G16: BSS | H16: 181.43322
A17: ACCESS-ISSUE | B17: 21.736591 | D17: Exclu | E17: 35.103108 | G17: ENVTECH | H17: 23.112121
A18: ACTIVE | B18: 518.31809 | D18: no impacts | E18: 34.280657 | G18: Exclu | H18: 35.103108
A19: Exclu | B19: 35.103108 | D19: No root cause | E19: 197.25816 | G19: Fiber AOF | H19: 0
A20: no impacts | B20: 34.280657 | D20: POWER ISSUE | E20: 1036.1963 | G20: IHS | H20: 352.63806
A21: No root cause | B21: 197.25816 | D21: RAN ISSUE | E21: 181.43322 | G21: IHS GRID ONLY | H21: 92.070631
A22: PASSIVE | B22: 1059.3084 | D22: SPARE-ISSUE | E22: 59.887942 | G22: no impacts | H22: 34.280657
A23: PLANNED WORKS | B23: 9.2457046 | D23: TRAVAUX OCM | E23: 9.2457046 | G23: No root cause | H23: 197.25816
A24: SPARE-ISSUE | B24: 59.887942 | D24: TRAVAUX-HUAWEI | E24: 0 | G24: Partners | H24: 27.820404
A25: Grand Total | B25: 1935.1387 | D25: TX ISSUE | E25: 336.88488 | G25: PDH | H25: 336.88488
D26: Grand Total | E26: 1935.1387 | G26: SPARE-ISSUE | H26: 59.887942
G27: TRAVAUX OCM | H27: 9.2457046
G28: TRAVAUX-HUAWEI | H28: 0
G29: Grand Total | H29: 1935.1387
E39: NUR DAILY RECAP - NUR1935
B40: RCA | C40: NUR | E40: RCA | F40: NUR | H40: RCA | I40: NUR
B41: ACCESS-ISSUE | C41: =GETPIVOTDATA("NUR DU 05/03/2026",$A$16,"CATEGORIE","ACCESS-ISSUE") -> 21.736591 | E41: ACCESS-ISSUE | F41: =GETPIVOTDATA("NUR DU 05/03/2026",$D$14,"SUB RCA","ACCESS-ISSUE") -> 21.736591 | H41: ACCESS-ISSUE | I41: =GETPIVOTDATA("NUR DU 05/03/2026",$G$12,"OCM NOMENCLATURE","ACCESS-ISSUE") -> 21.736591
B42: ACTIVE | C42: =GETPIVOTDATA("NUR DU 05/03/2026",$A$16,"CATEGORIE","ACTIVE") -> 518.31809 | E42: ENV TCH OCM | F42: =GETPIVOTDATA("NUR DU 05/03/2026",$D$14,"SUB RCA","ENVTECH") -> 23.112121 | H42: AKTIVCO With Backup | I42: =GETPIVOTDATA("NUR DU 05/03/2026",$G$12,"OCM NOMENCLATURE","AKTIVCO") -> 204.99122
B43: No root cause | C43: =GETPIVOTDATA("NUR DU 05/03/2026",$A$16,"CATEGORIE","No root cause") -> 197.25816 | E43: No root cause | F43: =GETPIVOTDATA("NUR DU 05/03/2026",$D$14,"SUB RCA","No root cause") -> 197.25816 | H43: AKTIVCO GRID ONLY | I43: =GETPIVOTDATA("NUR DU 05/03/2026",$G$12,"OCM NOMENCLATURE","AKTIVCO GRID ONLY") -> 358.67596
B44: PASSIVE | C44: =GETPIVOTDATA("NUR DU 05/03/2026",$A$16,"CATEGORIE","PASSIVE") -> 1059.3084 | E44: POWER ISSUE | F44: =GETPIVOTDATA("NUR DU 05/03/2026",$D$14,"SUB RCA","POWER ISSUE") -> 1036.1963 | H44: Hardware issue | I44: =GETPIVOTDATA("NUR DU 05/03/2026",$G$12,"OCM NOMENCLATURE","BSS") -> 181.43322
B45: PLANNED WORKS | C45: =GETPIVOTDATA("NUR DU 05/03/2026",$A$16,"CATEGORIE","PLANNED WORKS") -> 9.2457046 | E45: RAN ISSUE | F45: =GETPIVOTDATA("NUR DU 05/03/2026",$D$14,"SUB RCA","RAN ISSUE") -> 181.43322 | H45: ENVTECH | I45: =GETPIVOTDATA("NUR DU 05/03/2026",$G$12,"OCM NOMENCLATURE","ENVTECH") -> 23.112121
B46: SPARE-ISSUE | C46: =GETPIVOTDATA("NUR DU 05/03/2026",$A$16,"CATEGORIE","SPARE-ISSUE") -> 59.887942 | E46: SPARE-ISSUE | F46: =GETPIVOTDATA("NUR DU 05/03/2026",$D$14,"SUB RCA","SPARE-ISSUE") -> 59.887942 | H46: Fiber AOF | I46: =GETPIVOTDATA("NUR DU 05/03/2026",$G$12,"OCM NOMENCLATURE","Fiber AOF") -> 0
B47: Grand Total | C47: =GETPIVOTDATA("NUR DU 05/03/2026",$A$16) -> 1935.1387 | E47: PLANNED WORKS | F47: =GETPIVOTDATA("NUR DU 05/03/2026",$D$14,"SUB RCA","TRAVAUX OCM") -> 9.2457046 | H47: IHS | I47: =GETPIVOTDATA("NUR DU 05/03/2026",$G$12,"OCM NOMENCLATURE","IHS") -> 352.63806
E48: TX ISSUE | F48: =GETPIVOTDATA("NUR DU 05/03/2026",$D$14,"SUB RCA","TX ISSUE") -> 336.88488 | H48: IHS GRID ONLY | I48: =GETPIVOTDATA("NUR DU 05/03/2026",$G$12,"OCM NOMENCLATURE","IHS GRID ONLY") -> 92.070631
E49: Grand Total | F49: =GETPIVOTDATA("NUR DU 05/03/2026",$D$14) -> 1935.1387 | H49: No root cause | I49: =GETPIVOTDATA("NUR DU 05/03/2026",$G$12,"OCM NOMENCLATURE","No root cause") -> 197.25816
H50: Power MTN | I50: =GETPIVOTDATA("NUR DU 05/03/2026",$G$12,"OCM NOMENCLATURE","Partners") -> 27.820404
H51: TX issue MPR / ODU -- | I51: =GETPIVOTDATA("NUR DU 05/03/2026",$G$12,"OCM NOMENCLATURE","PDH") -> 336.88488
H52: SPARE-ISSUE | I52: =GETPIVOTDATA("NUR DU 05/03/2026",$G$12,"OCM NOMENCLATURE","SPARE-ISSUE") -> 59.887942
H53: PLANNED WORKS | I53: =GETPIVOTDATA("NUR DU 05/03/2026",$G$12,"OCM NOMENCLATURE","TRAVAUX OCM") -> 9.2457046
H54: Grand Total | I54: =GETPIVOTDATA("NUR DU 05/03/2026",$G$12) -> 1935.1387
B57: CTR_211

Sheet daily break down
I1: =SUBTOTAL(9,I3:I2458) -> 2961.4907 | J1: =SUBTOTAL(9,J3:J2458) -> 3313.6944 | K1: =SUBTOTAL(9,K3:K2458) -> 3288.5808 | L1: =SUBTOTAL(9,L3:L2458) -> 2931.9362 | M1: =SUBTOTAL(9,M3:M2458) -> 3209.912 | N1: =SUBTOTAL(9,N3:N2458) -> 2613.8488 | O1: =SUBTOTAL(9,O3:O2458) -> 2422.1886 | P1: =SUBTOTAL(9,P3:P2458) -> 2845.6173 | ... S1: =SUBTOTAL(9,S3:S2458) -> 2735.102 | T1: 42426084 | V1: 2818.6536 | W1: 3224.5484 | X1: 2912.9428 | Y1: =SUBTOTAL(9,Y3:Y2458) -> 2722.6223 | Z1: =SUBTOTAL(9,Z3:Z2458) -> 2436.7911 | AD1: =SUBTOTAL(9,AD3:AD2458) -> 2267.0744
A2: Nom du Physique | B2: Codesite | C2: CLUSTER | D2: Owner | E2: Topology | F2: Region | G2: Ville | H2: Equipementiers | I2: NUR 11/04/2026 | J2: NUR 12/04/2026 | K2: NUR 13/04/2026 | L2: NUR 14/04/2026 | M2: NUR 15/04/2026 | N2: NUR 16/04/2026 | O2: NUR 18/04/2026 | P2: NUR 19/04/2026 | Q2: NUR 20/04/2026 | R2: NUR 21/04/2026 | S2: NUR 22/04/2026 | T2: NUR 23/04/2026 | U2: NUR DU 25/04/2026 | V2: NUR DU 26/04/2026 | W2: NUR DU 27/04/2026 | X2: NUR DU 28/04/2026 | Y2: NUR DU 29/04/2026 | Z2: NUR DU 05/02/2026 | AA2: NUR 2G | AB2: NUR 3G | AC2: NUR 4G | AD2: NUR DU 05/03/2026 | AE2: oprationnel | AF2: Raison d'exclusion | AG2: OCM NOMENCLATURE | AH2: SUB RCA | AI2: CAUSE | AJ2: CATEGORIE | AK2: Verifications 05/03/2026 | AL2: SPOF | AM2: impacts | AN2: updates BOTX | AO2: INCIDENT 05/03/2026 | AP2: top offenders05/03/2026 | AQ2: RETOUR CAMUSAT 05/03/2026 | AR2: RETOUR IHS 05/03/2026 | AS2: Hourly IHS 05/03/2026 | AT2: Cells Huawei 03052026 12h | AU2: cells down 02052026 8h50 | AV2: cells down 02052026 13h50 | AW2: cells down 02052026 13h50 | AX2: cell downs 03052026 8h40 | AY2: OCM Ran 05/03/2026 17H | AZ2: OCM Ran 05/03/2026 10H | BA2: Ticket 05/03/2026 | BB2: Dashbord suivi TOP OFFENDERS05/03/2026 | BC2: SITE WITH GPS ISSUE || 14/04/2026: hardware issue, site with GPS issue (alarm : TDD down 09Apr 02pm) | BD2: nokia number cell | BE2: HUAWEI number cell | BF2: ZTE number cell | BG2: HIS SITE | BH2: TOPO HIS SITE
A3: Babylone-dispensaire | B3: LIT_648 | C3: =_xlfn.XLOOKUP(B3,'[1]daily break down'!$D:$D,'[1]daily break down'!$E:$E,"") -> Douala | D3: CAMUSAT | E3: Good Grid no GE - 12h | F3: LITTORAL | G3: Douala | H3: =_xlfn.XLOOKUP(B3,[2]CALCULATION!$B:$B,[2]CALCULATION!$H:$H,"") -> ZTE | I3: 0 | J3: 4.9197172 | K3: 5.0473093 | L3: 0 | M3: 12.959824 | N3: 27.407629 | O3: 0 | P3: 1.3761546 | Q3: 0 | R3: 0 | S3: 0 | T3: 22.30289 | U3: 0 | V3: 0 | W3: 22.30289 | X3: 0 | Y3: 0 | Z3: 0 | AA3: 23.540071 | AB3: 20.029746 | AC3: 77.566338 | AD3: 50.535694 | AE3: Operationnel | AG3: {=IFERROR(_xlfn.IFS( AI3="MPR ISSUE","PDH", AI3="BSS Hardware Issue","BSS", AI3="Sites strategiques, MLL, Pylone, etc.","ENVTECH", AI3="AKTIVCO DEFAUT GE & POWER Cabinet","AKTIVCO", AI3="AKTIVCO Coupure ENEO & Baisse de tension","AKTIVCO GRID ONLY", AI3="Coupure ENEO & Baisse de tension","IHS GRID ONLY", AI3="Defaut GE & POWER Cabinet","IHS", AI3="Sharing","Partners", AI3="Sites strategiques & DataCenter","SST & DC", AI3="Exclu","Exclu", AI3="SAT","SAT", AI3="SPARE-ISSUE","SPARE-ISSUE", AI3="Fiber CAmtel","TRANS_FO_CAMTEL", AI3="Fiber AOF","Fiber AOF", AI3="Projet OCM (HUAWEI)","TRAVAUX-HUAWEI", AI3="Projet OCM (NOKIA)","TRAVAUX-NOKIA", AI3="ACCESS-ISSUE","ACCESS-ISSUE", AI3="Projet OCM (ZTE, NOKIA, autres projets)","TRAVAUX OCM", AI3="No root CAuse","No root cause", AI3="ODU HS","PDH", AI3="IP & VLAN","PDH", AI3="Warehouse HUAWEI","SPARE-ISSUE", AI3="SPARE-HS","SPARE-ISSUE", AI3="Power Telco","BSS",AI3="no impacts","no impacts" ),"")} -> PDH | AH3: {=IFERROR(_xlfn.IFS( AI3="MPR ISSUE","TX ISSUE", AI3="BSS Hardware Issue","RAN ISSUE", AI3="Sites strategiques, MLL, Pylone, etc.","ENVTECH", AI3="AKTIVCO DEFAUT GE & POWER Cabinet","POWER ISSUE", AI3="AKTIVCO Coupure ENEO & Baisse de tension","POWER ISSUE", AI3="Coupure ENEO & Baisse de tension","POWER ISSUE", AI3="Defaut GE & POWER Cabinet","POWER ISSUE", AI3="Sharing","POWER ISSUE", AI3="Sites strategiques & DataCenter","POWER ISSUE", AI3="Exclu","Exclu", AI3="SAT","TX ISSUE", AI3="SPARE-ISSUE","SPARE-ISSUE", AI3="Fiber CAmtel","TX ISSUE", AI3="Fiber AOF","TX ISSUE", AI3="Projet OCM (HUAWEI)","TRAVAUX-HUAWEI", AI3="Projet OCM (NOKIA)","TRAVAUX -NOKIA", AI3="ACCESS-ISSUE","ACCESS-ISSUE", AI3="Projet OCM (ZTE, NOKIA, autres projets)","TRAVAUX OCM", AI3="No root CAuse","No root cause", AI3="ODU HS","TX ISSUE", AI3="IP & VLAN","TX ISSUE", AI3="Warehouse HUAWEI","SPARE-ISSUE", AI3="SPARE-HS","SPARE-ISSUE", AI3="Power Telco","RAN ISSUE",AI3="no impacts","no impacts" ),"")} -> TX ISSUE | AI3: MPR ISSUE | AJ3: {=IFERROR(_xlfn.IFS( AI3="MPR ISSUE","ACTIVE", AI3="BSS Hardware Issue","ACTIVE", AI3="Sites strategiques, MLL, Pylone, etc.","PASSIVE", AI3="AKTIVCO DEFAUT GE & POWER Cabinet","PASSIVE", AI3="AKTIVCO Coupure ENEO & Baisse de tension","PASSIVE", AI3="Coupure ENEO & Baisse de tension","PASSIVE", AI3="Defaut GE & POWER Cabinet","PASSIVE", AI3="Sharing","PASSIVE", AI3="Sites strategiques & DataCenter","PASSIVE", AI3="Exclu","Exclu", AI3="SAT","ACTIVE", AI3="SPARE-ISSUE","SPARE-ISSUE", AI3="Fiber CAmtel","ACTIVE", AI3="Fiber AOF","ACTIVE", AI3="Projet OCM (HUAWEI)","PLANNED WORKS", AI3="Projet OCM (NOKIA)","PLANNED WORKS", AI3="ACCESS-ISSUE","ACCESS-ISSUE", AI3="Projet OCM (ZTE, NOKIA, autres projets)","PLANNED WORKS", AI3="No root CAuse","No root cause", AI3="ODU HS","ACTIVE", AI3="IP & VLAN","ACTIVE", AI3="Warehouse HUAWEI","SPARE-ISSUE", AI3="SPARE-HS","SPARE-ISSUE", AI3="Power Telco","ACTIVE", AI3="no impacts","no impacts" ),"")} -> ACTIVE | AK3: (05/03/2026 groupe whatsapp ):LIT_528_Z_Newb-Ancien-Etage-New(LIT-528) : Need FME on the site to check MPR status || (05/03/2026 com ran 17h): Impacted by LIT_528_Z_Newb-Ancien-Etage-New(LIT-528)..;..;(05/03/2026 com ran 10h): Impacted by LIT_528_Z_Newb-Ancien-Etage-New(LIT-528)..;..;(05/03/2026 ticket)..INC-20260503-00012977...Others Transmission equipement fault | AL3: =IFERROR(MID(AM3, SEARCH("CTR_", AM3), 7), IFERROR(MID(AM3, SEARCH("SUO_", AM3), 7), IFERROR(MID(AM3, SEARCH("SUD_", AM3), 7), IFERROR(MID(AM3, SEARCH("NRO_", AM3), 7), IFERROR(MID(AM3, SEARCH("ADM_", AM3), 7), IFERROR(MID(AM3, SEARCH("NRD_", AM3), 7), IFERROR(MID(AM3, SEARCH("EXN_", AM3), 7), IFERROR(MID(AM3, SEARCH("LIT_", AM3), 7), IFERROR(MID(AM3, SEARCH("EST_", AM3), 7), MID(AM3, SEARCH("OST_",AM3), 7)))))))))) -> LIT_528 | AM3: Impacted by LIT_528_Z_Newb-Ancien-Etage-New(LIT-528) | AO3: =_xlfn.XLOOKUP(B3,'INCIDENT-05-03-2026'!E:E,'INCIDENT-05-03-2026'!F:F,"") | AP3: (05/03/2026 top offenders): Impacted by LIT_528_Z_Newb-Ancien-Etage-New(LIT-528) | AS3: =_xlfn.XLOOKUP(B3,'[3]tt num | region | site id'!$C:$C,'[3]tt num | region | site id'!$Q:$Q,"") | AT3: =_xlfn.XLOOKUP(B3,'[4]Cells Huawei 03052026 12h'!$B:$B,'[4]Cells Huawei 03052026 12h'!$T:$T,"") | AU3: =_xlfn.XLOOKUP(B3,'[5]cells down 02052026 8h50'!$B:$B,'[5]cells down 02052026 8h50'!$R:$R,"") | AV3: =_xlfn.XLOOKUP(B3,'[5]cells down 02052026 13h50'!$B:$B,'[5]cells down 02052026 13h50'!$R:$R,"") | AW3: =_xlfn.XLOOKUP(B3,'[5]cells down 02052026 13h50'!$B:$B,'[5]cells down 02052026 13h50'!$R:$R,"") | AX3: =_xlfn.XLOOKUP(B3,'[6]cell downs 03052026 8h40 '!$B:$B,'[6]cell downs 03052026 8h40 '!$R:$R,"") | AY3: =_xlfn.XLOOKUP(B3,'[7]ALL SITES DOWN'!$D:$D,'[7]ALL SITES DOWN'!$J:$J,"") -> (05/03/2026 com ran 17h): Impacted by LIT_528_Z_Newb-Ancien-Etage-New(LIT-528) | AZ3: =_xlfn.XLOOKUP(B3,'[8]ALL SITES DOWN'!$D:$D,'[8]ALL SITES DOWN'!$J:$J,"") -> (05/03/2026 com ran 10h): Impacted by LIT_528_Z_Newb-Ancien-Etage-New(LIT-528) | BA3: =_xlfn.XLOOKUP(B3,[9]sheet1!$AC:$AC,[9]sheet1!$AF:$AF,"") -> (05/03/2026 ticket)..INC-20260503-00012977...Others Transmission equipement fault | BB3: (05/03/2026 dashbord): | BD3: =_xlfn.XLOOKUP(B3,'[10]cell downs 18042026 17h'!$B:$B,'[10]cell downs 18042026 17h'!$B:$B,"") | BE3: =_xlfn.XLOOKUP(B3,'[11]Cells Huawei 19042026 15h'!$B:$B,'[11]Cells Huawei 19042026 15h'!$B:$B,"") | BF3: =_xlfn.XLOOKUP(B3,'[12]cells down 19042026 9H40'!$B:$B,'[12]cells down 19042026 9H40'!$B:$B,"") | BH3: Grid-Lithium
A4: Carrefour-Diderot | B4: CTR_841 | C4: =_xlfn.XLOOKUP(B4,'[1]daily break down'!$D:$D,'[1]daily break down'!$E:$E,"") -> Yaounde | D4: CAMUSAT | E4: Good Grid no GE - 8h | F4: CENTRE | G4: Yaounde | H4: =_xlfn.XLOOKUP(B4,[2]CALCULATION!$B:$B,[2]CALCULATION!$H:$H,"") -> ZTE | I4: 0 | J4: 0 | K4: 0 | L4: 0 | M4: 0 | N4: 0 | O4: 0 | P4: 2.0062323 | Q4: 48.931037 | R4: 12.206845 | S4: 12.248722 | T4: 13.868557 | U4: 13.868557 | V4: 13.868557 | W4: 13.868557 | X4: 13.339711 | Y4: 12.010302 | Z4: 49.656122 | AA4: 30.931516 | AB4: 26.423963 | AC4: 68.921214 | AD4: 49.229471 | AE4: Operationnel | AG4: {=IFERROR(_xlfn.IFS( AI4="MPR ISSUE","PDH", AI4="BSS Hardware Issue","BSS", AI4="Sites strategiques, MLL, Pylone, etc.","ENVTECH", AI4="AKTIVCO DEFAUT GE & POWER Cabinet","AKTIVCO", AI4="AKTIVCO Coupure ENEO & Baisse de tension","AKTIVCO GRID ONLY", AI4="Coupure ENEO & Baisse de tension","IHS GRID ONLY", AI4="Defaut GE & POWER Cabinet","IHS", AI4="Sharing","Partners", AI4="Sites strategiques & DataCenter","SST & DC", AI4="Exclu","Exclu", AI4="SAT","SAT", AI4="SPARE-ISSUE","SPARE-ISSUE", AI4="Fiber CAmtel","TRANS_FO_CAMTEL", AI4="Fiber AOF","Fiber AOF", AI4="Projet OCM (HUAWEI)","TRAVAUX-HUAWEI", AI4="Projet OCM (NOKIA)","TRAVAUX-NOKIA", AI4="ACCESS-ISSUE","ACCESS-ISSUE", AI4="Projet OCM (ZTE, NOKIA, autres projets)","TRAVAUX OCM", AI4="No root CAuse","No root cause", AI4="ODU HS","PDH", AI4="IP & VLAN","PDH", AI4="Warehouse HUAWEI","SPARE-ISSUE", AI4="SPARE-HS","SPARE-ISSUE", AI4="Power Telco","BSS",AI4="no impacts","no impacts" ),"")} -> PDH | AH4: {=IFERROR(_xlfn.IFS( AI4="MPR ISSUE","TX ISSUE", AI4="BSS Hardware Issue","RAN ISSUE", AI4="Sites strategiques, MLL, Pylone, etc.","ENVTECH", AI4="AKTIVCO DEFAUT GE & POWER Cabinet","POWER ISSUE", AI4="AKTIVCO Coupure ENEO & Baisse de tension","POWER ISSUE", AI4="Coupure ENEO & Baisse de tension","POWER ISSUE", AI4="Defaut GE & POWER Cabinet","POWER ISSUE", AI4="Sharing","POWER ISSUE", AI4="Sites strategiques & DataCenter","POWER ISSUE", AI4="Exclu","Exclu", AI4="SAT","TX ISSUE", AI4="SPARE-ISSUE","SPARE-ISSUE", AI4="Fiber CAmtel","TX ISSUE", AI4="Fiber AOF","TX ISSUE", AI4="Projet OCM (HUAWEI)","TRAVAUX-HUAWEI", AI4="Projet OCM (NOKIA)","TRAVAUX -NOKIA", AI4="ACCESS-ISSUE","ACCESS-ISSUE", AI4="Projet OCM (ZTE, NOKIA, autres projets)","TRAVAUX OCM", AI4="No root CAuse","No root cause", AI4="ODU HS","TX ISSUE", AI4="IP & VLAN","TX ISSUE", AI4="Warehouse HUAWEI","SPARE-ISSUE", AI4="SPARE-HS","SPARE-ISSUE", AI4="Power Telco","RAN ISSUE",AI4="no impacts","no impacts" ),"")} -> TX ISSUE | AI4: MPR ISSUE | AJ4: {=IFERROR(_xlfn.IFS( AI4="MPR ISSUE","ACTIVE", AI4="BSS Hardware Issue","ACTIVE", AI4="Sites strategiques, MLL, Pylone, etc.","PASSIVE", AI4="AKTIVCO DEFAUT GE & POWER Cabinet","PASSIVE", AI4="AKTIVCO Coupure ENEO & Baisse de tension","PASSIVE", AI4="Coupure ENEO & Baisse de tension","PASSIVE", AI4="Defaut GE & POWER Cabinet","PASSIVE", AI4="Sharing","PASSIVE", AI4="Sites strategiques & DataCenter","PASSIVE", AI4="Exclu","Exclu", AI4="SAT","ACTIVE", AI4="SPARE-ISSUE","SPARE-ISSUE", AI4="Fiber CAmtel","ACTIVE", AI4="Fiber AOF","ACTIVE", AI4="Projet OCM (HUAWEI)","PLANNED WORKS", AI4="Projet OCM (NOKIA)","PLANNED WORKS", AI4="ACCESS-ISSUE","ACCESS-ISSUE", AI4="Projet OCM (ZTE, NOKIA, autres projets)","PLANNED WORKS", AI4="No root CAuse","No root cause", AI4="ODU HS","ACTIVE", AI4="IP & VLAN","ACTIVE", AI4="Warehouse HUAWEI","SPARE-ISSUE", AI4="SPARE-HS","SPARE-ISSUE", AI4="Power Telco","ACTIVE", AI4="no impacts","no impacts" ),"")} -> ACTIVE | AK4: (05/03/2026 com ran 17h): 03.05.2026: FME Henry activated ETA=ASAP 03.05.2026: Need FME on the site to check MPR status..;..;(05/03/2026 com ran 10h): 01.05.2026 CAMUSAT: Grid outage and grid only site / Grid return awaited 30.04.26; Power alarms; Camusat feedback awaiting..;..;(05/03/2026 ticket)..INC-20260503-00014533...2026-05-04 01:28:32...no power issue u=54v load=47A / no action done Relance 1 BO TX ANALYSE ONGOING...user:OCM_NOC.CAMUSAT | AL4: =B4 -> CTR_841 | AO4: =_xlfn.XLOOKUP(B4,'INCIDENT-05-03-2026'!E:E,'INCIDENT-05-03-2026'!F:F,"") | AP4: (05/03/2026 top offenders): | AS4: =_xlfn.XLOOKUP(B4,'[3]tt num | region | site id'!$C:$C,'[3]tt num | region | site id'!$Q:$Q,"") | AT4: =_xlfn.XLOOKUP(B4,'[4]Cells Huawei 03052026 12h'!$B:$B,'[4]Cells Huawei 03052026 12h'!$T:$T,"") | AU4: =_xlfn.XLOOKUP(B4,'[5]cells down 02052026 8h50'!$B:$B,'[5]cells down 02052026 8h50'!$R:$R,"") | AV4: =_xlfn.XLOOKUP(B4,'[5]cells down 02052026 13h50'!$B:$B,'[5]cells down 02052026 13h50'!$R:$R,"") | AW4: =_xlfn.XLOOKUP(B4,'[5]cells down 02052026 13h50'!$B:$B,'[5]cells down 02052026 13h50'!$R:$R,"") | AX4: =_xlfn.XLOOKUP(B4,'[6]cell downs 03052026 8h40 '!$B:$B,'[6]cell downs 03052026 8h40 '!$R:$R,"") | AY4: =_xlfn.XLOOKUP(B4,'[7]ALL SITES DOWN'!$D:$D,'[7]ALL SITES DOWN'!$J:$J,"") -> (05/03/2026 com ran 17h): 03.05.2026: FME Henry activated ETA=ASAP 03.05.2026: Need FME on the site to check MPR status | AZ4: =_xlfn.XLOOKUP(B4,'[8]ALL SITES DOWN'!$D:$D,'[8]ALL SITES DOWN'!$J:$J,"") -> (05/03/2026 com ran 10h): 01.05.2026 CAMUSAT: Grid outage and grid only site / Grid return awaited 30.04.26; Power alarms; Camusat feedback awaiting | BA4: =_xlfn.XLOOKUP(B4,[9]sheet1!$AC:$AC,[9]sheet1!$AF:$AF,"") -> (05/03/2026 ticket)..INC-20260503-00014533...2026-05-04 01:28:32...no power issue u=54v load=47A / no action done Relance 1 BO TX ANALYSE ONGOING...user:OCM_NOC.CAMUSAT | BB4: (05/03/2026 dashbord): | BD4: =_xlfn.XLOOKUP(B4,'[10]cell downs 18042026 17h'!$B:$B,'[10]cell downs 18042026 17h'!$B:$B,"") | BE4: =_xlfn.XLOOKUP(B4,'[11]Cells Huawei 19042026 15h'!$B:$B,'[11]Cells Huawei 19042026 15h'!$B:$B,"") | BF4: =_xlfn.XLOOKUP(B4,'[12]cells down 19042026 9H40'!$B:$B,'[12]cells down 19042026 9H40'!$B:$B,"") | BH4: Grid-Lithium
A5: Ange-raphael-II | B5: LIT_696 | C5: =_xlfn.XLOOKUP(B5,'[1]daily break down'!$D:$D,'[1]daily break down'!$E:$E,"") -> Douala | D5: CAMUSAT | E5: Good Grid no GE - 8h | F5: LITTORAL | G5: Douala | H5: =_xlfn.XLOOKUP(B5,[2]CALCULATION!$B:$B,[2]CALCULATION!$H:$H,"") -> ZTE | I5: 0 | J5: 0 | K5: 0 | L5: 11.674254 | M5: 0 | N5: 0 | O5: 0.85897304 | P5: 10.660312 | Q5: 1.0623999 | R5: 3.882215 | S5: 4.6973851 | T5: 2.8014628 | U5: 6.6491312 | V5: 1.8401342 | W5: 2.8014628 | X5: 2.3936459 | Y5: 0 | Z5: 48.40039 | AA5: 13.089307 | AB5: 16.622391 | AC5: 66.586631 | AD5: 42.173647 | AE5: Operationnel | AG5: {=IFERROR(_xlfn.IFS( AI5="MPR ISSUE","PDH", AI5="BSS Hardware Issue","BSS", AI5="Sites strategiques, MLL, Pylone, etc.","ENVTECH", AI5="AKTIVCO DEFAUT GE & POWER Cabinet","AKTIVCO", AI5="AKTIVCO Coupure ENEO & Baisse de tension","AKTIVCO GRID ONLY", AI5="Coupure ENEO & Baisse de tension","IHS GRID ONLY", AI5="Defaut GE & POWER Cabinet","IHS", AI5="Sharing","Partners", AI5="Sites strategiques & DataCenter","SST & DC", AI5="Exclu","Exclu", AI5="SAT","SAT", AI5="SPARE-ISSUE","SPARE-ISSUE", AI5="Fiber CAmtel","TRANS_FO_CAMTEL", AI5="Fiber AOF","Fiber AOF", AI5="Projet OCM (HUAWEI)","TRAVAUX-HUAWEI", AI5="Projet OCM (NOKIA)","TRAVAUX-NOKIA", AI5="ACCESS-ISSUE","ACCESS-ISSUE", AI5="Projet OCM (ZTE, NOKIA, autres projets)","TRAVAUX OCM", AI5="No root CAuse","No root cause", AI5="ODU HS","PDH", AI5="IP & VLAN","PDH", AI5="Warehouse HUAWEI","SPARE-ISSUE", AI5="SPARE-HS","SPARE-ISSUE", AI5="Power Telco","BSS",AI5="no impacts","no impacts" ),"")} -> AKTIVCO GRID ONLY | AH5: {=IFERROR(_xlfn.IFS( AI5="MPR ISSUE","TX ISSUE", AI5="BSS Hardware Issue","RAN ISSUE", AI5="Sites strategiques, MLL, Pylone, etc.","ENVTECH", AI5="AKTIVCO DEFAUT GE & POWER Cabinet","POWER ISSUE", AI5="AKTIVCO Coupure ENEO & Baisse de tension","POWER ISSUE", AI5="Coupure ENEO & Baisse de tension","POWER ISSUE", AI5="Defaut GE & POWER Cabinet","POWER ISSUE", AI5="Sharing","POWER ISSUE", AI5="Sites strategiques & DataCenter","POWER ISSUE", AI5="Exclu","Exclu", AI5="SAT","TX ISSUE", AI5="SPARE-ISSUE","SPARE-ISSUE", AI5="Fiber CAmtel","TX ISSUE", AI5="Fiber AOF","TX ISSUE", AI5="Projet OCM (HUAWEI)","TRAVAUX-HUAWEI", AI5="Projet OCM (NOKIA)","TRAVAUX -NOKIA", AI5="ACCESS-ISSUE","ACCESS-ISSUE", AI5="Projet OCM (ZTE, NOKIA, autres projets)","TRAVAUX OCM", AI5="No root CAuse","No root cause", AI5="ODU HS","TX ISSUE", AI5="IP & VLAN","TX ISSUE", AI5="Warehouse HUAWEI","SPARE-ISSUE", AI5="SPARE-HS","SPARE-ISSUE", AI5="Power Telco","RAN ISSUE",AI5="no impacts","no impacts" ),"")} -> POWER ISSUE | AI5: AKTIVCO Coupure ENEO & Baisse de tension | AJ5: {=IFERROR(_xlfn.IFS( AI5="MPR ISSUE","ACTIVE", AI5="BSS Hardware Issue","ACTIVE", AI5="Sites strategiques, MLL, Pylone, etc.","PASSIVE", AI5="AKTIVCO DEFAUT GE & POWER Cabinet","PASSIVE", AI5="AKTIVCO Coupure ENEO & Baisse de tension","PASSIVE", AI5="Coupure ENEO & Baisse de tension","PASSIVE", AI5="Defaut GE & POWER Cabinet","PASSIVE", AI5="Sharing","PASSIVE", AI5="Sites strategiques & DataCenter","PASSIVE", AI5="Exclu","Exclu", AI5="SAT","ACTIVE", AI5="SPARE-ISSUE","SPARE-ISSUE", AI5="Fiber CAmtel","ACTIVE", AI5="Fiber AOF","ACTIVE", AI5="Projet OCM (HUAWEI)","PLANNED WORKS", AI5="Projet OCM (NOKIA)","PLANNED WORKS", AI5="ACCESS-ISSUE","ACCESS-ISSUE", AI5="Projet OCM (ZTE, NOKIA, autres projets)","PLANNED WORKS", AI5="No root CAuse","No root cause", AI5="ODU HS","ACTIVE", AI5="IP & VLAN","ACTIVE", AI5="Warehouse HUAWEI","SPARE-ISSUE", AI5="SPARE-HS","SPARE-ISSUE", AI5="Power Telco","ACTIVE", AI5="no impacts","no impacts" ),"")} -> PASSIVE | AK5: (05/03/2026 cell zte): 30/04/2026 : Power issue || Mail sent to camusat || Feedback camusat : FME en route pour le site ETA 12 :15. ..;..;(05/03/2026 cell zte): 30/04/2026 : Power issue || Mail sent to camusat || Feedback camusat : FME en route pour le site ETA 12 :15. ..;..;(05/03/2026 cell zte): 30/04/2026 : Power issue || Mail sent to camusat || Feedback camusat : FME en route pour le site ETA 12 :15. ..;..;(05/03/2026 ticket)..INC-20260503-00016442...2026-05-03 22:57:02...TX FME Kingsly 675245958 Huawei is on site for works (reinstallation of OCM side on site)...user:OCM_NOC.IHS | AL5: =B5 -> LIT_696 | AO5: =_xlfn.XLOOKUP(B5,'INCIDENT-05-03-2026'!E:E,'INCIDENT-05-03-2026'!F:F,"") | AP5: (05/03/2026 top offenders): Power status check Ongoing | AS5: =_xlfn.XLOOKUP(B5,'[3]tt num | region | site id'!$C:$C,'[3]tt num | region | site id'!$Q:$Q,"") | AT5: =_xlfn.XLOOKUP(B5,'[4]Cells Huawei 03052026 12h'!$B:$B,'[4]Cells Huawei 03052026 12h'!$T:$T,"") | AU5: =_xlfn.XLOOKUP(B5,'[5]cells down 02052026 8h50'!$B:$B,'[5]cells down 02052026 8h50'!$R:$R,"") -> (05/03/2026 cell zte): 30/04/2026 : Power issue || Mail sent to camusat || Feedback camusat : FME en route pour le site ETA 12 :15. | AV5: =_xlfn.XLOOKUP(B5,'[5]cells down 02052026 13h50'!$B:$B,'[5]cells down 02052026 13h50'!$R:$R,"") -> (05/03/2026 cell zte): 30/04/2026 : Power issue || Mail sent to camusat || Feedback camusat : FME en route pour le site ETA 12 :15. | AW5: =_xlfn.XLOOKUP(B5,'[5]cells down 02052026 13h50'!$B:$B,'[5]cells down 02052026 13h50'!$R:$R,"") -> (05/03/2026 cell zte): 30/04/2026 : Power issue || Mail sent to camusat || Feedback camusat : FME en route pour le site ETA 12 :15. | AX5: =_xlfn.XLOOKUP(B5,'[6]cell downs 03052026 8h40 '!$B:$B,'[6]cell downs 03052026 8h40 '!$R:$R,"") | AY5: =_xlfn.XLOOKUP(B5,'[7]ALL SITES DOWN'!$D:$D,'[7]ALL SITES DOWN'!$J:$J,"") | AZ5: =_xlfn.XLOOKUP(B5,'[8]ALL SITES DOWN'!$D:$D,'[8]ALL SITES DOWN'!$J:$J,"") | BA5: =_xlfn.XLOOKUP(B5,[9]sheet1!$AC:$AC,[9]sheet1!$AF:$AF,"") -> (05/03/2026 ticket)..INC-20260503-00016442...2026-05-03 22:57:02...TX FME Kingsly 675245958 Huawei is on site for works (reinstallation of OCM side on site)...user:OCM_NOC.IHS | BB5: (05/03/2026 dashbord): | BD5: =_xlfn.XLOOKUP(B5,'[10]cell downs 18042026 17h'!$B:$B,'[10]cell downs 18042026 17h'!$B:$B,"") | BE5: =_xlfn.XLOOKUP(B5,'[11]Cells Huawei 19042026 15h'!$B:$B,'[11]Cells Huawei 19042026 15h'!$B:$B,"") | BF5: =_xlfn.XLOOKUP(B5,'[12]cells down 19042026 9H40'!$B:$B,'[12]cells down 19042026 9H40'!$B:$B,"")
A6: Oyomambang-Ekorezok | B6: CTR_560 | C6: =_xlfn.XLOOKUP(B6,'[1]daily break down'!$D:$D,'[1]daily break down'!$E:$E,"") -> Yaounde | D6: CAMUSAT | E6: Good Grid + GE | F6: CENTRE | G6: Yaounde | H6: =_xlfn.XLOOKUP(B6,[2]CALCULATION!$B:$B,[2]CALCULATION!$H:$H,"") -> ZTE | I6: 3.7152787 | J6: 1.0600992 | K6: 0.65361995 | L6: 0.0534874 | M6: 2.0929286 | N6: 0.053005853 | O6: 0.54500432 | P6: 6.9734621 | Q6: 4.3984692 | R6: 0.62510166 | S6: 0 | T6: 0 | U6: 0 | V6: 0 | W6: 0 | X6: 0 | Y6: 0 | Z6: 34.813823 | AA6: 21.817261 | AB6: 18.551669 | AC6: 55.80279 | AD6: 38.444029 | AE6: Operationnel | AG6: {=IFERROR(_xlfn.IFS( AI6="MPR ISSUE","PDH", AI6="BSS Hardware Issue","BSS", AI6="Sites strategiques, MLL, Pylone, etc.","ENVTECH", AI6="AKTIVCO DEFAUT GE & POWER Cabinet","AKTIVCO", AI6="AKTIVCO Coupure ENEO & Baisse de tension","AKTIVCO GRID ONLY", AI6="Coupure ENEO & Baisse de tension","IHS GRID ONLY", AI6="Defaut GE & POWER Cabinet","IHS", AI6="Sharing","Partners", AI6="Sites strategiques & DataCenter","SST & DC", AI6="Exclu","Exclu", AI6="SAT","SAT", AI6="SPARE-ISSUE","SPARE-ISSUE", AI6="Fiber CAmtel","TRANS_FO_CAMTEL", AI6="Fiber AOF","Fiber AOF", AI6="Projet OCM (HUAWEI)","TRAVAUX-HUAWEI", AI6="Projet OCM (NOKIA)","TRAVAUX-NOKIA", AI6="ACCESS-ISSUE","ACCESS-ISSUE", AI6="Projet OCM (ZTE, NOKIA, autres projets)","TRAVAUX OCM", AI6="No root CAuse","No root cause", AI6="ODU HS","PDH", AI6="IP & VLAN","PDH", AI6="Warehouse HUAWEI","SPARE-ISSUE", AI6="SPARE-HS","SPARE-ISSUE", AI6="Power Telco","BSS",AI6="no impacts","no impacts" ),"")} -> PDH | AH6: {=IFERROR(_xlfn.IFS( AI6="MPR ISSUE","TX ISSUE", AI6="BSS Hardware Issue","RAN ISSUE", AI6="Sites strategiques, MLL, Pylone, etc.","ENVTECH", AI6="AKTIVCO DEFAUT GE & POWER Cabinet","POWER ISSUE", AI6="AKTIVCO Coupure ENEO & Baisse de tension","POWER ISSUE", AI6="Coupure ENEO & Baisse de tension","POWER ISSUE", AI6="Defaut GE & POWER Cabinet","POWER ISSUE", AI6="Sharing","POWER ISSUE", AI6="Sites strategiques & DataCenter","POWER ISSUE", AI6="Exclu","Exclu", AI6="SAT","TX ISSUE", AI6="SPARE-ISSUE","SPARE-ISSUE", AI6="Fiber CAmtel","TX ISSUE", AI6="Fiber AOF","TX ISSUE", AI6="Projet OCM (HUAWEI)","TRAVAUX-HUAWEI", AI6="Projet OCM (NOKIA)","TRAVAUX -NOKIA", AI6="ACCESS-ISSUE","ACCESS-ISSUE", AI6="Projet OCM (ZTE, NOKIA, autres projets)","TRAVAUX OCM", AI6="No root CAuse","No root cause", AI6="ODU HS","TX ISSUE", AI6="IP & VLAN","TX ISSUE", AI6="Warehouse HUAWEI","SPARE-ISSUE", AI6="SPARE-HS","SPARE-ISSUE", AI6="Power Telco","RAN ISSUE",AI6="no impacts","no impacts" ),"")} -> TX ISSUE | AI6: MPR ISSUE | AJ6: {=IFERROR(_xlfn.IFS( AI6="MPR ISSUE","ACTIVE", AI6="BSS Hardware Issue","ACTIVE", AI6="Sites strategiques, MLL, Pylone, etc.","PASSIVE", AI6="AKTIVCO DEFAUT GE & POWER Cabinet","PASSIVE", AI6="AKTIVCO Coupure ENEO & Baisse de tension","PASSIVE", AI6="Coupure ENEO & Baisse de tension","PASSIVE", AI6="Defaut GE & POWER Cabinet","PASSIVE", AI6="Sharing","PASSIVE", AI6="Sites strategiques & DataCenter","PASSIVE", AI6="Exclu","Exclu", AI6="SAT","ACTIVE", AI6="SPARE-ISSUE","SPARE-ISSUE", AI6="Fiber CAmtel","ACTIVE", AI6="Fiber AOF","ACTIVE", AI6="Projet OCM (HUAWEI)","PLANNED WORKS", AI6="Projet OCM (NOKIA)","PLANNED WORKS", AI6="ACCESS-ISSUE","ACCESS-ISSUE", AI6="Projet OCM (ZTE, NOKIA, autres projets)","PLANNED WORKS", AI6="No root CAuse","No root cause", AI6="ODU HS","ACTIVE", AI6="IP & VLAN","ACTIVE", AI6="Warehouse HUAWEI","SPARE-ISSUE", AI6="SPARE-HS","SPARE-ISSUE", AI6="Power Telco","ACTIVE", AI6="no impacts","no impacts" ),"")} -> ACTIVE | AK6: (05/03/2026 com ran 10h): 03.05.2026:FME Mohamadou activated for intervention ETA=03:00 PM 03.05.2026: BV activer le FME pour check statut du chassis et refaire le ligne antennaire. interpeller le BoTx pour assistance si pas toujours OK. | AL6: =B6 -> CTR_560 | AO6: =_xlfn.XLOOKUP(B6,'INCIDENT-05-03-2026'!E:E,'INCIDENT-05-03-2026'!F:F,"") | AP6: (05/03/2026 top offenders): | AS6: =_xlfn.XLOOKUP(B6,'[3]tt num | region | site id'!$C:$C,'[3]tt num | region | site id'!$Q:$Q,"") | AT6: =_xlfn.XLOOKUP(B6,'[4]Cells Huawei 03052026 12h'!$B:$B,'[4]Cells Huawei 03052026 12h'!$T:$T,"") | AU6: =_xlfn.XLOOKUP(B6,'[5]cells down 02052026 8h50'!$B:$B,'[5]cells down 02052026 8h50'!$R:$R,"") | AV6: =_xlfn.XLOOKUP(B6,'[5]cells down 02052026 13h50'!$B:$B,'[5]cells down 02052026 13h50'!$R:$R,"") | AW6: =_xlfn.XLOOKUP(B6,'[5]cells down 02052026 13h50'!$B:$B,'[5]cells down 02052026 13h50'!$R:$R,"") | AX6: =_xlfn.XLOOKUP(B6,'[6]cell downs 03052026 8h40 '!$B:$B,'[6]cell downs 03052026 8h40 '!$R:$R,"") | AY6: =_xlfn.XLOOKUP(B6,'[7]ALL SITES DOWN'!$D:$D,'[7]ALL SITES DOWN'!$J:$J,"") | AZ6: =_xlfn.XLOOKUP(B6,'[8]ALL SITES DOWN'!$D:$D,'[8]ALL SITES DOWN'!$J:$J,"") -> (05/03/2026 com ran 10h): 03.05.2026:FME Mohamadou activated for intervention ETA=03:00 PM 03.05.2026: BV activer le FME pour check statut du chassis et refaire le ligne antennaire. interpeller le BoTx pour assistance si pas toujours OK. | BA6: =_xlfn.XLOOKUP(B6,[9]sheet1!$AC:$AC,[9]sheet1!$AF:$AF,"") | BB6: (05/03/2026 dashbord): | BD6: =_xlfn.XLOOKUP(B6,'[10]cell downs 18042026 17h'!$B:$B,'[10]cell downs 18042026 17h'!$B:$B,"") | BE6: =_xlfn.XLOOKUP(B6,'[11]Cells Huawei 19042026 15h'!$B:$B,'[11]Cells Huawei 19042026 15h'!$B:$B,"") | BF6: =_xlfn.XLOOKUP(B6,'[12]cells down 19042026 9H40'!$B:$B,'[12]cells down 19042026 9H40'!$B:$B,"")
A7: Lada | B7: CTR_667 | C7: =_xlfn.XLOOKUP(B7,'[1]daily break down'!$D:$D,'[1]daily break down'!$E:$E,"") -> Yaounde | D7: CAMUSAT | E7: Bad Grid + Solar + GE | F7: CENTRE | G7: Lada | H7: =_xlfn.XLOOKUP(B7,[2]CALCULATION!$B:$B,[2]CALCULATION!$H:$H,"") -> ZTE | I7: 0 | J7: 0 | K7: 0 | L7: 0 | M7: 8.6248299 | N7: 8.5509213 | O7: 0 | P7: 4.926441 | Q7: 33.85929 | R7: 36.982818 | S7: 36.982604 | T7: 36.982818 | U7: 36.982818 | V7: 36.982729 | W7: 36.982818 | X7: 36.982818 | Y7: 36.982818 | Z7: 36.982818 | AA7: 32.372936 | AB7: 27.540622 | AC7: 44.323622 | AD7: 36.982818 | AE7: Operationnel | AG7: {=IFERROR(_xlfn.IFS( AI7="MPR ISSUE","PDH", AI7="BSS Hardware Issue","BSS", AI7="Sites strategiques, MLL, Pylone, etc.","ENVTECH", AI7="AKTIVCO DEFAUT GE & POWER Cabinet","AKTIVCO", AI7="AKTIVCO Coupure ENEO & Baisse de tension","AKTIVCO GRID ONLY", AI7="Coupure ENEO & Baisse de tension","IHS GRID ONLY", AI7="Defaut GE & POWER Cabinet","IHS", AI7="Sharing","Partners", AI7="Sites strategiques & DataCenter","SST & DC", AI7="Exclu","Exclu", AI7="SAT","SAT", AI7="SPARE-ISSUE","SPARE-ISSUE", AI7="Fiber CAmtel","TRANS_FO_CAMTEL", AI7="Fiber AOF","Fiber AOF", AI7="Projet OCM (HUAWEI)","TRAVAUX-HUAWEI", AI7="Projet OCM (NOKIA)","TRAVAUX-NOKIA", AI7="ACCESS-ISSUE","ACCESS-ISSUE", AI7="Projet OCM (ZTE, NOKIA, autres projets)","TRAVAUX OCM", AI7="No root CAuse","No root cause", AI7="ODU HS","PDH", AI7="IP & VLAN","PDH", AI7="Warehouse HUAWEI","SPARE-ISSUE", AI7="SPARE-HS","SPARE-ISSUE", AI7="Power Telco","BSS",AI7="no impacts","no impacts" ),"")} -> BSS | AH7: {=IFERROR(_xlfn.IFS( AI7="MPR ISSUE","TX ISSUE", AI7="BSS Hardware Issue","RAN ISSUE", AI7="Sites strategiques, MLL, Pylone, etc.","ENVTECH", AI7="AKTIVCO DEFAUT GE & POWER Cabinet","POWER ISSUE", AI7="AKTIVCO Coupure ENEO & Baisse de tension","POWER ISSUE", AI7="Coupure ENEO & Baisse de tension","POWER ISSUE", AI7="Defaut GE & POWER Cabinet","POWER ISSUE", AI7="Sharing","POWER ISSUE", AI7="Sites strategiques & DataCenter","POWER ISSUE", AI7="Exclu","Exclu", AI7="SAT","TX ISSUE", AI7="SPARE-ISSUE","SPARE-ISSUE", AI7="Fiber CAmtel","TX ISSUE", AI7="Fiber AOF","TX ISSUE", AI7="Projet OCM (HUAWEI)","TRAVAUX-HUAWEI", AI7="Projet OCM (NOKIA)","TRAVAUX -NOKIA", AI7="ACCESS-ISSUE","ACCESS-ISSUE", AI7="Projet OCM (ZTE, NOKIA, autres projets)","TRAVAUX OCM", AI7="No root CAuse","No root cause", AI7="ODU HS","TX ISSUE", AI7="IP & VLAN","TX ISSUE", AI7="Warehouse HUAWEI","SPARE-ISSUE", AI7="SPARE-HS","SPARE-ISSUE", AI7="Power Telco","RAN ISSUE",AI7="no impacts","no impacts" ),"")} -> RAN ISSUE | AI7: BSS Hardware issue | AJ7: {=IFERROR(_xlfn.IFS( AI7="MPR ISSUE","ACTIVE", AI7="BSS Hardware Issue","ACTIVE", AI7="Sites strategiques, MLL, Pylone, etc.","PASSIVE", AI7="AKTIVCO DEFAUT GE & POWER Cabinet","PASSIVE", AI7="AKTIVCO Coupure ENEO & Baisse de tension","PASSIVE", AI7="Coupure ENEO & Baisse de tension","PASSIVE", AI7="Defaut GE & POWER Cabinet","PASSIVE", AI7="Sharing","PASSIVE", AI7="Sites strategiques & DataCenter","PASSIVE", AI7="Exclu","Exclu", AI7="SAT","ACTIVE", AI7="SPARE-ISSUE","SPARE-ISSUE", AI7="Fiber CAmtel","ACTIVE", AI7="Fiber AOF","ACTIVE", AI7="Projet OCM (HUAWEI)","PLANNED WORKS", AI7="Projet OCM (NOKIA)","PLANNED WORKS", AI7="ACCESS-ISSUE","ACCESS-ISSUE", AI7="Projet OCM (ZTE, NOKIA, autres projets)","PLANNED WORKS", AI7="No root CAuse","No root cause", AI7="ODU HS","ACTIVE", AI7="IP & VLAN","ACTIVE", AI7="Warehouse HUAWEI","SPARE-ISSUE", AI7="SPARE-HS","SPARE-ISSUE", AI7="Power Telco","ACTIVE", AI7="no impacts","no impacts" ),"")} -> ACTIVE | AK7: (05/03/2026 ticket)..INC-20260503-00010751...Others Transmission equipement fault || (05/04/2026 BOTX): Probable probleme de connectique | AL7: =B7 -> CTR_667 | AN7: (05/04/2026 BOTX): Probable probleme de connectique | AO7: =_xlfn.XLOOKUP(B7,'INCIDENT-05-03-2026'!E:E,'INCIDENT-05-03-2026'!F:F,"") | AP7: (05/03/2026 top offenders): | AS7: =_xlfn.XLOOKUP(B7,'[3]tt num | region | site id'!$C:$C,'[3]tt num | region | site id'!$Q:$Q,"") | AT7: =_xlfn.XLOOKUP(B7,'[4]Cells Huawei 03052026 12h'!$B:$B,'[4]Cells Huawei 03052026 12h'!$T:$T,"") | AU7: =_xlfn.XLOOKUP(B7,'[5]cells down 02052026 8h50'!$B:$B,'[5]cells down 02052026 8h50'!$R:$R,"") | AV7: =_xlfn.XLOOKUP(B7,'[5]cells down 02052026 13h50'!$B:$B,'[5]cells down 02052026 13h50'!$R:$R,"") | AW7: =_xlfn.XLOOKUP(B7,'[5]cells down 02052026 13h50'!$B:$B,'[5]cells down 02052026 13h50'!$R:$R,"") | AX7: =_xlfn.XLOOKUP(B7,'[6]cell downs 03052026 8h40 '!$B:$B,'[6]cell downs 03052026 8h40 '!$R:$R,"") | AY7: =_xlfn.XLOOKUP(B7,'[7]ALL SITES DOWN'!$D:$D,'[7]ALL SITES DOWN'!$J:$J,"") | AZ7: =_xlfn.XLOOKUP(B7,'[8]ALL SITES DOWN'!$D:$D,'[8]ALL SITES DOWN'!$J:$J,"") | BA7: =_xlfn.XLOOKUP(B7,[9]sheet1!$AC:$AC,[9]sheet1!$AF:$AF,"") -> (05/03/2026 ticket)..INC-20260503-00010751...Others Transmission equipement fault | BB7: (05/03/2026 dashbord): | BD7: =_xlfn.XLOOKUP(B7,'[10]cell downs 18042026 17h'!$B:$B,'[10]cell downs 18042026 17h'!$B:$B,"") | BE7: =_xlfn.XLOOKUP(B7,'[11]Cells Huawei 19042026 15h'!$B:$B,'[11]Cells Huawei 19042026 15h'!$B:$B,"") | BF7: =_xlfn.XLOOKUP(B7,'[12]cells down 19042026 9H40'!$B:$B,'[12]cells down 19042026 9H40'!$B:$B,"") | BH7: Grid-Gen
A8: Fin-goudron-Mbangue | B8: LIT_844 | C8: =_xlfn.XLOOKUP(B8,'[1]daily break down'!$D:$D,'[1]daily break down'!$E:$E,"") -> Douala | D8: CAMUSAT | E8: Bad-Grid-GE | F8: LITTORAL | G8: Douala | H8: =_xlfn.XLOOKUP(B8,[2]CALCULATION!$B:$B,[2]CALCULATION!$H:$H,"") -> ZTE | I8: 0 | J8: 0 | K8: 0 | L8: 0 | M8: 0 | N8: 0 | O8: 0.2306254 | P8: 3.535947 | Q8: 0.11619554 | R8: 29.782441 | S8: 0 | T8: 4.4848623 | U8: 0 | V8: 0 | W8: 4.4848623 | X8: 7.3005396 | Y8: 3.0113816 | Z8: 1.4239883 | AA8: 16.795459 | AB8: 14.292117 | AC8: 56.087371 | AD8: 36.44534 | AE8: Operationnel | AG8: {=IFERROR(_xlfn.IFS( AI8="MPR ISSUE","PDH", AI8="BSS Hardware Issue","BSS", AI8="Sites strategiques, MLL, Pylone, etc.","ENVTECH", AI8="AKTIVCO DEFAUT GE & POWER Cabinet","AKTIVCO", AI8="AKTIVCO Coupure ENEO & Baisse de tension","AKTIVCO GRID ONLY", AI8="Coupure ENEO & Baisse de tension","IHS GRID ONLY", AI8="Defaut GE & POWER Cabinet","IHS", AI8="Sharing","Partners", AI8="Sites strategiques & DataCenter","SST & DC", AI8="Exclu","Exclu", AI8="SAT","SAT", AI8="SPARE-ISSUE","SPARE-ISSUE", AI8="Fiber CAmtel","TRANS_FO_CAMTEL", AI8="Fiber AOF","Fiber AOF", AI8="Projet OCM (HUAWEI)","TRAVAUX-HUAWEI", AI8="Projet OCM (NOKIA)","TRAVAUX-NOKIA", AI8="ACCESS-ISSUE","ACCESS-ISSUE", AI8="Projet OCM (ZTE, NOKIA, autres projets)","TRAVAUX OCM", AI8="No root CAuse","No root cause", AI8="ODU HS","PDH", AI8="IP & VLAN","PDH", AI8="Warehouse HUAWEI","SPARE-ISSUE", AI8="SPARE-HS","SPARE-ISSUE", AI8="Power Telco","BSS",AI8="no impacts","no impacts" ),"")} -> AKTIVCO GRID ONLY | AH8: {=IFERROR(_xlfn.IFS( AI8="MPR ISSUE","TX ISSUE", AI8="BSS Hardware Issue","RAN ISSUE", AI8="Sites strategiques, MLL, Pylone, etc.","ENVTECH", AI8="AKTIVCO DEFAUT GE & POWER Cabinet","POWER ISSUE", AI8="AKTIVCO Coupure ENEO & Baisse de tension","POWER ISSUE", AI8="Coupure ENEO & Baisse de tension","POWER ISSUE", AI8="Defaut GE & POWER Cabinet","POWER ISSUE", AI8="Sharing","POWER ISSUE", AI8="Sites strategiques & DataCenter","POWER ISSUE", AI8="Exclu","Exclu", AI8="SAT","TX ISSUE", AI8="SPARE-ISSUE","SPARE-ISSUE", AI8="Fiber CAmtel","TX ISSUE", AI8="Fiber AOF","TX ISSUE", AI8="Projet OCM (HUAWEI)","TRAVAUX-HUAWEI", AI8="Projet OCM (NOKIA)","TRAVAUX -NOKIA", AI8="ACCESS-ISSUE","ACCESS-ISSUE", AI8="Projet OCM (ZTE, NOKIA, autres projets)","TRAVAUX OCM", AI8="No root CAuse","No root cause", AI8="ODU HS","TX ISSUE", AI8="IP & VLAN","TX ISSUE", AI8="Warehouse HUAWEI","SPARE-ISSUE", AI8="SPARE-HS","SPARE-ISSUE", AI8="Power Telco","RAN ISSUE",AI8="no impacts","no impacts" ),"")} -> POWER ISSUE | AI8: AKTIVCO Coupure ENEO & Baisse de tension | AJ8: {=IFERROR(_xlfn.IFS( AI8="MPR ISSUE","ACTIVE", AI8="BSS Hardware Issue","ACTIVE", AI8="Sites strategiques, MLL, Pylone, etc.","PASSIVE", AI8="AKTIVCO DEFAUT GE & POWER Cabinet","PASSIVE", AI8="AKTIVCO Coupure ENEO & Baisse de tension","PASSIVE", AI8="Coupure ENEO & Baisse de tension","PASSIVE", AI8="Defaut GE & POWER Cabinet","PASSIVE", AI8="Sharing","PASSIVE", AI8="Sites strategiques & DataCenter","PASSIVE", AI8="Exclu","Exclu", AI8="SAT","ACTIVE", AI8="SPARE-ISSUE","SPARE-ISSUE", AI8="Fiber CAmtel","ACTIVE", AI8="Fiber AOF","ACTIVE", AI8="Projet OCM (HUAWEI)","PLANNED WORKS", AI8="Projet OCM (NOKIA)","PLANNED WORKS", AI8="ACCESS-ISSUE","ACCESS-ISSUE", AI8="Projet OCM (ZTE, NOKIA, autres projets)","PLANNED WORKS", AI8="No root CAuse","No root cause", AI8="ODU HS","ACTIVE", AI8="IP & VLAN","ACTIVE", AI8="Warehouse HUAWEI","SPARE-ISSUE", AI8="SPARE-HS","SPARE-ISSUE", AI8="Power Telco","ACTIVE", AI8="no impacts","no impacts" ),"")} -> PASSIVE | AK8: (05/03/2026 com ran 17h): Impacted by LIT_713_Z_Kotto-Baden-Baden(LIT-713) || (035/03/2026 groupe whatssapp ): INC-20260503-00006521 LIT_713_Z_Kotto-Baden-Baden(LIT-713) ,Delestage prolongé dans la zone retour de notre FME | AL8: =IFERROR(MID(AM8, SEARCH("CTR_", AM8), 7), IFERROR(MID(AM8, SEARCH("SUO_", AM8), 7), IFERROR(MID(AM8, SEARCH("SUD_", AM8), 7), IFERROR(MID(AM8, SEARCH("NRO_", AM8), 7), IFERROR(MID(AM8, SEARCH("ADM_", AM8), 7), IFERROR(MID(AM8, SEARCH("NRD_", AM8), 7), IFERROR(MID(AM8, SEARCH("EXN_", AM8), 7), IFERROR(MID(AM8, SEARCH("LIT_", AM8), 7), IFERROR(MID(AM8, SEARCH("EST_", AM8), 7), MID(AM8, SEARCH("OST_",AM8), 7)))))))))) -> LIT_713 | AM8: Impacted by LIT_713_Z_Kotto-Baden-Baden(LIT-713) | AO8: =_xlfn.XLOOKUP(B8,'INCIDENT-05-03-2026'!E:E,'INCIDENT-05-03-2026'!F:F,"") | AP8: (05/03/2026 top offenders): Impacted by LIT_713_Z_Kotto-Baden-Baden(LIT-713) | AS8: =_xlfn.XLOOKUP(B8,'[3]tt num | region | site id'!$C:$C,'[3]tt num | region | site id'!$Q:$Q,"") | AT8: =_xlfn.XLOOKUP(B8,'[4]Cells Huawei 03052026 12h'!$B:$B,'[4]Cells Huawei 03052026 12h'!$T:$T,"") | AU8: =_xlfn.XLOOKUP(B8,'[5]cells down 02052026 8h50'!$B:$B,'[5]cells down 02052026 8h50'!$R:$R,"") | AV8: =_xlfn.XLOOKUP(B8,'[5]cells down 02052026 13h50'!$B:$B,'[5]cells down 02052026 13h50'!$R:$R,"") | AW8: =_xlfn.XLOOKUP(B8,'[5]cells down 02052026 13h50'!$B:$B,'[5]cells down 02052026 13h50'!$R:$R,"") | AX8: =_xlfn.XLOOKUP(B8,'[6]cell downs 03052026 8h40 '!$B:$B,'[6]cell downs 03052026 8h40 '!$R:$R,"") | AY8: =_xlfn.XLOOKUP(B8,'[7]ALL SITES DOWN'!$D:$D,'[7]ALL SITES DOWN'!$J:$J,"") -> (05/03/2026 com ran 17h): Impacted by LIT_713_Z_Kotto-Baden-Baden(LIT-713) | AZ8: =_xlfn.XLOOKUP(B8,'[8]ALL SITES DOWN'!$D:$D,'[8]ALL SITES DOWN'!$J:$J,"") | BA8: =_xlfn.XLOOKUP(B8,[9]sheet1!$AC:$AC,[9]sheet1!$AF:$AF,"") | BB8: (05/03/2026 dashbord): | BD8: =_xlfn.XLOOKUP(B8,'[10]cell downs 18042026 17h'!$B:$B,'[10]cell downs 18042026 17h'!$B:$B,"") | BE8: =_xlfn.XLOOKUP(B8,'[11]Cells Huawei 19042026 15h'!$B:$B,'[11]Cells Huawei 19042026 15h'!$B:$B,"") | BF8: =_xlfn.XLOOKUP(B8,'[12]cells down 19042026 9H40'!$B:$B,'[12]cells down 19042026 9H40'!$B:$B,"")
A9: NR-Omnisport-Qtier-Yambassa | B9: CTR_566 | C9: =_xlfn.XLOOKUP(B9,'[1]daily break down'!$D:$D,'[1]daily break down'!$E:$E,"") -> Yaounde | D9: CAMUSAT | E9: Good Grid no GE - 8h | F9: CENTRE | G9: Yaounde | H9: =_xlfn.XLOOKUP(B9,[2]CALCULATION!$B:$B,[2]CALCULATION!$H:$H,"") -> ZTE | I9: 3.4843679 | J9: 9.1953205 | K9: 9.1744535 | L9: 9.2277625 | M9: 13.025207 | N9: 24.078158 | O9: 0 | P9: 2.9564853 | Q9: 2.8731241 | R9: 3.2196775 | S9: 0.76334135 | T9: 2.9626919 | U9: 16.532975 | V9: 17.700887 | W9: 2.9626919 | X9: 6.7759743 | Y9: 4.5641036 | Z9: 22.417338 | AA9: 17.123934 | AB9: 14.81796 | AC9: 54.324036 | AD9: 35.74922 | AE9: Operationnel | AG9: {=IFERROR(_xlfn.IFS( AI9="MPR ISSUE","PDH", AI9="BSS Hardware Issue","BSS", AI9="Sites strategiques, MLL, Pylone, etc.","ENVTECH", AI9="AKTIVCO DEFAUT GE & POWER Cabinet","AKTIVCO", AI9="AKTIVCO Coupure ENEO & Baisse de tension","AKTIVCO GRID ONLY", AI9="Coupure ENEO & Baisse de tension","IHS GRID ONLY", AI9="Defaut GE & POWER Cabinet","IHS", AI9="Sharing","Partners", AI9="Sites strategiques & DataCenter","SST & DC", AI9="Exclu","Exclu", AI9="SAT","SAT", AI9="SPARE-ISSUE","SPARE-ISSUE", AI9="Fiber CAmtel","TRANS_FO_CAMTEL", AI9="Fiber AOF","Fiber AOF", AI9="Projet OCM (HUAWEI)","TRAVAUX-HUAWEI", AI9="Projet OCM (NOKIA)","TRAVAUX-NOKIA", AI9="ACCESS-ISSUE","ACCESS-ISSUE", AI9="Projet OCM (ZTE, NOKIA, autres projets)","TRAVAUX OCM", AI9="No root CAuse","No root cause", AI9="ODU HS","PDH", AI9="IP & VLAN","PDH", AI9="Warehouse HUAWEI","SPARE-ISSUE", AI9="SPARE-HS","SPARE-ISSUE", AI9="Power Telco","BSS",AI9="no impacts","no impacts" ),"")} -> AKTIVCO GRID ONLY | AH9: {=IFERROR(_xlfn.IFS( AI9="MPR ISSUE","TX ISSUE", AI9="BSS Hardware Issue","RAN ISSUE", AI9="Sites strategiques, MLL, Pylone, etc.","ENVTECH", AI9="AKTIVCO DEFAUT GE & POWER Cabinet","POWER ISSUE", AI9="AKTIVCO Coupure ENEO & Baisse de tension","POWER ISSUE", AI9="Coupure ENEO & Baisse de tension","POWER ISSUE", AI9="Defaut GE & POWER Cabinet","POWER ISSUE", AI9="Sharing","POWER ISSUE", AI9="Sites strategiques & DataCenter","POWER ISSUE", AI9="Exclu","Exclu", AI9="SAT","TX ISSUE", AI9="SPARE-ISSUE","SPARE-ISSUE", AI9="Fiber CAmtel","TX ISSUE", AI9="Fiber AOF","TX ISSUE", AI9="Projet OCM (HUAWEI)","TRAVAUX-HUAWEI", AI9="Projet OCM (NOKIA)","TRAVAUX -NOKIA", AI9="ACCESS-ISSUE","ACCESS-ISSUE", AI9="Projet OCM (ZTE, NOKIA, autres projets)","TRAVAUX OCM", AI9="No root CAuse","No root cause", AI9="ODU HS","TX ISSUE", AI9="IP & VLAN","TX ISSUE", AI9="Warehouse HUAWEI","SPARE-ISSUE", AI9="SPARE-HS","SPARE-ISSUE", AI9="Power Telco","RAN ISSUE",AI9="no impacts","no impacts" ),"")} -> POWER ISSUE | AI9: AKTIVCO Coupure ENEO & Baisse de tension | AJ9: {=IFERROR(_xlfn.IFS( AI9="MPR ISSUE","ACTIVE", AI9="BSS Hardware Issue","ACTIVE", AI9="Sites strategiques, MLL, Pylone, etc.","PASSIVE", AI9="AKTIVCO DEFAUT GE & POWER Cabinet","PASSIVE", AI9="AKTIVCO Coupure ENEO & Baisse de tension","PASSIVE", AI9="Coupure ENEO & Baisse de tension","PASSIVE", AI9="Defaut GE & POWER Cabinet","PASSIVE", AI9="Sharing","PASSIVE", AI9="Sites strategiques & DataCenter","PASSIVE", AI9="Exclu","Exclu", AI9="SAT","ACTIVE", AI9="SPARE-ISSUE","SPARE-ISSUE", AI9="Fiber CAmtel","ACTIVE", AI9="Fiber AOF","ACTIVE", AI9="Projet OCM (HUAWEI)","PLANNED WORKS", AI9="Projet OCM (NOKIA)","PLANNED WORKS", AI9="ACCESS-ISSUE","ACCESS-ISSUE", AI9="Projet OCM (ZTE, NOKIA, autres projets)","PLANNED WORKS", AI9="No root CAuse","No root cause", AI9="ODU HS","ACTIVE", AI9="IP & VLAN","ACTIVE", AI9="Warehouse HUAWEI","SPARE-ISSUE", AI9="SPARE-HS","SPARE-ISSUE", AI9="Power Telco","ACTIVE", AI9="no impacts","no impacts" ),"")} -> PASSIVE | AK9: (05/03/2026 com ran 17h): 03.05.2026 CAMUSAT: Grid outage and Grid only site / Grid return awaited..;..;(05/03/2026 ticket)..INC-20260503-00003219...2026-05-03 10:01:18... 01.05.2026: FSMF réçu faulty, 02 nouvelles pièces de rechange envoyées ETD 03/05/2026...user:TCHOUPOU BAUDOIN VALDAS | AL9: =B9 -> CTR_566 | AO9: =_xlfn.XLOOKUP(B9,'INCIDENT-05-03-2026'!E:E,'INCIDENT-05-03-2026'!F:F,"") | AP9: (05/03/2026 top offenders): | AS9: =_xlfn.XLOOKUP(B9,'[3]tt num | region | site id'!$C:$C,'[3]tt num | region | site id'!$Q:$Q,"") | AT9: =_xlfn.XLOOKUP(B9,'[4]Cells Huawei 03052026 12h'!$B:$B,'[4]Cells Huawei 03052026 12h'!$T:$T,"") | AU9: =_xlfn.XLOOKUP(B9,'[5]cells down 02052026 8h50'!$B:$B,'[5]cells down 02052026 8h50'!$R:$R,"") | AV9: =_xlfn.XLOOKUP(B9,'[5]cells down 02052026 13h50'!$B:$B,'[5]cells down 02052026 13h50'!$R:$R,"") | AW9: =_xlfn.XLOOKUP(B9,'[5]cells down 02052026 13h50'!$B:$B,'[5]cells down 02052026 13h50'!$R:$R,"") | AX9: =_xlfn.XLOOKUP(B9,'[6]cell downs 03052026 8h40 '!$B:$B,'[6]cell downs 03052026 8h40 '!$R:$R,"") | AY9: =_xlfn.XLOOKUP(B9,'[7]ALL SITES DOWN'!$D:$D,'[7]ALL SITES DOWN'!$J:$J,"") -> (05/03/2026 com ran 17h): 03.05.2026 CAMUSAT: Grid outage and Grid only site / Grid return awaited | AZ9: =_xlfn.XLOOKUP(B9,'[8]ALL SITES DOWN'!$D:$D,'[8]ALL SITES DOWN'!$J:$J,"") | BA9: =_xlfn.XLOOKUP(B9,[9]sheet1!$AC:$AC,[9]sheet1!$AF:$AF,"") -> (05/03/2026 ticket)..INC-20260503-00003219...2026-05-03 10:01:18... 01.05.2026: FSMF réçu faulty, 02 nouvelles pièces de rechange envoyées ETD 03/05/2026...user:TCHOUPOU BAUDOIN VALDAS | BB9: (05/03/2026 dashbord): | BD9: =_xlfn.XLOOKUP(B9,'[10]cell downs 18042026 17h'!$B:$B,'[10]cell downs 18042026 17h'!$B:$B,"") | BE9: =_xlfn.XLOOKUP(B9,'[11]Cells Huawei 19042026 15h'!$B:$B,'[11]Cells Huawei 19042026 15h'!$B:$B,"") | BF9: =_xlfn.XLOOKUP(B9,'[12]cells down 19042026 9H40'!$B:$B,'[12]cells down 19042026 9H40'!$B:$B,"")
A10: Ekoumdoum-Chatel | B10: CTR_762 | C10: =_xlfn.XLOOKUP(B10,'[1]daily break down'!$D:$D,'[1]daily break down'!$E:$E,"") -> Yaounde | D10: CAMUSAT | E10: Good Grid + GE | F10: CENTRE | G10: Yaounde | H10: =_xlfn.XLOOKUP(B10,[2]CALCULATION!$B:$B,[2]CALCULATION!$H:$H,"") -> ZTE | I10: 0 | J10: 0.67981968 | K10: 1.4655262 | L10: 1.4481727 | M10: 0.98413962 | N10: 3.1526711 | O10: 0 | P10: 1.5383112 | Q10: 2.3112478 | R10: 0 | S10: 1.2546621 | T10: 3.4888445 | U10: 2.4707469 | V10: 0 | W10: 3.4888445 | X10: 3.3742185 | Y10: 0.0036918612 | Z10: 41.605671 | AA10: 20.90852 | AB10: 20.24937 | AC10: 48.552218 | AD10: 35.103108 | AE10: Operationnel | AG10: {=IFERROR(_xlfn.IFS( AI10="MPR ISSUE","PDH", AI10="BSS Hardware Issue","BSS", AI10="Sites strategiques, MLL, Pylone, etc.","ENVTECH", AI10="AKTIVCO DEFAUT GE & POWER Cabinet","AKTIVCO", AI10="AKTIVCO Coupure ENEO & Baisse de tension","AKTIVCO GRID ONLY", AI10="Coupure ENEO & Baisse de tension","IHS GRID ONLY", AI10="Defaut GE & POWER Cabinet","IHS", AI10="Sharing","Partners", AI10="Sites strategiques & DataCenter","SST & DC", AI10="Exclu","Exclu", AI10="SAT","SAT", AI10="SPARE-ISSUE","SPARE-ISSUE", AI10="Fiber CAmtel","TRANS_FO_CAMTEL", AI10="Fiber AOF","Fiber AOF", AI10="Projet OCM (HUAWEI)","TRAVAUX-HUAWEI", AI10="Projet OCM (NOKIA)","TRAVAUX-NOKIA", AI10="ACCESS-ISSUE","ACCESS-ISSUE", AI10="Projet OCM (ZTE, NOKIA, autres projets)","TRAVAUX OCM", AI10="No root CAuse","No root cause", AI10="ODU HS","PDH", AI10="IP & VLAN","PDH", AI10="Warehouse HUAWEI","SPARE-ISSUE", AI10="SPARE-HS","SPARE-ISSUE", AI10="Power Telco","BSS",AI10="no impacts","no impacts" ),"")} -> Exclu | AH10: {=IFERROR(_xlfn.IFS( AI10="MPR ISSUE","TX ISSUE", AI10="BSS Hardware Issue","RAN ISSUE", AI10="Sites strategiques, MLL, Pylone, etc.","ENVTECH", AI10="AKTIVCO DEFAUT GE & POWER Cabinet","POWER ISSUE", AI10="AKTIVCO Coupure ENEO & Baisse de tension","POWER ISSUE", AI10="Coupure ENEO & Baisse de tension","POWER ISSUE", AI10="Defaut GE & POWER Cabinet","POWER ISSUE", AI10="Sharing","POWER ISSUE", AI10="Sites strategiques & DataCenter","POWER ISSUE", AI10="Exclu","Exclu", AI10="SAT","TX ISSUE", AI10="SPARE-ISSUE","SPARE-ISSUE", AI10="Fiber CAmtel","TX ISSUE", AI10="Fiber AOF","TX ISSUE", AI10="Projet OCM (HUAWEI)","TRAVAUX-HUAWEI", AI10="Projet OCM (NOKIA)","TRAVAUX -NOKIA", AI10="ACCESS-ISSUE","ACCESS-ISSUE", AI10="Projet OCM (ZTE, NOKIA, autres projets)","TRAVAUX OCM", AI10="No root CAuse","No root cause", AI10="ODU HS","TX ISSUE", AI10="IP & VLAN","TX ISSUE", AI10="Warehouse HUAWEI","SPARE-ISSUE", AI10="SPARE-HS","SPARE-ISSUE", AI10="Power Telco","RAN ISSUE",AI10="no impacts","no impacts" ),"")} -> Exclu | AI10: EXCLU | AJ10: {=IFERROR(_xlfn.IFS( AI10="MPR ISSUE","ACTIVE", AI10="BSS Hardware Issue","ACTIVE", AI10="Sites strategiques, MLL, Pylone, etc.","PASSIVE", AI10="AKTIVCO DEFAUT GE & POWER Cabinet","PASSIVE", AI10="AKTIVCO Coupure ENEO & Baisse de tension","PASSIVE", AI10="Coupure ENEO & Baisse de tension","PASSIVE", AI10="Defaut GE & POWER Cabinet","PASSIVE", AI10="Sharing","PASSIVE", AI10="Sites strategiques & DataCenter","PASSIVE", AI10="Exclu","Exclu", AI10="SAT","ACTIVE", AI10="SPARE-ISSUE","SPARE-ISSUE", AI10="Fiber CAmtel","ACTIVE", AI10="Fiber AOF","ACTIVE", AI10="Projet OCM (HUAWEI)","PLANNED WORKS", AI10="Projet OCM (NOKIA)","PLANNED WORKS", AI10="ACCESS-ISSUE","ACCESS-ISSUE", AI10="Projet OCM (ZTE, NOKIA, autres projets)","PLANNED WORKS", AI10="No root CAuse","No root cause", AI10="ODU HS","ACTIVE", AI10="IP & VLAN","ACTIVE", AI10="Warehouse HUAWEI","SPARE-ISSUE", AI10="SPARE-HS","SPARE-ISSUE", AI10="Power Telco","ACTIVE", AI10="no impacts","no impacts" ),"")} -> Exclu | AK10: (05/03/2026 com ran 10h): 02.05.2026: Site Vandaliser. Inventaire cote Active et Passive en cours. Update ASAP 02/05/2026 CAMUSAT: site vandilisé le regional de spider est dans le site pour investigation.note que la tension du site actuel est 53 V load 18 A ,Fme sera sur demain pour plus d'information | AL10: =B10 -> CTR_762 | AO10: =_xlfn.XLOOKUP(B10,'INCIDENT-05-03-2026'!E:E,'INCIDENT-05-03-2026'!F:F,"") | AP10: (05/03/2026 top offenders): | AS10: =_xlfn.XLOOKUP(B10,'[3]tt num | region | site id'!$C:$C,'[3]tt num | region | site id'!$Q:$Q,"") | AT10: =_xlfn.XLOOKUP(B10,'[4]Cells Huawei 03052026 12h'!$B:$B,'[4]Cells Huawei 03052026 12h'!$T:$T,"") | AU10: =_xlfn.XLOOKUP(B10,'[5]cells down 02052026 8h50'!$B:$B,'[5]cells down 02052026 8h50'!$R:$R,"") | AV10: =_xlfn.XLOOKUP(B10,'[5]cells down 02052026 13h50'!$B:$B,'[5]cells down 02052026 13h50'!$R:$R,"") | AW10: =_xlfn.XLOOKUP(B10,'[5]cells down 02052026 13h50'!$B:$B,'[5]cells down 02052026 13h50'!$R:$R,"") | AX10: =_xlfn.XLOOKUP(B10,'[6]cell downs 03052026 8h40 '!$B:$B,'[6]cell downs 03052026 8h40 '!$R:$R,"") | AY10: =_xlfn.XLOOKUP(B10,'[7]ALL SITES DOWN'!$D:$D,'[7]ALL SITES DOWN'!$J:$J,"") | AZ10: =_xlfn.XLOOKUP(B10,'[8]ALL SITES DOWN'!$D:$D,'[8]ALL SITES DOWN'!$J:$J,"") -> (05/03/2026 com ran 10h): 02.05.2026: Site Vandaliser. Inventaire cote Active et Passive en cours. Update ASAP 02/05/2026 CAMUSAT: site vandilisé le regional de spider est dans le site pour investigation.note que la tension du site actuel est 53 V load 18 A ,Fme sera sur demain pour plus d'information | BA10: =_xlfn.XLOOKUP(B10,[9]sheet1!$AC:$AC,[9]sheet1!$AF:$AF,"") | BB10: (05/03/2026 dashbord): | BD10: =_xlfn.XLOOKUP(B10,'[10]cell downs 18042026 17h'!$B:$B,'[10]cell downs 18042026 17h'!$B:$B,"") | BE10: =_xlfn.XLOOKUP(B10,'[11]Cells Huawei 19042026 15h'!$B:$B,'[11]Cells Huawei 19042026 15h'!$B:$B,"") | BF10: =_xlfn.XLOOKUP(B10,'[12]cells down 19042026 9H40'!$B:$B,'[12]cells down 19042026 9H40'!$B:$B,"")
A11: Nkolfoulou-I | B11: CTR_671 | C11: =_xlfn.XLOOKUP(B11,'[1]daily break down'!$D:$D,'[1]daily break down'!$E:$E,"") -> Yaounde | D11: CAMUSAT | E11: Good Grid + GE | F11: CENTRE | G11: Yaounde | H11: =_xlfn.XLOOKUP(B11,[2]CALCULATION!$B:$B,[2]CALCULATION!$H:$H,"") -> ZTE | I11: 0.20198226 | J11: 3.5356438 | K11: 0.21411012 | L11: 0 | M11: 0 | N11: 0 | O11: 0 | P11: 0 | Q11: 0 | R11: 0 | S11: 1.4464249 | T11: 0 | U11: 3.9678947 | V11: 0 | W11: 0 | X11: 0 | Y11: 1.2382003 | Z11: 0 | AA11: 0 | AB11: 0 | AC11: 66.292132 | AD11: 34.570588 | AE11: Operationnel | AG11: {=IFERROR(_xlfn.IFS( AI11="MPR ISSUE","PDH", AI11="BSS Hardware Issue","BSS", AI11="Sites strategiques, MLL, Pylone, etc.","ENVTECH", AI11="AKTIVCO DEFAUT GE & POWER Cabinet","AKTIVCO", AI11="AKTIVCO Coupure ENEO & Baisse de tension","AKTIVCO GRID ONLY", AI11="Coupure ENEO & Baisse de tension","IHS GRID ONLY", AI11="Defaut GE & POWER Cabinet","IHS", AI11="Sharing","Partners", AI11="Sites strategiques & DataCenter","SST & DC", AI11="Exclu","Exclu", AI11="SAT","SAT", AI11="SPARE-ISSUE","SPARE-ISSUE", AI11="Fiber CAmtel","TRANS_FO_CAMTEL", AI11="Fiber AOF","Fiber AOF", AI11="Projet OCM (HUAWEI)","TRAVAUX-HUAWEI", AI11="Projet OCM (NOKIA)","TRAVAUX-NOKIA", AI11="ACCESS-ISSUE","ACCESS-ISSUE", AI11="Projet OCM (ZTE, NOKIA, autres projets)","TRAVAUX OCM", AI11="No root CAuse","No root cause", AI11="ODU HS","PDH", AI11="IP & VLAN","PDH", AI11="Warehouse HUAWEI","SPARE-ISSUE", AI11="SPARE-HS","SPARE-ISSUE", AI11="Power Telco","BSS",AI11="no impacts","no impacts" ),"")} -> AKTIVCO | AH11: {=IFERROR(_xlfn.IFS( AI11="MPR ISSUE","TX ISSUE", AI11="BSS Hardware Issue","RAN ISSUE", AI11="Sites strategiques, MLL, Pylone, etc.","ENVTECH", AI11="AKTIVCO DEFAUT GE & POWER Cabinet","POWER ISSUE", AI11="AKTIVCO Coupure ENEO & Baisse de tension","POWER ISSUE", AI11="Coupure ENEO & Baisse de tension","POWER ISSUE", AI11="Defaut GE & POWER Cabinet","POWER ISSUE", AI11="Sharing","POWER ISSUE", AI11="Sites strategiques & DataCenter","POWER ISSUE", AI11="Exclu","Exclu", AI11="SAT","TX ISSUE", AI11="SPARE-ISSUE","SPARE-ISSUE", AI11="Fiber CAmtel","TX ISSUE", AI11="Fiber AOF","TX ISSUE", AI11="Projet OCM (HUAWEI)","TRAVAUX-HUAWEI", AI11="Projet OCM (NOKIA)","TRAVAUX -NOKIA", AI11="ACCESS-ISSUE","ACCESS-ISSUE", AI11="Projet OCM (ZTE, NOKIA, autres projets)","TRAVAUX OCM", AI11="No root CAuse","No root cause", AI11="ODU HS","TX ISSUE", AI11="IP & VLAN","TX ISSUE", AI11="Warehouse HUAWEI","SPARE-ISSUE", AI11="SPARE-HS","SPARE-ISSUE", AI11="Power Telco","RAN ISSUE",AI11="no impacts","no impacts" ),"")} -> POWER ISSUE | AI11: AKTIVCO Defaut GE & Power Cabinet | AJ11: {=IFERROR(_xlfn.IFS( AI11="MPR ISSUE","ACTIVE", AI11="BSS Hardware Issue","ACTIVE", AI11="Sites strategiques, MLL, Pylone, etc.","PASSIVE", AI11="AKTIVCO DEFAUT GE & POWER Cabinet","PASSIVE", AI11="AKTIVCO Coupure ENEO & Baisse de tension","PASSIVE", AI11="Coupure ENEO & Baisse de tension","PASSIVE", AI11="Defaut GE & POWER Cabinet","PASSIVE", AI11="Sharing","PASSIVE", AI11="Sites strategiques & DataCenter","PASSIVE", AI11="Exclu","Exclu", AI11="SAT","ACTIVE", AI11="SPARE-ISSUE","SPARE-ISSUE", AI11="Fiber CAmtel","ACTIVE", AI11="Fiber AOF","ACTIVE", AI11="Projet OCM (HUAWEI)","PLANNED WORKS", AI11="Projet OCM (NOKIA)","PLANNED WORKS", AI11="ACCESS-ISSUE","ACCESS-ISSUE", AI11="Projet OCM (ZTE, NOKIA, autres projets)","PLANNED WORKS", AI11="No root CAuse","No root cause", AI11="ODU HS","ACTIVE", AI11="IP & VLAN","ACTIVE", AI11="Warehouse HUAWEI","SPARE-ISSUE", AI11="SPARE-HS","SPARE-ISSUE", AI11="Power Telco","ACTIVE", AI11="no impacts","no impacts" ),"")} -> PASSIVE | AK11: (05/04/2026 BOTX): Impacted by power issue at fraternite adama(CTR_849) | AL11: CTR_849 | AM11: Impacted by power issue at fraternite adama(CTR_849) | AN11: (05/04/2026 BOTX): Impacted by power issue at fraternite adama | AO11: =_xlfn.XLOOKUP(B11,'INCIDENT-05-03-2026'!E:E,'INCIDENT-05-03-2026'!F:F,"") | AP11: (05/03/2026 top offenders): | AS11: =_xlfn.XLOOKUP(B11,'[3]tt num | region | site id'!$C:$C,'[3]tt num | region | site id'!$Q:$Q,"") | AT11: =_xlfn.XLOOKUP(B11,'[4]Cells Huawei 03052026 12h'!$B:$B,'[4]Cells Huawei 03052026 12h'!$T:$T,"") | AU11: =_xlfn.XLOOKUP(B11,'[5]cells down 02052026 8h50'!$B:$B,'[5]cells down 02052026 8h50'!$R:$R,"") | AV11: =_xlfn.XLOOKUP(B11,'[5]cells down 02052026 13h50'!$B:$B,'[5]cells down 02052026 13h50'!$R:$R,"") | AW11: =_xlfn.XLOOKUP(B11,'[5]cells down 02052026 13h50'!$B:$B,'[5]cells down 02052026 13h50'!$R:$R,"") | AX11: =_xlfn.XLOOKUP(B11,'[6]cell downs 03052026 8h40 '!$B:$B,'[6]cell downs 03052026 8h40 '!$R:$R,"") | AY11: =_xlfn.XLOOKUP(B11,'[7]ALL SITES DOWN'!$D:$D,'[7]ALL SITES DOWN'!$J:$J,"") | AZ11: =_xlfn.XLOOKUP(B11,'[8]ALL SITES DOWN'!$D:$D,'[8]ALL SITES DOWN'!$J:$J,"") | BA11: =_xlfn.XLOOKUP(B11,[9]sheet1!$AC:$AC,[9]sheet1!$AF:$AF,"") | BB11: (05/03/2026 dashbord): 04/05/2026 : Need BO RAN analysis | BD11: =_xlfn.XLOOKUP(B11,'[10]cell downs 18042026 17h'!$B:$B,'[10]cell downs 18042026 17h'!$B:$B,"") | BE11: =_xlfn.XLOOKUP(B11,'[11]Cells Huawei 19042026 15h'!$B:$B,'[11]Cells Huawei 19042026 15h'!$B:$B,"") | BF11: =_xlfn.XLOOKUP(B11,'[12]cells down 19042026 9H40'!$B:$B,'[12]cells down 19042026 9H40'!$B:$B,"")
